Workbook

Sheet 1.1 竞品拓词法 （至少48个）
A1: 竞品拓词导出_2023-08-25 ASIN:B0CBMDZ475,B0C63R7VCH,B0CCR13CHL,B0C3VLZX1D,B0C7K43LQ5,B0C7K45WHD,B0CFQJYVBJ,B0C2N9ZC5H,B0CFDKDLLR,B0C5CF1CN4,B0CDNY7PMG,B0CF53MV9R,B0C7K9WSW7,B0C7TR8TP6,B0C8N7YQ3J,B0785JVT1S,B0C2HL81DD,B0C6YKBY2P,B0C9WKTZ9T,B0C9M54CQH,B0CCRFR838,B0C8HKGKPD,B0BVWLNLZH,B0CBV4Y8VZ,B0C5JV54V2,B0BVWRCRTH,B0CDBP6Y3L,B07X22JL28,B0C527MY54,B0C7Q3HPM9,B0C5CDR9MB,B0C9QX8X4V,B0C5R2TCVD,B0C6JS5QMK,B0C68MT9CL,B0C9LTK1CN,B0CFQHXB6N,B0CBTXSDWJ,B0C6B6B83L,B0C8LV6BF8,B0CF5J98RS,B0CD9SRZGG,B0C9QZFJ1K,B0CCXVRWWP,B0C8B63H49,B0CCJ2L8G1,B0CCVR112B,B0C61TR1D1,B0C6YJBPQ3,B0C7JVKCQC,B0CCT2B6F8,B0CB86F58J
A2: # | B2: 关键词 | C2: 相关性-自动百分比 | D2: 相关性-自动 | E2: 自然位前4占位率 | F2: 自然位前8占位率 | G2: 自然位前16占位率 | H2: 自然位前32占位率 | I2: 自然位前48占位率 | J2: 搜索量 | K2: 排名 | L2: 相关性-手动
A3: 1 | B3: retractable garden hose 50 ft | C3: 0.7357 | D3: 高相关 | E3: 0.9063 | F3: 0.6563 | G3: 0.5313 | H3: 0.3984 | I3: 0.3646 | J3: 565 | K3: 573972
A4: 2 | B4: 50ft expandable garden hose | C4: 0.7018 | D4: 高相关 | E4: 0.8125 | F4: 0.6719 | G4: 0.5547 | H4: 0.4648 | I4: 0.3932 | J4: 732 | K4: 442190
A5: 3 | B5: flexible hose 50 ft expandable | C5: 0.6865 | D5: 高相关 | E5: 0.8438 | F5: 0.5938 | G5: 0.4922 | H5: 0.4414 | I5: 0.3828 | J5: 424 | K5: 765865
A6: 4 | B6: water hose expandable | C6: 0.6596 | D6: 高相关 | E6: 0.7188 | F6: 0.6875 | G6: 0.5469 | H6: 0.4844 | I6: 0.4141 | J6: 1338 | K6: 237792
A7: 5 | B7: best expandable hose | C7: 0.6516 | D7: 高相关 | E7: 0.75 | F7: 0.5938 | G7: 0.5469 | H7: 0.4766 | I7: 0.4245 | J7: 308 | K7: 1047275
A8: 6 | B8: water hose 50 ft expandable | C8: 0.6416 | D8: 高相关 | E8: 0.6875 | F8: 0.6719 | G8: 0.5547 | H8: 0.4922 | I8: 0.4089 | J8: 717 | K8: 451756
A9: 7 | B9: garden hose expandable | C9: 0.6316 | D9: 高相关 | E9: 0.7188 | F9: 0.6094 | G9: 0.5156 | H9: 0.4414 | I9: 0.388 | J9: 2565 | K9: 119481
A10: 8 | B10: expandable garden hose 50ft | C10: 0.6005 | D10: 高相关 | E10: 0.6563 | F10: 0.5625 | G10: 0.5781 | H10: 0.4688 | I10: 0.4063 | J10: 262 | K10: 1221793
A11: 9 | B11: expandable garden hose 50 ft | C11: 0.5856 | D11: 高相关 | E11: 0.6563 | F11: 0.5469 | G11: 0.5078 | H11: 0.4727 | I11: 0.3828 | J11: 12616 | K11: 19917
A12: 10 | B12: shrinkable garden hose | C12: 0.579 | D12: 高相关 | E12: 0.7813 | F12: 0.4844 | G12: 0.3125 | H12: 0.2148 | I12: 0.1797 | J12: 313 | K12: 1031124
A13: 11 | B13: expandable garden hose 50 ft+ | C13: 0.5675 | D13: 高相关 | E13: 0.5938 | F13: 0.6094 | G13: 0.5078 | H13: 0.4336 | I13: 0.3906 | J13: 1964 | K13: 158909
A14: 12 | B14: hose expandable | C14: 0.5598 | D14: 高相关 | E14: 0.5938 | F14: 0.5469 | G14: 0.5547 | H14: 0.4492 | I14: 0.3854 | J14: 1873 | K14: 166988
... A1814: 1812 | B1814: camper water hose | C1814: 0 | D1814: 不相关 | E1814: 0 | F1814: 0 | G1814: 0 | H1814: 0 | I1814: 0 | J1814: 1050 | K1814: 305556

Sheet 1.2 以词拓词（词根法）
A1: 以词拓词导出_2023-08-25 词根: hose
A2: # | B2: 关键词 | C2: 匹配模式 | D2: 搜索量 | E2: 排名 | F2: 相关性-手动
A3: 1 | B3: hose | C3: 精准匹配 | D3: 376633 | E3: 666
A4: 2 | B4: hoses | C4: 精准匹配 | D4: 24720 | E4: 45373
A5: 3 | B5: garden hose | C5: 词组匹配 | D5: 545566 | E5: 347
A6: 4 | B6: water hose | C6: 词组匹配 | D6: 213612 | E6: 1714
A7: 5 | B7: hose nozzle | C7: 词组匹配,下拉框匹配 | D7: 177929 | E7: 2303
A8: 6 | B8: hose reel | C8: 词组匹配,下拉框匹配 | D8: 155358 | E8: 2857
A9: 7 | B9: hose holder | C9: 词组匹配,下拉框匹配 | D9: 122462 | E9: 4161
A10: 8 | B10: expandable garden hose | C10: 词组匹配 | D10: 112845 | E10: 4741
A11: 9 | B11: garden hose 100 ft | C11: 词组匹配 | D11: 90937 | E11: 6685
A12: 10 | B12: soaker hose | C12: 词组匹配 | D12: 90312 | E12: 6761
A13: 11 | B13: garden hose holder | C13: 词组匹配 | D13: 89887 | E13: 6814
A14: 12 | B14: garden hose nozzle | C14: 词组匹配 | D14: 84370 | E14: 7558
... A2414: 2412 | B2414: fertilizer hose attachment | C2414: 词组匹配 | D2414: 1041 | E2414: 1199329

Sheet 1.3品类拓词法
A1: 品类拓词导出_2023-08-25 品类: Garden Hoses
A2: # | B2: 关键词 | C2: 搜索量 | D2: 排名 | E2: 相关性-手动
A3: 1 | B3: garden hose | C3: 545566 | D3: 347
A4: 2 | B4: hose | C4: 376633 | D4: 666
A5: 3 | B5: water hose | C5: 213612 | D5: 1714
A6: 4 | B6: garden hose 100 ft | C6: 90937 | D6: 6685
A7: 5 | B7: soaker hose | C7: 90312 | D7: 6761
A8: 6 | B8: water hose 100ft | C8: 82391 | D8: 7861
A9: 7 | B9: 100 ft garden hose | C9: 65650 | D9: 12796
A10: 8 | B10: flexzilla garden hose | C10: 63891 | D10: 13493
A11: 9 | B11: sprinkler hose | C11: 22958 | D11: 49352
A12: 10 | B12: flexzilla | C12: 22325 | D12: 50878
A13: 11 | B13: short garden hose | C13: 21708 | D13: 52578
A14: 12 | B14: flexzilla garden hose 100ft | C14: 17795 | D14: 65498
... A1131: 1129 | B1131: rv hoses | C1131: 1291 | D1131: 975667

Sheet 2. 竞品拓词结果表
A1: Garden hose 关键词库
A2: # | B2: 关键词 | C2: 相关性-自动百分比 | D2: 相关性-自动 | E2: 自然位前4占位率 | F2: 自然位前8占位率 | G2: 自然位前16占位率 | H2: 自然位前32占位率 | I2: 自然位前48占位率 | J2: 搜索量 | K2: 排名 | L2: 流量大小 | M2: 相关性 | N2: 修饰词类型 | O2: 搜索转化率
A3: 134 | B3: garden hose | C3: 0.2346 | D3: 低相关 | E3: 0.25 | F3: 0.25 | G3: 0.1875 | H3: 0.1914 | I3: 0.1875 | J3: 108448 | K3: 809 | L3: 流量大 | M3: =D3 | N3: 场景词 | O3: =VLOOKUP(B3,'附表-搜索转化率'!A:F,6,FALSE)
A4: 111 | B4: hose | C4: 0.2684 | D4: 低相关 | E4: 0.2813 | F4: 0.2656 | G4: 0.2578 | H4: 0.2227 | I4: 0.237 | J4: 99024 | K4: 952 | L4: 流量大 | M4: =D4 | N4: 产品词 | O4: =VLOOKUP(B4,'附表-搜索转化率'!A:F,6,FALSE)
A5: 82 | B5: water hose | C5: 0.3169 | D5: 中相关 | E5: 0.3438 | F5: 0.3125 | G5: 0.2734 | H5: 0.2773 | I5: 0.2161 | J5: 59975 | K5: 2316 | L5: 流量大 | M5: =D5 | N5: 受众词 | O5: =VLOOKUP(B5,'附表-搜索转化率'!A:F,6,FALSE)
A6: 1566 | B6: hose nozzle | C6: 0 | D6: 不相关 | E6: 0 | F6: 0 | G6: 0 | H6: 0 | I6: 0 | J6: 55830 | K6: 2633 | L6: 流量大 | M6: =D6 | N6: 配件词 | O6: =VLOOKUP(B6,'附表-搜索转化率'!A:F,6,FALSE)
A7: 66 | B7: garden hose 100 ft | C7: 0.3696 | D7: 中相关 | E7: 0.4375 | F7: 0.3125 | G7: 0.3203 | H7: 0.2578 | I7: 0.2214 | J7: 42696 | K7: 4373 | L7: 流量大 | M7: =D7 | N7: 尺寸词 | O7: =VLOOKUP(B7,'附表-搜索转化率'!A:F,6,FALSE)
A8: 146 | B8: garden hose 50 ft | C8: 0.2241 | D8: 低相关 | E8: 0.2188 | F8: 0.2344 | G8: 0.2344 | H8: 0.2109 | I8: 0.2083 | J8: 41733 | K8: 4576 | L8: 流量大 | M8: =D8 | N8: 尺寸词 | O8: =VLOOKUP(B8,'附表-搜索转化率'!A:F,6,FALSE)
A9: 1135 | B9: ensure | C9: 0 | D9: 不相关 | E9: 0 | F9: 0 | G9: 0 | H9: 0 | I9: 0 | J9: 41266 | K9: 4671 | L9: 流量大 | M9: =D9 | N9: 无关词 | O9: =VLOOKUP(B9,'附表-搜索转化率'!A:F,6,FALSE)
A10: 1456 | B10: hose holder | C10: 0 | D10: 不相关 | E10: 0 | F10: 0 | G10: 0 | H10: 0 | I10: 0 | J10: 31904 | K10: 5526 | L10: 流量大 | M10: =D10 | N10: 不相关词 | O10: =VLOOKUP(B10,'附表-搜索转化率'!A:F,6,FALSE)
A11: 1295 | B11: soaker hose | C11: 0 | D11: 不相关 | E11: 0 | F11: 0 | G11: 0 | H11: 0 | I11: 0 | J11: 31106 | K11: 5793 | L11: 流量大 | M11: =D11 | N11: NA | O11: =VLOOKUP(B11,'附表-搜索转化率'!A:F,6,FALSE)
A12: 31 | B12: expandable garden hose | C12: 0.4795 | D12: 中相关 | E12: 0.4688 | F12: 0.5469 | G12: 0.4609 | H12: 0.4141 | I12: 0.3411 | J12: 29166 | K12: 6470 | L12: 流量大 | M12: =D12 | N12: 功能词 | O12: =VLOOKUP(B12,'附表-搜索转化率'!A:F,6,FALSE)
A13: 93 | B13: water hose 100ft | C13: 0.294 | D13: 低相关 | E13: 0.2813 | F13: 0.3594 | G13: 0.2656 | H13: 0.2422 | I13: 0.224 | J13: 26353 | K13: 7614 | L13: 流量大 | M13: =D13 | N13: 尺寸词 | O13: =VLOOKUP(B13,'附表-搜索转化率'!A:F,6,FALSE)
A14: 1483 | B14: built bars | C14: 0 | D14: 不相关 | E14: 0 | F14: 0 | G14: 0 | H14: 0 | I14: 0 | J14: 23924 | K14: 8786 | L14: 流量大 | M14: =D14 | N14: 不相关词 | O14: =VLOOKUP(B14,'附表-搜索转化率'!A:F,6,FALSE)
... A25: 290 | B25: pocket hose | C25: 0.0826 | D25: 低相关 | E25: 0.0313 | F25: 0.0625 | G25: 0.2031 | H25: 0.2227 | I25: 0.1771 | J25: 13575 | K25: 18251 | L25: 流量大 | M25: =D25 | N25: 功能词 | O25: =VLOOKUP(B25,'附表-搜索转化率'!A:F,6,FALSE)
A26: 1041 | B26: core power | C26: 0 | D26: 不相关 | E26: 0 | F26: 0 | G26: 0 | H26: 0 | I26: 0 | J26: 13338 | K26: 18668 | L26: 流量大 | M26: =D26 | O26: =VLOOKUP(B26,'附表-搜索转化率'!A:F,6,FALSE)
A27: 1674 | B27: soaker hose 100 ft for garden beds | C27: 0 | D27: 不相关 | E27: 0 | F27: 0 | G27: 0 | H27: 0 | I27: 0 | J27: 13277 | K27: 18772 | L27: 流量大 | M27: =D27 | O27: =VLOOKUP(B27,'附表-搜索转化率'!A:F,6,FALSE)
A28: 1623 | B28: water hose nozzle | C28: 0 | D28: 不相关 | E28: 0 | F28: 0 | G28: 0 | H28: 0 | I28: 0 | J28: 12883 | K28: 19436 | L28: 流量大 | M28: =D28 | O28: =VLOOKUP(B28,'附表-搜索转化率'!A:F,6,FALSE)
A29: 9 | B29: expandable garden hose 50 ft | C29: 0.5856 | D29: 高相关 | E29: 0.6563 | F29: 0.5469 | G29: 0.5078 | H29: 0.4727 | I29: 0.3828 | J29: 12616 | K29: 19917 | L29: 流量大 | M29: =D29 | N29: 尺寸词 | O29: =VLOOKUP(B29,'附表-搜索转化率'!A:F,6,FALSE)
A30: 684 | B30: gardening | C30: 0.0007 | D30: 不相关 | E30: 0 | F30: 0 | G30: 0 | H30: 0.0078 | I30: 0.0052 | J30: 12318 | K30: 20520 | L30: 流量中上等 | M30: =D30 | O30: =VLOOKUP(B30,'附表-搜索转化率'!A:F,6,FALSE)
A31: 1288 | B31: garden sprayer | C31: 0 | D31: 不相关 | E31: 0 | F31: 0 | G31: 0 | H31: 0 | I31: 0 | J31: 12217 | K31: 20700 | L31: 流量中上等 | M31: =D31 | O31: =VLOOKUP(B31,'附表-搜索转化率'!A:F,6,FALSE)
A32: 486 | B32: flexzilla garden hose | C32: 0.0089 | D32: 不相关 | E32: 0 | F32: 0 | G32: 0 | H32: 0.0859 | I32: 0.0964 | J32: 11808 | K32: 21536 | L32: 流量中上等 | M32: =D32 | O32: =VLOOKUP(B32,'附表-搜索转化率'!A:F,6,FALSE)
A33: 276 | B33: copper bullet hose 50ft | C33: 0.0964 | D33: 低相关 | E33: 0.0313 | F33: 0.0938 | G33: 0.2109 | H33: 0.2617 | I33: 0.2474 | J33: 11454 | K33: 22329 | L33: 流量中上等 | M33: =D33 | N33: 尺寸词 | O33: =VLOOKUP(B33,'附表-搜索转化率'!A:F,6,FALSE)
A34: 1241 | B34: sprayer | C34: 0 | D34: 不相关 | E34: 0 | F34: 0 | G34: 0 | H34: 0 | I34: 0 | J34: 10818 | K34: 23912 | L34: 流量中上等 | M34: =D34 | O34: =VLOOKUP(B34,'附表-搜索转化率'!A:F,6,FALSE)
A35: 284 | B35: garden hose 25ft | C35: 0.0852 | D35: 低相关 | E35: 0.0938 | F35: 0.0938 | G35: 0.0625 | H35: 0.0547 | I35: 0.0573 | J35: 10227 | K35: 25535 | L35: 流量中上等 | M35: =D35 | N35: 尺寸词 | O35: =VLOOKUP(B35,'附表-搜索转化率'!A:F,6,FALSE)
A36: 938 | B36: water hose holder | C36: 0 | D36: 不相关 | E36: 0 | F36: 0 | G36: 0 | H36: 0 | I36: 0 | J36: 9823 | K36: 26728 | L36: 流量中上等 | M36: =D36 | O36: =VLOOKUP(B36,'附表-搜索转化率'!A:F,6,FALSE)
A37: 884 | B37: rv water hose | C37: 0.0001 | D37: 不相关 | E37: 0 | F37: 0 | G37: 0 | H37: 0 | I37: 0.0026 | J37: 9747 | K37: 26977 | L37: 流量中上等 | M37: =D37 | O37: =VLOOKUP(B37,'附表-搜索转化率'!A:F,6,FALSE)
A38: 1130 | B38: pool hose | C38: 0 | D38: 不相关 | E38: 0 | F38: 0 | G38: 0 | H38: 0 | I38: 0 | J38: 9338 | K38: 28328 | L38: 流量中上等 | M38: =D38 | O38: =VLOOKUP(B38,'附表-搜索转化率'!A:F,6,FALSE)
A39: 13 | B39: expandable hose | C39: 0.5584 | D39: 高相关 | E39: 0.625 | F39: 0.5625 | G39: 0.4609 | H39: 0.3672 | I39: 0.349 | J39: 9227 | K39: 28703 | L39: 流量中上等 | M39: =D39 | O39: =VLOOKUP(B39,'附表-搜索转化率'!A:F,6,FALSE)
A40: 1079 | B40: cpap hose | C40: 0 | D40: 不相关 | E40: 0 | F40: 0 | G40: 0 | H40: 0 | I40: 0 | J40: 8666 | K40: 30859 | L40: 流量中上等 | M40: =D40 | O40: =VLOOKUP(B40,'附表-搜索转化率'!A:F,6,FALSE)
A41: 434 | B41: zero g hose | C41: 0.0194 | D41: 低相关 | E41: 0 | F41: 0 | G41: 0.0703 | H41: 0.0859 | I41: 0.0937 | J41: 8343 | K41: 32242 | L41: 流量中上等 | M41: =D41 | O41: =VLOOKUP(B41,'附表-搜索转化率'!A:F,6,FALSE)
A42: 129 | B42: garden hoses | C42: 0.2385 | D42: 低相关 | E42: 0.2188 | F42: 0.25 | G42: 0.2813 | H42: 0.25 | I42: 0.2318 | J42: 7934 | K42: 34171 | L42: 流量中上等 | M42: =D42 | O42: =VLOOKUP(B42,'附表-搜索转化率'!A:F,6,FALSE)
A43: 722 | B43: 50 | C43: 0.0004 | D43: 不相关 | E43: 0 | F43: 0 | G43: 0 | H43: 0 | I43: 0.013 | J43: 7479 | K43: 36561 | L43: 流量中上等 | M43: =D43 | O43: =VLOOKUP(B43,'附表-搜索转化率'!A:F,6,FALSE)
A44: 1303 | B44: soaker hose 50 ft for garden beds | C44: 0 | D44: 不相关 | E44: 0 | F44: 0 | G44: 0 | H44: 0 | I44: 0 | J44: 7449 | K44: 36729 | L44: 流量中上等 | M44: =D44 | O44: =VLOOKUP(B44,'附表-搜索转化率'!A:F,6,FALSE)
A45: 1005 | B45: amazing grass | C45: 0 | D45: 不相关 | E45: 0 | F45: 0 | G45: 0 | H45: 0 | I45: 0 | J45: 7353 | K45: 37302 | L45: 流量中上等 | M45: =D45 | O45: =VLOOKUP(B45,'附表-搜索转化率'!A:F,6,FALSE)
A46: 1153 | B46: hose nozzle sprayer heavy duty | C46: 0 | D46: 不相关 | E46: 0 | F46: 0 | G46: 0 | H46: 0 | I46: 0 | J46: 7207 | K46: 38162 | L46: 流量中上等 | M46: =D46 | O46: =VLOOKUP(B46,'附表-搜索转化率'!A:F,6,FALSE)
A47: 948 | B47: garden hose quick connect fittings | C47: 0 | D47: 不相关 | E47: 0 | F47: 0 | G47: 0 | H47: 0 | I47: 0 | J47: 7196 | K47: 38211 | L47: 流量中上等 | M47: =D47 | O47: =VLOOKUP(B47,'附表-搜索转化率'!A:F,6,FALSE)
... A1725: 1733 | B1725: soaker garden hose | C1725: 0 | D1725: 不相关 | E1725: 0 | F1725: 0 | G1725: 0 | H1725: 0 | I1725: 0 | J1725: 126 | K1725: 2402089 | L1725: 流量小词 | M1725: =D1725 | O1725: =VLOOKUP(B1725,'附表-搜索转化率'!A:F,6,FALSE)

Sheet 3.词频统计
B1: 3.词根统计表
A2: 1个单词词根 | G2: 2个单词词根 | M2: 3个单词词根
A3: # | B3: 单词 | C3: 单词翻译 | D3: 出现次数词频 | E3: 搜索量加权词频 (亚马逊官方方法) | G3: # | H3: 单词 | I3: 单词翻译 | J3: 出现次数词频 | K3: 搜索量加权词频(亚马逊官方方法) | M3: # | N3: 单词 | O3: 单词翻译 | P3: 出现次数词频 | Q3: 搜索量加权词频(亚马逊官方方法)
A4: 1 | B4: hose | C4: 软管 | D4: 464 | E4: 7601.82 | G4: 1 | H4: garden hose | I4: 花园软管 | J4: 180 | K4: 4278.37 | M4: 1 | N4: expandable garden hose | O4: 可扩展的花园软管 | P4: 34 | Q4: 443.04
A5: 2 | B5: garden | C5: 花园 | D5: 209 | E5: 4558.73 | G5: 2 | H5: water hose | I5: 水管 | J5: 66 | K5: 928.11 | M5: 2 | N5: hose 50 ft | O5: 软管50英尺 | P5: 34 | Q5: 356.84
A6: 3 | B6: ft | C6: 英尺 | D6: 167 | E6: 982.57 | G6: 3 | H6: expandable garden | I6: 可扩展花园 | J6: 35 | K6: 444.6 | M6: 3 | N6: hose 100 ft | O6: 软管100英尺 | P6: 39 | Q6: 248.02
A7: 4 | B7: water | C7: 水 | D7: 83 | E7: 969.04 | G7: 4 | H7: 50 ft | I7: 50英尺 | J7: 53 | K7: 426.75 | M7: 4 | N7: garden hose 50 | O7: 花园软管50 | P7: 17 | Q7: 214.74
A8: 5 | B8: expandable | C8: 可扩展 | D8: 90 | E8: 623.42 | G8: 5 | H8: 100 ft | I8: 100英尺 | J8: 62 | K8: 399.68 | M8: 5 | N8: garden hose 100 | O8: 花园软管 | P8: 21 | Q8: 183.07
A9: 6 | B9: 50 | C9: 50 | D9: 75 | E9: 473.86 | G9: 6 | H9: hose 50 | I9: 软管50 | J9: 48 | K9: 384.52 | M9: 6 | N9: ft garden hose | O9: ft花园软管 | P9: 11 | Q9: 151.05
A10: 7 | B10: 100 | C10: 100 | D10: 81 | E10: 438.79 | G10: 7 | H10: hose 100ft | I10: 软管100英尺 | J10: 25 | K10: 269.3 | M10: 7 | N10: water hose 100ft | O10: 水管100英尺 | P10: 6 | Q10: 134.88
A11: 8 | B11: 100ft | C11: 100英尺 | D11: 36 | E11: 303.59 | G11: 8 | H11: hose 100 | I11: 软管100 | J11: 46 | K11: 256.58 | M11: 8 | N11: copper bullet hose | O11: 铜质子弹软管 | P11: 7 | Q11: 130.48
A12: 9 | B12: bullet | C12: 子弹 | D12: 33 | E12: 215.51 | G12: 9 | H12: copper bullet | I12: 铜子弹 | J12: 16 | K12: 166.24 | M12: 9 | N12: garden hose 100ft | O12: 花园软管100英尺 | P12: 9 | Q12: 96.22
A13: 10 | B13: copper | C13: 铜 | D13: 21 | E13: 178.92 | G13: 10 | H13: bullet hose | I13: 子弹软管 | J13: 16 | K13: 162.17 | M13: 10 | N13: water hose 50 | O13: 水管50 | P13: 7 | Q13: 95.78
A14: 11 | B14: retractable | C14: 可伸缩的 | D14: 16 | E14: 157.57 | G14: 11 | H14: ft garden | I14: ft花园 | J14: 12 | K14: 152.86 | M14: 11 | N14: retractable garden hose | O14: 可伸缩花园软管 | P14: 5 | Q14: 94.78
A15: 12 | B15: flexible | C15: 灵活的 | D15: 26 | E15: 151.8 | G15: 12 | H15: pocket hose | I15: 袖珍软管 | J15: 20 | K15: 142.14 | M15: 12 | N15: flexible garden hose | O15: 柔性花园软管 | P15: 9 | Q15: 87.14
A16: 13 | B16: pocket | C16: 口袋 | D16: 21 | E16: 143.22 | G16: 13 | H16: retractable garden | I16: 可伸缩花园 | J16: 6 | K16: 96.08 | M16: 13 | N16: 100 ft garden | O16: 100英尺花园 | P16: 4 | Q16: 85.9
A17: 14 | B17: hoses | C17: 软管 | D17: 34 | E17: 127.36 | G17: 14 | H17: flexible garden | J17: 10 | K17: 88.14 | M17: 14 | N17: garden hose 25ft | O17: 花园软管25英尺 | P17: 3 | Q17: 55.13
A18: 15 | B18: 25 | C18: 25 | D18: 32 | E18: 100.67 | G18: 15 | H18: 25 ft | I18: 25英尺 | J18: 26 | K18: 84.89 | M18: 15 | N18: hose 25 ft | O18: 软管25英尺 | P18: 16 | Q18: 49.88
A19: 16 | B19: 50ft | C19: 50英尺 | D19: 19 | E19: 85.41 | G19: 16 | H19: expandable hose | I19: 可膨胀软管 | J19: 13 | K19: 73.98 | M19: 16 | N19: ft expandable garden | P19: 6 | Q19: 40.6
A20: 17 | B20: 75 | C20: 75 | D20: 25 | E20: 75.57 | G20: 17 | H20: hose 50ft | I20: 软管50英尺 | J20: 12 | K20: 68.13 | M20: 17 | N20: bullet hose 50ft | O20: 子弹软管50英尺 | P20: 1 | Q20: 34.87
A21: 18 | B21: 25ft | C21: 25英尺 | D21: 10 | E21: 68.81 | G21: 18 | H21: ft expandable | J21: 15 | K21: 64.17 | M21: 18 | N21: foot garden hose | P21: 5 | Q21: 33.74
A22: 19 | B22: foot | C22: 脚 | D22: 18 | E22: 61.37 | G22: 19 | H22: hose 25ft | I22: 软管25英尺 | J22: 6 | K22: 61.85 | M22: 19 | N22: hose 75 ft | O22: 软管75英尺 | P22: 12 | Q22: 31.09
A23: 20 | B23: heavy | C23: 沉重的 | D23: 15 | E23: 46 | G23: 20 | H23: garden hoses | I23: 花园软管 | J23: 16 | K23: 61.46 | M23: 20 | N23: mangueras para jardín | O23: 曼格拉斯帕拉尔丁 | P23: 2 | Q23: 29.87
A24: 21 | B24: duty | C24: 责任 | D24: 15 | E24: 46 | G24: 21 | H24: hose 25 | I24: 软管25 | J24: 18 | K24: 53.71 | M24: 21 | N24: 100 ft expandable | P24: 4 | Q24: 29.23
A25: 22 | B25: flex | C25: 伸缩 | D25: 12 | E25: 43.82 | G25: 22 | H25: retractable hose | I25: 可伸缩软管 | J25: 4 | K25: 47.67 | M25: 22 | N25: garden hose 75 | O25: 花园软管75 | P25: 7 | Q25: 28.01
A26: 23 | B26: feet | C26: 脚 | D26: 25 | E26: 42.82 | G26: 23 | H26: 75 ft | I26: 75英尺 | J26: 18 | K26: 46.92 | M26: 23 | N26: garden hose expandable | O26: 花园软管可扩展 | P26: 9 | Q26: 25.21
A27: 24 | B27: steel | C27: 钢铁 | D27: 17 | E27: 39.3 | G27: 24 | H27: heavy duty | I27: 重型 | J27: 15 | K27: 46 | M27: 24 | N27: 50 ft garden | O27: 50英尺花园 | P27: 2 | Q27: 24.99
A28: 25 | B28: silver | C28: 银 | D28: 11 | E28: 35.33 | G28: 25 | H28: hose expandable | I28: 软管可膨胀 | J28: 18 | K28: 44.9 | M28: 25 | N28: silver bullet hose | O28: 银子弹软管 | P28: 5 | Q28: 24.72
A29: 26 | B29: mangueras | C29: 软管 | D29: 5 | E29: 35.3 | G29: 26 | H29: hose 75 | I29: 软管75 | J29: 15 | K29: 43.92 | M29: 26 | N29: hose copper bullet | P29: 5 | Q29: 22.99
A30: 27 | B30: para | C30: 第段 | D30: 4 | E30: 33.06 | G30: 27 | H30: silver bullet | I30: 银弹 | J30: 11 | K30: 35.33 | M30: 27 | N30: pocket hose copper | P30: 4 | Q30: 21.99
A31: 28 | B31: expanding | C31: 正在扩展 | D31: 10 | E31: 30.52 | G31: 28 | H31: flex hose | I31: 挠性软管 | J31: 7 | K31: 34.83 | M31: 28 | N31: para jardín flexible | P31: 1 | Q31: 21.34
A32: 29 | B32: jardín | C32: 花园 | D32: 2 | E32: 29.87 | G32: 29 | H32: foot garden | J32: 5 | K32: 33.74 | M32: 29 | N32: flexzilla garden hose | O32: Flexzilla花园软管 | P32: 3 | Q32: 21.15
A33: 30 | B33: collapsible | C33: 可折叠 | D33: 11 | E33: 27.93 | G33: 30 | H33: ft hose | I33: 英尺软管 | J33: 10 | K33: 31.58 | M33: 30 | N33: 50 ft expandable | P33: 5 | Q33: 19.68
A34: 31 | B34: outdoor | C34: 户外的 | D34: 11 | E34: 27.49 | G34: 31 | H34: mangueras para | I34: 曼格拉斯山 | J34: 2 | K34: 29.87 | M34: 31 | N34: 25 ft garden | P34: 2 | Q34: 19.3
A35: 32 | B35: flexzilla | C35: Flexzilla | D35: 3 | E35: 21.15 | G35: 32 | H35: para jardín | I35: 帕拉贾尔丁 | J35: 2 | K35: 29.87 | M35: 32 | N35: garden hose 50ft | O35: 花园软管50英尺 | P35: 6 | Q35: 19.25
A36: 33 | B36: lightweight | C36: 轻量级 | D36: 9 | E36: 20.89 | G36: 33 | H36: steel hose | I36: 钢软管 | J36: 10 | K36: 27.09 | M36: 33 | N36: garden hose 25 | O36: 花园软管25 | P36: 5 | Q36: 15.73
A37: 34 | B37: manguera | C37: 软管 | D37: 5 | E37: 20.22 | G37: 34 | H37: flexible hose | I37: 挠性软管 | J37: 8 | K37: 25.09 | M37: 34 | N37: bullet hose 100 | O37: 子弹软管100 | P37: 2 | Q37: 15.1
A38: 35 | B38: pipe | C38: 管 | D38: 4 | E38: 18.48 | G38: 35 | H38: hose copper | I38: 铜软管 | J38: 5 | K38: 22.99 | M38: 35 | N38: pocket hose 50 | O38: 袋式软管50 | P38: 2 | Q38: 14.66
A39: 36 | B39: agua | C39: 水 | D39: 5 | E39: 18.44 | G39: 36 | H39: jardín flexible | J39: 1 | K39: 21.34 | M39: 36 | N39: expandable water hose | O39: 可膨胀水管 | P39: 5 | Q39: 14.55
A40: 37 | B40: de | C40: 德德 | D40: 5 | E40: 18.44 | G40: 37 | H40: flexzilla garden | I40: flexzilla花园 | J40: 3 | K40: 21.15 | M40: 37 | N40: manguera de agua | O40: 曼格拉-德阿瓜 | P40: 3 | Q40: 14.49
...

Sheet 4.标题怎么写
A1: 标题 | B1: 内容
A2: 标题1： | B2: VIENECI Hose Garden Hose, Durable Flexible Water Hose with 10 Function Spray Hose Nozzle, 3/4 inch Solid Brass Fittings, Extra Strength Fabric, Lightweight & No-kink Expanding Hose(25FT) | C2: 选出优秀竞品10个标题结合词频统计
A3: 标题2： | B3: Joeys Garden Expandable Garden Hose with 8 Function Hose Nozzle, Lightweight Anti-Kink Flexible Garden Hoses, Extra Strength Fabric with Double Latex Core (25 FT, Black)
A4: 标题3 | B4: Gardguard 25ft Garden Hose Expandable: Expandable Water Hose with Durable 3-Layers Latex and 10 Function Nozzle, Durable Water Hose with Solid Fittings (BLUE)
A5: 标题4 | B5: Flexi Hose with 8 Function Nozzle, Lightweight Expandable Garden Hose, No-Kink Flexibility, 3/4 Inch Solid Brass Fittings and Double Latex Core
A6: 标题5 | B6: TheFitLife Flexible and Expandable Garden Hose - Triple Latex Core with 3/4 Inch Solid Brass Fittings and 8 Function Spray Nozzle, Portable and Kink Free Water Hose (25 FT)
A7: 标题6 | B7: Joeys Garden Expandable Garden Hose with 8 Function Hose Nozzle, Lightweight Anti-Kink Flexible Garden Hoses, Extra Strength Fabric with Double Latex Core (25 FT, Green)
A8: 标题7 | B8: Garden Hose Expandable 50ft, Self-Locking Leakproof Water Hose With 10 Function Spray Nozzle,Heavy Duty Flexible Hose,3/4" Solid Brass Connectors,Lightweight No-Kink Flexible Water Hose(Black)
A9: 标题8 | B9: 25ft Garden Hose Lightweight Extra Strength Fabric and 4-Layer Latex Core, 3/4" Solid Brass Fittings, No-Kink, Best Choice for Watering and Washing (Black)
A10: 标题9 | B10: Knoikos Expandable Garden Hose 25ft - Expanding Water Hose with 10 Function Nozzle, Easy Storage Garden Water Hose
A11: 标题10 | B11: Zoflaro Garden Hose 50ft, Expandable Water Hose 50 feet with 10 Function Nozzle Spray, Extra Strength 3750D, Durable 4-Layers Latex Flexible Expandable Hose with 3/4" Solid Brass Fittings, Leakproof
A13: 标题 | B13: Garden Hose , (Brand) 100ft Water Hose with 10 function Spray lightweight expandable garden hose nozzle flexible water with 3/4" Solid Brass Fittings, Leakproof (Black)

Sheet 5.ASIN表
A1: 同类产品ASIN表 （ASIN定投备用）
A2: 图片 | B2: 是否同类 | C2: ASIN | D2: 品牌 | E2: 类目路径 | F2: 大类目 | G2: 大类BSR | H2: 小类目 | I2: 小类BSR | J2: 近30天销量 | K2: 价格($) | L2: Prime价格($) | M2: FBA($) | N2: 评分 | O2: 评分数 | P2: 留评率 | Q2: 变体数
B3: 否 | C3: B003TFE7ZM | D3: Flexzilla | E3: Patio, Lawn & Garden:Gardening & Lawn Care:Watering Equipment:Garden Hoses | F3: Patio, Lawn & Garden | G3: 10 | H3: Garden Hoses | I3: 1 | J3: 37379 | K3: 39.97 | M3: 8.77 | N3: 4.5 | O3: 75158 | P3: 0.0361 | Q3: 15
B4: 否 | C4: B07D3TFDLK | D4: Giraffe Tools | E4: Patio, Lawn & Garden:Gardening & Lawn Care:Watering Equipment:Garden Hoses | F4: Patio, Lawn & Garden | G4: 82 | H4: Garden Hoses | I4: 2 | J4: 12711 | K4: 27.96 | M4: 7.65 | N4: 4.4 | O4: 11874 | P4: 0.0242 | Q4: 8
B5: 是 | C5: B07X22JL28 | D5: Flexi Hose | E5: Patio, Lawn & Garden:Gardening & Lawn Care:Watering Equipment:Garden Hoses | F5: Patio, Lawn & Garden | G5: 161 | H5: Garden Hoses | I5: 3 | J5: 13131 | K5: 59.99 | M5: 6.39 | N5: 4.2 | O5: 49758 | P5: 0.0389 | Q5: 10
B6: 否 | C6: B071KT21BK | D6: BIONIC STEEL | E6: Patio, Lawn & Garden:Gardening & Lawn Care:Watering Equipment:Garden Hoses | F6: Patio, Lawn & Garden | G6: 162 | H6: Garden Hoses | I6: 4 | J6: 13468 | K6: 55.25 | M6: 9.73 | N6: 4.4 | O6: 29173 | P6: 0.0816 | Q6: 4
B7: 否 | C7: B094K7ZLV7 | D7: FEVONE | E7: Patio, Lawn & Garden:Gardening & Lawn Care:Watering Equipment:Garden Hoses | F7: Patio, Lawn & Garden | G7: 220 | H7: Garden Hoses | I7: 6 | J7: 4339 | K7: 20.39 | M7: 8.77 | N7: 4.4 | O7: 1404 | P7: 0.0288 | Q7: 8
B8: 是 | C8: B07JCD8TG7 | D8: Pocket Hose | E8: Patio, Lawn & Garden:Gardening & Lawn Care:Watering Equipment:Garden Hoses | F8: Patio, Lawn & Garden | G8: 202 | H8: Garden Hoses | I8: 5 | J8: 13712 | K8: 29.88 | M8: 5.69 | N8: 3.9 | O8: 13941 | P8: 0.0538 | Q8: 4
B9: 是 | C9: B0C7KB84HK | D9: Xergur | E9: Patio, Lawn & Garden:Gardening & Lawn Care:Watering Equipment:Garden Hoses | F9: Patio, Lawn & Garden | G9: 293 | H9: Garden Hoses | I9: 13 | J9: 362 | K9: 14.9 | M9: 5.4 | N9: 5 | O9: 1 | P9: 0 | Q9: 1
B10: 否 | C10: B09FF5HV6D | D10: FEVONE | E10: Patio, Lawn & Garden:Gardening & Lawn Care:Watering Equipment:Garden Hoses | F10: Patio, Lawn & Garden | G10: 228 | H10: Garden Hoses | I10: 8 | J10: 3089 | K10: 23.99 | L10: 19.19 | M10: 8.77 | N10: 4.4 | O10: 912 | P10: 0.0142 | Q10: 10
B11: 否 | C11: B08RDQZ7M2 | D11: LINEX | E11: Patio, Lawn & Garden:Gardening & Lawn Care:Watering Equipment:Garden Hoses | F11: Patio, Lawn & Garden | G11: 225 | H11: Garden Hoses | I11: 7 | J11: 5242 | K11: 23.69 | M11: 6.1 | N11: 4.2 | O11: 2962 | P11: 0.0368 | Q11: 5
B12: 否 | C12: B07HN2PBH2 | D12: Cesun | E12: Patio, Lawn & Garden:Gardening & Lawn Care:Watering Equipment:Garden Hoses | F12: Patio, Lawn & Garden | G12: 244 | H12: Garden Hoses | I12: 10 | J12: 3416 | K12: 27.99 | M12: 8.13 | N12: 4.4 | O12: 7098 | P12: 0.0375 | Q12: 7
B13: 否 | C13: B082PPZWDV | D13: Rosy Earth | E13: Patio, Lawn & Garden:Gardening & Lawn Care:Watering Equipment:Garden Hoses | F13: Patio, Lawn & Garden | G13: 240 | H13: Garden Hoses | I13: 9 | J13: 10109 | K13: 42.99 | M13: 8.29 | N13: 4.5 | O13: 4349 | P13: 0.0518 | Q13: 4
B14: 否 | C14: B01GHSBKOS | D14: zero-G | E14: Patio, Lawn & Garden:Gardening & Lawn Care:Watering Equipment:Garden Hoses | F14: Patio, Lawn & Garden | G14: 264 | H14: Garden Hoses | I14: 11 | J14: 7619 | K14: 68.95 | M14: 13.09 | N14: 4.4 | O14: 4275 | P14: 0.0265 | Q14: 7
B15: 否 | C15: B07MHQHH2H | D15: BIONIC STEEL | E15: Patio, Lawn & Garden:Gardening & Lawn Care:Watering Equipment:Garden Hoses | F15: Patio, Lawn & Garden | G15: 283 | H15: Garden Hoses | I15: 12 | J15: 4440 | K15: 34.99 | M15: 8.13 | N15: 4.3 | O15: 9067 | P15: 0 | Q15: 3
B16: 否 | C16: B093FWFLGG | D16: FEVONE | E16: Patio, Lawn & Garden:Gardening & Lawn Care:Watering Equipment:Garden Hoses | F16: Patio, Lawn & Garden | G16: 406 | H16: Garden Hoses | I16: 15 | J16: 3168 | K16: 46.99 | L16: 39.94 | M16: 11.97 | N16: 4 | O16: 1082 | P16: 0.0278 | Q16: 5
B17: 否 | C17: B07F2FZN8K | D17: SPECILITE | E17: Patio, Lawn & Garden:Gardening & Lawn Care:Watering Equipment:Garden Hoses | F17: Patio, Lawn & Garden | G17: 404 | H17: Garden Hoses | I17: 14 | J17: 7428 | K17: 37.99 | M17: 8.29 | N17: 4.5 | O17: 7047 | P17: 0.0346 | Q17: 14
B18: 否 | C18: B0BQ72VWDZ | D18: Unywarse | E18: Patio, Lawn & Garden:Gardening & Lawn Care:Watering Equipment:Garden Hoses | F18: Patio, Lawn & Garden | G18: 424 | H18: Garden Hoses | I18: 16 | J18: 9601 | K18: 59.99 | L18: 42.99 | M18: 8.13 | N18: 4.8 | O18: 2609 | P18: 0.0905 | Q18: 4
B19: 否 | C19: B0B1DVFW1J | D19: Hlinker | E19: Patio, Lawn & Garden:Gardening & Lawn Care:Watering Equipment:Garden Hoses | F19: Patio, Lawn & Garden | G19: 456 | H19: Garden Hoses | I19: 18 | J19: 5568 | K19: 49.99 | M19: 7.33 | N19: 4.2 | O19: 713 | P19: 0.03 | Q19: 4
B20: 否 | C20: B0BWJV1Y7H | D20: Rcfunkid | E20: Patio, Lawn & Garden:Gardening & Lawn Care:Watering Equipment:Garden Hoses | F20: Patio, Lawn & Garden | G20: 480 | H20: Garden Hoses | I20: 19 | J20: 8402 | K20: 69.99 | M20: 9.73 | N20: 4.7 | O20: 2261 | P20: 0.0832 | Q20: 3
B21: 是 | C21: B0CF53MV9R | D21: VERENIX | E21: Patio, Lawn & Garden:Gardening & Lawn Care:Watering Equipment:Garden Hoses | F21: Patio, Lawn & Garden | G21: 545 | H21: Garden Hoses | I21: 22 | J21: 1354 | K21: 39.97 | M21: 7.94 | N21: 4.3 | O21: 17 | P21: 0.0052 | Q21: 2
B22: 否 | C22: B01E1DANAI | D22: Flexzilla | E22: Patio, Lawn & Garden:Gardening & Lawn Care:Watering Equipment:Garden Hoses | F22: Patio, Lawn & Garden | G22: 444 | H22: Garden Hoses | I22: 17 | J22: 5400 | K22: 64.97 | M22: 14.35 | N22: 4.5 | O22: 3057 | P22: 0.0228 | Q22: 11
B23: 是 | C23: B0C7TZ75QJ | D23: GUKOK | E23: Patio, Lawn & Garden:Gardening & Lawn Care:Watering Equipment:Garden Hoses | F23: Patio, Lawn & Garden | G23: 585 | H23: Garden Hoses | I23: 25 | J23: 7133 | K23: 44.99 | L23: 27.99 | M23: 6.39 | N23: 4.1 | O23: 1550 | P23: 0.0279 | Q23: 4
B24: 否 | C24: B0CG5DV5M3 | D24: Yofidra | E24: Patio, Lawn & Garden:Gardening & Lawn Care:Watering Equipment:Garden Hoses | F24: Patio, Lawn & Garden | G24: 503 | H24: Garden Hoses | I24: 20 | J24: 725 | K24: 69.99 | N24: 4.3 | O24: 1648 | P24: 0.0221 | Q24: 2
B25: 是 | C25: B0C5JV54V2 | D25: Xergur | E25: Patio, Lawn & Garden:Gardening & Lawn Care:Watering Equipment:Garden Hoses | F25: Patio, Lawn & Garden | G25: 540 | H25: Garden Hoses | I25: 21 | J25: 1885 | K25: 15.99 | M25: 4.75 | N25: 2.7 | O25: 4 | P25: 0.0016 | Q25: 1
B26: 否 | C26: B014M9PEXC | D26: Teknor Apex | E26: Patio, Lawn & Garden:Gardening & Lawn Care:Watering Equipment:Garden Hoses | F26: Patio, Lawn & Garden | G26: 562 | H26: Garden Hoses | I26: 23 | J26: 4629 | K26: 44.79 | M26: 7.81 | N26: 4.5 | O26: 6729 | P26: 0.0225 | Q26: 1
B27: 否 | C27: B092HKSPP5 | D27: OnBrand | E27: Patio, Lawn & Garden:Gardening & Lawn Care:Watering Equipment:Garden Hoses | F27: Patio, Lawn & Garden | G27: 590 | H27: Garden Hoses | I27: 26 | J27: 4455 | K27: 43.99 | M27: 9.57 | N27: 4.3 | O27: 2516 | P27: 0.0797 | Q27: 9
B28: 否 | C28: B08D6LC8DR | D28: Orgrimmar | E28: Patio, Lawn & Garden:Gardening & Lawn Care:Watering Equipment:Garden Hoses | F28: Patio, Lawn & Garden | G28: 580 | H28: Garden Hoses | I28: 24 | J28: 5550 | K28: 15.09 | M28: 5.4 | N28: 3.8 | O28: 1959 | P28: 0.0195 | Q28: 12
B29: 否 | C29: B0BWH7788Y | D29: Kebose | E29: Patio, Lawn & Garden:Gardening & Lawn Care:Watering Equipment:Garden Hoses | F29: Patio, Lawn & Garden | G29: 696 | H29: Garden Hoses | I29: 29 | J29: 3152 | K29: 33.99 | M29: 8.61 | N29: 4.6 | O29: 880 | P29: 0.1037 | Q29: 1
B30: 否 | C30: B004CR4NLO | D30: LDR Industries | E30: Patio, Lawn & Garden:Gardening & Lawn Care:Watering Equipment:Garden Hoses | F30: Patio, Lawn & Garden | G30: 778 | H30: Garden Hoses | I30: 32 | J30: 4556 | K30: 8.58 | M30: 5.4 | N30: 4.5 | O30: 3670 | P30: 0.0241 | Q30: 1
B31: 否 | C31: B0BNMJX95D | D31: Double Couple | E31: Patio, Lawn & Garden:Gardening & Lawn Care:Watering Equipment:Garden Hoses | F31: Patio, Lawn & Garden | G31: 681 | H31: Garden Hoses | I31: 28 | J31: 2596 | K31: 19.99 | M31: 8.93 | N31: 4.2 | O31: 2131 | P31: 0.0401 | Q31: 2
B32: 否 | C32: B0BK1QXZNC | D32: Secbulk | E32: Patio, Lawn & Garden:Gardening & Lawn Care:Watering Equipment:Garden Hoses | F32: Patio, Lawn & Garden | G32: 734 | H32: Garden Hoses | I32: 31 | J32: 5146 | K32: 49.99 | M32: 7.33 | N32: 4.3 | O32: 628 | P32: 0.0321 | Q32: 3
B33: 是 | C33: B0C5CDR9MB | D33: GUKOK | E33: Patio, Lawn & Garden:Gardening & Lawn Care:Watering Equipment:Garden Hoses | F33: Patio, Lawn & Garden | G33: 721 | H33: Garden Hoses | I33: 30 | J33: 2810 | K33: 42.99 | M33: 7.65 | N33: 4 | O33: 16 | P33: 0.0018 | Q33: 1
B34: 否 | C34: B07W4XKK9S | D34: Flexon | E34: Patio, Lawn & Garden:Gardening & Lawn Care:Watering Equipment:Garden Hoses | F34: Patio, Lawn & Garden | G34: 804 | H34: Garden Hoses | I34: 33 | J34: 4540 | K34: 39.84 | M34: 15.61 | N34: 4 | O34: 1072 | P34: 0.0443 | Q34: 1
B35: 是 | C35: B0CFDKDLLR | D35: GUKOK | E35: Patio, Lawn & Garden:Gardening & Lawn Care:Watering Equipment:Garden Hoses | F35: Patio, Lawn & Garden | G35: 877 | H35: Garden Hoses | I35: 36 | J35: 595 | K35: 29.99 | M35: 6.39 | N35: 3.9 | O35: 13 | P35: 0.0185 | Q35: 1
B36: 否 | C36: B00790RLMO | D36: Swan | E36: Patio, Lawn & Garden:Gardening & Lawn Care:Watering Equipment:Garden Hoses | F36: Patio, Lawn & Garden | G36: 998 | H36: Garden Hoses | I36: 41 | J36: 2124 | K36: 12.79 | M36: 7.65 | N36: 4.1 | O36: 1063 | P36: 0.0052 | Q36: 1
... B43: 是 | C43: B0C6JQMVSB | D43: Lefree | E43: Patio, Lawn & Garden:Gardening & Lawn Care:Watering Equipment:Garden Hoses | F43: Patio, Lawn & Garden | G43: 1129 | H43: Garden Hoses | I43: 47 | J43: 4526 | K43: 64.99 | M43: 7.81 | N43: 4.4 | O43: 7139 | P43: 0 | Q43: 6
B44: 否 | C44: B0BK1T5L9P | D44: Secbulk | E44: Patio, Lawn & Garden:Gardening & Lawn Care:Watering Equipment:Garden Hoses | F44: Patio, Lawn & Garden | G44: 1142 | H44: Garden Hoses | I44: 48 | J44: 3451 | K44: 28.99 | L44: 26.09 | M44: 5.69 | N44: 4.2 | O44: 802 | P44: 0.0603 | Q44: 4
B45: 否 | C45: B07S46BQWP | D45: Rocky Mountain Goods | E45: Patio, Lawn & Garden:Gardening & Lawn Care:Watering Equipment:Garden Hoses | F45: Patio, Lawn & Garden | G45: 1017 | H45: Garden Hoses | I45: 42 | J45: 3663 | K45: 13.95 | M45: 4.24 | N45: 4.1 | O45: 6704 | P45: 0.0371 | Q45: 3
B46: 否 | C46: B0C7TR8TP6 | D46: GAMSOD | E46: Patio, Lawn & Garden:Gardening & Lawn Care:Watering Equipment:Garden Hoses | F46: Patio, Lawn & Garden | G46: 1231 | H46: Garden Hoses | I46: 52 | J46: 1177 | K46: 32.39 | N46: 4.3 | O46: 862 | P46: 0 | Q46: 4
...

Sheet 附表-搜索转化率
A1: 搜索词 | B1: 搜索量 （过去 360 天） | C1: 搜索量增长 （过去 90 天） | D1: 搜索量增长 （过去 180 天） | E1: 点击份额 （过去 360 天） | F1: 搜索转化率 （过去 360 天） | G1: 点击率最高的商品1（标题） | H1: 点击率最高的商品1 (ASIN) | I1: 点击率最高的商品2（标题） | J1: 点击率最高的商品2 (ASIN) | K1: 点击率最高的商品3（标题） | L1: 点击率最高的商品3 (ASIN)
A2: garden hose | B2: 6134657 | C2: 0.3962 | D2: 3.0374 | E2: 0.3112 | F2: 0.0129 | G2: Flexzilla Garden Hose 5/8 in. x 50 ft Heavy Duty Lightweight Drinking Water Safe ZillaGreen - HFZG550YW-E | H2: B003TFE7ZM | I2: Unywarse Metal Garden Hose 50ft Stainless Steel Heavy Duty Water Hose with 10 Function Nozzle Flexible Lightweight Kink Free & Tangle Free Pet Proof Puncture Proof Hose for Yard Outdoor | J2: B0BQ72VWDZ | K2: Pocket Hose Silver Bullet 50 ft Turbo Shot Nozzle Multiple Spray Patterns Expandable Garden Hose 3/4 in Solid Aluminum Fittings Lead-Free Lightweight and No-Kink | L2: B07JCD8TG7
A3: hose | B3: 3834107 | C3: 0.6018 | D3: 2.346 | E3: 0.2177 | F3: 0.0153 | G3: Pocket Hose Silver Bullet 75 ft Turbo Shot Nozzle Multiple Spray Patterns Expandable Garden Hose 3/4 in Solid Aluminum Fittings Lightweight and No-Kink | H3: B07JCDHKH4 | I3: Flexzilla Garden Hose 5/8 in. x 50 ft Heavy Duty Lightweight Drinking Water Safe ZillaGreen - HFZG550YW-E | J3: B003TFE7ZM | K3: Pocket Hose Silver Bullet 50 ft Turbo Shot Nozzle Multiple Spray Patterns Expandable Garden Hose 3/4 in Solid Aluminum Fittings Lead-Free Lightweight and No-Kink | L3: B07JCD8TG7
A4: water hose | B4: 2502159 | C4: 0.5635 | D4: 2.4004 | E4: 0.1259 | F4: 0.0102 | G4: Flexzilla Garden Hose 5/8 in. x 50 ft Heavy Duty Lightweight Drinking Water Safe ZillaGreen - HFZG550YW-E | H4: B003TFE7ZM | I4: Camco TastePURE Drinking Water Hose for RV 25 Feet White (22783) | J4: B004ME11FS | K4: NGreen Stainless Steel Garden Hose - Flexible Metal Water Hose with Nozzle Puncture Rust Proof and Corrosion Resistant Never Kink and High Pressure Collapsible and Easy to Store (25FT) | L4: B0BQRQDNC4
A5: expandable garden hose | B5: 1292297 | C5: 0.3673 | D5: 4.7801 | E5: 0.0483 | F5: 0.0062 | G5: Pocket Hose Silver Bullet 25 ft Turbo Shot Nozzle Multiple Spray Patterns Expandable Garden Hose 3/4 in Solid Aluminum Fittings Lightweight and No-Kink | H5: B07JQZWJJS | I5: Pocket Hose Silver Bullet 75 ft Turbo Shot Nozzle Multiple Spray Patterns Expandable Garden Hose 3/4 in Solid Aluminum Fittings Lightweight and No-Kink | J5: B07JCDHKH4 | K5: Flexi Hose with 8 Function Nozzle Expandable Garden Hose Lightweight & No-Kink Flexible Garden Hose 3/4 inch Solid Brass Fittings and Double Latex Core 50 ft Blue Black | L5: B07X22JL28
A6: water hose 100ft | B6: 717057 | C6: 0.4737 | D6: 2.699 | E6: 0.028 | F6: 0.0102 | G6: Flexon FA58100CN Farm and Ranch Garden Hose 100 ft Red | H6: B07W4XKK9S | I6: Metal Garden Hose 100FT Stainless Steel Heavy Duty Water Hose With 10 Function Nozzle No-Tangle & No-Kink Tough & Flexible Durable and Lightweight Rust Proof hose for Yard Outdoor RV | J6: B0BWJV1Y7H | K6: Pocket Hose Silver Bullet 100 ft Turbo Shot Nozzle Multiple Spray Patterns Expandable Garden Hose 3/4 in Solid Aluminum Fittings Lightweight and No-Kink | L6: B07JCJFJFY
A7: garden hose 100 ft | B7: 638204 | C7: 1.0321 | D7: 2.6092 | E7: 0.0304 | F7: 0.0142 | G7: Flexon FA58100CN Farm and Ranch Garden Hose 100 ft Red | H7: B07W4XKK9S | I7: Metal Garden Hose 100FT Stainless Steel Heavy Duty Water Hose With 10 Function Nozzle No-Tangle & No-Kink Tough & Flexible Durable and Lightweight Rust Proof hose for Yard Outdoor RV | J7: B0BWJV1Y7H | K7: Flexzilla Garden Hose 5/8 in. x 100 ft. Heavy Duty Lightweight Drinking Water Safe ZillaGreen - HFZG5100YW-E | L7: B0080JA346
A8: garden hose 50 ft | B8: 544363 | C8: 1.3158 | D8: 1.2302 | E8: 0.0256 | F8: 0.0173 | G8: Flexzilla Garden Hose 5/8 in. x 50 ft Heavy Duty Lightweight Drinking Water Safe ZillaGreen - HFZG550YW-E | H8: B003TFE7ZM | I8: Unywarse Metal Garden Hose 50ft Stainless Steel Heavy Duty Water Hose with 10 Function Nozzle Flexible Lightweight Kink Free & Tangle Free Pet Proof Puncture Proof Hose for Yard Outdoor | J8: B0BQ72VWDZ | K8: Pocket Hose Silver Bullet 50 ft Turbo Shot Nozzle Multiple Spray Patterns Expandable Garden Hose 3/4 in Solid Aluminum Fittings Lead-Free Lightweight and No-Kink | L8: B07JCD8TG7
A9: 100 ft garden hose | B9: 471191 | C9: 0.6322 | D9: 4.8674 | E9: 0.0277 | F9: 0.0193 | G9: Flexon FA58100CN Farm and Ranch Garden Hose 100 ft Red | H9: B07W4XKK9S | I9: Metal Garden Hose 100FT Stainless Steel Heavy Duty Water Hose With 10 Function Nozzle No-Tangle & No-Kink Tough & Flexible Durable and Lightweight Rust Proof hose for Yard Outdoor RV | J9: B0BWJV1Y7H | K9: Flexzilla Garden Hose 5/8 in. x 100 ft. Heavy Duty Lightweight Drinking Water Safe ZillaGreen - HFZG5100YW-E | L9: B0080JA346
A10: flexible garden hose | B10: 387747 | C10: 0.8706 | D10: 5.8972 | E10: 0.0244 | F10: 0.0109 | G10: Pocket Hose Silver Bullet 25 ft Turbo Shot Nozzle Multiple Spray Patterns Expandable Garden Hose 3/4 in Solid Aluminum Fittings Lightweight and No-Kink | H10: B07JQZWJJS | I10: Flexzilla Garden Hose 5/8 in. x 50 ft Heavy Duty Lightweight Drinking Water Safe ZillaGreen - HFZG550YW-E | J10: B003TFE7ZM | K10: Flexi Hose with 8 Function Nozzle Expandable Garden Hose Lightweight & No-Kink Flexible Garden Hose 3/4 inch Solid Brass Fittings and Double Latex Core 50 ft Blue Black | L10: B07X22JL28
A11: expandable garden hose 100ft | B11: 350059 | C11: 1.057 | D11: 12.8129 | E11: 0.0122 | F11: 0.0068 | G11: KETTOYA 100FT Expandable Garden Hose No-Kink Lightweight Flexible Water Hose with 10-Pattern Spray Nozzle New Gen Multilayer Integrated Leakproof Hose Pipe 3/4 Brass Alloy Connector Repairable | H11: B0BZVNLBF1 | I11: Lefree Garden Hose 100ft Expandable Garden Hose Leak-Proof with 40 Layers of Innovative Nano Rubber 2024 Version/New Patented Lightweight Durable No-Kink Flexible Water Hose (Black) | J11: B0C6JQMVSB | K11: Pocket Hose Silver Bullet 100 ft Turbo Shot Nozzle Multiple Spray Patterns Expandable Garden Hose 3/4 in Solid Aluminum Fittings Lightweight and No-Kink | L11: B07JCJFJFY
A12: water hose 50 ft | B12: 455425 | C12: 0.5549 | D12: 2.1964 | E12: 0.0178 | F12: 0.0143 | G12: Flexzilla Garden Hose 5/8 in. x 50 ft Heavy Duty Lightweight Drinking Water Safe ZillaGreen - HFZG550YW-E | H12: B003TFE7ZM | I12: Pocket Hose Silver Bullet 50 ft Turbo Shot Nozzle Multiple Spray Patterns Expandable Garden Hose 3/4 in Solid Aluminum Fittings Lead-Free Lightweight and No-Kink | J12: B07JCD8TG7 | K12: Garden Lead-in Water Hose 5/8 Inch x 50 Foot Heavy Duty Flexible Water Hose Garden hose Extender/Hose Reel Connector Max Pressure 150 PSI/10 BAR with 3/4 GHT Fittings | L12: B09VXHVRKP
A13: pocket hose | B13: 301512 | C13: 0.5549 | D13: 6.6816 | E13: 0.0351 | F13: 0.0282 | G13: Pocket Hose Silver Bullet 50 ft Turbo Shot Nozzle Multiple Spray Patterns Expandable Garden Hose 3/4 in Solid Aluminum Fittings Lead-Free Lightweight and No-Kink | H13: B07JCD8TG7 | I13: 2024 Pocket Hose Copper Bullet AS-SEEN-ON-TV Expands to 25 ft REMOVABLE Turbo Shot Multi-Pattern Nozzle 650psi 3/4 in Solid Copper Anodized Aluminum Fittings Lead-Free Lightweight No-Kink Garden Hose | J13: B0BT3WJG1T | K13: 2024 Pocket Hose Copper Bullet AS-SEEN-ON-TV Expands to 50 ft REMOVABLE Turbo Shot Multi-Pattern Nozzle 650psi 3/4 in Solid Copper Anodized Aluminum Fittings Lead-Free Lightweight No-Kink Garden Hose | L13: B0BT47Z44M
... A21: 50 ft garden hose | B21: 160412 | C21: 0.6276 | D21: 4.5471 | E21: 0.0089 | F21: 0.0232 | G21: Flexzilla Garden Hose 5/8 in. x 50 ft Heavy Duty Lightweight Drinking Water Safe ZillaGreen - HFZG550YW-E | H21: B003TFE7ZM | I21: Garden Lead-in Water Hose 5/8 Inch x 50 Foot Heavy Duty Flexible Water Hose Garden hose Extender/Hose Reel Connector Max Pressure 150 PSI/10 BAR with 3/4 GHT Fittings | J21: B09VXHVRKP | K21: Flexon 1/2-Inch by 50-Foot Reinforced Garden Hose FR1250 Green | L21: B0016ARXN0
