Workbook

Sheet Sheet1
A1: 关键词 | B1: 0.6875 | D1: 0.875
B2: 广告 | C2: 自然 | D2: 广告 | E2: 自然 | F2: 广告 | G2: 自然 | H2: 广告 | I2: 自然
A3: bed vacuum cleaner uv sanitizing | B3: 3 | C3: 5 | E3: 3
A4: mattress vacuum cleaner uv sanitizing | B4: 5 | C4: 4 | E4: 3
A5: vacuum for bed mattress | B5: 2 | C5: 4 | E5: 3
A6: dust mite vacuum | B6: 7 | C6: / | E6: 5
A7: uv vacuum cleaner for mattress | B7: 3 | C7: 2 | E7: 2
A8: mattress vacuum for pet hair | B8: 3 | C8: 2 | E8: 2
A9: pet hair vacuum cleaners for bed | B9: 1 | C9: 3 | D9: 1 | E9: 3
A11: mattress vacuum cleaner | B11: 4 | C11: 1 | E11: 1
A12: pet hair vacuum cleaners for bed | B12: 2 | C12: 3 | D12: 1 | E12: 3
A13: vacuum for bed mattress | B13: 3 | C13: 4 | E13: 3
A14: bed mattress vacuum cleaner | B14: 1 | C14: 5 | E14: 3
A15: mattress vacuum | B15: / | C15: 1 | E15: 2

Sheet 除螨仪
A1: 时间 | B1: 国家 | C1: 数量 | D1: 售价 | E1: 销售额 | F1: 单个毛利 | G1: 广告预算 | H1: 实际广告 | I1: 活动费 | J1: 毛利 | K1: 毛利率 | L1: 毛利(RMB) | M1: 销售额(RMB) | N1: 广告占比 | O1: 广告订单 | P1: 自然订单 | Q1: 广告订单占比 | R1: ACOS
A2: 2025/7/8 - 2025/7/11 | B2: DE | C2: =SUMIF(B11:B1000,B2,C11:C1000) | D2: 55.85 | E2: =SUMIF(B11:B1000,B2,E11:E1000) | G2: =SUMIF(B11:B1000,B2,G11:G1000) | H2: =SUMIF(B11:B1000,B2,H11:H1000) | I2: =SUMIF(B11:B1000,B2,I11:I1000) | J2: =SUMIF(B11:B1000,B2,J11:J1000) | K2: =J2/E2 | L2: =SUMIF(B11:B1000,B2,L11:L1000) | M2: =SUMIF(B11:B1000,B2,M11:M1000) | N2: =H2/E2 | O2: =SUMIF(B11:B1000,B2,O11:O1000) | P2: =C2-O2 | Q2: =O2/C2 | R2: =H2/(E2*Q2)
B3: FR | C3: =SUMIF(B12:B1001,B3,C12:C1001) | D3: 58 | E3: =SUMIF(B12:B1001,B3,E12:E1001) | G3: =SUMIF(B12:B1001,B3,G12:G1001) | H3: =SUMIF(B12:B1001,B3,H12:H1001) | I3: =SUMIF(B12:B1001,B3,I12:I1001) | J3: =SUMIF(B12:B1001,B3,J12:J1001) | K3: =J3/E3 | L3: =SUMIF(B12:B1001,B3,L12:L1001) | M3: =SUMIF(B12:B1001,B3,M12:M1001) | N3: =H3/E3 | O3: =SUMIF(B12:B1001,B3,O12:O1001) | P3: =C3-O3 | Q3: =O3/C3 | R3: =H3/(E3*Q3)
B4: IT | C4: =SUMIF(B13:B1002,B4,C13:C1002) | D4: 58.8 | E4: =SUMIF(B13:B1002,B4,E13:E1002) | G4: =SUMIF(B13:B1002,B4,G13:G1002) | H4: =SUMIF(B13:B1002,B4,H13:H1002) | I4: =SUMIF(B13:B1002,B4,I13:I1002) | J4: =SUMIF(B13:B1002,B4,J13:J1002) | K4: =J4/E4 | L4: =SUMIF(B13:B1002,B4,L13:L1002) | M4: =SUMIF(B13:B1002,B4,M13:M1002) | N4: =H4/E4 | O4: =SUMIF(B13:B1002,B4,O13:O1002) | P4: =C4-O4 | Q4: =O4/C4 | R4: =H4/(E4*Q4)
B5: ES | C5: =SUMIF(B14:B1003,B5,C14:C1003) | D5: 59.35 | E5: =SUMIF(B14:B1003,B5,E14:E1003) | G5: =SUMIF(B14:B1003,B5,G14:G1003) | H5: =SUMIF(B14:B1003,B5,H14:H1003) | I5: =SUMIF(B14:B1003,B5,I14:I1003) | J5: =SUMIF(B14:B1003,B5,J14:J1003) | K5: =J5/E5 | L5: =SUMIF(B14:B1003,B5,L14:L1003) | M5: =SUMIF(B14:B1003,B5,M14:M1003) | N5: =H5/E5 | O5: =SUMIF(B14:B1003,B5,O14:O1003) | P5: =C5-O5 | Q5: =O5/C5 | R5: =H5/(E5*Q5)
B6: UK | C6: =SUMIF(B15:B1004,B6,C15:C1004) | D6: 67.99 | E6: =SUMIF(B15:B1004,B6,E15:E1004) | G6: =SUMIF(B15:B1004,B6,G15:G1004) | H6: =SUMIF(B15:B1004,B6,H15:H1004) | I6: =SUMIF(B15:B1004,B6,I15:I1004) | J6: =SUMIF(B15:B1004,B6,J15:J1004) | K6: =J6/E6 | L6: =SUMIF(B15:B1004,B6,L15:L1004) | M6: =SUMIF(B15:B1004,B6,M15:M1004) | N6: =H6/E6 | O6: =SUMIF(B15:B1004,B6,O15:O1004) | P6: =C6-O6 | Q6: =O6/C6 | R6: =H6/(E6*Q6)
B7: US | C7: =SUMIF(B16:B1005,B7,C16:C1005) | D7: 49.99 | E7: =SUMIF(B16:B1005,B7,E16:E1005) | G7: =SUMIF(B16:B1005,B7,G16:G1005) | H7: =SUMIF(B16:B1005,B7,H16:H1005) | I7: =SUMIF(B16:B1005,B7,I16:I1005) | J7: =SUMIF(B16:B1005,B7,J16:J1005) | K7: =J7/E7 | L7: =SUMIF(B16:B1005,B7,L16:L1005) | M7: =SUMIF(B16:B1005,B7,M16:M1005) | N7: =H7/E7 | O7: =SUMIF(B16:B1005,B7,O16:O1005) | P7: =C7-O7 | Q7: =O7/C7 | R7: =H7/(E7*Q7)
B8: 汇总 | C8: =SUM(C2:C7) | K8: =L8/M8 | L8: =SUM(L2:L7) | M8: =SUM(M2:M7) | O8: =SUM(O2:O7) | P8: =C8-O8 | Q8: =O8/C8
A10: 时间 | B10: 国家 | C10: 数量 | D10: 售价 | E10: 销售额 | F10: 单个毛利 | G10: 广告预算 | H10: 实际广告 | I10: 活动费 | J10: 毛利 | K10: 毛利率 | L10: 毛利(RMB) | M10: 销售额(RMB) | N10: 广告占比 | O10: 广告订单 | P10: 自然订单 | Q10: 广告订单占比 | R10: ACOS
A11: 45846 | B11: DE | C11: 27 | D11: 55.85 | E11: =C11*D11 | F11: 2.5 | G11: =C11*8 | H11: 141.95 | I11: =E11*0.025 | J11: =F11*C11+G11-H11-I11 | K11: =J11/E11 | L11: =J11*8 | M11: =E11*8 | N11: =H11/E11 | O11: 14 | P11: =C11-O11 | Q11: =O11/C11 | R11: =H11/(E11*Q11)
B12: FR | C12: 3 | D12: 58 | E12: =C12*D12 | F12: -1.7 | G12: =C12*8 | H12: 9.29 | I12: =E12*0.025 | J12: =F12*C12+G12-H12-I12 | K12: =J12/E12 | L12: =J12*8 | M12: =E12*8 | N12: =H12/E12 | O12: 2 | P12: =C12-O12 | Q12: =O12/C12 | R12: =H12/(E12*Q12)
B13: IT | C13: 8 | D13: 58.8 | E13: =C13*D13 | F13: 1.9 | G13: =C13*8 | H13: 147.26 | I13: =E13*0.025 | J13: =F13*C13+G13-H13-I13 | K13: =J13/E13 | L13: =J13*8 | M13: =E13*8 | N13: =H13/E13 | O13: 8 | P13: =C13-O13 | Q13: =O13/C13 | R13: =H13/(E13*Q13)
B14: ES | C14: 17 | D14: 59.35 | E14: =C14*D14 | F14: 2.53 | G14: =C14*8 | H14: 280.15 | I14: =E14*0.025 | J14: =F14*C14+G14-H14-I14 | K14: =J14/E14 | L14: =J14*8 | M14: =E14*8 | N14: =H14/E14 | O14: 18 | P14: =C14-O14 | Q14: =O14/C14 | R14: =H14/(E14*Q14)
B15: UK | C15: 29 | D15: 67.99 | E15: =C15*D15 | F15: 12.5 | G15: =C15*10 | H15: 178.07 | I15: =E15*0.025 | J15: =F15*C15+G15-H15-I15 | K15: =J15/E15 | L15: =J15*9 | M15: =E15*9 | N15: =H15/E15 | O15: 17 | P15: =C15-O15 | Q15: =O15/C15 | R15: =H15/(E15*Q15)
B16: US | C16: 20 | D16: 49.99 | E16: =C16*D16 | F16: 6.43 | H16: 236.38 | I16: 25 | J16: =C16*F16-H16-I16 | K16: =J16/E16 | L16: =J16*7 | M16: =E16*7 | N16: =H16/E16 | O16: 15 | P16: =C16-O16 | Q16: =O16/C16 | R16: =H16/(E16*Q16)
B17: 汇总 | C17: =SUM(C11:C16) | K17: =L17/M17 | L17: =SUM(L11:L16) | M17: =SUM(M11:M16) | O17: =SUM(O11:O16) | P17: =C17-O17 | Q17: =O17/C17
A19: 时间 | B19: 国家 | C19: 数量 | D19: 售价 | E19: 销售额 | F19: 单个毛利 | G19: 广告预算 | H19: 实际广告 | I19: 活动费 | J19: 毛利 | K19: 毛利率 | L19: 毛利(RMB) | M19: 销售额(RMB) | N19: 广告占比 | O19: 广告订单 | P19: 自然订单 | Q19: 广告订单占比 | R19: ACOS
A20: 45847 | B20: DE | C20: 23 | D20: 55.85 | E20: =C20*D20 | F20: =(6*2.5+17*6.5)/23 | G20: =C20*8 | H20: 144.7 | I20: =E20*0.025 | J20: =F20*C20+G20-H20-I20 | K20: =J20/E20 | L20: =J20*8 | M20: =E20*8 | N20: =H20/E20 | O20: 8 | P20: =C20-O20 | Q20: =O20/C20 | R20: =H20/(E20*Q20)
B21: FR | C21: 2 | D21: 58 | E21: =C21*D21 | F21: -1.7 | G21: =C21*8 | H21: 7.63 | I21: =E21*0.025 | J21: =F21*C21+G21-H21-I21 | K21: =J21/E21 | L21: =J21*8 | M21: =E21*8 | N21: =H21/E21 | O21: 0 | P21: =C21-O21 | Q21: =O21/C21 | R21: =H21/(E21*Q21)
B22: IT | C22: 28 | D22: 58.8 | E22: =C22*D22 | F22: =(6*1.9+21*6.23)/27 | G22: =C22*8 | H22: 142.02 | I22: =E22*0.025 | J22: =F22*C22+G22-H22-I22 | K22: =J22/E22 | L22: =J22*8 | M22: =E22*8 | N22: =H22/E22 | O22: 6 | P22: =C22-O22 | Q22: =O22/C22 | R22: =H22/(E22*Q22)
B23: ES | C23: 27 | D23: 59.35 | E23: =C23*D23 | F23: =(6*2.53+21*6.78)/27 | G23: =C23*8 | H23: 165.58 | I23: =E23*0.025 | J23: =F23*C23+G23-H23-I23 | K23: =J23/E23 | L23: =J23*8 | M23: =E23*8 | N23: =H23/E23 | O23: 7 | P23: =C23-O23 | Q23: =O23/C23 | R23: =H23/(E23*Q23)
B24: UK | C24: 16 | D24: 67.99 | E24: =67.99*12+80.61*4 | F24: =(21*4+12.5*12)/16 | G24: =C24*10 | H24: 120.44 | I24: =E24*0.025 | J24: =F24*C24+G24-H24-I24 | K24: =J24/E24 | L24: =J24*9 | M24: =E24*9 | N24: =H24/E24 | O24: 7 | P24: =C24-O24 | Q24: =O24/C24 | R24: =H24/(E24*Q24)
B25: US | C25: 23 | D25: 49.99 | E25: =C25*D25 | F25: 6.43 | H25: 200.8 | I25: 25 | J25: =C25*F25-H25-I25 | K25: =J25/E25 | L25: =J25*7 | M25: =E25*7 | N25: =H25/E25 | O25: 8 | P25: =C25-O25 | Q25: =O25/C25 | R25: =H25/(E25*Q25)
B26: 汇总 | C26: =SUM(C20:C25) | K26: =L26/M26 | L26: =SUM(L20:L25) | M26: =SUM(M20:M25) | O26: =SUM(O20:O25) | P26: =C26-O26 | Q26: =O26/C26
A28: 时间 | B28: 国家 | C28: 数量 | D28: 售价 | E28: 销售额 | F28: 单个毛利 | G28: 广告预算 | H28: 实际广告 | I28: 活动费 | J28: 毛利 | K28: 毛利率 | L28: 毛利(RMB) | M28: 销售额(RMB) | N28: 广告占比 | O28: 广告订单 | P28: 自然订单 | Q28: 广告订单占比 | R28: ACOS
A29: 45848 | B29: DE | C29: 24 | D29: 55.85 | E29: =C29*D29 | F29: 6.5 | G29: =C29*8 | H29: 176.46 | I29: =E29*0.025 | J29: =F29*C29+G29-H29-I29 | K29: =J29/E29 | L29: =J29*8 | M29: =E29*8 | N29: =H29/E29 | O29: 14 | P29: =C29-O29 | Q29: =O29/C29 | R29: =H29/(E29*Q29)
B30: FR | C30: 2 | D30: 58 | E30: =C30*D30 | F30: -1.7 | G30: =C30*8 | H30: 28.27 | I30: =E30*0.025 | J30: =F30*C30+G30-H30-I30 | K30: =J30/E30 | L30: =J30*8 | M30: =E30*8 | N30: =H30/E30 | O30: 0 | P30: =C30-O30 | Q30: =O30/C30 | R30: =H30/(E30*Q30)
B31: IT | C31: 29 | D31: 58.8 | E31: =C31*D31 | F31: 6.23 | G31: =C31*8 | H31: 103.98 | I31: =E31*0.025 | J31: =F31*C31+G31-H31-I31 | K31: =J31/E31 | L31: =J31*8 | M31: =E31*8 | N31: =H31/E31 | O31: 11 | P31: =C31-O31 | Q31: =O31/C31 | R31: =H31/(E31*Q31)
B32: ES | C32: 17 | D32: 59.35 | E32: =C32*D32 | F32: 6.78 | G32: =C32*8 | H32: 128.06 | I32: =E32*0.025 | J32: =F32*C32+G32-H32-I32 | K32: =J32/E32 | L32: =J32*8 | M32: =E32*8 | N32: =H32/E32 | O32: 7 | P32: =C32-O32 | Q32: =O32/C32 | R32: =H32/(E32*Q32)
B33: UK | C33: 9 | D33: 80.61 | E33: =C33*D33 | F33: 21 | G33: =C33*10 | H33: 64.94 | I33: =E33*0.025 | J33: =F33*C33+G33-H33-I33 | K33: =J33/E33 | L33: =J33*9 | M33: =E33*9 | N33: =H33/E33 | O33: 5 | P33: =C33-O33 | Q33: =O33/C33 | R33: =H33/(E33*Q33)
B34: US | C34: 15 | D34: 49.99 | E34: =C34*D34 | F34: 6.43 | H34: 122.35 | I34: 25 | J34: =C34*F34-H34-I34 | K34: =J34/E34 | L34: =J34*7 | M34: =E34*7 | N34: =H34/E34 | O34: 3 | P34: =C34-O34 | Q34: =O34/C34 | R34: =H34/(E34*Q34)
B35: 汇总 | C35: =SUM(C29:C34) | K35: =L35/M35 | L35: =SUM(L29:L34) | M35: =SUM(M29:M34) | O35: =SUM(O29:O34) | P35: =C35-O35 | Q35: =O35/C35
A37: 时间 | B37: 国家 | C37: 数量 | D37: 售价 | E37: 销售额 | F37: 单个毛利 | G37: 广告预算 | H37: 实际广告 | I37: 活动费 | J37: 毛利 | K37: 毛利率 | L37: 毛利(RMB) | M37: 销售额(RMB) | N37: 广告占比 | O37: 广告订单 | P37: 自然订单 | Q37: 广告订单占比 | R37: ACOS
A38: 45849 | B38: DE | C38: 29 | D38: 55.85 | E38: =C38*D38 | F38: =(6.5*12+10.5*17)/29 | G38: =C38*8 | H38: 147.15 | I38: =E38*0.025 | J38: =F38*C38+G38-H38-I38 | K38: =J38/E38 | L38: =J38*8 | M38: =E38*8 | N38: =H38/E38 | O38: 15 | P38: =C38-O38 | Q38: =O38/C38 | R38: =H38/(E38*Q38)
B39: FR | C39: 1 | D39: 58 | E39: =C39*D39 | F39: -1.7 | G39: =C39*8 | H39: 19.33 | I39: =E39*0.025 | J39: =F39*C39+G39-H39-I39 | K39: =J39/E39 | L39: =J39*8 | M39: =E39*8 | N39: =H39/E39 | O39: 1 | P39: =C39-O39 | Q39: =O39/C39 | R39: =H39/(E39*Q39)
B40: IT | C40: 19 | D40: 58.8 | E40: =C40*D40 | F40: =(6*6.23+10.48*13)/C40 | G40: =C40*8 | H40: 79.98 | I40: =E40*0.025 | J40: =F40*C40+G40-H40-I40 | K40: =J40/E40 | L40: =J40*8 | M40: =E40*8 | N40: =H40/E40 | O40: 5 | P40: =C40-O40 | Q40: =O40/C40 | R40: =H40/(E40*Q40)
B41: ES | C41: 16 | D41: 59.35 | E41: =C41*D41 | F41: =(6*6.78+11.3*10)/C41 | G41: =C41*8 | H41: 96.84 | I41: =E41*0.025 | J41: =F41*C41+G41-H41-I41 | K41: =J41/E41 | L41: =J41*8 | M41: =E41*8 | N41: =H41/E41 | O41: 4 | P41: =C41-O41 | Q41: =O41/C41 | R41: =H41/(E41*Q41)
B42: UK | C42: 7 | D42: 80.61 | E42: =C42*D42 | F42: 21 | G42: =C42*10 | H42: 39.46 | I42: =E42*0.025 | J42: =F42*C42+G42-H42-I42 | K42: =J42/E42 | L42: =J42*9 | M42: =E42*9 | N42: =H42/E42 | O42: 2 | P42: =C42-O42 | Q42: =O42/C42 | R42: =H42/(E42*Q42)
B43: US | C43: 25 | D43: 49.99 | E43: =C43*D43 | F43: 6.43 | H43: 132.78 | I43: 25 | J43: =C43*F43-H43-I43 | K43: =J43/E43 | L43: =J43*7 | M43: =E43*7 | N43: =H43/E43 | O43: 14 | P43: =C43-O43 | Q43: =O43/C43 | R43: =H43/(E43*Q43)
B44: 汇总 | C44: =SUM(C38:C43) | K44: =L44/M44 | L44: =SUM(L38:L43) | M44: =SUM(M38:M43) | O44: =SUM(O38:O43) | P44: =C44-O44 | Q44: =O44/C44
...

Sheet SKU001MV2501
A1: 汇总 | B1: 国家 | C1: 数量 | D1: 售价 | E1: 销售额 | F1: 毛利 | G1: 广告预算 | H1: 实际广告 | I1: 活动费 | J1: 毛利 | K1: 毛利率 | L1: 毛利(RMB) | M1: 销售额(RMB) | N1: 广告占比 | O1: 广告订单 | P1: 自然订单 | Q1: 广告订单占比 | R1: ACOS | S1: 折扣
A2: 开始时间 | B2: DE | C2: =SUMIFS($C$10:$C$3498,$B$10:$B$3498,B2,$A$10:$A$3498,">="&$A$3,$A$10:$A$3498,"<="&$A$5) | D2: 55.85 | E2: =SUMIFS($E$10:$E$3498,$B$10:$B$3498,B2,$A$10:$A$3498,">="&$A$3,$A$10:$A$3498,"<="&$A$5) | G2: =SUMIFS($G$10:$G$3498,$B$10:$B$3498,B2,$A$10:$A$3498,">="&$A$3,$A$10:$A$3498,"<="&$A$5) | H2: =SUMIFS($H$10:$H$3498,$B$10:$B$3498,B2,$A$10:$A$3498,">="&$A$3,$A$10:$A$3498,"<="&$A$5) | I2: =SUMIFS($I$10:$I$3498,$B$10:$B$3498,B2,$A$10:$A$3498,">="&$A$3,$A$10:$A$3498,"<="&$A$5) | J2: =SUMIFS($J$10:$J$3498,$B$10:$B$3498,B2,$A$10:$A$3498,">="&$A$3,$A$10:$A$3498,"<="&$A$5) | K2: =J2/E2 | L2: =SUMIFS($L$10:$L$3498,$B$10:$B$3498,B2,$A$10:$A$3498,">="&$A$3,$A$10:$A$3498,"<="&$A$5) | M2: =SUMIFS($M$10:$M$3498,$B$10:$B$3498,B2,$A$10:$A$3498,">="&$A$3,$A$10:$A$3498,"<="&$A$5) | N2: =H2/E2 | O2: =SUMIFS($O$10:$O$3498,$B$10:$B$3498,B2,$A$10:$A$3498,">="&$A$3,$A$10:$A$3498,"<="&$A$5) | P2: =C2-O2 | Q2: =O2/C2 | R2: =H2/(E2*Q2)
A3: 46082 | B3: FR | C3: =SUMIFS($C$10:$C$3498,$B$10:$B$3498,B3,$A$10:$A$3498,">="&$A$3,$A$10:$A$3498,"<="&$A$5) | D3: 58 | E3: =SUMIFS($E$10:$E$3498,$B$10:$B$3498,B3,$A$10:$A$3498,">="&$A$3,$A$10:$A$3498,"<="&$A$5) | G3: =SUMIFS($G$10:$G$3498,$B$10:$B$3498,B3,$A$10:$A$3498,">="&$A$3,$A$10:$A$3498,"<="&$A$5) | H3: =SUMIFS($H$10:$H$3498,$B$10:$B$3498,B3,$A$10:$A$3498,">="&$A$3,$A$10:$A$3498,"<="&$A$5) | I3: =SUMIFS($I$10:$I$3498,$B$10:$B$3498,B3,$A$10:$A$3498,">="&$A$3,$A$10:$A$3498,"<="&$A$5) | J3: =SUMIFS($J$10:$J$3498,$B$10:$B$3498,B3,$A$10:$A$3498,">="&$A$3,$A$10:$A$3498,"<="&$A$5) | K3: =J3/E3 | L3: =SUMIFS($L$10:$L$3498,$B$10:$B$3498,B3,$A$10:$A$3498,">="&$A$3,$A$10:$A$3498,"<="&$A$5) | M3: =SUMIFS($M$10:$M$3498,$B$10:$B$3498,B3,$A$10:$A$3498,">="&$A$3,$A$10:$A$3498,"<="&$A$5) | N3: =H3/E3 | O3: =SUMIFS($O$10:$O$3498,$B$10:$B$3498,B3,$A$10:$A$3498,">="&$A$3,$A$10:$A$3498,"<="&$A$5) | P3: =C3-O3 | Q3: =O3/C3 | R3: =H3/(E3*Q3)
A4: 结束时间 | B4: IT | C4: =SUMIFS($C$10:$C$3498,$B$10:$B$3498,B4,$A$10:$A$3498,">="&$A$3,$A$10:$A$3498,"<="&$A$5) | D4: 58.8 | E4: =SUMIFS($E$10:$E$3498,$B$10:$B$3498,B4,$A$10:$A$3498,">="&$A$3,$A$10:$A$3498,"<="&$A$5) | G4: =SUMIFS($G$10:$G$3498,$B$10:$B$3498,B4,$A$10:$A$3498,">="&$A$3,$A$10:$A$3498,"<="&$A$5) | H4: =SUMIFS($H$10:$H$3498,$B$10:$B$3498,B4,$A$10:$A$3498,">="&$A$3,$A$10:$A$3498,"<="&$A$5) | I4: =SUMIFS($I$10:$I$3498,$B$10:$B$3498,B4,$A$10:$A$3498,">="&$A$3,$A$10:$A$3498,"<="&$A$5) | J4: =SUMIFS($J$10:$J$3498,$B$10:$B$3498,B4,$A$10:$A$3498,">="&$A$3,$A$10:$A$3498,"<="&$A$5) | K4: =J4/E4 | L4: =SUMIFS($L$10:$L$3498,$B$10:$B$3498,B4,$A$10:$A$3498,">="&$A$3,$A$10:$A$3498,"<="&$A$5) | M4: =SUMIFS($M$10:$M$3498,$B$10:$B$3498,B4,$A$10:$A$3498,">="&$A$3,$A$10:$A$3498,"<="&$A$5) | N4: =H4/E4 | O4: =SUMIFS($O$10:$O$3498,$B$10:$B$3498,B4,$A$10:$A$3498,">="&$A$3,$A$10:$A$3498,"<="&$A$5) | P4: =C4-O4 | Q4: =O4/C4 | R4: =H4/(E4*Q4)
A5: 46112 | B5: ES | C5: =SUMIFS($C$10:$C$3498,$B$10:$B$3498,B5,$A$10:$A$3498,">="&$A$3,$A$10:$A$3498,"<="&$A$5) | D5: 59.35 | E5: =SUMIFS($E$10:$E$3498,$B$10:$B$3498,B5,$A$10:$A$3498,">="&$A$3,$A$10:$A$3498,"<="&$A$5) | G5: =SUMIFS($G$10:$G$3498,$B$10:$B$3498,B5,$A$10:$A$3498,">="&$A$3,$A$10:$A$3498,"<="&$A$5) | H5: =SUMIFS($H$10:$H$3498,$B$10:$B$3498,B5,$A$10:$A$3498,">="&$A$3,$A$10:$A$3498,"<="&$A$5) | I5: =SUMIFS($I$10:$I$3498,$B$10:$B$3498,B5,$A$10:$A$3498,">="&$A$3,$A$10:$A$3498,"<="&$A$5) | J5: =SUMIFS($J$10:$J$3498,$B$10:$B$3498,B5,$A$10:$A$3498,">="&$A$3,$A$10:$A$3498,"<="&$A$5) | K5: =J5/E5 | L5: =SUMIFS($L$10:$L$3498,$B$10:$B$3498,B5,$A$10:$A$3498,">="&$A$3,$A$10:$A$3498,"<="&$A$5) | M5: =SUMIFS($M$10:$M$3498,$B$10:$B$3498,B5,$A$10:$A$3498,">="&$A$3,$A$10:$A$3498,"<="&$A$5) | N5: =H5/E5 | O5: =SUMIFS($O$10:$O$3498,$B$10:$B$3498,B5,$A$10:$A$3498,">="&$A$3,$A$10:$A$3498,"<="&$A$5) | P5: =C5-O5 | Q5: =O5/C5 | R5: =H5/(E5*Q5)
A6: 即日 | B6: UK | C6: =SUMIFS($C$10:$C$3498,$B$10:$B$3498,B6,$A$10:$A$3498,">="&$A$3,$A$10:$A$3498,"<="&$A$5) | D6: 55.3 | E6: =SUMIFS($E$10:$E$3498,$B$10:$B$3498,B6,$A$10:$A$3498,">="&$A$3,$A$10:$A$3498,"<="&$A$5) | G6: =SUMIFS($G$10:$G$3498,$B$10:$B$3498,B6,$A$10:$A$3498,">="&$A$3,$A$10:$A$3498,"<="&$A$5) | H6: =SUMIFS($H$10:$H$3498,$B$10:$B$3498,B6,$A$10:$A$3498,">="&$A$3,$A$10:$A$3498,"<="&$A$5) | I6: =SUMIFS($I$10:$I$3498,$B$10:$B$3498,B6,$A$10:$A$3498,">="&$A$3,$A$10:$A$3498,"<="&$A$5) | J6: =SUMIFS($J$10:$J$3498,$B$10:$B$3498,B6,$A$10:$A$3498,">="&$A$3,$A$10:$A$3498,"<="&$A$5) | K6: =J6/E6 | L6: =SUMIFS($L$10:$L$3498,$B$10:$B$3498,B6,$A$10:$A$3498,">="&$A$3,$A$10:$A$3498,"<="&$A$5) | M6: =SUMIFS($M$10:$M$3498,$B$10:$B$3498,B6,$A$10:$A$3498,">="&$A$3,$A$10:$A$3498,"<="&$A$5) | N6: =H6/E6 | O6: =SUMIFS($O$10:$O$3498,$B$10:$B$3498,B6,$A$10:$A$3498,">="&$A$3,$A$10:$A$3498,"<="&$A$5) | P6: =C6-O6 | Q6: =O6/C6 | R6: =H6/(E6*Q6)
A7: =NOW() | B7: US | C7: =SUMIFS($C$10:$C$3498,$B$10:$B$3498,B7,$A$10:$A$3498,">="&$A$3,$A$10:$A$3498,"<="&$A$5) | D7: 49.99 | E7: =SUMIFS($E$10:$E$3498,$B$10:$B$3498,B7,$A$10:$A$3498,">="&$A$3,$A$10:$A$3498,"<="&$A$5) | G7: =SUMIFS($G$10:$G$3498,$B$10:$B$3498,B7,$A$10:$A$3498,">="&$A$3,$A$10:$A$3498,"<="&$A$5) | H7: =SUMIFS($H$10:$H$3498,$B$10:$B$3498,B7,$A$10:$A$3498,">="&$A$3,$A$10:$A$3498,"<="&$A$5) | I7: =SUMIFS($I$10:$I$3498,$B$10:$B$3498,B7,$A$10:$A$3498,">="&$A$3,$A$10:$A$3498,"<="&$A$5) | J7: =SUMIFS($J$10:$J$3498,$B$10:$B$3498,B7,$A$10:$A$3498,">="&$A$3,$A$10:$A$3498,"<="&$A$5) | K7: =J7/E7 | L7: =SUMIFS($L$10:$L$3498,$B$10:$B$3498,B7,$A$10:$A$3498,">="&$A$3,$A$10:$A$3498,"<="&$A$5) | M7: =SUMIFS($M$10:$M$3498,$B$10:$B$3498,B7,$A$10:$A$3498,">="&$A$3,$A$10:$A$3498,"<="&$A$5) | N7: =H7/E7 | O7: =SUMIFS($O$10:$O$3498,$B$10:$B$3498,B7,$A$10:$A$3498,">="&$A$3,$A$10:$A$3498,"<="&$A$5) | P7: =C7-O7 | Q7: =O7/C7 | R7: =H7/(E7*Q7)
B8: 汇总 | C8: =SUM(C2:C7) | K8: =L8/M8 | L8: =SUM(L2:L7) | M8: =SUM(M2:M7) | O8: =SUM(O2:O7) | P8: =C8-O8 | Q8: =O8/C8
B9: 分割线
A10: 时间 | B10: 国家 | C10: 数量 | D10: 售价 | E10: 销售额 | F10: 毛利 | G10: 广告预算 | H10: 实际广告 | I10: 活动费 | J10: 毛利 | K10: 毛利率 | L10: 毛利(RMB) | M10: 销售额(RMB) | N10: 广告占比 | O10: 广告订单 | P10: 自然订单 | Q10: 广告订单占比 | R10: ACOS | S10: COUPON
A11: 46019 | B11: DE | D11: 55.85 | E11: 0 | F11: 15.78 | G11: 0 | I11: 0 | J11: 0 | K11: 0 | L11: 0 | M11: 0 | N11: 0 | P11: 0 | Q11: 0 | R11: 0 | S11: VC-0%
A12: 46019 | B12: FR | D12: 58 | E12: 0 | F12: 15.88 | G12: 0 | I12: 0 | J12: 0 | K12: 0 | L12: 0 | M12: 0 | N12: 0 | P12: 0 | Q12: 0 | R12: 0 | S12: VC-0%
A13: 46019 | B13: IT | C13: 1 | D13: 58.8 | E13: 58.8 | F13: 16.27 | G13: 8 | I13: 1.47 | J13: 22.8 | K13: 0.3877551 | L13: 182.4 | M13: 470.4 | N13: 0 | P13: 1 | Q13: 0 | R13: 0 | S13: VC-0%
A14: 46019 | B14: ES | D14: 59.35 | E14: 0 | F14: 15.72 | G14: 0 | I14: 0 | J14: 0 | K14: 0 | L14: 0 | M14: 0 | N14: 0 | P14: 0 | Q14: 0 | R14: 0 | S14: VC-0%
A15: 46019 | B15: UK | C15: 1 | D15: 52.3 | E15: 52.3 | F15: 14.72 | G15: 8 | H15: 14.18 | I15: 1.3075 | J15: 7.2325 | K15: 0.13828872 | L15: 65.0925 | M15: 470.7 | N15: 0.27112811 | O15: 0 | P15: 1 | Q15: 0 | R15: 0 | S15: VC-0%
A16: 46019 | B16: 汇总 | C16: 2 | E16: 111.1 | F16: 78.37 | J16: 30.0325 | K16: 0.27031953 | L16: 247.4925 | M16: 941.1 | O16: 0 | P16: 2 | Q16: 0
B17: 分割线
A18: 时间 | B18: 国家 | C18: 数量 | D18: 售价 | E18: 销售额 | F18: 毛利 | G18: 广告预算 | H18: 实际广告 | I18: 活动费 | J18: 毛利 | K18: 毛利率 | L18: 毛利(RMB) | M18: 销售额(RMB) | N18: 广告占比 | O18: 广告订单 | P18: 自然订单 | Q18: 广告订单占比 | R18: ACOS | S18: COUPON
A19: 46020 | B19: DE | D19: 55.85 | E19: 0 | F19: 15.78 | G19: 0 | I19: 0 | J19: 0 | K19: 0 | L19: 0 | M19: 0 | N19: 0 | P19: 0 | Q19: 0 | R19: 0 | S19: VC-0%
A20: 46020 | B20: FR | D20: 58 | E20: 0 | F20: 15.88 | G20: 0 | I20: 0 | J20: 0 | K20: 0 | L20: 0 | M20: 0 | N20: 0 | P20: 0 | Q20: 0 | R20: 0 | S20: VC-0%
A21: 46020 | B21: IT | D21: 58.8 | E21: 0 | F21: 16.27 | G21: 0 | I21: 0 | J21: 0 | K21: 0 | L21: 0 | M21: 0 | N21: 0 | P21: 0 | Q21: 0 | R21: 0 | S21: VC-0%
A22: 46020 | B22: ES | D22: 59.35 | E22: 0 | F22: 15.72 | G22: 0 | I22: 0 | J22: 0 | K22: 0 | L22: 0 | M22: 0 | N22: 0 | P22: 0 | Q22: 0 | R22: 0 | S22: VC-0%
A23: 46020 | B23: UK | C23: 3 | D23: 52.3 | E23: 156.9 | F23: 5.6 | G23: 24 | H23: 15.72 | I23: 3.9225 | J23: 21.1575 | K23: 0.13484704 | L23: 190.4175 | M23: 1412.1 | N23: 0.1001912 | O23: 0 | P23: 3 | Q23: 0 | R23: 0 | S23: VC-12%
A24: 46020 | B24: 汇总 | C24: 3 | E24: 156.9 | F24: 69.25 | J24: 21.1575 | K24: 0.13484704 | L24: 190.4175 | M24: 1412.1 | O24: 0 | P24: 3 | Q24: 0
B25: 分割线
A26: 时间 | B26: 国家 | C26: 数量 | D26: 售价 | E26: 销售额 | F26: 毛利 | G26: 广告预算 | H26: 实际广告 | I26: 活动费 | J26: 毛利 | K26: 毛利率 | L26: 毛利(RMB) | M26: 销售额(RMB) | N26: 广告占比 | O26: 广告订单 | P26: 自然订单 | Q26: 广告订单占比 | R26: ACOS | S26: COUPON
A27: 46021 | B27: DE | C27: 2 | D27: 55.85 | E27: 111.7 | F27: 15.78 | G27: 16 | I27: 2.7925 | J27: 44.7675 | K27: 0.40078335 | L27: 358.14 | M27: 893.6 | N27: 0 | P27: 2 | Q27: 0 | R27: 0 | S27: VC-0%
A28: 46021 | B28: FR | D28: 58 | E28: 0 | F28: 15.88 | G28: 0 | I28: 0 | J28: 0 | K28: 0 | L28: 0 | M28: 0 | N28: 0 | P28: 0 | Q28: 0 | R28: 0 | S28: VC-0%
A29: 46021 | B29: IT | D29: 58.8 | E29: 0 | F29: 16.27 | G29: 0 | I29: 0 | J29: 0 | K29: 0 | L29: 0 | M29: 0 | N29: 0 | P29: 0 | Q29: 0 | R29: 0 | S29: VC-0%
A30: 46021 | B30: ES | D30: 59.35 | E30: 0 | F30: 15.72 | G30: 0 | I30: 0 | J30: 0 | K30: 0 | L30: 0 | M30: 0 | N30: 0 | P30: 0 | Q30: 0 | R30: 0 | S30: VC-0%
A31: 46021 | B31: UK | C31: 3 | D31: 52.3 | E31: 156.9 | F31: 5.6 | G31: 24 | H31: 10.36 | I31: 3.9225 | J31: 26.5175 | K31: 0.16900892 | L31: 238.6575 | M31: 1412.1 | N31: 0.066029318 | O31: 2 | P31: 1 | Q31: 0.66666667 | R31: 0.099043977 | S31: VC-12%
A32: 46021 | B32: 汇总 | C32: 5 | E32: 268.6 | F32: 69.25 | J32: 71.285 | K32: 0.26539464 | L32: 596.7975 | M32: 2305.7 | O32: 2 | P32: 3 | Q32: 0.4
B33: 分割线
A34: 时间 | B34: 国家 | C34: 数量 | D34: 售价 | E34: 销售额 | F34: 毛利 | G34: 广告预算 | H34: 实际广告 | I34: 活动费 | J34: 毛利 | K34: 毛利率 | L34: 毛利(RMB) | M34: 销售额(RMB) | N34: 广告占比 | O34: 广告订单 | P34: 自然订单 | Q34: 广告订单占比 | R34: ACOS | S34: COUPON
A35: 46022 | B35: DE | D35: 55.85 | E35: 0 | F35: 15.78 | G35: 0 | H35: 0 | I35: 0 | J35: 0 | K35: 0 | L35: 0 | M35: 0 | N35: 0 | O35: 0 | P35: 0 | Q35: 0 | R35: 0 | S35: VC-0%
A36: 46022 | B36: FR | D36: 58 | E36: 0 | F36: 15.88 | G36: 0 | I36: 0 | J36: 0 | K36: 0 | L36: 0 | M36: 0 | N36: 0 | P36: 0 | Q36: 0 | R36: 0 | S36: VC-0%
A37: 46022 | B37: IT | C37: 1 | D37: 58.8 | E37: 58.8 | F37: 16.27 | G37: 8 | I37: 1.47 | J37: 22.8 | K37: 0.3877551 | L37: 182.4 | M37: 470.4 | N37: 0 | P37: 1 | Q37: 0 | R37: 0 | S37: VC-0%
A38: 46022 | B38: ES | C38: 1 | D38: 59.35 | E38: 59.35 | F38: 15.72 | G38: 8 | H38: 0.27 | I38: 1.48375 | J38: 21.96625 | K38: 0.37011373 | L38: 175.73 | M38: 474.8 | N38: 0.0045492839 | O38: 0 | P38: 1 | Q38: 0 | R38: 0 | S38: VC-0%
A39: 46022 | B39: UK | C39: 1 | D39: 52.3 | E39: 52.3 | F39: 14.72 | G39: 8 | H39: 12.88 | I39: 1.3075 | J39: 8.5325 | K39: 0.16314532 | L39: 76.7925 | M39: 470.7 | N39: 0.24627151 | O39: 0 | P39: 1 | Q39: 0 | R39: 0 | S39: VC-0%
A40: 46022 | B40: 汇总 | C40: 3 | E40: 170.45 | F40: 78.37 | J40: 53.29875 | K40: 0.31269434 | L40: 434.9225 | M40: 1415.9 | O40: 0 | P40: 3 | Q40: 0
...

Sheet 除-价格-毛利
A1: 国家 | B1: COUPON | C1: 利润 | D1: PO价 | E1: 售价
A2: DE | B2: VC-0% | C2: 15.78 | D2: 55.85 | E2: 67.99
A3: DE | B3: VC-5% | C3: 11.78 | D3: 55.85 | E3: 67.99
A4: DE | B4: VC-10% | C4: 7.78 | D4: 55.85 | E4: 67.99
A5: DE | B5: VC-15% | C5: 3.78 | D5: 55.85 | E5: 67.99
A6: DE | B6: BD-10.09 | C6: 5.69 | D6: 55.85 | E6: 67.99
A7: DE | B7: BD-12.97 | C7: 4.06 | D7: 55.85 | E7: 67.99
A8: FR | B8: VC-0% | C8: 15.01 | D8: 55.35 | E8: 67.99
A9: FR | B9: VC-5% | C9: 11.01 | D9: 55.35 | E9: 67.99
A10: FR | B10: VC-10% | C10: 7.01 | D10: 55.35 | E10: 67.99
A11: FR | B11: VC-15% | C11: 3.01 | D11: 55.35 | E11: 67.99
A12: FR | B12: BD-9.21 | C12: 6.67 | D12: 55.35 | E12: 67.99
A13: FR | B13: BD-5.87 | C13: 10.01 | D13: 55.35 | E13: 67.99
... A28: UK | B28: BD-10.42 | C28: 2.72 | D28: 48.3 | E28: 55.88

Sheet AP100A
A1: 汇总 | B1: 国家 | C1: 数量 | D1: 售价 | E1: 销售额 | F1: 毛利 | G1: 广告预算 | H1: 实际广告 | I1: 活动费 | J1: 毛利 | K1: 毛利率 | L1: 毛利(RMB) | M1: 销售额(RMB) | N1: 广告占比 | O1: 广告订单 | P1: 自然订单 | Q1: 广告订单占比 | R1: ACOS | S1: 折扣
A2: 开始时间 | B2: DE | C2: =SUMIFS($C$10:$C$3487,$B$10:$B$3487,B2,$A$10:$A$3487,">="&$A$3,$A$10:$A$3487,"<="&$A$5) | D2: 55.85 | E2: =SUMIFS($E$10:$E$3487,$B$10:$B$3487,B2,$A$10:$A$3487,">="&$A$3,$A$10:$A$3487,"<="&$A$5) | G2: =SUMIFS($G$10:$G$3487,$B$10:$B$3487,B2,$A$10:$A$3487,">="&$A$3,$A$10:$A$3487,"<="&$A$5) | H2: =SUMIFS($H$10:$H$3487,$B$10:$B$3487,B2,$A$10:$A$3487,">="&$A$3,$A$10:$A$3487,"<="&$A$5) | I2: =SUMIFS($I$10:$I$3487,$B$10:$B$3487,B2,$A$10:$A$3487,">="&$A$3,$A$10:$A$3487,"<="&$A$5) | J2: =SUMIFS($J$10:$J$3487,$B$10:$B$3487,B2,$A$10:$A$3487,">="&$A$3,$A$10:$A$3487,"<="&$A$5) | K2: =J2/E2 | L2: =SUMIFS($L$10:$L$3487,$B$10:$B$3487,B2,$A$10:$A$3487,">="&$A$3,$A$10:$A$3487,"<="&$A$5) | M2: =SUMIFS($M$10:$M$3487,$B$10:$B$3487,B2,$A$10:$A$3487,">="&$A$3,$A$10:$A$3487,"<="&$A$5) | N2: =H2/E2 | O2: =SUMIFS($O$10:$O$3487,$B$10:$B$3487,B2,$A$10:$A$3487,">="&$A$3,$A$10:$A$3487,"<="&$A$5) | P2: =C2-O2 | Q2: =O2/C2 | R2: =H2/(E2*Q2)
A3: 46082 | B3: FR | C3: =SUMIFS($C$10:$C$3487,$B$10:$B$3487,B3,$A$10:$A$3487,">="&$A$3,$A$10:$A$3487,"<="&$A$5) | D3: 58 | E3: =SUMIFS($E$10:$E$3487,$B$10:$B$3487,B3,$A$10:$A$3487,">="&$A$3,$A$10:$A$3487,"<="&$A$5) | G3: =SUMIFS($G$10:$G$3487,$B$10:$B$3487,B3,$A$10:$A$3487,">="&$A$3,$A$10:$A$3487,"<="&$A$5) | H3: =SUMIFS($H$10:$H$3487,$B$10:$B$3487,B3,$A$10:$A$3487,">="&$A$3,$A$10:$A$3487,"<="&$A$5) | I3: =SUMIFS($I$10:$I$3487,$B$10:$B$3487,B3,$A$10:$A$3487,">="&$A$3,$A$10:$A$3487,"<="&$A$5) | J3: =SUMIFS($J$10:$J$3487,$B$10:$B$3487,B3,$A$10:$A$3487,">="&$A$3,$A$10:$A$3487,"<="&$A$5) | K3: =J3/E3 | L3: =SUMIFS($L$10:$L$3487,$B$10:$B$3487,B3,$A$10:$A$3487,">="&$A$3,$A$10:$A$3487,"<="&$A$5) | M3: =SUMIFS($M$10:$M$3487,$B$10:$B$3487,B3,$A$10:$A$3487,">="&$A$3,$A$10:$A$3487,"<="&$A$5) | N3: =H3/E3 | O3: =SUMIFS($O$10:$O$3487,$B$10:$B$3487,B3,$A$10:$A$3487,">="&$A$3,$A$10:$A$3487,"<="&$A$5) | P3: =C3-O3 | Q3: =O3/C3 | R3: =H3/(E3*Q3)
A4: 结束时间 | B4: IT | C4: =SUMIFS($C$10:$C$3487,$B$10:$B$3487,B4,$A$10:$A$3487,">="&$A$3,$A$10:$A$3487,"<="&$A$5) | D4: 58.8 | E4: =SUMIFS($E$10:$E$3487,$B$10:$B$3487,B4,$A$10:$A$3487,">="&$A$3,$A$10:$A$3487,"<="&$A$5) | G4: =SUMIFS($G$10:$G$3487,$B$10:$B$3487,B4,$A$10:$A$3487,">="&$A$3,$A$10:$A$3487,"<="&$A$5) | H4: =SUMIFS($H$10:$H$3487,$B$10:$B$3487,B4,$A$10:$A$3487,">="&$A$3,$A$10:$A$3487,"<="&$A$5) | I4: =SUMIFS($I$10:$I$3487,$B$10:$B$3487,B4,$A$10:$A$3487,">="&$A$3,$A$10:$A$3487,"<="&$A$5) | J4: =SUMIFS($J$10:$J$3487,$B$10:$B$3487,B4,$A$10:$A$3487,">="&$A$3,$A$10:$A$3487,"<="&$A$5) | K4: =J4/E4 | L4: =SUMIFS($L$10:$L$3487,$B$10:$B$3487,B4,$A$10:$A$3487,">="&$A$3,$A$10:$A$3487,"<="&$A$5) | M4: =SUMIFS($M$10:$M$3487,$B$10:$B$3487,B4,$A$10:$A$3487,">="&$A$3,$A$10:$A$3487,"<="&$A$5) | N4: =H4/E4 | O4: =SUMIFS($O$10:$O$3487,$B$10:$B$3487,B4,$A$10:$A$3487,">="&$A$3,$A$10:$A$3487,"<="&$A$5) | P4: =C4-O4 | Q4: =O4/C4 | R4: =H4/(E4*Q4)
A5: 46112 | B5: ES | C5: =SUMIFS($C$10:$C$3487,$B$10:$B$3487,B5,$A$10:$A$3487,">="&$A$3,$A$10:$A$3487,"<="&$A$5) | D5: 59.35 | E5: =SUMIFS($E$10:$E$3487,$B$10:$B$3487,B5,$A$10:$A$3487,">="&$A$3,$A$10:$A$3487,"<="&$A$5) | G5: =SUMIFS($G$10:$G$3487,$B$10:$B$3487,B5,$A$10:$A$3487,">="&$A$3,$A$10:$A$3487,"<="&$A$5) | H5: =SUMIFS($H$10:$H$3487,$B$10:$B$3487,B5,$A$10:$A$3487,">="&$A$3,$A$10:$A$3487,"<="&$A$5) | I5: =SUMIFS($I$10:$I$3487,$B$10:$B$3487,B5,$A$10:$A$3487,">="&$A$3,$A$10:$A$3487,"<="&$A$5) | J5: =SUMIFS($J$10:$J$3487,$B$10:$B$3487,B5,$A$10:$A$3487,">="&$A$3,$A$10:$A$3487,"<="&$A$5) | K5: =J5/E5 | L5: =SUMIFS($L$10:$L$3487,$B$10:$B$3487,B5,$A$10:$A$3487,">="&$A$3,$A$10:$A$3487,"<="&$A$5) | M5: =SUMIFS($M$10:$M$3487,$B$10:$B$3487,B5,$A$10:$A$3487,">="&$A$3,$A$10:$A$3487,"<="&$A$5) | N5: =H5/E5 | O5: =SUMIFS($O$10:$O$3487,$B$10:$B$3487,B5,$A$10:$A$3487,">="&$A$3,$A$10:$A$3487,"<="&$A$5) | P5: =C5-O5 | Q5: =O5/C5 | R5: =H5/(E5*Q5)
A6: 即日 | B6: UK | C6: =SUMIFS($C$10:$C$3487,$B$10:$B$3487,B6,$A$10:$A$3487,">="&$A$3,$A$10:$A$3487,"<="&$A$5) | D6: 55.3 | E6: =SUMIFS($E$10:$E$3487,$B$10:$B$3487,B6,$A$10:$A$3487,">="&$A$3,$A$10:$A$3487,"<="&$A$5) | G6: =SUMIFS($G$10:$G$3487,$B$10:$B$3487,B6,$A$10:$A$3487,">="&$A$3,$A$10:$A$3487,"<="&$A$5) | H6: =SUMIFS($H$10:$H$3487,$B$10:$B$3487,B6,$A$10:$A$3487,">="&$A$3,$A$10:$A$3487,"<="&$A$5) | I6: =SUMIFS($I$10:$I$3487,$B$10:$B$3487,B6,$A$10:$A$3487,">="&$A$3,$A$10:$A$3487,"<="&$A$5) | J6: =SUMIFS($J$10:$J$3487,$B$10:$B$3487,B6,$A$10:$A$3487,">="&$A$3,$A$10:$A$3487,"<="&$A$5) | K6: =J6/E6 | L6: =SUMIFS($L$10:$L$3487,$B$10:$B$3487,B6,$A$10:$A$3487,">="&$A$3,$A$10:$A$3487,"<="&$A$5) | M6: =SUMIFS($M$10:$M$3487,$B$10:$B$3487,B6,$A$10:$A$3487,">="&$A$3,$A$10:$A$3487,"<="&$A$5) | N6: =H6/E6 | O6: =SUMIFS($O$10:$O$3487,$B$10:$B$3487,B6,$A$10:$A$3487,">="&$A$3,$A$10:$A$3487,"<="&$A$5) | P6: =C6-O6 | Q6: =O6/C6 | R6: =H6/(E6*Q6)
A7: =NOW() | B7: US | C7: =SUMIFS($C$10:$C$3487,$B$10:$B$3487,B7,$A$10:$A$3487,">="&$A$3,$A$10:$A$3487,"<="&$A$5) | D7: 49.99 | E7: =SUMIFS($E$10:$E$3487,$B$10:$B$3487,B7,$A$10:$A$3487,">="&$A$3,$A$10:$A$3487,"<="&$A$5) | G7: =SUMIFS($G$10:$G$3487,$B$10:$B$3487,B7,$A$10:$A$3487,">="&$A$3,$A$10:$A$3487,"<="&$A$5) | H7: =SUMIFS($H$10:$H$3487,$B$10:$B$3487,B7,$A$10:$A$3487,">="&$A$3,$A$10:$A$3487,"<="&$A$5) | I7: =SUMIFS($I$10:$I$3487,$B$10:$B$3487,B7,$A$10:$A$3487,">="&$A$3,$A$10:$A$3487,"<="&$A$5) | J7: =SUMIFS($J$10:$J$3487,$B$10:$B$3487,B7,$A$10:$A$3487,">="&$A$3,$A$10:$A$3487,"<="&$A$5) | K7: =J7/E7 | L7: =SUMIFS($L$10:$L$3487,$B$10:$B$3487,B7,$A$10:$A$3487,">="&$A$3,$A$10:$A$3487,"<="&$A$5) | M7: =SUMIFS($M$10:$M$3487,$B$10:$B$3487,B7,$A$10:$A$3487,">="&$A$3,$A$10:$A$3487,"<="&$A$5) | N7: =H7/E7 | O7: =SUMIFS($O$10:$O$3487,$B$10:$B$3487,B7,$A$10:$A$3487,">="&$A$3,$A$10:$A$3487,"<="&$A$5) | P7: =C7-O7 | Q7: =O7/C7 | R7: =H7/(E7*Q7)
B8: 汇总 | C8: =SUM(C2:C7) | K8: =L8/M8 | L8: =SUM(L2:L7) | M8: =SUM(M2:M7) | O8: =SUM(O2:O7) | P8: =C8-O8 | Q8: =O8/C8
B9: 分割线
A10: 时间 | B10: 国家 | C10: 数量 | D10: 售价 | E10: 销售额 | F10: 毛利 | G10: 广告预算 | H10: 实际广告 | I10: 活动费 | J10: 毛利 | K10: 毛利率 | L10: 毛利(RMB) | M10: 销售额(RMB) | N10: 广告占比 | O10: 广告订单 | P10: 自然订单 | Q10: 广告订单占比 | R10: ACOS | S10: COUPON
A11: 46034 | B11: DE | C11: 0 | D11: {=_xlfn.XLOOKUP(B11&S11,'净-价格-毛利'!A:A&'净-价格-毛利'!B:B,'净-价格-毛利'!D:D,0)} | E11: =C11*D11 | F11: {=_xlfn.XLOOKUP(B11&S11,'净-价格-毛利'!A:A&'净-价格-毛利'!B:B,'净-价格-毛利'!C:C,0)} | G11: =C11*5 | I11: =E11*0.025 | J11: =F11*C11+G11-H11-I11 | K11: =IFERROR(J11/E11,0) | L11: =J11*8 | M11: =E11*8 | N11: =IFERROR(H11/E11,0) | P11: =C11-O11 | Q11: =IFERROR(O11/C11,0) | R11: =IFERROR(H11/(E11*Q11),0) | S11: VC-0%
A12: 46034 | B12: DE | C12: 4 | D12: {=_xlfn.XLOOKUP(B12&S12,'净-价格-毛利'!A:A&'净-价格-毛利'!B:B,'净-价格-毛利'!D:D,0)} | E12: =C12*D12 | F12: {=_xlfn.XLOOKUP(B12&S12,'净-价格-毛利'!A:A&'净-价格-毛利'!B:B,'净-价格-毛利'!C:C,0)} | G12: =C12*6 | H12: 111.54 | I12: =E12*0.025 | J12: =F12*C12+G12-H12-I12 | K12: =IFERROR(J12/E12,0) | L12: =J12*8 | M12: =E12*8 | N12: =IFERROR(H12/E12,0) | O12: 4 | P12: =C12-O12 | Q12: =IFERROR(O12/C12,0) | R12: =IFERROR(H12/(E12*Q12),0) | S12: SC-49.99
A13: 46034 | B13: FR | C13: 0 | D13: {=_xlfn.XLOOKUP(B13&S13,'净-价格-毛利'!A:A&'净-价格-毛利'!B:B,'净-价格-毛利'!D:D,0)} | E13: =C13*D13 | F13: {=_xlfn.XLOOKUP(B13&S13,'净-价格-毛利'!A:A&'净-价格-毛利'!B:B,'净-价格-毛利'!C:C,0)} | G13: =C13*5 | I13: =E13*0.025 | J13: =F13*C13+G13-H13-I13 | K13: =IFERROR(J13/E13,0) | L13: =J13*8 | M13: =E13*8 | N13: =IFERROR(H13/E13,0) | P13: =C13-O13 | Q13: =IFERROR(O13/C13,0) | R13: =IFERROR(H13/(E13*Q13),0) | S13: VC-0%
A14: 46034 | B14: FR | C14: 1 | D14: {=_xlfn.XLOOKUP(B14&S14,'净-价格-毛利'!A:A&'净-价格-毛利'!B:B,'净-价格-毛利'!D:D,0)} | E14: =C14*D14 | F14: {=_xlfn.XLOOKUP(B14&S14,'净-价格-毛利'!A:A&'净-价格-毛利'!B:B,'净-价格-毛利'!C:C,0)} | G14: =C14*6 | H14: 26.33 | I14: =E14*0.025 | J14: =F14*C14+G14-H14-I14 | K14: =IFERROR(J14/E14,0) | L14: =J14*8 | M14: =E14*8 | N14: =IFERROR(H14/E14,0) | O14: 1 | P14: =C14-O14 | Q14: =IFERROR(O14/C14,0) | R14: =IFERROR(H14/(E14*Q14),0) | S14: SC-51.99
A15: 46034 | B15: IT | C15: 0 | D15: {=_xlfn.XLOOKUP(B15&S15,'净-价格-毛利'!A:A&'净-价格-毛利'!B:B,'净-价格-毛利'!D:D,0)} | E15: =C15*D15 | F15: {=_xlfn.XLOOKUP(B15&S15,'净-价格-毛利'!A:A&'净-价格-毛利'!B:B,'净-价格-毛利'!C:C,0)} | G15: =C15*5 | I15: =E15*0.025 | J15: =F15*C15+G15-H15-I15 | K15: =IFERROR(J15/E15,0) | L15: =J15*8 | M15: =E15*8 | N15: =IFERROR(H15/E15,0) | P15: =C15-O15 | Q15: =IFERROR(O15/C15,0) | R15: =IFERROR(H15/(E15*Q15),0) | S15: VC-0%
A16: 46034 | B16: IT | C16: 0 | D16: {=_xlfn.XLOOKUP(B16&S16,'净-价格-毛利'!A:A&'净-价格-毛利'!B:B,'净-价格-毛利'!D:D,0)} | E16: =C16*D16 | F16: {=_xlfn.XLOOKUP(B16&S16,'净-价格-毛利'!A:A&'净-价格-毛利'!B:B,'净-价格-毛利'!C:C,0)} | G16: =C16*6 | I16: =E16*0.025 | J16: =F16*C16+G16-H16-I16 | K16: =IFERROR(J16/E16,0) | L16: =J16*8 | M16: =E16*8 | N16: =IFERROR(H16/E16,0) | P16: =C16-O16 | Q16: =IFERROR(O16/C16,0) | R16: =IFERROR(H16/(E16*Q16),0) | S16: SC-51.99
A17: 46034 | B17: ES | C17: 0 | D17: {=_xlfn.XLOOKUP(B17&S17,'净-价格-毛利'!A:A&'净-价格-毛利'!B:B,'净-价格-毛利'!D:D,0)} | E17: =C17*D17 | F17: {=_xlfn.XLOOKUP(B17&S17,'净-价格-毛利'!A:A&'净-价格-毛利'!B:B,'净-价格-毛利'!C:C,0)} | G17: =C17*5 | I17: =E17*0.025 | J17: =F17*C17+G17-H17-I17 | K17: =IFERROR(J17/E17,0) | L17: =J17*8 | M17: =E17*8 | N17: =IFERROR(H17/E17,0) | P17: =C17-O17 | Q17: =IFERROR(O17/C17,0) | R17: =IFERROR(H17/(E17*Q17),0) | S17: VC-0%
A18: 46034 | B18: ES | C18: 1 | D18: {=_xlfn.XLOOKUP(B18&S18,'净-价格-毛利'!A:A&'净-价格-毛利'!B:B,'净-价格-毛利'!D:D,0)} | E18: =C18*D18 | F18: {=_xlfn.XLOOKUP(B18&S18,'净-价格-毛利'!A:A&'净-价格-毛利'!B:B,'净-价格-毛利'!C:C,0)} | G18: =C18*6 | H18: 5.72 | I18: =E18*0.025 | J18: =F18*C18+G18-H18-I18 | K18: =IFERROR(J18/E18,0) | L18: =J18*8 | M18: =E18*8 | N18: =IFERROR(H18/E18,0) | O18: 0 | P18: =C18-O18 | Q18: =IFERROR(O18/C18,0) | R18: =IFERROR(H18/(E18*Q18),0) | S18: SC-51.99
A19: 46034 | B19: UK | C19: 0 | D19: {=_xlfn.XLOOKUP(B19&S19,'净-价格-毛利'!A:A&'净-价格-毛利'!B:B,'净-价格-毛利'!D:D,0)} | E19: =C19*D19 | F19: {=_xlfn.XLOOKUP(B19&S19,'净-价格-毛利'!A:A&'净-价格-毛利'!B:B,'净-价格-毛利'!C:C,0)} | G19: =C19*5 | H19: 23.42 | I19: =E19*0.025 | J19: =F19*C19+G19-H19-I19 | K19: =IFERROR(J19/E19,0) | L19: =J19*9 | M19: =E19*9 | N19: =IFERROR(H19/E19,0) | O19: 0 | P19: =C19-O19 | Q19: =IFERROR(O19/C19,0) | R19: =IFERROR(H19/(E19*Q19),0) | S19: VC-0%
A20: 46034 | B20: UK | C20: 0 | D20: {=_xlfn.XLOOKUP(B20&S20,'净-价格-毛利'!A:A&'净-价格-毛利'!B:B,'净-价格-毛利'!D:D,0)} | E20: =C20*D20 | F20: {=_xlfn.XLOOKUP(B20&S20,'净-价格-毛利'!A:A&'净-价格-毛利'!B:B,'净-价格-毛利'!C:C,0)} | G20: =C20*6 | H20: 0 | I20: =E20*0.025 | J20: =F20*C20+G20-H20-I20 | K20: =IFERROR(J20/E20,0) | L20: =J20*9 | M20: =E20*9 | N20: =IFERROR(H20/E20,0) | O20: 0 | P20: =C20-O20 | Q20: =IFERROR(O20/C20,0) | R20: =IFERROR(H20/(E20*Q20),0) | S20: SC-45.99
A21: 46034 | B21: US | C21: 0 | D21: {=_xlfn.XLOOKUP(B21&S21,'净-价格-毛利'!A:A&'净-价格-毛利'!B:B,'净-价格-毛利'!D:D,0)} | E21: =C21*D21 | F21: {=_xlfn.XLOOKUP(B21&S21,'净-价格-毛利'!A:A&'净-价格-毛利'!B:B,'净-价格-毛利'!C:C,0)} | I21: =E21*0.025 | J21: =C21*F21-H21-I21 | K21: =IFERROR(J21/E21,0) | L21: =J21*7 | M21: =E21*7 | N21: =IFERROR(H21/E21,0) | P21: =C21-O21 | Q21: =IFERROR(O21/C21,0)
A22: 46034 | B22: 汇总 | C22: =SUM(C11:C21) | E22: =SUM(E11:E21) | F22: =SUM(F11:F20) | J22: =SUM(J11:J21) | K22: =IFERROR(J22/E22,0) | L22: =SUM(L11:L21) | M22: =SUM(M11:M21) | O22: =SUM(O11:O20) | P22: =C22-O22 | Q22: =IFERROR(O22/C22,0)
B23: 分割线
A24: 时间 | B24: 国家 | C24: 数量 | D24: 售价 | E24: 销售额 | F24: 毛利 | G24: 广告预算 | H24: 实际广告 | I24: 活动费 | J24: 毛利 | K24: 毛利率 | L24: 毛利(RMB) | M24: 销售额(RMB) | N24: 广告占比 | O24: 广告订单 | P24: 自然订单 | Q24: 广告订单占比 | R24: ACOS | S24: COUPON
A25: 46035 | B25: DE | C25: 0 | D25: {=_xlfn.XLOOKUP(B25&S25,'净-价格-毛利'!A:A&'净-价格-毛利'!B:B,'净-价格-毛利'!D:D,0)} | E25: =C25*D25 | F25: {=_xlfn.XLOOKUP(B25&S25,'净-价格-毛利'!A:A&'净-价格-毛利'!B:B,'净-价格-毛利'!C:C,0)} | G25: =C25*5 | I25: =E25*0.025 | J25: =F25*C25+G25-H25-I25 | K25: =IFERROR(J25/E25,0) | L25: =J25*8 | M25: =E25*8 | N25: =IFERROR(H25/E25,0) | P25: =C25-O25 | Q25: =IFERROR(O25/C25,0) | R25: =IFERROR(H25/(E25*Q25),0) | S25: VC-0%
A26: 46035 | B26: DE | C26: 4 | D26: {=_xlfn.XLOOKUP(B26&S26,'净-价格-毛利'!A:A&'净-价格-毛利'!B:B,'净-价格-毛利'!D:D,0)} | E26: =C26*D26 | F26: {=_xlfn.XLOOKUP(B26&S26,'净-价格-毛利'!A:A&'净-价格-毛利'!B:B,'净-价格-毛利'!C:C,0)} | G26: =C26*6 | H26: 118.37 | I26: =E26*0.025 | J26: =F26*C26+G26-H26-I26 | K26: =IFERROR(J26/E26,0) | L26: =J26*8 | M26: =E26*8 | N26: =IFERROR(H26/E26,0) | O26: 3 | P26: =C26-O26 | Q26: =IFERROR(O26/C26,0) | R26: =IFERROR(H26/(E26*Q26),0) | S26: SC-49.99
A27: 46035 | B27: FR | C27: 0 | D27: {=_xlfn.XLOOKUP(B27&S27,'净-价格-毛利'!A:A&'净-价格-毛利'!B:B,'净-价格-毛利'!D:D,0)} | E27: =C27*D27 | F27: {=_xlfn.XLOOKUP(B27&S27,'净-价格-毛利'!A:A&'净-价格-毛利'!B:B,'净-价格-毛利'!C:C,0)} | G27: =C27*5 | I27: =E27*0.025 | J27: =F27*C27+G27-H27-I27 | K27: =IFERROR(J27/E27,0) | L27: =J27*8 | M27: =E27*8 | N27: =IFERROR(H27/E27,0) | P27: =C27-O27 | Q27: =IFERROR(O27/C27,0) | R27: =IFERROR(H27/(E27*Q27),0) | S27: VC-0%
A28: 46035 | B28: FR | C28: 0 | D28: {=_xlfn.XLOOKUP(B28&S28,'净-价格-毛利'!A:A&'净-价格-毛利'!B:B,'净-价格-毛利'!D:D,0)} | E28: =C28*D28 | F28: {=_xlfn.XLOOKUP(B28&S28,'净-价格-毛利'!A:A&'净-价格-毛利'!B:B,'净-价格-毛利'!C:C,0)} | G28: =C28*6 | H28: 30.92 | I28: =E28*0.025 | J28: =F28*C28+G28-H28-I28 | K28: =IFERROR(J28/E28,0) | L28: =J28*8 | M28: =E28*8 | N28: =IFERROR(H28/E28,0) | O28: 0 | P28: =C28-O28 | Q28: =IFERROR(O28/C28,0) | R28: =IFERROR(H28/(E28*Q28),0) | S28: SC-51.99
A29: 46035 | B29: IT | C29: 0 | D29: {=_xlfn.XLOOKUP(B29&S29,'净-价格-毛利'!A:A&'净-价格-毛利'!B:B,'净-价格-毛利'!D:D,0)} | E29: =C29*D29 | F29: {=_xlfn.XLOOKUP(B29&S29,'净-价格-毛利'!A:A&'净-价格-毛利'!B:B,'净-价格-毛利'!C:C,0)} | G29: =C29*5 | I29: =E29*0.025 | J29: =F29*C29+G29-H29-I29 | K29: =IFERROR(J29/E29,0) | L29: =J29*8 | M29: =E29*8 | N29: =IFERROR(H29/E29,0) | P29: =C29-O29 | Q29: =IFERROR(O29/C29,0) | R29: =IFERROR(H29/(E29*Q29),0) | S29: VC-0%
A30: 46035 | B30: IT | C30: 0 | D30: {=_xlfn.XLOOKUP(B30&S30,'净-价格-毛利'!A:A&'净-价格-毛利'!B:B,'净-价格-毛利'!D:D,0)} | E30: =C30*D30 | F30: {=_xlfn.XLOOKUP(B30&S30,'净-价格-毛利'!A:A&'净-价格-毛利'!B:B,'净-价格-毛利'!C:C,0)} | G30: =C30*6 | I30: =E30*0.025 | J30: =F30*C30+G30-H30-I30 | K30: =IFERROR(J30/E30,0) | L30: =J30*8 | M30: =E30*8 | N30: =IFERROR(H30/E30,0) | P30: =C30-O30 | Q30: =IFERROR(O30/C30,0) | R30: =IFERROR(H30/(E30*Q30),0) | S30: SC-51.99
A31: 46035 | B31: ES | C31: 0 | D31: {=_xlfn.XLOOKUP(B31&S31,'净-价格-毛利'!A:A&'净-价格-毛利'!B:B,'净-价格-毛利'!D:D,0)} | E31: =C31*D31 | F31: {=_xlfn.XLOOKUP(B31&S31,'净-价格-毛利'!A:A&'净-价格-毛利'!B:B,'净-价格-毛利'!C:C,0)} | G31: =C31*5 | I31: =E31*0.025 | J31: =F31*C31+G31-H31-I31 | K31: =IFERROR(J31/E31,0) | L31: =J31*8 | M31: =E31*8 | N31: =IFERROR(H31/E31,0) | P31: =C31-O31 | Q31: =IFERROR(O31/C31,0) | R31: =IFERROR(H31/(E31*Q31),0) | S31: VC-0%
A32: 46035 | B32: ES | C32: 3 | D32: {=_xlfn.XLOOKUP(B32&S32,'净-价格-毛利'!A:A&'净-价格-毛利'!B:B,'净-价格-毛利'!D:D,0)} | E32: =C32*D32 | F32: {=_xlfn.XLOOKUP(B32&S32,'净-价格-毛利'!A:A&'净-价格-毛利'!B:B,'净-价格-毛利'!C:C,0)} | G32: =C32*6 | H32: 29.39 | I32: =E32*0.025 | J32: =F32*C32+G32-H32-I32 | K32: =IFERROR(J32/E32,0) | L32: =J32*8 | M32: =E32*8 | N32: =IFERROR(H32/E32,0) | O32: 0 | P32: =C32-O32 | Q32: =IFERROR(O32/C32,0) | R32: =IFERROR(H32/(E32*Q32),0) | S32: SC-51.99
A33: 46035 | B33: UK | C33: 0 | D33: {=_xlfn.XLOOKUP(B33&S33,'净-价格-毛利'!A:A&'净-价格-毛利'!B:B,'净-价格-毛利'!D:D,0)} | E33: =C33*D33 | F33: {=_xlfn.XLOOKUP(B33&S33,'净-价格-毛利'!A:A&'净-价格-毛利'!B:B,'净-价格-毛利'!C:C,0)} | G33: =C33*5 | H33: 8.2 | I33: =E33*0.025 | J33: =F33*C33+G33-H33-I33 | K33: =IFERROR(J33/E33,0) | L33: =J33*9 | M33: =E33*9 | N33: =IFERROR(H33/E33,0) | O33: 0 | P33: =C33-O33 | Q33: =IFERROR(O33/C33,0) | R33: =IFERROR(H33/(E33*Q33),0) | S33: VC-0%
A34: 46035 | B34: UK | C34: 0 | D34: {=_xlfn.XLOOKUP(B34&S34,'净-价格-毛利'!A:A&'净-价格-毛利'!B:B,'净-价格-毛利'!D:D,0)} | E34: =C34*D34 | F34: {=_xlfn.XLOOKUP(B34&S34,'净-价格-毛利'!A:A&'净-价格-毛利'!B:B,'净-价格-毛利'!C:C,0)} | G34: =C34*6 | I34: =E34*0.025 | J34: =F34*C34+G34-H34-I34 | K34: =IFERROR(J34/E34,0) | L34: =J34*9 | M34: =E34*9 | N34: =IFERROR(H34/E34,0) | P34: =C34-O34 | Q34: =IFERROR(O34/C34,0) | R34: =IFERROR(H34/(E34*Q34),0) | S34: SC-45.99
A35: 46035 | B35: US | C35: 0 | D35: {=_xlfn.XLOOKUP(B35&S35,'净-价格-毛利'!A:A&'净-价格-毛利'!B:B,'净-价格-毛利'!D:D,0)} | E35: =C35*D35 | F35: {=_xlfn.XLOOKUP(B35&S35,'净-价格-毛利'!A:A&'净-价格-毛利'!B:B,'净-价格-毛利'!C:C,0)} | I35: =E35*0.025 | J35: =C35*F35-H35-I35 | K35: =IFERROR(J35/E35,0) | L35: =J35*7 | M35: =E35*7 | N35: =IFERROR(H35/E35,0) | P35: =C35-O35 | Q35: =IFERROR(O35/C35,0)
A36: 46035 | B36: 汇总 | C36: =SUM(C25:C35) | E36: =SUM(E25:E35) | F36: =SUM(F25:F34) | J36: =SUM(J25:J35) | K36: =IFERROR(J36/E36,0) | L36: =SUM(L25:L35) | M36: =SUM(M25:M35) | O36: =SUM(O25:O34) | P36: =C36-O36 | Q36: =IFERROR(O36/C36,0)
B37: 分割线
A38: 时间 | B38: 国家 | C38: 数量 | D38: 售价 | E38: 销售额 | F38: 毛利 | G38: 广告预算 | H38: 实际广告 | I38: 活动费 | J38: 毛利 | K38: 毛利率 | L38: 毛利(RMB) | M38: 销售额(RMB) | N38: 广告占比 | O38: 广告订单 | P38: 自然订单 | Q38: 广告订单占比 | R38: ACOS | S38: COUPON
A39: 46036 | B39: DE | C39: 0 | D39: {=_xlfn.XLOOKUP(B39&S39,'净-价格-毛利'!A:A&'净-价格-毛利'!B:B,'净-价格-毛利'!D:D,0)} | E39: =C39*D39 | F39: {=_xlfn.XLOOKUP(B39&S39,'净-价格-毛利'!A:A&'净-价格-毛利'!B:B,'净-价格-毛利'!C:C,0)} | G39: =C39*5 | I39: =E39*0.025 | J39: =F39*C39+G39-H39-I39 | K39: =IFERROR(J39/E39,0) | L39: =J39*8 | M39: =E39*8 | N39: =IFERROR(H39/E39,0) | P39: =C39-O39 | Q39: =IFERROR(O39/C39,0) | R39: =IFERROR(H39/(E39*Q39),0) | S39: VC-0%
A40: 46036 | B40: DE | C40: 1 | D40: {=_xlfn.XLOOKUP(B40&S40,'净-价格-毛利'!A:A&'净-价格-毛利'!B:B,'净-价格-毛利'!D:D,0)} | E40: =C40*D40 | F40: {=_xlfn.XLOOKUP(B40&S40,'净-价格-毛利'!A:A&'净-价格-毛利'!B:B,'净-价格-毛利'!C:C,0)} | G40: =C40*6 | H40: 108.23 | I40: =E40*0.025 | J40: =F40*C40+G40-H40-I40 | K40: =IFERROR(J40/E40,0) | L40: =J40*8 | M40: =E40*8 | N40: =IFERROR(H40/E40,0) | O40: 1 | P40: =C40-O40 | Q40: =IFERROR(O40/C40,0) | R40: =IFERROR(H40/(E40*Q40),0) | S40: SC-49.99
...

Sheet 净-价格-毛利
A1: 国家 | B1: COUPON | C1: 利润 | D1: PO价 | E1: 售价
A2: DE | B2: VC-0% | C2: 9.49 | D2: 34.5 | E2: 49.99
A3: DE | B3: VC-5% | C3: 6.99 | D3: 34.5 | E3: =E2*0.95
A4: DE | B4: VC-10% | C4: 4.49 | D4: 34.5 | E4: =49.99*0.9
A5: DE | B5: VC-15% | C5: 1.99 | D5: 34.5 | E5: =49.99*0.85
A6: DE | B6: BD-6.31 | C6: 2.93 | D6: 34.5
A7: DE | B7: BD-7.56 | C7: 1.68 | D7: 34.5 | E7: 42.49
A8: DE | B8: BD-7.5 | C8: 1.74 | D8: 34.5 | E8: 42.49
A9: DE | B9: SC-49.99 | C9: 6.68 | D9: 49.99 | E9: 49.99
A10: DE | B10: SC-52.99 | C10: 8.85 | D10: 52.99 | E10: 52.99
A11: FR | B11: VC-0% | C11: 8.77 | D11: 34.5 | E11: 51.99
A12: FR | B12: VC-5% | C12: 6.27 | D12: 34.5 | E12: =E11*0.95
A13: FR | B13: VC-10% | C13: 3.77 | D13: 34.5 | E13: =51.99*0.9
A14: FR | B14: VC-15% | C14: 1.27 | D14: 34.5 | E14: =51.99*0.85
A15: FR | B15: BD-7.56 | C15: 2.48 | D15: 34.5 | E15: 45.59
A16: FR | B16: BD-1.9 | C16: 7.58 | D16: 34.5 | E16: 43.31
A17: FR | B17: SC-51.99 | C17: 6.33 | D17: 51.99 | E17: 51.99
A18: FR | B18: SC-54.99 | C18: 8.19 | D18: 54.99 | E18: 54.99
A19: IT | B19: VC-0% | C19: 8.66 | D19: 34.5 | E19: 51.99
A20: IT | B20: VC-5% | C20: 6.16 | D20: 34.5 | E20: =E19*0.95
A21: IT | B21: VC-10% | C21: 3.66 | D21: 34.5 | E21: =51.99*0.9
A22: IT | B22: VC-15% | C22: 1.16 | D22: 34.5 | E22: =51.99*0.85
A23: IT | B23: BD-8.25 | C23: 1.12 | D23: 34.5 | E23: 46.74
A24: IT | B24: BD-7.02 | C24: 2.35 | D24: 34.5 | E24: 39.72
A25: IT | B25: SC-51.99 | C25: 8.11 | D25: 51.99 | E25: 51.99
A26: ES | B26: VC-0% | C26: 8.21 | D26: 34.5 | E26: 51.99
A27: ES | B27: VC-5% | C27: 5.71 | D27: 34.5 | E27: =E26*0.95
A28: ES | B28: VC-10% | C28: 3.21 | D28: 34.5 | E28: =51.99*0.9
A29: ES | B29: VC-15% | C29: 0.71 | D29: 34.5 | E29: =51.99*0.85
A30: ES | B30: BD-6.82 | C30: 2.11 | D30: 34.5 | E30: 46.74
A31: ES | B31: BD-5.8 | C31: 3.13 | D31: 34.5 | E31: 39.72
A32: ES | B32: SC-51.99 | C32: 8.43 | D32: 51.99 | E32: 51.99
A33: ES | B33: SC-54.99 | C33: 10.29 | D33: 54.99 | E33: 54.99
A34: UK | B34: VC-0% | C34: 8.52 | D34: 27.5 | E34: 45.99
A35: UK | B35: VC-10% | C35: 3.92 | D35: 27.5 | E35: =E34*0.9
A36: UK | B36: VC-15% | C36: 1.63 | D36: 27.5 | E36: =E34*0.85
A37: UK | B37: BD-6.25 | C37: 2.27 | D37: 27.5 | E37: 42.49
A38: UK | B38: BD-5.32 | C38: 3.2 | D38: 27.5
A39: UK | B39: BD-5.63 | C39: 2.89 | D39: 27.5 | E39: 38.24
A40: UK | B40: SC-45.99 | C40: 6.32 | D40: 45.99 | E40: 45.99

Sheet 气泵
A1: 汇总 | B1: 国家 | C1: 数量 | D1: 售价 | E1: 销售额 | F1: 毛利 | G1: 广告预算 | H1: 实际广告 | I1: 活动费 | J1: 毛利 | K1: 毛利率 | L1: 毛利(RMB) | M1: 销售额(RMB) | N1: 广告占比 | O1: 广告订单 | P1: 自然订单 | Q1: 广告订单占比 | R1: ACOS | S1: 折扣
A2: 开始时间 | B2: DE | C2: =SUMIFS($C$10:$C$666,$B$10:$B$666,B2,$A$10:$A$666,">="&$A$3,$A$10:$A$666,"<="&$A$5) | D2: 65 | E2: =SUMIFS($E$10:$E$666,$B$10:$B$666,B2,$A$10:$A$666,">="&$A$3,$A$10:$A$666,"<="&$A$5) | G2: =SUMIFS($G$10:$G$666,$B$10:$B$666,B2,$A$10:$A$666,">="&$A$3,$A$10:$A$666,"<="&$A$5) | H2: =SUMIFS($H$10:$H$666,$B$10:$B$666,B2,$A$10:$A$666,">="&$A$3,$A$10:$A$666,"<="&$A$5) | I2: =SUMIFS($I$10:$I$666,$B$10:$B$666,B2,$A$10:$A$666,">="&$A$3,$A$10:$A$666,"<="&$A$5) | J2: =SUMIFS($J$10:$J$666,$B$10:$B$666,B2,$A$10:$A$666,">="&$A$3,$A$10:$A$666,"<="&$A$5) | K2: =J2/E2 | L2: =SUMIFS($L$10:$L$666,$B$10:$B$666,B2,$A$10:$A$666,">="&$A$3,$A$10:$A$666,"<="&$A$5) | M2: =SUMIFS($M$10:$M$666,$B$10:$B$666,B2,$A$10:$A$666,">="&$A$3,$A$10:$A$666,"<="&$A$5) | N2: =H2/E2 | O2: =SUMIFS($O$10:$O$666,$B$10:$B$666,B2,$A$10:$A$666,">="&$A$3,$A$10:$A$666,"<="&$A$5) | P2: =C2-O2 | Q2: =O2/C2 | R2: =H2/(E2*Q2)
A3: 45931 | B3: FR | C3: =SUMIFS($C$10:$C$666,$B$10:$B$666,B3,$A$10:$A$666,">="&$A$3,$A$10:$A$666,"<="&$A$5) | D3: 65 | E3: =SUMIFS($E$10:$E$666,$B$10:$B$666,B3,$A$10:$A$666,">="&$A$3,$A$10:$A$666,"<="&$A$5) | G3: =SUMIFS($G$10:$G$666,$B$10:$B$666,B3,$A$10:$A$666,">="&$A$3,$A$10:$A$666,"<="&$A$5) | H3: =SUMIFS($H$10:$H$666,$B$10:$B$666,B3,$A$10:$A$666,">="&$A$3,$A$10:$A$666,"<="&$A$5) | I3: =SUMIFS($I$10:$I$666,$B$10:$B$666,B3,$A$10:$A$666,">="&$A$3,$A$10:$A$666,"<="&$A$5) | J3: =SUMIFS($J$10:$J$666,$B$10:$B$666,B3,$A$10:$A$666,">="&$A$3,$A$10:$A$666,"<="&$A$5) | K3: =J3/E3 | L3: =SUMIFS($L$10:$L$666,$B$10:$B$666,B3,$A$10:$A$666,">="&$A$3,$A$10:$A$666,"<="&$A$5) | M3: =SUMIFS($M$10:$M$666,$B$10:$B$666,B3,$A$10:$A$666,">="&$A$3,$A$10:$A$666,"<="&$A$5) | N3: =H3/E3 | O3: =SUMIFS($O$10:$O$666,$B$10:$B$666,B3,$A$10:$A$666,">="&$A$3,$A$10:$A$666,"<="&$A$5) | P3: =C3-O3 | Q3: =O3/C3 | R3: =H3/(E3*Q3)
A4: 结束时间 | B4: IT | C4: =SUMIFS($C$10:$C$666,$B$10:$B$666,B4,$A$10:$A$666,">="&$A$3,$A$10:$A$666,"<="&$A$5) | D4: 65 | E4: =SUMIFS($E$10:$E$666,$B$10:$B$666,B4,$A$10:$A$666,">="&$A$3,$A$10:$A$666,"<="&$A$5) | G4: =SUMIFS($G$10:$G$666,$B$10:$B$666,B4,$A$10:$A$666,">="&$A$3,$A$10:$A$666,"<="&$A$5) | H4: =SUMIFS($H$10:$H$666,$B$10:$B$666,B4,$A$10:$A$666,">="&$A$3,$A$10:$A$666,"<="&$A$5) | I4: =SUMIFS($I$10:$I$666,$B$10:$B$666,B4,$A$10:$A$666,">="&$A$3,$A$10:$A$666,"<="&$A$5) | J4: =SUMIFS($J$10:$J$666,$B$10:$B$666,B4,$A$10:$A$666,">="&$A$3,$A$10:$A$666,"<="&$A$5) | K4: =J4/E4 | L4: =SUMIFS($L$10:$L$666,$B$10:$B$666,B4,$A$10:$A$666,">="&$A$3,$A$10:$A$666,"<="&$A$5) | M4: =SUMIFS($M$10:$M$666,$B$10:$B$666,B4,$A$10:$A$666,">="&$A$3,$A$10:$A$666,"<="&$A$5) | N4: =H4/E4 | O4: =SUMIFS($O$10:$O$666,$B$10:$B$666,B4,$A$10:$A$666,">="&$A$3,$A$10:$A$666,"<="&$A$5) | P4: =C4-O4 | Q4: =O4/C4 | R4: =H4/(E4*Q4)
A5: =NOW() | B5: ES | C5: =SUMIFS($C$10:$C$666,$B$10:$B$666,B5,$A$10:$A$666,">="&$A$3,$A$10:$A$666,"<="&$A$5) | D5: 65 | E5: =SUMIFS($E$10:$E$666,$B$10:$B$666,B5,$A$10:$A$666,">="&$A$3,$A$10:$A$666,"<="&$A$5) | G5: =SUMIFS($G$10:$G$666,$B$10:$B$666,B5,$A$10:$A$666,">="&$A$3,$A$10:$A$666,"<="&$A$5) | H5: =SUMIFS($H$10:$H$666,$B$10:$B$666,B5,$A$10:$A$666,">="&$A$3,$A$10:$A$666,"<="&$A$5) | I5: =SUMIFS($I$10:$I$666,$B$10:$B$666,B5,$A$10:$A$666,">="&$A$3,$A$10:$A$666,"<="&$A$5) | J5: =SUMIFS($J$10:$J$666,$B$10:$B$666,B5,$A$10:$A$666,">="&$A$3,$A$10:$A$666,"<="&$A$5) | K5: =J5/E5 | L5: =SUMIFS($L$10:$L$666,$B$10:$B$666,B5,$A$10:$A$666,">="&$A$3,$A$10:$A$666,"<="&$A$5) | M5: =SUMIFS($M$10:$M$666,$B$10:$B$666,B5,$A$10:$A$666,">="&$A$3,$A$10:$A$666,"<="&$A$5) | N5: =H5/E5 | O5: =SUMIFS($O$10:$O$666,$B$10:$B$666,B5,$A$10:$A$666,">="&$A$3,$A$10:$A$666,"<="&$A$5) | P5: =C5-O5 | Q5: =O5/C5 | R5: =H5/(E5*Q5)
A6: 即日 | B6: UK | C6: =SUMIFS($C$10:$C$666,$B$10:$B$666,B6,$A$10:$A$666,">="&$A$3,$A$10:$A$666,"<="&$A$5) | E6: =SUMIFS($E$10:$E$666,$B$10:$B$666,B6,$A$10:$A$666,">="&$A$3,$A$10:$A$666,"<="&$A$5) | G6: =SUMIFS($G$10:$G$666,$B$10:$B$666,B6,$A$10:$A$666,">="&$A$3,$A$10:$A$666,"<="&$A$5) | H6: =SUMIFS($H$10:$H$666,$B$10:$B$666,B6,$A$10:$A$666,">="&$A$3,$A$10:$A$666,"<="&$A$5) | I6: =SUMIFS($I$10:$I$666,$B$10:$B$666,B6,$A$10:$A$666,">="&$A$3,$A$10:$A$666,"<="&$A$5) | J6: =SUMIFS($J$10:$J$666,$B$10:$B$666,B6,$A$10:$A$666,">="&$A$3,$A$10:$A$666,"<="&$A$5) | K6: =J6/E6 | L6: =SUMIFS($L$10:$L$666,$B$10:$B$666,B6,$A$10:$A$666,">="&$A$3,$A$10:$A$666,"<="&$A$5) | M6: =SUMIFS($M$10:$M$666,$B$10:$B$666,B6,$A$10:$A$666,">="&$A$3,$A$10:$A$666,"<="&$A$5) | N6: =H6/E6 | O6: =SUMIFS($O$10:$O$666,$B$10:$B$666,B6,$A$10:$A$666,">="&$A$3,$A$10:$A$666,"<="&$A$5) | P6: =C6-O6 | Q6: =O6/C6 | R6: =H6/(E6*Q6)
A7: =NOW() | B7: US | C7: =SUMIFS($C$10:$C$666,$B$10:$B$666,B7,$A$10:$A$666,">="&$A$3,$A$10:$A$666,"<="&$A$5) | E7: =SUMIFS($E$10:$E$666,$B$10:$B$666,B7,$A$10:$A$666,">="&$A$3,$A$10:$A$666,"<="&$A$5) | G7: =SUMIFS($G$10:$G$666,$B$10:$B$666,B7,$A$10:$A$666,">="&$A$3,$A$10:$A$666,"<="&$A$5) | H7: =SUMIFS($H$10:$H$666,$B$10:$B$666,B7,$A$10:$A$666,">="&$A$3,$A$10:$A$666,"<="&$A$5) | I7: =SUMIFS($I$10:$I$666,$B$10:$B$666,B7,$A$10:$A$666,">="&$A$3,$A$10:$A$666,"<="&$A$5) | J7: =SUMIFS($J$10:$J$666,$B$10:$B$666,B7,$A$10:$A$666,">="&$A$3,$A$10:$A$666,"<="&$A$5) | K7: =J7/E7 | L7: =SUMIFS($L$10:$L$666,$B$10:$B$666,B7,$A$10:$A$666,">="&$A$3,$A$10:$A$666,"<="&$A$5) | M7: =SUMIFS($M$10:$M$666,$B$10:$B$666,B7,$A$10:$A$666,">="&$A$3,$A$10:$A$666,"<="&$A$5) | N7: =H7/E7 | O7: =SUMIFS($O$10:$O$666,$B$10:$B$666,B7,$A$10:$A$666,">="&$A$3,$A$10:$A$666,"<="&$A$5) | P7: =C7-O7 | Q7: =O7/C7 | R7: =H7/(E7*Q7)
B8: 汇总 | C8: =SUM(C2:C7) | K8: =L8/M8 | L8: =SUM(L2:L7) | M8: =SUM(M2:M7) | O8: =SUM(O2:O7) | P8: =C8-O8 | Q8: =O8/C8
B9: 分割线
A10: 时间 | B10: 国家 | C10: 数量 | D10: 售价 | E10: 销售额 | F10: 毛利 | G10: 广告预算 | H10: 实际广告 | I10: 活动费 | J10: 毛利 | K10: 毛利率 | L10: 毛利(RMB) | M10: 销售额(RMB) | N10: 广告占比 | O10: 广告订单 | P10: 自然订单 | Q10: 广告订单占比 | R10: ACOS | S10: COUPON
A11: 45931 | B11: DE | C11: 0 | D11: {=_xlfn.XLOOKUP(B11&S11,'气-价格-毛利'!A:A&'气-价格-毛利'!B:B,'气-价格-毛利'!D:D,0)} | E11: =C11*D11 | F11: {=_xlfn.XLOOKUP(B11&S11,'气-价格-毛利'!A:A&'气-价格-毛利'!B:B,'气-价格-毛利'!C:C,0)} | G11: =C11*8 | I11: =E11*0.025 | J11: =F11*C11+G11-H11-I11 | K11: =IFERROR(J11/E11,0) | L11: =J11*8 | M11: =E11*8 | N11: =IFERROR(H11/E11,0) | P11: =C11-O11 | Q11: =IFERROR(O11/C11,0) | R11: =IFERROR(H11/(E11*Q11),0) | S11: VC-0%
A12: 45931 | B12: DE | C12: 1 | D12: {=_xlfn.XLOOKUP(B12&S12,'气-价格-毛利'!A:A&'气-价格-毛利'!B:B,'气-价格-毛利'!D:D,0)} | E12: =C12*D12 | F12: {=_xlfn.XLOOKUP(B12&S12,'气-价格-毛利'!A:A&'气-价格-毛利'!B:B,'气-价格-毛利'!C:C,0)} | G12: =C12*10 | I12: =E12*0.025 | J12: =F12*C12+G12-H12-I12 | K12: =IFERROR(J12/E12,0) | L12: =J12*8 | M12: =E12*8 | N12: =IFERROR(H12/E12,0) | P12: =C12-O12 | Q12: =IFERROR(O12/C12,0) | R12: =IFERROR(H12/(E12*Q12),0) | S12: SC-15%
A13: 45931 | B13: FR | C13: 0 | D13: {=_xlfn.XLOOKUP(B13&S13,'气-价格-毛利'!A:A&'气-价格-毛利'!B:B,'气-价格-毛利'!D:D,0)} | E13: =C13*D13 | F13: {=_xlfn.XLOOKUP(B13&S13,'气-价格-毛利'!A:A&'气-价格-毛利'!B:B,'气-价格-毛利'!C:C,0)} | G13: =C13*8 | I13: =E13*0.025 | J13: =F13*C13+G13-H13-I13 | K13: =IFERROR(J13/E13,0) | L13: =J13*8 | M13: =E13*8 | N13: =IFERROR(H13/E13,0) | P13: =C13-O13 | Q13: =IFERROR(O13/C13,0) | R13: =IFERROR(H13/(E13*Q13),0) | S13: VC-0%
A14: 45931 | B14: FR | C14: 0 | D14: {=_xlfn.XLOOKUP(B14&S14,'气-价格-毛利'!A:A&'气-价格-毛利'!B:B,'气-价格-毛利'!D:D,0)} | E14: =C14*D14 | F14: {=_xlfn.XLOOKUP(B14&S14,'气-价格-毛利'!A:A&'气-价格-毛利'!B:B,'气-价格-毛利'!C:C,0)} | G14: =C14*10 | I14: =E14*0.025 | J14: =F14*C14+G14-H14-I14 | K14: =IFERROR(J14/E14,0) | L14: =J14*8 | M14: =E14*8 | N14: =IFERROR(H14/E14,0) | P14: =C14-O14 | Q14: =IFERROR(O14/C14,0) | R14: =IFERROR(H14/(E14*Q14),0) | S14: SC-15%
A15: 45931 | B15: IT | C15: 0 | D15: {=_xlfn.XLOOKUP(B15&S15,'气-价格-毛利'!A:A&'气-价格-毛利'!B:B,'气-价格-毛利'!D:D,0)} | E15: =C15*D15 | F15: {=_xlfn.XLOOKUP(B15&S15,'气-价格-毛利'!A:A&'气-价格-毛利'!B:B,'气-价格-毛利'!C:C,0)} | G15: =C15*8 | I15: =E15*0.025 | J15: =F15*C15+G15-H15-I15 | K15: =IFERROR(J15/E15,0) | L15: =J15*8 | M15: =E15*8 | N15: =IFERROR(H15/E15,0) | P15: =C15-O15 | Q15: =IFERROR(O15/C15,0) | R15: =IFERROR(H15/(E15*Q15),0) | S15: VC-0%
A16: 45931 | B16: IT | C16: 3 | D16: {=_xlfn.XLOOKUP(B16&S16,'气-价格-毛利'!A:A&'气-价格-毛利'!B:B,'气-价格-毛利'!D:D,0)} | E16: =C16*D16 | F16: {=_xlfn.XLOOKUP(B16&S16,'气-价格-毛利'!A:A&'气-价格-毛利'!B:B,'气-价格-毛利'!C:C,0)} | G16: =C16*10 | I16: =E16*0.025 | J16: =F16*C16+G16-H16-I16 | K16: =IFERROR(J16/E16,0) | L16: =J16*8 | M16: =E16*8 | N16: =IFERROR(H16/E16,0) | P16: =C16-O16 | Q16: =IFERROR(O16/C16,0) | R16: =IFERROR(H16/(E16*Q16),0) | S16: SC-15%
A17: 45931 | B17: ES | C17: 0 | D17: {=_xlfn.XLOOKUP(B17&S17,'气-价格-毛利'!A:A&'气-价格-毛利'!B:B,'气-价格-毛利'!D:D,0)} | E17: =C17*D17 | F17: {=_xlfn.XLOOKUP(B17&S17,'气-价格-毛利'!A:A&'气-价格-毛利'!B:B,'气-价格-毛利'!C:C,0)} | G17: =C17*8 | I17: =E17*0.025 | J17: =F17*C17+G17-H17-I17 | K17: =IFERROR(J17/E17,0) | L17: =J17*8 | M17: =E17*8 | N17: =IFERROR(H17/E17,0) | P17: =C17-O17 | Q17: =IFERROR(O17/C17,0) | R17: =IFERROR(H17/(E17*Q17),0) | S17: VC-0%
A18: 45931 | B18: ES | C18: 1 | D18: {=_xlfn.XLOOKUP(B18&S18,'气-价格-毛利'!A:A&'气-价格-毛利'!B:B,'气-价格-毛利'!D:D,0)} | E18: =C18*D18 | F18: {=_xlfn.XLOOKUP(B18&S18,'气-价格-毛利'!A:A&'气-价格-毛利'!B:B,'气-价格-毛利'!C:C,0)} | G18: =C18*10 | I18: =E18*0.025 | J18: =F18*C18+G18-H18-I18 | K18: =IFERROR(J18/E18,0) | L18: =J18*8 | M18: =E18*8 | N18: =IFERROR(H18/E18,0) | P18: =C18-O18 | Q18: =IFERROR(O18/C18,0) | R18: =IFERROR(H18/(E18*Q18),0) | S18: SC-15%
A19: 45931 | B19: UK | D19: {=_xlfn.XLOOKUP(B19&S19,'气-价格-毛利'!A:A&'气-价格-毛利'!B:B,'气-价格-毛利'!D:D,0)} | E19: =C19*D19 | F19: {=_xlfn.XLOOKUP(B19&S19,'气-价格-毛利'!A:A&'气-价格-毛利'!B:B,'气-价格-毛利'!C:C,0)} | G19: =C19*8 | I19: =E19*0.025 | J19: =F19*C19+G19-H19-I19 | K19: =IFERROR(J19/E19,0) | L19: =J19*9 | M19: =E19*9 | N19: =IFERROR(H19/E19,0) | P19: =C19-O19 | Q19: =IFERROR(O19/C19,0) | R19: =IFERROR(H19/(E19*Q19),0)
A20: 45931 | B20: UK | D20: {=_xlfn.XLOOKUP(B20&S20,'气-价格-毛利'!A:A&'气-价格-毛利'!B:B,'气-价格-毛利'!D:D,0)} | E20: =C20*D20 | F20: {=_xlfn.XLOOKUP(B20&S20,'气-价格-毛利'!A:A&'气-价格-毛利'!B:B,'气-价格-毛利'!C:C,0)} | G20: =C20*8 | I20: =E20*0.025 | J20: =F20*C20+G20-H20-I20 | K20: =IFERROR(J20/E20,0) | L20: =J20*9 | M20: =E20*9 | N20: =IFERROR(H20/E20,0) | P20: =C20-O20 | Q20: =IFERROR(O20/C20,0) | R20: =IFERROR(H20/(E20*Q20),0)
A21: 45931 | B21: US | D21: {=_xlfn.XLOOKUP(B21&S21,'气-价格-毛利'!A:A&'气-价格-毛利'!B:B,'气-价格-毛利'!D:D,0)} | E21: =C21*D21 | F21: {=_xlfn.XLOOKUP(B21&S21,'气-价格-毛利'!A:A&'气-价格-毛利'!B:B,'气-价格-毛利'!C:C,0)} | I21: =E21*0.025 | J21: =C21*F21-H21-I21 | K21: =IFERROR(J21/E21,0) | L21: =J21*7 | M21: =E21*7 | N21: =IFERROR(H21/E21,0) | P21: =C21-O21 | Q21: =IFERROR(O21/C21,0)
A22: 45931 | B22: 汇总 | C22: =SUM(C11:C21) | E22: =SUM(E11:E21) | F22: =SUM(F11:F20) | J22: =SUM(J11:J21) | K22: =IFERROR(J22/E22,0) | L22: =SUM(L11:L21) | M22: =SUM(M11:M21) | O22: =SUM(O11:O20) | P22: =C22-O22 | Q22: =IFERROR(O22/C22,0)
B23: 分割线
A24: 时间 | B24: 国家 | C24: 数量 | D24: 售价 | E24: 销售额 | F24: 毛利 | G24: 广告预算 | H24: 实际广告 | I24: 活动费 | J24: 毛利 | K24: 毛利率 | L24: 毛利(RMB) | M24: 销售额(RMB) | N24: 广告占比 | O24: 广告订单 | P24: 自然订单 | Q24: 广告订单占比 | R24: ACOS | S24: COUPON
A25: 45932 | B25: DE | C25: 0 | D25: {=_xlfn.XLOOKUP(B25&S25,'气-价格-毛利'!A:A&'气-价格-毛利'!B:B,'气-价格-毛利'!D:D,0)} | E25: =C25*D25 | F25: {=_xlfn.XLOOKUP(B25&S25,'气-价格-毛利'!A:A&'气-价格-毛利'!B:B,'气-价格-毛利'!C:C,0)} | G25: =C25*8 | I25: =E25*0.025 | J25: =F25*C25+G25-H25-I25 | K25: =IFERROR(J25/E25,0) | L25: =J25*8 | M25: =E25*8 | N25: =IFERROR(H25/E25,0) | P25: =C25-O25 | Q25: =IFERROR(O25/C25,0) | R25: =IFERROR(H25/(E25*Q25),0) | S25: VC-0%
A26: 45932 | B26: DE | C26: 3 | D26: {=_xlfn.XLOOKUP(B26&S26,'气-价格-毛利'!A:A&'气-价格-毛利'!B:B,'气-价格-毛利'!D:D,0)} | E26: =C26*D26 | F26: {=_xlfn.XLOOKUP(B26&S26,'气-价格-毛利'!A:A&'气-价格-毛利'!B:B,'气-价格-毛利'!C:C,0)} | G26: =C26*10 | I26: =E26*0.025 | J26: =F26*C26+G26-H26-I26 | K26: =IFERROR(J26/E26,0) | L26: =J26*8 | M26: =E26*8 | N26: =IFERROR(H26/E26,0) | P26: =C26-O26 | Q26: =IFERROR(O26/C26,0) | R26: =IFERROR(H26/(E26*Q26),0) | S26: SC-15%
A27: 45932 | B27: FR | C27: 0 | D27: {=_xlfn.XLOOKUP(B27&S27,'气-价格-毛利'!A:A&'气-价格-毛利'!B:B,'气-价格-毛利'!D:D,0)} | E27: =C27*D27 | F27: {=_xlfn.XLOOKUP(B27&S27,'气-价格-毛利'!A:A&'气-价格-毛利'!B:B,'气-价格-毛利'!C:C,0)} | G27: =C27*8 | I27: =E27*0.025 | J27: =F27*C27+G27-H27-I27 | K27: =IFERROR(J27/E27,0) | L27: =J27*8 | M27: =E27*8 | N27: =IFERROR(H27/E27,0) | P27: =C27-O27 | Q27: =IFERROR(O27/C27,0) | R27: =IFERROR(H27/(E27*Q27),0) | S27: VC-0%
A28: 45932 | B28: FR | C28: 0 | D28: {=_xlfn.XLOOKUP(B28&S28,'气-价格-毛利'!A:A&'气-价格-毛利'!B:B,'气-价格-毛利'!D:D,0)} | E28: =C28*D28 | F28: {=_xlfn.XLOOKUP(B28&S28,'气-价格-毛利'!A:A&'气-价格-毛利'!B:B,'气-价格-毛利'!C:C,0)} | G28: =C28*10 | I28: =E28*0.025 | J28: =F28*C28+G28-H28-I28 | K28: =IFERROR(J28/E28,0) | L28: =J28*8 | M28: =E28*8 | N28: =IFERROR(H28/E28,0) | P28: =C28-O28 | Q28: =IFERROR(O28/C28,0) | R28: =IFERROR(H28/(E28*Q28),0) | S28: SC-15%
A29: 45932 | B29: IT | C29: 0 | D29: {=_xlfn.XLOOKUP(B29&S29,'气-价格-毛利'!A:A&'气-价格-毛利'!B:B,'气-价格-毛利'!D:D,0)} | E29: =C29*D29 | F29: {=_xlfn.XLOOKUP(B29&S29,'气-价格-毛利'!A:A&'气-价格-毛利'!B:B,'气-价格-毛利'!C:C,0)} | G29: =C29*8 | I29: =E29*0.025 | J29: =F29*C29+G29-H29-I29 | K29: =IFERROR(J29/E29,0) | L29: =J29*8 | M29: =E29*8 | N29: =IFERROR(H29/E29,0) | P29: =C29-O29 | Q29: =IFERROR(O29/C29,0) | R29: =IFERROR(H29/(E29*Q29),0) | S29: VC-0%
A30: 45932 | B30: IT | C30: 4 | D30: {=_xlfn.XLOOKUP(B30&S30,'气-价格-毛利'!A:A&'气-价格-毛利'!B:B,'气-价格-毛利'!D:D,0)} | E30: =C30*D30 | F30: {=_xlfn.XLOOKUP(B30&S30,'气-价格-毛利'!A:A&'气-价格-毛利'!B:B,'气-价格-毛利'!C:C,0)} | G30: =C30*10 | I30: =E30*0.025 | J30: =F30*C30+G30-H30-I30 | K30: =IFERROR(J30/E30,0) | L30: =J30*8 | M30: =E30*8 | N30: =IFERROR(H30/E30,0) | P30: =C30-O30 | Q30: =IFERROR(O30/C30,0) | R30: =IFERROR(H30/(E30*Q30),0) | S30: SC-15%
A31: 45932 | B31: ES | C31: 0 | D31: {=_xlfn.XLOOKUP(B31&S31,'气-价格-毛利'!A:A&'气-价格-毛利'!B:B,'气-价格-毛利'!D:D,0)} | E31: =C31*D31 | F31: {=_xlfn.XLOOKUP(B31&S31,'气-价格-毛利'!A:A&'气-价格-毛利'!B:B,'气-价格-毛利'!C:C,0)} | G31: =C31*8 | I31: =E31*0.025 | J31: =F31*C31+G31-H31-I31 | K31: =IFERROR(J31/E31,0) | L31: =J31*8 | M31: =E31*8 | N31: =IFERROR(H31/E31,0) | P31: =C31-O31 | Q31: =IFERROR(O31/C31,0) | R31: =IFERROR(H31/(E31*Q31),0) | S31: VC-0%
A32: 45932 | B32: ES | C32: 2 | D32: {=_xlfn.XLOOKUP(B32&S32,'气-价格-毛利'!A:A&'气-价格-毛利'!B:B,'气-价格-毛利'!D:D,0)} | E32: =C32*D32 | F32: {=_xlfn.XLOOKUP(B32&S32,'气-价格-毛利'!A:A&'气-价格-毛利'!B:B,'气-价格-毛利'!C:C,0)} | G32: =C32*10 | I32: =E32*0.025 | J32: =F32*C32+G32-H32-I32 | K32: =IFERROR(J32/E32,0) | L32: =J32*8 | M32: =E32*8 | N32: =IFERROR(H32/E32,0) | P32: =C32-O32 | Q32: =IFERROR(O32/C32,0) | R32: =IFERROR(H32/(E32*Q32),0) | S32: SC-15%
A33: 45932 | B33: UK | D33: {=_xlfn.XLOOKUP(B33&S33,'气-价格-毛利'!A:A&'气-价格-毛利'!B:B,'气-价格-毛利'!D:D,0)} | E33: =C33*D33 | F33: {=_xlfn.XLOOKUP(B33&S33,'气-价格-毛利'!A:A&'气-价格-毛利'!B:B,'气-价格-毛利'!C:C,0)} | G33: =C33*8 | I33: =E33*0.025 | J33: =F33*C33+G33-H33-I33 | K33: =IFERROR(J33/E33,0) | L33: =J33*9 | M33: =E33*9 | N33: =IFERROR(H33/E33,0) | P33: =C33-O33 | Q33: =IFERROR(O33/C33,0) | R33: =IFERROR(H33/(E33*Q33),0)
A34: 45932 | B34: UK | D34: {=_xlfn.XLOOKUP(B34&S34,'气-价格-毛利'!A:A&'气-价格-毛利'!B:B,'气-价格-毛利'!D:D,0)} | E34: =C34*D34 | F34: {=_xlfn.XLOOKUP(B34&S34,'气-价格-毛利'!A:A&'气-价格-毛利'!B:B,'气-价格-毛利'!C:C,0)} | G34: =C34*8 | I34: =E34*0.025 | J34: =F34*C34+G34-H34-I34 | K34: =IFERROR(J34/E34,0) | L34: =J34*9 | M34: =E34*9 | N34: =IFERROR(H34/E34,0) | P34: =C34-O34 | Q34: =IFERROR(O34/C34,0) | R34: =IFERROR(H34/(E34*Q34),0)
A35: 45932 | B35: US | D35: {=_xlfn.XLOOKUP(B35&S35,'气-价格-毛利'!A:A&'气-价格-毛利'!B:B,'气-价格-毛利'!D:D,0)} | E35: =C35*D35 | F35: {=_xlfn.XLOOKUP(B35&S35,'气-价格-毛利'!A:A&'气-价格-毛利'!B:B,'气-价格-毛利'!C:C,0)} | I35: =E35*0.025 | J35: =C35*F35-H35-I35 | K35: =IFERROR(J35/E35,0) | L35: =J35*7 | M35: =E35*7 | N35: =IFERROR(H35/E35,0) | P35: =C35-O35 | Q35: =IFERROR(O35/C35,0)
A36: 45932 | B36: 汇总 | C36: =SUM(C25:C35) | E36: =SUM(E25:E35) | F36: =SUM(F25:F34) | J36: =SUM(J25:J35) | K36: =IFERROR(J36/E36,0) | L36: =SUM(L25:L35) | M36: =SUM(M25:M35) | O36: =SUM(O25:O34) | P36: =C36-O36 | Q36: =IFERROR(O36/C36,0)
B37: 分割线
A38: 时间 | B38: 国家 | C38: 数量 | D38: 售价 | E38: 销售额 | F38: 毛利 | G38: 广告预算 | H38: 实际广告 | I38: 活动费 | J38: 毛利 | K38: 毛利率 | L38: 毛利(RMB) | M38: 销售额(RMB) | N38: 广告占比 | O38: 广告订单 | P38: 自然订单 | Q38: 广告订单占比 | R38: ACOS | S38: COUPON
A39: 45933 | B39: DE | C39: 0 | D39: {=_xlfn.XLOOKUP(B39&S39,'气-价格-毛利'!A:A&'气-价格-毛利'!B:B,'气-价格-毛利'!D:D,0)} | E39: =C39*D39 | F39: {=_xlfn.XLOOKUP(B39&S39,'气-价格-毛利'!A:A&'气-价格-毛利'!B:B,'气-价格-毛利'!C:C,0)} | G39: =C39*8 | I39: =E39*0.025 | J39: =F39*C39+G39-H39-I39 | K39: =IFERROR(J39/E39,0) | L39: =J39*8 | M39: =E39*8 | N39: =IFERROR(H39/E39,0) | P39: =C39-O39 | Q39: =IFERROR(O39/C39,0) | R39: =IFERROR(H39/(E39*Q39),0) | S39: VC-0%
