Workbook

Sheet 市场概览（开发数据）
A1: 市场一览 | B1: Y-2总日销 | C1: Y-1总日销 | D1: Y总日销 | E1: Y-2均单价 | F1: Y-1均单价 | G1: Y均单价 | H1: 3年日销趋势图 | I1: 3年均单价趋势图 | J1: 核心词近3年变化 | K1: 月均搜索 | L1: Y-2 | M1: Y-1 | N1: Y
K2: grass pee pads for dogs with tray | L2: 6643 | M2: 2662 | N2: 1746
K3: puppy grass pee pad with tray | L3: 4847 | M3: 1646 | N3: 4945
B4: 350 | C4: 503 | D4: 1296.6 | E4: 49.99 | F4: 37.03 | G4: 38.52 | K4: indoor dog potty | L4: 9080 | M4: 12813 | N4: 12395
K5: dog toilet | L5: 4407 | M5: 4612 | N5: 4624
K6: dog potty tray | L6: 7114 | M6: 10600 | N6: 14161
A7: 链接数量 | C7: 品牌数量 | E7: 卖家数量 | G7: 平均评论数 | H7: 品牌占比饼状图 | I7: 卖家占比饼状图 | J7: 产品定价区间分析 | L7: Y-2 | M7: Y-1 | N7: Y
A8: 100 | C8: 79 | E8: 75 | G8: 734 | K8: 链接数量 | L8: 43 | M8: 56 | N8: 54
A9: TOP5品牌名 | B9: 链接数 | C9: 销售额占比 | D9: TOP5卖家名 | E9: 链接数 | F9: 销售额占比 | G9: 平均评分值 | K9: 平均评分数 | L9: 799.4 | M9: 751.8 | N9: 754.3
A10: PETMAKER | B10: 3 | C10: 0.448 | D10: Amazon | E10: 7 | F10: 0.5114 | G10: 4.1 | K10: 平均评分值 | L10: 3.9 | M10: 4.07 | N10: 4.12
A11: LOOBANI | B11: 5 | C11: 0.0884 | D11: ColoBright | E11: 5 | F11: 0.0938 | G11: 最早上架时间 | K11: 平均销量 | L11: 169.9 | M11: 193.6 | N11: 486.6
A12: Iris Ohyama | B12: 1 | C12: 0.0508 | D12: Key Savings | E12: 5 | F12: 0.0345 | G12: 38278 | K12: 销量占比 | L12: 0.6823 | M12: 0.7101 | N12: 0.5661
A13: Skywin | B13: 5 | C13: 0.0325 | D13: AMAN LIFE | E13: 3 | F13: 0.0273 | G13: 节点分布 | J13: 核心竞对分析 | L13: B0DLH3TBYC | M13: B0F32KMV8Y | N13: B0F5QRY8FW
A14: HQ4US 4LEGS | B14: 3 | C14: 0.0258 | D14: eenk | E14: 1 | F14: 0.0245 | G14: Trays | K14: 月销量 | L14: 1239 | M14: 457 | N14: 193
A15: 其他 | B15: =A8-B10-B11-B12-B13-B14 | C15: =1-C10-C11-C12-C13-C14 | D15: 其他 | E15: =A8-E10-E11-E12-E13-E14 | F15: =1-F10-F11-F12-F13-F14 | K15: 成交价 | L15: 19.99 | M15: 18.99 | N15: 18.74
A16: 关键词趋势分析 | K16: 评分数 | L16: 257 | M16: 47 | N16: 39
H17: 从关键词对比可看出，传统仿真草皮款式呈明显下滑趋势；室内狗厕所+狗用便盆托盘俩个词呈明显领先。 | K17: 评分值 | L17: 4.6 | M17: 4.1 | N17: 4.5
K18: 收录词数 | L18: 289 | M18: 119 | N18: 69
J19: 产品对比分析 | L19: 新品 | M19: 竞品asin1 | N19: 竞品asin2 | O19: 产品主要优势为隐藏磁吸固定（工厂有申请专利）
K20: 包装信息 | L20: 9.9*9.8*2.1in | M20: 11.6*6.9*2.1in | N20: 9.9*8.5*2.9in
K21: 材质 | L21: 硅胶 | M21: 硅胶 | N21: 硅胶
A22: 集中度分析 | K22: 尺寸 | L22: 24*24in | M22: 24*24in | N22: 24*24in
A23: TOP10均销量 | B23: TOP10均销售额 | C23: NO.50月销量 | D23: NO.50月销售额 | E23: NO.100月销量 | F23: NO.100月销售额 | G23: 快速增长的品类，目前头部垄断较高，多为塑料隔板老款型号。前十中有3个为硅胶材质，趋势优于传统款 | K23: 尿垫固定方式 | L23: 磁铁吸附 | M23: / | N23: 独立塑料扣
A24: 2980 | B24: 107166.58 | C24: 148 | D24: 5919 | E24: 56 | F24: 1977 | K24: 唇边高度 | L24: 0.7in | M24: 0.59in | N24: 0.79in
A25: 销售类型分析 | K25: 产品表面处理 | L25: 无 | M25: 菱形图案 | N25: 无
A26: 发货类型 | B26: 链接数量 | C26: 销量占比 | D26: 平均评论数 | E26: 平均评分值 | F26: 亚马逊自营权重较大，为美国品牌传统硬塑料+草皮款。与开发款式不一样，开发为针对训练器的小狗+全生命期母狗的室内场景隔尿垫，这类产品增长迅速，建议以慢节奏方式进场，放狗狗店铺 场景化运营。 | J26: 客户需求（评价）分析 | L26: 描述 | O26: BS1 | P26: BS2 | Q26: B0DLH3TBYC | R26: B0F32KMV8Y | S26: B0F5QRY8FW
A27: FBA | B27: 75 | C27: 0.3928 | D27: 482 | E27: 4.1 | K27: 场景一 | L27: 室内狗狗宠物将其与尿垫组合使用——多为中小型犬
A28: FBM | B28: 5 | C28: 0.033 | D28: 221 | E28: 4.3 | K28: 场景二 | L28: 室内狗笼训练期定点上厕所使用——多为小狗刚到家训练 | R28: / | S28: /
A29: AMZ | B29: 7 | C29: 0.4819 | D29: 1885 | E29: 4.2 | K29: 场景三 | L29: 室内特殊的猫咪种类使用——多为抗拒猫砂盆or后肢不便 | S29: /
A30: 其他 | B30: 13 | C30: 0.0923 | D30: 1671 | E30: 3.9 | K30: 好评点NO.1 | L30: 防水性好，保护了木板 | O30: BS1 | P30: BS2 | Q30: B0DLH3TBYC | R30: B0F32KMV8Y | S30: B0F5QRY8FW
A31: 账号国家 | B31: 链接数量 | C31: 销量占比 | D31: / | K31: 好评点NO.2 | L31: 易于清洁
A32: 中国 | B32: 60 | C32: 0.302 | K32: 好评点NO.3 | L32: 稳定性强（地面放置+固定尿垫两方面）
A33: 美国 | B33: 37 | C33: 0.6785 | K33: 差评点NO.1 | L33: 尺寸问题
A34: 其他 | B34: 3 | C34: 0.0195 | K34: 差评点NO.2 | L34: 耐用性（狗狗破坏）
A35: 上架时间分析 | J35: 开发产品自述 | K35: 价格段市场概括 | L35: 20-40价格段近三年一直占比最高，这个价格段评分逐年缓慢提升，说明这一价格段，新硅胶新材质售后更低，销量近三年均上升，尤其24年出现翻倍增长趋势。说明这类产品为刚需。评分数无明显增长，说明该价格段新品进入难度低。
H36: 近期上架多为硅胶材质款/三面隔板款（针对公狗）新品更加细分场景，老品多为搭建塑料隔板款/仿真草皮款
A41: 价格段分析 | K41: 产品销售切入点 | L41: ①通过隐形磁铁固定尿垫，优化了安装步骤，并通过隐形减少狗啃咬固定器概率，降低因狗狗啃咬导致的退款概率；
H42: 价格段分散，销量主要集中在20-40美金，开发款式建议小尺寸在20左右，大尺寸在30左右两款变体进行布局 | L42: ②通过市调尿垫尺寸，确认选择主流尺寸链接围绕选定尺寸进行埋词，减少因尺寸不合适的差评与退款；（需运营一同确认）
L43: ③通过增加2元左右纸盒包装，比竞对opp袋缩小物流成本；（需运营一同确认）
L44: ④通过主推如厕训练期小狗+小型狗+母狗+特殊情况猫咪，链接围绕细分宠物，减少不适配的宠物购买导致的差评与退款
...

Sheet 竞对推广分析（运营数据）
A1: 链接 分析 | B1: 主图 | C1: ASIN | D1: 链接 | E1: 类目/节点 | F1: 排名（大类/小类） | G1: 品牌 | H1: 最终售价 | I1: 划线价比率 | J1: 评分 | K1: 评论数 | L1: 预估日销 | M1: 月销量 | N1: 上架时间 | O1: 推广用时 | P1: 变体数 | Q1: 促销力度 | R1: 是否捆绑促销 | S1: 是否有视频 | T1: 测评力度（首月） | V1: 评论质量 | W1: 站外信息（判断站外类型是内容推广，对应的内容信息是什么；还是放量出单，对应价格折扣比是多少 效果如何？） | AC1: 竞对日销多少，持续多长时间激活秒杀的？ | AD1: 竞对的活动效果如何？ | AE1: 竞品推广期间是否有断货 | AF1: 竞对是什么时候开始的站内广告的？ | AG1: 站内广告用的是什么打法？ | AH1: 流量的分布流量的来源入口，收录词数量 | AI1: 推广类型 | AJ1: 卖家背景 | AL1: 品牌背景检索 | AN1: 策略 总结
W2: Facebook | X2: INS | Y2: Youtube | Z2: Google | AA2: Tiktok | AB2: 独立站（品牌流量，私域水平）
T3: 首月排名 | U3: 评论数
A4: 新品 | C4: B0DZNVSXT3 | D4: https://www.amazon.com/dp/B0DZNVSXT3 | E4: Wheel & Tire Air Compressors & Inflators | F4: 6971 | G4: Infloza | H4: 29.99 | J4: 5 | K4: 4 | L4: =M4/K4 | M4: 117 | N4: 45733 | O4: 30天 | P4: 1 | Q4: 15% off | R4: 无 | S4: 2个视频 1个展示 1个红人 | T4: 6917 | U4: 5 | V4: 通过服务商刷单为主，评论质量一般。 | AD4: / | AF4: 有评论之后开广告 | AG4: sp+sb+sd | AH4: 自然流量：43.11%，广告流量：53.71% 流量词：321 | AI4: 链接质量可以 前期以刷单为主，先刷划线价然后叠加站内优惠券、折后价在整个新品类目较有竞争力，有评论基础后开了少量广告，广告占比高达85%，属于站内广告猛推+免评单的暴力打法 | AJ4: 账号公司地址为广州，店铺主做办公椅产品，除该新链接外，无突出链接，运营深度一般 另一品牌X xishe是安吉工厂背景，在供应链上有深耕，但是精细化运营和品牌化能力较弱 | AL4: Owner：Zhao Fugang 同源品牌： X xishe CHAIROYAL CHAIRELAX SAMOFU | AN4: 视觉差异：突出电池续航和多用功能，主图采用45°侧视场景图方案，附图A+多采用场景化素材，突出不同人群和使用需求 广告打法：在有评论的基础下，结合刷单以及站内折扣逐步推进。 产品差异：目前在功能上均为一致，主要质感差异在于电池续航方面，需在这方面优化体验感 突出产品的性价比，提升整体链接的转化率 卖点差异：更多强调产品硬件参数项优势，以及便携性
A5: 热销品 | C5: B0D6BGPQKW | D5: https://www.amazon.com/dp/B0D6BGPQKW | E5: Wheel & Tire Air Compressors & Inflators | F5: 867 | G5: Powools | H5: 34.99 | J5: 4.4 | K5: 450 | L5: =M5/30 | M5: 3800 | N5: 45571 | O5: 30天 | P5: 2 | Q5: 10 | R5: 无 | S5: 13个视频 2个场景 5个安装 6个买家秀 | T5: 339 | U5: 57 | V5: 一开始 先刷单 、免评+留评都刷，三天后合并评论、大概20天左右 合并的变体被拆、刷出的单已经回评、评分在4.7以上不影响推广节奏、 | AC5: 日销100左右，不到1个月激活秒杀 | AD5: 1.5倍增长 | AF5: 有评论之后开广告 | AG5: sp+sb+sd | AH5: 自然流量：66.52%，广告流量：7.57% 流量词：723 | AI5: 前期高定价且站内叠加大额折扣 ，订单销量保持2500-3500， 12月份断货、 1月份恢复推广增加+视频广告。这时候也开始有推荐流量了 ，销量也开始恢复且保持增长 近 30天销量大概4000+ 。1月份标价59.99，叠加50%优惠券之后29.99。效果不如预期。随之下调为39.98+30%优惠券 ，折后价：27.99， 价格又调整59.99，会员折后价格仅会员可见39.99 ，叠加30%优惠券 折后价41.99，站外20天+bd连报28天，销量恢复到3000+，最近的购物车价格是49.99 会员折扣价格39.99 春促活动价34.99 | AJ5: 账号公司地址为杭州，垂直店铺，只做办公椅，运营能力较强 另一品牌Razzor账号注册公司为安吉一办公椅厂，推测为工厂背景 | AL5: Owner：Dai, Mingyue 同源品牌： RAZZOR
A6: 选择的竞对分析 | C6: B0DNLYRCPL | D6: https://www.amazon.com/dp/B0DNLYRCPL | E6: Wheel & Tire Air Compressors & Inflators | F6: 4151 | G6: Olgeo | H6: 29.99 | J6: 4.5 | K6: 44 | L6: =M6/30 | M6: 900 | N6: 45639 | O6: 60天 | P6: 1 | Q6: / | R6: 无 | S6: 无视频 | T6: 3436 | U6: 15 | V6: 直接合并链接、然后在刷单、再拆分出来单独推 | W6: 无站外 | AC6: 目前日销40左右，大概用1个半月激活秒杀 | AD6: 1.5倍增长 | AF6: 有评论之后开广告 | AG6: sp | AH6: 自然流量：93.69%，广告流量：3.68% 流量词：321 | AI6: 一开始获取绿标+刷单获取评论，都是自然流量，后面慢慢打一点广告，截止目前自然流量占比还在70%以上 其中父体发生了4次变更，竞对不仅做了站外，也合并到不同变体中去带，今年2月份正式分离出来单独推 2月份销量300+、3月份价格下调到29.99,参加活动，月销量冲到800+
A7: 失败品分析 （） | C7: B0DQY1PL59 | D7: https://www.amazon.com/dp/B0DQY1PL59 | E7: Wheel & Tire Air Compressors & Inflators | F7: 72610 | G7: Jrapotu | H7: 39.99 | J7: 2 | K7: 1 | L7: =M7/30 | M7: 50 | N7: 45644 | O7: 120天 | P7: 1 | Q7: / | R7: 无 | S7: 无视频 | T7: 312942 | U7: 3 | V7: 刷了3个评论全掉了、被上了一个直评之后也不及时补分数 | W7: 无站外 | AC7: 暂无数据 | AD7: / | AI7: 前期推广力度很低，基本没有干预且广告花费很少，没有投放核心词，属于精铺提供方式 失败原因为推广力度太小，前期干预太少，以及产品品质不佳
A9: 评论策略 | B9: 上评方式 | C9: 数量
A10: 前置动作 | B10: QC全检 | C10: 出货前全检、试装，减少产品品质问题
B11: 质保承诺 | C11: 说明书提供售后邮箱，承诺质保，提供换货和退款
B12: 差评拦截 | C12: 针对到货后5天的订单，发送关怀邮件
A13: 早期评论 | B13: 提前发Vine链接 | C13: 20
B14: 网红测评 | C14: 2
B15: TOP测评 | C15: 2
B16: 主链接Vine | C16: 10
A17: 应急评论（前期来差评） | B17: CA站点测评 | C17: 5 | H17: 直接在CA刷同ASIN好评 评论同步
B18: 低价种子链接 | C18: 20
B19: 站外联系删差评 | C19: /
A20: 中长期评论 | B20: 明信片邀评 | C20: 4%回评率
B21: 延长质保卡邀评 | C21: 1%回评率
B22: 后台点击邀评 | C22: 1%回评率
A24: 关键词分析 | C24: 搜索排名 | E24: 搜索量 | F24: 品牌ABA分析数据 | S24: 前三转化之和 | U24: 自然位首行ASIN | AK24: 广告建议CPC | AM24: 差异判断 | AO24: 这个产品分到了20%，它分到 20 次点击，然后按照类目 10% 的平均转化率来讲，这个类目给到 100 个流量应该出百一十单，但这个卖家只出了一单。它的转化的共享是10%，点击共有 20% 这两个字比就是 50% ，说明它没有利用好这个流量给它带来转化，那如果它这个两者之比越低，说明它的这个词里面会越不稳定。就低于类目平均。他就他在这个词里面就相当于他是劣势的，那如果你的产品力跟产品价格都在这个词上能跟他去衡量的话，你就可以针对性去打这个词。
F25: 第一 | K25: 第二 | O25: 第三
F26: ASIN | G26: 点击共享 | H26: 转化共享 | J26: 两者之比 | K26: ASIN | L26: 点击共享 | M26: 转化共享 | N26: 两者之比 | O26: ASIN | P26: 点击共享 | Q26: 转化共享 | R26: 两者之比 | AK26: 最低 | AL26: 最高
A27: 核心词 | B27: tire inflator portable air compressor | C27: 2339 | E27: 289620 | J27: #DIV/0! | N27: #DIV/0! | R27: #DIV/0! | S27: 0
B28: air compressor | C28: 3558 | E28: 189232 | J28: #DIV/0! | N28: #DIV/0! | R28: #DIV/0! | S28: 0
B29: tire inflator | C29: 3550 | E29: 185799 | J29: #DIV/0! | N29: #DIV/0! | R29: #DIV/0! | S29: 0
B30: air pump for car tires | C30: 6899 | E30: 125771 | J30: #DIV/0! | N30: #DIV/0! | R30: #DIV/0! | S30: 0
B31: air compressor for car | C31: 5899 | E31: 87093 | J31: #DIV/0! | N31: #DIV/0! | R31: #DIV/0! | S31: 0
B32: air compressor for car | J32: #DIV/0! | N32: #DIV/0! | R32: #DIV/0! | S32: 0
A33: 长尾词 | B33: air compressor | J33: #DIV/0! | N33: #DIV/0! | R33: #DIV/0! | S33: 0
B34: tire inflator | J34: #DIV/0! | N34: #DIV/0! | R34: #DIV/0! | S34: 0
B35: air pump for car tires | J35: #DIV/0! | N35: #DIV/0! | R35: #DIV/0! | S35: 0
B36: air compressor for car | J36: #DIV/0! | N36: #DIV/0! | R36: #DIV/0! | S36: 0
B37: air compressor for car | J37: #DIV/0! | N37: #DIV/0! | R37: #DIV/0! | S37: 0
B38: air compressor for car | J38: #DIV/0! | N38: #DIV/0! | R38: #DIV/0! | S38: 0
A39: 流量词 | B39: air compressor | J39: #DIV/0! | N39: #DIV/0! | R39: #DIV/0! | S39: 0
B40: tire inflator | J40: #DIV/0! | N40: #DIV/0! | R40: #DIV/0! | S40: 0
B41: air pump for car tires | J41: #DIV/0! | N41: #DIV/0! | R41: #DIV/0! | S41: 0
A42: 品牌词 | B42: HYCJ | J42: #DIV/0! | N42: #DIV/0! | R42: #DIV/0! | S42: 0
...

Sheet 产品定位（产品数据）
A1: 产品定位 | B1: 销售品牌 | D1: 核心 卖点 | E1: 产品上的卖点 | L1: 标准 | M1: 目的 | N1: 备货标准 | O1: 销量标准 | P1: 利润标准
L2: 规模款 | M2: 为了市场占有率和降低我们的生产成本，类目市场占有率达到30%以上，才可以形成品牌扩张。 | N2: 根据推广计划备货不能断货，可备总数分批发货 | O2: 日销100单以上 | P2: 5%-15% | Q2: 注意规模款和利润款因为客单不一样，针对的人群不一样，所以就算再一个店铺也要区分品牌，最好是不在同一个店铺
A3: 定价 | C3: 折扣 | L3: 利润款 | M3: 利润款占整个产品数量的60%，让公司形成竞争力，利润款的销量是规模款的60%，但是利润是他的1.5倍。 | N3: 根据推广计划备货不能断货，可备总数分批发货 | O3: 日销50单以上 | P3: 15%-25%
L4: 结构款 | M4: 促进其他产品的销售，带给客户更高的满意度和完整的购物体验（为了让流量在店铺里面闭环），以及老客户多频次的进入店铺。 | N4: 可以断货不可以冗余 | O4: 日销10单以上 | P4: 5%-15%
A5: 类目节点 | L5: 止损款 | M5: 退市产品，要淘汰的产品，当月净毛利小于1000，且月净毛利小于 起订货值的33% | O5: 尽量不亏本清库 | P5: 0%-10%
E6: 打法或者策略上的竞争优势 | L6: 流量款 | M6: 为了引流量，给其他产品带来销量，不管是连带还是复购，还是跳转，如果只是买了引流的产品，叫引流失败；引流款可以在规模款里面，也可以在利润款和结构款里面，具体看目的是什么。 | N6: 如果是规模款就跟着规模款走，结构就跟着结构款走，如果是利润款就跟着利润款走。
A7: 目标人群 | B7: 使用场景
A13: 类目评论分析
A14: 使用人群 | B14: 使用人群：携带宠物出行的宠物主人 使用场景：普通宠物出行、宠物受伤行动不便出行、老年宠物出行、小型犬（幼犬出行）、要去人多的地方，保护宠物安全（由于提到具体使用场景的数量很少，所以没有进行数量统计） 用户需求：推车能够平稳推动，不颠簸、空间大，宠物可在推车上活动、带有收纳空间，便于携带一些小物件 | I14: 该产品主要面对的用户群体是携带宠物出行的宠物主人，用户主要需求是推车能够平稳推动，不颠簸，空间大。综合用户提及的好评点在购买产品时会重点关注产品的组装方式、空间大小、是否带有收纳区、是否带有网格窗口。这款产品产生差评主要是由车轮质量、置物架、拉链、提篮织物质量、安全扣造成的。 通过看用户的评论图片，这类产品主要用于中小型犬和多宠家庭出行，建议将这两个场景作为产品的主推场景
A15: 正面评价 | B15: 1、易于组装 23.21% 2、空间大 16.07% 3、底部有收纳区 10.71% 4、带有网格布料，能见度大 8.93% 5、面料好 8.93% 6、可折叠 5.36% 7、易于使用 3.57% 8、推杆高度合适 3.57% 其余好评有车轮质量好 3.57%、车轮平稳 3.57%、置物架 1.79%、有安全扣 1.79%、颜色和设计 1.79%、通风 1.79%、铝制结构 1.79%、开口大，宠物容易进去 1.79%、车轮360度旋转 1.79%
A16: 负面评价 | B16: 1、车轮质量差 摇晃、不稳 29.41% 2、杯架浅、放东西容易倒 10.29% 3、拉链难用、难找、质量差 8.82% 4、提篮织物裂开 5.88% 5、安全扣不牢固 5.88% 6、配件遗漏 4.41% 7、内衬薄 4.41% 其余差评有空间小 4.41%、车轮脱落 4.41%、推车不稳，容易倾斜 2.94%、质量差 1.47%、织物不能拆卸、不易于清洗 1.47%、折叠困难 1.47%、有塑料味 1.47%、推手高度不可调节 1.47%、提篮难拆卸 1.47%、配件不合适 1.47%、没有安全扣 1.47%、金属杆断裂 1.47%、车轮生锈 1.47%、车轮难拆卸 1.47%、产品重 1.47%、产品有划痕 1.47%。
A17: 已满足需求 | C17: 样品满足需求点 | E17: 待满足需求 | G17: 样品优化需求点 | I17: 产品改良方案
A18: 易于组装 | C18: √ | E18: 车轮质量差 摇晃、不稳 | G18: 车轮360度旋转，带有减震弹簧
A19: 空间大 | C19: √ | E19: 拉链难用、难找、质量差 | G19: 提篮采用卡扣设计
A20: 底部有收纳区 | C20: √ | E20: 杯架浅、放东西容易倒
A21: 有网格窗口、可见度大 | C21: √ | E21: 提篮织物裂开 | G21: 牛津布材质
A22: 可折叠收纳 | C22: √ | E22: 安全扣不牢固

Sheet 定价表
A1: 汇率 | B1: 美元 | C1: 欧元 | D1: 英镑 | E1: 加元 | F1: 运输方式 | G1: 空运 | H1: 慢船 | I1: 以星 | J1: 合德快船 | K1: 美森快船 | L1: 欧洲海运 | M1: 卡航 | N1: 铁路
A2: 兑人民币 | B2: 6.8 | C2: 7.1 | D2: 8.3 | E2: 5 | G2: =50 | H2: 7.5 | I2: 11.5 | J2: 12.5 | K2: 17 | L2: 8 | M2: 22 | N2: 14
A3: VC活动价 | B3: 汇率 | C3: 国家 | D3: 报价比例 | E3: 售价美金 | F3: 报价美金 | G3: 物流方式 | H3: 头程价格 | I3: 采购价 | J3: 国内总成本 | K3: 装箱数量 | L3: 移仓费/个 | M3: 换标费 0.5/个 | N3: 入库费/箱/1.5 | O3: 装箱费 2.5/箱 | P3: 箱唛 0.5/张/箱 | Q3: 出库费 1.5/箱 | R3: 自提费 1.5/箱 | S3: 入库总费用 | T3: 入库单个费用 | U3: 利润P0 | V3: 回款扣点 | W3: 广告费占比 | X3: 广告费 | Y3: 活动促销比例 | Z3: 活动促销/美金 | AA3: 最低活动价/美金 | AB3: 利润P3 | AC3: P1--VC | AD3: P1--SC | AE3: P3对应的投资回报率=P3/国内成本 | AF3: 国内成本占比 | AG3: 一期回款金额70%/美金 | AH3: 一期回款毛利P2=回款-国内总成本-海外仓费用 | AI3: 一期回款比例=一期回款/商品成本 | AJ3: 一期回款比例=一期回款/（国内+海外仓） | AK3: 一期投资回报=70^%部分的毛利/成本 | AL3: 营销费/cost
A4: 打气泵S | B4: =IF(C4="US",$B$2,IF(C4="UK",$D$2,IF(C4="ES",$C$2,IF(C4="CA",$E$2,$C$2)))) | C4: UK | D4: 0.62 | E4: 33.32 | F4: =E4*D4 | G4: 空运 | H4: =INDEX($G$2:$N$2, MATCH(G4, $G$1:$N$1, 0)) | I4: 70 | J4: =SUM(H4:I4) | K4: 16 | L4: 0 | M4: 0 | N4: 1.5 | O4: 0 | P4: 1 | Q4: 1.5 | R4: 1.5 | S4: =SUM(N4:R4)+(L4+M4)*K4 | T4: =S4/K4*B4 | U4: =F4*B4-J4-T4 | V4: 0.02 | W4: 0.08 | X4: =E4*W4*B4 | Y4: 0.1 | Z4: =E4*Y4 | AA4: =E4-Z4 | AB4: =U4-F4*V4*B4-X4-Z4*B4 | AC4: =AB4/(F4*B4) | AD4: =AB4/(E4*B4) | AE4: =AB4/J4 | AF4: =J4/B4/F4 | AG4: =F4*0.7 | AH4: =AG4*B4-T4-J4 | AI4: =AG4*B4/J4 | AJ4: =AG4*B4/(J4+T4) | AK4: =AH4/J4 | AL4: =(X4/B4+Z4)/F4
A5: 打气泵 A | B5: =IF(C5="US",$B$2,IF(C5="UK",$D$2,IF(C5="ES",$C$2,IF(C5="CA",$E$2,$C$2)))) | C5: UK | D5: 0.62 | E5: 33.32 | F5: =E5*D5 | G5: 美森快船 | H5: =INDEX($G$2:$N$2, MATCH(G5, $G$1:$N$1, 0)) | I5: 70 | J5: =SUM(H5:I5) | K5: 16 | L5: 0 | M5: 0 | N5: 1.5 | O5: 0 | P5: 1 | Q5: 1.5 | R5: 1.5 | S5: =SUM(N5:R5)+(L5+M5)*K5 | T5: =S5/K5*B5 | U5: =F5*B5-J5-T5 | V5: 0.02 | W5: 0.08 | X5: =E5*W5*B5 | Y5: 0.1 | Z5: =E5*Y5 | AA5: =E5-Z5 | AB5: =U5-F5*V5*B5-X5-Z5*B5 | AC5: =AB5/(F5*B5) | AD5: =AB5/(E5*B5) | AE5: =AB5/J5 | AF5: =J5/B5/F5 | AG5: =F5*0.7 | AH5: =AG5*B5-T5-J5 | AI5: =AG5*B5/J5 | AJ5: =AG5*B5/(J5+T5) | AK5: =AH5/J5 | AL5: =(X5/B5+Z5)/F5
A6: 打气泵 V | B6: =IF(C6="US",$B$2,IF(C6="UK",$D$2,IF(C6="ES",$C$2,IF(C6="CA",$E$2,$C$2)))) | C6: UK | D6: 0.62 | E6: 33.32 | F6: =E6*D6 | G6: 美森快船 | H6: =INDEX($G$2:$N$2, MATCH(G6, $G$1:$N$1, 0)) | I6: 70 | J6: =SUM(H6:I6) | K6: 16 | L6: 0 | M6: 0 | N6: 1.5 | O6: 0 | P6: 1 | Q6: 1.5 | R6: 1.5 | S6: =SUM(N6:R6)+(L6+M6)*K6 | T6: =S6/K6*B6 | U6: =F6*B6-J6-T6 | V6: 0.02 | W6: 0.08 | X6: =E6*W6*B6 | Y6: 0.1 | Z6: =E6*Y6 | AA6: =E6-Z6 | AB6: =U6-F6*V6*B6-X6-Z6*B6 | AC6: =AB6/(F6*B6) | AD6: =AB6/(E6*B6) | AE6: =AB6/J6 | AF6: =J6/B6/F6 | AG6: =F6*0.7 | AH6: =AG6*B6-T6-J6 | AI6: =AG6*B6/J6 | AJ6: =AG6*B6/(J6+T6) | AK6: =AH6/J6 | AL6: =(X6/B6+Z6)/F6
A7: 竞对价格 | B7: =IF(C7="US",$B$2,IF(C7="UK",$D$2,IF(C7="ES",$C$2,IF(C7="CA",$E$2,$C$2)))) | C7: US | D7: 0.62 | E7: 33.32 | F7: =E7*D7 | G7: 美森快船 | H7: =INDEX($G$2:$N$2, MATCH(G7, $G$1:$N$1, 0)) | I7: 70 | J7: =SUM(H7:I7) | K7: 16 | L7: 0 | M7: 0 | N7: 1.5 | O7: 0 | P7: 1 | Q7: 1.5 | R7: 1.5 | S7: =SUM(N7:R7)+(L7+M7)*K7 | T7: =S7/K7*B7 | U7: =F7*B7-J7-T7 | V7: 0.02 | W7: 0.08 | X7: =E7*W7*B7 | Y7: 0.1 | Z7: =E7*Y7 | AA7: =E7-Z7 | AB7: =U7-F7*V7*B7-X7-Z7*B7 | AC7: =AB7/(F7*B7) | AD7: =AB7/(E7*B7) | AE7: =AB7/J7 | AF7: =J7/B7/F7 | AG7: =F7*0.7 | AH7: =AG7*B7-T7-J7 | AI7: =AG7*B7/J7 | AJ7: =AG7*B7/(J7+T7) | AK7: =AH7/J7 | AL7: =(X7/B7+Z7)/F7
A9: SC站内推广 | B9: 汇率 | C9: 国家 | D9: 有无VAT | E9: 成本价(0边利) | F9: 建议价(20%边利) | G9: 实际定价 | H9: 采购价 | I9: FBA Fee | J9: 佣金比例 | K9: VAT | L9: 预估退货率 | M9: 推广费率 | N9: FBA仓储费 | O9: 其他费用 | P9: 长 | Q9: 宽 | R9: 高 | S9: 包装后实重 | T9: 体积重 | U9: 计费重 | V9: 运输方式 | W9: 运费单价 | X9: 运费 | Y9: 利润/USD | Z9: 利润率
A10: 打气泵日常价 | B10: 6.8 | C10: US | D10: 无 | E10: =IF(D10="有",(H10/B10+I10+X10/B10)/(0.99999-J10-K10-L10-M10),(H10/B10+I10+X10/B10)/(0.99999-J10-L10-M10)) | F10: =IF(D10="有",(H10/B10+I10+X10/B10)/(0.8-J10-K10-L10-M10-N10-O10),(H10/B10+I10+X10/B10)/(0.8-J10-L10-M10-N10-O10)) | G10: 29.99 | H10: 56 | I10: 5 | J10: 0.15 | K10: 0 | L10: 0 | M10: 0 | N10: 0.01 | O10: 0.02 | P10: 14.6 | Q10: 8.8 | R10: 4.9 | S10: 0.46 | T10: =P10*Q10*R10/6000 | U10: =MAX(S10:T10) | V10: 慢船 | W10: =INDEX($G$2:$N$2, MATCH(V10, $G$1:$N$1, 0)) | X10: =U10*W10 | Y10: =G10-SUM(J10:O10)*G10-I10-H10/B10-X10/B10 | Z10: =Y10/G10
A11: 打气泵活动价 | B11: =IF(C11="US",$B$2,IF(C11="UK",$D$2,IF(C11="ES",$C$2,IF(C11="CA",$E$2,$C$2)))) | C11: US | D11: 无 | E11: =IF(D11="有",(H11/B11+I11+X11/B11)/(0.99999-J11-K11-L11-M11),(H11/B11+I11+X11/B11)/(0.99999-J11-L11-M11)) | F11: =IF(D11="有",(H11/B11+I11+X11/B11)/(0.8-J11-K11-L11-M11-N11-O11),(H11/B11+I11+X11/B11)/(0.8-J11-L11-M11-N11-O11)) | G11: 25.49 | H11: 56 | I11: 5 | J11: 0.15 | K11: 0 | L11: 0.05 | M11: 0.08 | N11: 0.01 | O11: 0.02 | P11: 14.6 | Q11: 8.8 | R11: 4.9 | S11: 0.46 | T11: =P11*Q11*R11/6000 | U11: =MAX(S11:T11) | V11: 慢船 | W11: =INDEX($G$2:$N$2, MATCH(V11, $G$1:$N$1, 0)) | X11: =U11*W11 | Y11: =G11-SUM(J11:O11)*G11-I11-H11/B11-X11/B11 | Z11: =Y11/G11
A12: 竞对日常价 | B12: =IF(C12="US",$B$2,IF(C12="UK",$D$2,IF(C12="ES",$C$2,IF(C12="CA",$E$2,$C$2)))) | C12: US | D12: 无 | E12: =IF(D12="有",(H12/B12+I12+X12/B12)/(0.99999-J12-K12-L12-M12),(H12/B12+I12+X12/B12)/(0.99999-J12-L12-M12)) | F12: =IF(D12="有",(H12/B12+I12+X12/B12)/(0.8-J12-K12-L12-M12-N12-O12),(H12/B12+I12+X12/B12)/(0.8-J12-L12-M12-N12-O12)) | G12: 29.99 | H12: 56 | I12: 5 | J12: 0.15 | K12: 0 | L12: 0.05 | M12: 0.15 | N12: 0.01 | O12: 0.02 | P12: 14.6 | Q12: 8.8 | R12: 4.9 | S12: 0.46 | T12: =P12*Q12*R12/6000 | U12: =MAX(S12:T12) | V12: 以星 | W12: =INDEX($G$2:$N$2, MATCH(V12, $G$1:$N$1, 0)) | X12: =U12*W12 | Y12: =G12-SUM(J12:O12)*G12-I12-H12/B12-X12/B12 | Z12: =Y12/G12
A13: 竞对活动价 | B13: 6.8 | C13: US | D13: 无 | E13: =IF(D13="有",(H13/B13+I13+X13/B13)/(0.99999-J13-K13-L13-M13),(H13/B13+I13+X13/B13)/(0.99999-J13-L13-M13)) | F13: =IF(D13="有",(H13/B13+I13+X13/B13)/(0.8-J13-K13-L13-M13-N13-O13),(H13/B13+I13+X13/B13)/(0.8-J13-L13-M13-N13-O13)) | G13: 23.99 | H13: 56 | I13: 5 | J13: 0.15 | K13: 0 | L13: 0.05 | M13: 0.08 | N13: 1 | O13: 0.02 | P13: 14.6 | Q13: 8.8 | R13: 4.9 | S13: 0.46 | T13: =P13*Q13*R13/6000 | U13: =MAX(S13:T13) | V13: 以星 | W13: =INDEX($G$2:$N$2, MATCH(V13, $G$1:$N$1, 0)) | X13: =U13*W13 | Y13: =G13-SUM(J13:O13)*G13-I13-H13/B13-X13/B13 | Z13: =Y13/G13
A14: 竞对活动价 | B14: 7 | C14: US | D14: 无 | E14: =IF(D14="有",(H14/B14+I14+X14/B14)/(0.99999-J14-K14-L14-M14),(H14/B14+I14+X14/B14)/(0.99999-J14-L14-M14)) | F14: =IF(D14="有",(H14/B14+I14+X14/B14)/(0.8-J14-K14-L14-M14-N14-O14),(H14/B14+I14+X14/B14)/(0.8-J14-L14-M14-N14-O14)) | G14: 29.99 | H14: 61 | I14: 8 | J14: 0.06 | K14: 0 | L14: 0.05 | M14: 0.08 | N14: 1 | O14: 0.02 | P14: 23 | Q14: 23 | R14: 13 | S14: 0.8 | T14: =P14*Q14*R14/6000 | U14: =MAX(S14:T14) | V14: 以星 | W14: =INDEX($G$2:$N$2, MATCH(V14, $G$1:$N$1, 0)) | X14: =U14*W14 | Y14: =G14-SUM(J14:O14)*G14-I14-H14/B14-X14/B14 | Z14: =Y14/G14
A16: 站外推广 | B16: 汇率 | C16: 国家 | D16: 有无VAT | E16: 成本价(0边利) | F16: 建议价(20%边利) | G16: 实际定价 | H16: 采购价 | I16: FBA Fee | J16: 佣金比例 | K16: VAT | L16: 预估退货率 | M16: 折扣力度 | N16: FBA仓储费 | O16: 其他费用 | P16: 长 | Q16: 宽 | R16: 高 | S16: 包装后实重 | T16: 体积重 | U16: 计费重 | V16: 运输方式 | W16: 运费单价 | X16: 运费 | Y16: 利润/USD | Z16: 利润率
A17: 打气泵 | B17: 6.8 | C17: US | D17: 无 | E17: =H17/B17+I17+X17/B17+(G17*(1-M17)*(J17+L17+N17+O17)) | F17: =(H17/B17+I17+X17/B17+(G17*(1-M17)*(J17+L17+N17+O17)))/0.8 | G17: 59.99 | H17: 56 | I17: 5.48 | J17: 0.15 | K17: 0 | L17: 0.03 | M17: 0.6 | N17: 0.01 | O17: 0.02 | P17: 13.8 | Q17: 10.8 | R17: 3.7 | S17: 0.35 | T17: =P17*Q17*R17/6000 | U17: =MAX(S17:T17) | V17: 铁路 | W17: =INDEX($G$2:$N$2, MATCH(V17, $G$1:$N$1, 0)) | X17: =U17*W17 | Y17: =(G17*(1-M17))-H17/B17-I17-X17/B17-(J17+L17+N17+O17)*(G17*(1-M17)) | Z17: =Y17/G17
A18: 竞对站外价格 | B18: =IF(C18="US",$B$2,IF(C18="UK",$D$2,IF(C18="ES",$C$2,IF(C18="CA",$E$2,$C$2)))) | C18: US | D18: 无 | E18: =H18/B18+I18+X18/B18+(G18*(1-M18)*(J18+L18+N18+O18)) | F18: =(H18/B18+I18+X18/B18+(G18*(1-M18)*(J18+L18+N18+O18)))/0.8 | G18: 59.99 | H18: 56 | I18: 5.48 | J18: 0.15 | K18: 0 | L18: 0.05 | M18: 0.6 | N18: 0.01 | O18: 0.02 | P18: 13.8 | Q18: 10.8 | R18: 3.7 | S18: 0.35 | T18: =P18*Q18*R18/6000 | U18: =MAX(S18:T18) | V18: 以星 | W18: =INDEX($G$2:$N$2, MATCH(V18, $G$1:$N$1, 0)) | X18: =U18*W18 | Y18: =(G18*(1-M18))-H18/B18-I18-X18/B18-(J18+L18+N18+O18)*(G18*(1-M18)) | Z18: =Y18/G18
A21: Woot | B21: 汇率 | C21: 国家 | D21: 报价比例 | E21: 售价美金 | F21: 报价美金 | G21: 采购价 | H21: 头程 | I21: 国内总成本 | J21: 广告费占比 | K21: 广告费 | L21: 利润/RMB | M21: Woot利润率
A22: 打气泵 | B22: =IF(C22="US",$B$2,IF(C22="UK",$D$2,IF(C22="ES",$C$2,IF(C22="CA",$E$2,$C$2)))) | C22: US | D22: 0.44 | E22: 29.99 | F22: =E22*D22 | G22: 56 | H22: =X9 | I22: =SUM(G22:H22) | J22: 0.15 | K22: =E22*B22*J22 | L22: =F22*B22-I22-K22 | M22: =L22/(E22*B22)
A23: 回款定价表
A24: 售价 | B24: 月销量 | C24: 销售总额 | D24: MC | E24: 佣金 | F24: 配送费 | G24: RMA扣减 | H24: 广告费 | I24: 促销费 | J24: FBA仓储 | K24: 弃置费用 | L24: VAT | M24: 成本总计 | N24: 回款额 | O24: 回款率 | P24: 净毛利 | Q24: 净毛利率
A25: =$G$10 | B25: 1 | C25: =A25*B25 | D25: =(H10+X10)/$B$10*B25 | E25: =A25*B25*$J$10 | F25: =B25*$I$10 | G25: =B25*A25*$L$10 | H25: =$M$10*C25 | I25: 0 | J25: =$N$10 | K25: 0 | L25: =K10 | M25: =D25+E25+F25+G25+H25+I25+J25+K25+L25 | N25: =C25-E25-L25-J25-D25-F25-H25-I25-K25 | O25: =N25/C25 | P25: =C25-M25 | Q25: =P25/C25
A26: =$G$10 | B26: 200 | C26: =A26*B26 | D26: =(H11+X11)/$B$10*B26 | E26: =A26*B26*$J$10 | F26: =B26*$I$10 | G26: =B26*A26*$L$10 | H26: =$M$10*C26 | I26: 0 | J26: =$N$10 | K26: 0 | L26: =K11 | M26: =D26+E26+F26+G26+H26+I26+J26+K26+L26 | N26: =C26-E26-L26-J26-D26-F26-H26-I26-K26 | O26: =N26/C26 | P26: =C26-M26 | Q26: =P26/C26
A27: 底价定价表
A28: Asin | B28: SKU | C28: Price | D28: All cost | E28: Profit | F28: Profit% | G28: MC | H28: 佣金 | I28: 配送费 | J28: 退货均摊 | K28: VAT税率 | L28: 佣金率 | M28: 退货率 | N28: 折扣% off | O28: 底价
A29: WOOT | B29: WWW0 | C29: =G10 | D29: =G29+H29+I29+J29+K29*C29+C29*N29 | E29: =C29-D29 | F29: =E29/C29 | G29: =(H10+X10)/$B$10 | H29: =C29*$J$10 | I29: =$I$10 | J29: =C29*$L$10 | K29: 0 | L29: =$J$10 | M29: =L18*$L$10 | N29: =$M$10 | O29: =(G29+I29)/(1-K29-L29-M29)

Sheet SC+VC推广计划拆解
A1: 第一阶段：0~7天 | C1: 阶段目标：安排完划线价就要转vc的做DF，开售一周（刷单+报活动）活动全年拉满就转回SC； | J1: 推广计划根据库存量来定，不断货，不冗余
A2: 步骤 | B2: 目标 | C2: 处理的结果
A3: 第一步 | B3: 划线价（30%）
A4: 第二步 | B4: 刷单数量安排
A5: 第三步 | B5: VC测试报活动
A6: 第四步 | B6: 开启PO,同时申请手动订单
A8: 第二阶段：8~28天 | C8: 阶段目标：转SC推广，提升刷单关键词自然位，拉大流量提升单量和排名，为VC BD做准备；
A9: ASIN | D9: 定价 | E9: 139 | L9: M01 | M9: M02 | N9: M03
A10: 终期流量目标 | B10: =IFERROR(B11/B13,0) | D10: 折扣 | E10: 30 | K10: 广告花费 | L10: =SUM(I30,I50,I70,I99) | M10: =SUM(I119,#REF!,B188,E188) | N10: =SUM(H188:Q188)
A11: 终期日销目标 | B11: 10 | D11: 成交价 | E11: =E9-E10 | K11: 总销售额 | L11: =I102+I73+I53+I33 | M11: =SUM(I122,#REF!,B191,E191) | N11: =SUM(H191:Q191)
A12: CTR目标 | B12: 0.003 | D12: 不含广告利润额 | E12: 28.43 | F12: 利润额扣除退货率，不扣除广告占比 | K12: 广告占比 | L12: =L10/L11 | M12: =M10/M11 | N12: =N10/N11
A13: CVR目标 | B13: 0.05
A14: 广告单占比目标 | B14: 0.8
A15: 目标评论数 | B15: 5
A16: 站外目标出单
A17: 联盟目标出单
A19: （目标）第二阶段详细计划 Part1 | C19: 开售W2 | M19: 实际完成数据 | O19: 开售W2 | Y19: 完成差额 | AA19: 开售W2
A20: 数据预测 | B20: Day 1 | C20: Day 2 | D20: Day 3 | E20: Day 4 | F20: Day 5 | G20: Day 6 | H20: Day 7 | I20: 合计 | M20: 数据预测 | N20: Day 1 | O20: Day 2 | P20: Day 3 | Q20: Day 4 | R20: Day 5 | S20: Day 6 | T20: Day 7 | U20: 合计 | Y20: 数据预测 | Z20: Day 1 | AA20: Day 2 | AB20: Day 3 | AC20: Day 4 | AD20: Day 5 | AE20: Day 6 | AF20: Day 7 | AG20: 合计
A21: 目标总单量 | B21: 1 | C21: 2 | D21: 3 | E21: 4 | F21: 5 | G21: 5 | H21: 6 | I21: =SUM(B21:H21) | M21: 总单量 | N21: 12 | O21: 23 | P21: 26 | Q21: 25 | R21: 11 | S21: 52 | T21: 12 | U21: =SUM(N21:T21) | Y21: 总单量 | Z21: =N21-B21 | AA21: =O21-C21 | AB21: =P21-D21 | AC21: =Q21-E21 | AD21: =R21-F21 | AE21: =S21-G21 | AF21: =T21-H21 | AG21: =SUM(Z21:AF21)
A22: 总流量 | B22: =B21/B28 | C22: =C21/C28 | D22: =D21/D28 | E22: =E21/E28 | F22: =F21/F28 | G22: =G21/G28 | H22: =H21/H28 | I22: =SUM(B22:H22) | M22: 总流量 | N22: =N21/N28 | O22: =O21/O28 | P22: =P21/P28 | Q22: =Q21/Q28 | R22: =R21/R28 | S22: =S21/S28 | T22: =T21/T28 | U22: =SUM(N22:T22) | Y22: 总流量 | Z22: =N22-B22 | AA22: =O22-C22 | AB22: =P22-D22 | AC22: =Q22-E22 | AD22: =R22-F22 | AE22: =S22-G22 | AF22: =T22-H22 | AG22: =SUM(Z22:AF22)
A23: 广告单占比 | B23: 1 | C23: 1 | D23: 1 | E23: 1 | F23: 1 | G23: 0.9 | H23: 0.9 | I23: =I25/I21 | M23: 广告单占比 | N23: 1 | O23: 1 | P23: 1 | Q23: 1 | R23: 1 | S23: 0.9 | T23: 0.9 | U23: =U25/U21 | Y23: 广告单占比 | Z23: =N23-B23 | AA23: =O23-C23 | AB23: =P23-D23 | AC23: =Q23-E23 | AD23: =R23-F23 | AE23: =S23-G23 | AF23: =T23-H23 | AG23: =AG25/AG21
A24: 自然单量 | B24: =B21-B25 | C24: =C21-C25 | D24: =D21-D25 | E24: =E21-E25 | F24: =F21-F25 | G24: =G21-G25 | H24: =H21-H25 | I24: =SUM(B24:H24) | M24: 自然单量 | N24: 12 | O24: =O21-O25 | P24: =P21-P25 | Q24: =Q21-Q25 | R24: =R21-R25 | S24: =S21-S25 | T24: =T21-T25 | U24: =SUM(N24:T24) | Y24: 自然单量 | Z24: =N24-B24 | AA24: =O24-C24 | AB24: =P24-D24 | AC24: =Q24-E24 | AD24: =R24-F24 | AE24: =S24-G24 | AF24: =T24-H24 | AG24: =SUM(Z24:AF24)
A25: 广告单量 | B25: =B21*B23 | C25: =C21*C23 | D25: =D21*D23 | E25: =E21*E23 | F25: =F21*F23 | G25: =G21*G23 | H25: =H21*H23 | I25: =SUM(B25:H25) | M25: 广告单量 | N25: =N21*N23 | O25: =O21*O23 | P25: =P21*P23 | Q25: =Q21*Q23 | R25: =R21*R23 | S25: =S21*S23 | T25: =T21*T23 | U25: =SUM(N25:T25) | Y25: 广告单量 | Z25: =N25-B25 | AA25: =O25-C25 | AB25: =P25-D25 | AC25: =Q25-E25 | AD25: =R25-F25 | AE25: =S25-G25 | AF25: =T25-H25 | AG25: =SUM(Z25:AF25)
A26: CPC | B26: 3.8 | C26: 3.8 | D26: 3.8 | E26: 3.8 | F26: 3.8 | G26: 3.8 | H26: 3.8 | I26: =AVERAGE(B26:H26) | M26: CPC | N26: 3.8 | O26: 3.8 | P26: 3.8 | Q26: 3.8 | R26: 3.8 | S26: 3.8 | T26: 3.8 | U26: =AVERAGE(N26:T26) | Y26: CPC | Z26: =N26-B26 | AA26: =O26-C26 | AB26: =P26-D26 | AC26: =Q26-E26 | AD26: =R26-F26 | AE26: =S26-G26 | AF26: =T26-H26 | AG26: =AVERAGE(Z26:AF26)
A27: 点击率CTR | B27: 0.003 | C27: 0.003 | D27: 0.003 | E27: 0.003 | F27: 0.003 | G27: 0.003 | H27: 0.003 | I27: =AVERAGE(B27:H27) | M27: 点击率CTR | N27: 0.003 | O27: 0.003 | P27: 0.003 | Q27: 0.003 | R27: 0.003 | S27: 0.003 | T27: 0.003 | U27: =AVERAGE(N27:T27) | Y27: 点击率CTR | Z27: =N27-B27 | AA27: =O27-C27 | AB27: =P27-D27 | AC27: =Q27-E27 | AD27: =R27-F27 | AE27: =S27-G27 | AF27: =T27-H27 | AG27: =AVERAGE(Z27:AF27)
A28: 转化率CVR | B28: 0.04 | C28: 0.04 | D28: 0.04 | E28: 0.04 | F28: 0.04 | G28: 0.04 | H28: 0.04 | I28: =AVERAGE(B28:H28) | J28: 累计出单 | K28: =I21 | M28: 转化率CVR | N28: 0.04 | O28: 0.04 | P28: 0.04 | Q28: 0.04 | R28: 0.04 | S28: 0.04 | T28: 0.04 | U28: =AVERAGE(N28:T28) | V28: 累计出单 | W28: =U21 | Y28: 转化率CVR | Z28: =N28-B28 | AA28: =O28-C28 | AB28: =P28-D28 | AC28: =Q28-E28 | AD28: =R28-F28 | AE28: =S28-G28 | AF28: =T28-H28 | AG28: =AVERAGE(Z28:AF28) | AH28: 累计出单 | AI28: =AG21
A29: 广告点击量 | B29: =B25/B28 | C29: =C25/C28 | D29: =D25/D28 | E29: =E25/E28 | F29: =F25/F28 | G29: =G25/G28 | H29: =H25/H28 | I29: =SUM(B29:H29) | J29: 本周CPA | K29: =I30/I25 | M29: 广告点击量 | N29: =N25/N28 | O29: =O25/O28 | P29: =P25/P28 | Q29: =Q25/Q28 | R29: =R25/R28 | S29: =S25/S28 | T29: =T25/T28 | U29: =SUM(N29:T29) | V29: 本周CPA | W29: =U30/U25 | Y29: 广告点击量 | Z29: =N29-B29 | AA29: =O29-C29 | AB29: =P29-D29 | AC29: =Q29-E29 | AD29: =R29-F29 | AE29: =S29-G29 | AF29: =T29-H29 | AG29: =SUM(Z29:AF29) | AH29: 本周CPA | AI29: =AG30/AG25
A30: 广告花费 | B30: =B26*B29 | C30: =C26*C29 | D30: =D26*D29 | E30: =E26*E29 | F30: =F26*F29 | G30: =G26*G29 | H30: =H26*H29 | I30: =SUM(B30:H30) | J30: 本周广告占比 | K30: =I30/I33 | M30: 广告花费 | N30: =N26*N29 | O30: =O26*O29 | P30: =P26*P29 | Q30: =Q26*Q29 | R30: =R26*R29 | S30: =S26*S29 | T30: =T26*T29 | U30: =SUM(N30:T30) | V30: 本周广告占比 | W30: =U30/U33 | Y30: 广告花费 | Z30: =N30-B30 | AA30: =O30-C30 | AB30: =P30-D30 | AC30: =Q30-E30 | AD30: =R30-F30 | AE30: =S30-G30 | AF30: =T30-H30 | AG30: =SUM(Z30:AF30) | AH30: 本周广告占比 | AI30: =AG30/AG33
A31: 广告ACOS | B31: =B30/B32 | C31: =C30/C32 | D31: =D30/D32 | E31: =E30/E32 | F31: =F30/F32 | G31: =G30/G32 | H31: =H30/H32 | I31: =I30/I32 | M31: 广告ACOS | N31: =N30/N32 | O31: =O30/O32 | P31: =P30/P32 | Q31: =Q30/Q32 | R31: =R30/R32 | S31: =S30/S32 | T31: =T30/T32 | U31: =U30/U32 | Y31: 广告ACOS | Z31: =N31-B31 | AA31: =O31-C31 | AB31: =P31-D31 | AC31: =Q31-E31 | AD31: =R31-F31 | AE31: =S31-G31 | AF31: =T31-H31 | AG31: =AG30/AG32
A32: 广告销售额 | B32: =B25*$E$11 | C32: =C25*$E$11 | D32: =D25*$E$11 | E32: =E25*$E$11 | F32: =F25*$E$11 | G32: =G25*$E$11 | H32: =H25*$E$11 | I32: =SUM(B32:H32) | J32: 本周利润额 | K32: =I34 | M32: 广告销售额 | N32: =N25*$E$11 | O32: =O25*$E$11 | P32: =P25*$E$11 | Q32: =Q25*$E$11 | R32: =R25*$E$11 | S32: =S25*$E$11 | T32: =T25*$E$11 | U32: =SUM(N32:T32) | V32: 本周利润额 | W32: =U34 | Y32: 广告销售额 | Z32: =N32-B32 | AA32: =O32-C32 | AB32: =P32-D32 | AC32: =Q32-E32 | AD32: =R32-F32 | AE32: =S32-G32 | AF32: =T32-H32 | AG32: =SUM(Z32:AF32) | AH32: 本周利润额 | AI32: =AG34
A33: 总销售额 | B33: =B21*$E$11 | C33: =C21*$E$11 | D33: =D21*$E$11 | E33: =E21*$E$11 | F33: =F21*$E$11 | G33: =G21*$E$11 | H33: =H21*$E$11 | I33: =SUM(B33:H33) | J33: 本周利润率 | K33: =K32/I33 | M33: 总销售额 | N33: =N21*$E$11 | O33: =O21*$E$11 | P33: =P21*$E$11 | Q33: =Q21*$E$11 | R33: =R21*$E$11 | S33: =S21*$E$11 | T33: =T21*$E$11 | U33: =SUM(N33:T33) | V33: 本周利润率 | W33: =W32/U33 | Y33: 总销售额 | Z33: =N33-B33 | AA33: =O33-C33 | AB33: =P33-D33 | AC33: =Q33-E33 | AD33: =R33-F33 | AE33: =S33-G33 | AF33: =T33-H33 | AG33: =SUM(Z33:AF33) | AH33: 本周利润率 | AI33: =AI32/AG33
A34: 利润 | B34: =B21*$E$12-B30 | C34: =C21*$E$12-C30 | D34: =D21*$E$12-D30 | E34: =E21*$E$12-E30 | F34: =F21*$E$12-F30 | G34: =G21*$E$12-G30 | H34: =H21*$E$12-H30 | I34: =SUM(B34:H34) | J34: 结余利润额 | K34: =K32 | M34: 利润 | N34: =N21*$E$12-N30 | O34: =O21*$E$12-O30 | P34: =P21*$E$12-P30 | Q34: =Q21*$E$12-Q30 | R34: =R21*$E$12-R30 | S34: =S21*$E$12-S30 | T34: =T21*$E$12-T30 | U34: =SUM(N34:T34) | V34: 结余利润额 | W34: =W32 | Y34: 利润 | Z34: =N34-B34 | AA34: =O34-C34 | AB34: =P34-D34 | AC34: =Q34-E34 | AD34: =R34-F34 | AE34: =S34-G34 | AF34: =T34-H34 | AG34: =SUM(Z34:AF34) | AH34: 结余利润额 | AI34: =AI32
A35: 执行策略
A39: （目标）第二阶段详细计划 Part2 | C39: 开售W3 | M39: 实际完成数据 | O39: 开售W3 | Y39: 完成差额 | AA39: 开售W3
A40: 数据预测 | B40: Day 1 | C40: Day 2 | D40: Day 3 | E40: Day 4 | F40: Day 5 | G40: Day 6 | H40: Day 7 | I40: 合计 | M40: 数据预测 | N40: Day 1 | O40: Day 2 | P40: Day 3 | Q40: Day 4 | R40: Day 5 | S40: Day 6 | T40: Day 7 | U40: 合计 | Y40: 数据预测 | Z40: Day 1 | AA40: Day 2 | AB40: Day 3 | AC40: Day 4 | AD40: Day 5 | AE40: Day 6 | AF40: Day 7 | AG40: 合计
A41: 目标总单量 | B41: 1 | C41: 2 | D41: 3 | E41: 4 | F41: 5 | G41: 5 | H41: 6 | I41: =SUM(B41:H41) | M41: 总单量 | N41: 12 | O41: 23 | P41: 26 | Q41: 25 | R41: 11 | S41: 52 | T41: 12 | U41: =SUM(N41:T41) | Y41: 总单量 | Z41: =N41-B41 | AA41: =O41-C41 | AB41: =P41-D41 | AC41: =Q41-E41 | AD41: =R41-F41 | AE41: =S41-G41 | AF41: =T41-H41 | AG41: =SUM(Z41:AF41)
A42: 总流量 | B42: =B41/B48 | C42: =C41/C48 | D42: =D41/D48 | E42: =E41/E48 | F42: =F41/F48 | G42: =G41/G48 | H42: =H41/H48 | I42: =SUM(B42:H42) | M42: 总流量 | N42: =N41/N48 | O42: =O41/O48 | P42: =P41/P48 | Q42: =Q41/Q48 | R42: =R41/R48 | S42: =S41/S48 | T42: =T41/T48 | U42: =SUM(N42:T42) | Y42: 总流量 | Z42: =N42-B42 | AA42: =O42-C42 | AB42: =P42-D42 | AC42: =Q42-E42 | AD42: =R42-F42 | AE42: =S42-G42 | AF42: =T42-H42 | AG42: =SUM(Z42:AF42)
A43: 广告单占比 | B43: 1 | C43: 1 | D43: 1 | E43: 1 | F43: 1 | G43: 0.9 | H43: 0.9 | I43: =I45/I41 | M43: 广告单占比 | N43: 1 | O43: 1 | P43: 1 | Q43: 1 | R43: 1 | S43: 0.9 | T43: 0.9 | U43: =U45/U41 | Y43: 广告单占比 | Z43: =N43-B43 | AA43: =O43-C43 | AB43: =P43-D43 | AC43: =Q43-E43 | AD43: =R43-F43 | AE43: =S43-G43 | AF43: =T43-H43 | AG43: =AG45/AG41
A44: 自然单量 | B44: =B41-B45 | C44: =C41-C45 | D44: =D41-D45 | E44: =E41-E45 | F44: =F41-F45 | G44: =G41-G45 | H44: =H41-H45 | I44: =SUM(B44:H44) | M44: 自然单量 | N44: 12 | O44: =O41-O45 | P44: =P41-P45 | Q44: =Q41-Q45 | R44: =R41-R45 | S44: =S41-S45 | T44: =T41-T45 | U44: =SUM(N44:T44) | Y44: 自然单量 | Z44: =N44-B44 | AA44: =O44-C44 | AB44: =P44-D44 | AC44: =Q44-E44 | AD44: =R44-F44 | AE44: =S44-G44 | AF44: =T44-H44 | AG44: =SUM(Z44:AF44)
A45: 广告单量 | B45: =B41*B43 | C45: =C41*C43 | D45: =D41*D43 | E45: =E41*E43 | F45: =F41*F43 | G45: =G41*G43 | H45: =H41*H43 | I45: =SUM(B45:H45) | M45: 广告单量 | N45: =N41*N43 | O45: =O41*O43 | P45: =P41*P43 | Q45: =Q41*Q43 | R45: =R41*R43 | S45: =S41*S43 | T45: =T41*T43 | U45: =SUM(N45:T45) | Y45: 广告单量 | Z45: =N45-B45 | AA45: =O45-C45 | AB45: =P45-D45 | AC45: =Q45-E45 | AD45: =R45-F45 | AE45: =S45-G45 | AF45: =T45-H45 | AG45: =SUM(Z45:AF45)
...

Sheet SC推广计划拆解
A1: 第一阶段：0~14天 | C1: 阶段目标：打收录、等首评、找到流量入口后再放大广告 | J1: 推广计划根据库存量来定，不断货，不冗余
A2: ASIN | D2: 定价 | E2: US$139.00
A3: 终期流量目标 | B3: 160 | D3: 折扣 | E3: 30
A4: 终期日销目标 | B4: 8 | D4: 成交价 | E4: US$109.00
A5: CTR目标 | B5: 0.003 | D5: 利润额 | E5: US$28.43 | F5: 利润额扣除退货率，不扣除广告占比
A6: CVR目标 | B6: 0.05
A7: 广告单占比目标 | B7: 0.8
A8: 目标评论数 | B8: 5
A9: 划线价（30%）
A10: 刷单数量安排
A11: 站外目标出单
A12: 联盟目标出单
A14: （目标）第一阶段详细计划 Part1 | C14: 开售W1 | M14: 实际完成数据 | O14: 开售W1 | Y14: 完成差额 | AA14: 开售W1
A15: 数据预测 | B15: Day 1 | C15: Day 2 | D15: Day 3 | E15: Day 4 | F15: Day 5 | G15: Day 6 | H15: Day 7 | I15: 合计 | M15: 数据预测 | N15: Day 1 | O15: Day 2 | P15: Day 3 | Q15: Day 4 | R15: Day 5 | S15: Day 6 | T15: Day 7 | U15: 合计 | Y15: 数据预测 | Z15: Day 1 | AA15: Day 2 | AB15: Day 3 | AC15: Day 4 | AD15: Day 5 | AE15: Day 6 | AF15: Day 7 | AG15: 合计
A16: 目标总单量 | B16: 1 | C16: 2 | D16: 3 | E16: 4 | F16: 5 | G16: 5 | H16: 6 | I16: =SUM(B16:H16) | M16: 总单量 | N16: 12 | O16: 23 | P16: 26 | Q16: 25 | R16: 11 | S16: 52 | T16: 12 | U16: =SUM(N16:T16) | Y16: 总单量 | Z16: =N16-B16 | AA16: =O16-C16 | AB16: =P16-D16 | AC16: =Q16-E16 | AD16: =R16-F16 | AE16: =S16-G16 | AF16: =T16-H16 | AG16: =SUM(Z16:AF16)
A17: 总流量 | B17: =B16/B23 | C17: =C16/C23 | D17: =D16/D23 | E17: =E16/E23 | F17: =F16/F23 | G17: =G16/G23 | H17: =H16/H23 | I17: =SUM(B17:H17) | M17: 总流量 | N17: =N16/N23 | O17: =O16/O23 | P17: =P16/P23 | Q17: =Q16/Q23 | R17: =R16/R23 | S17: =S16/S23 | T17: =T16/T23 | U17: =SUM(N17:T17) | Y17: 总流量 | Z17: =N17-B17 | AA17: =O17-C17 | AB17: =P17-D17 | AC17: =Q17-E17 | AD17: =R17-F17 | AE17: =S17-G17 | AF17: =T17-H17 | AG17: =SUM(Z17:AF17)
A18: 广告单占比 | B18: 1 | C18: 1 | D18: 1 | E18: 1 | F18: 1 | G18: 0.9 | H18: 0.9 | I18: =I20/I16 | M18: 广告单占比 | N18: 1 | O18: 1 | P18: 1 | Q18: 1 | R18: 1 | S18: 0.9 | T18: 0.9 | U18: =U20/U16 | Y18: 广告单占比 | Z18: =N18-B18 | AA18: =O18-C18 | AB18: =P18-D18 | AC18: =Q18-E18 | AD18: =R18-F18 | AE18: =S18-G18 | AF18: =T18-H18 | AG18: =AG20/AG16
A19: 自然单量 | B19: =B16-B20 | C19: =C16-C20 | D19: =D16-D20 | E19: =E16-E20 | F19: =F16-F20 | G19: =G16-G20 | H19: =H16-H20 | I19: =SUM(B19:H19) | M19: 自然单量 | N19: 12 | O19: =O16-O20 | P19: =P16-P20 | Q19: =Q16-Q20 | R19: =R16-R20 | S19: =S16-S20 | T19: =T16-T20 | U19: =SUM(N19:T19) | Y19: 自然单量 | Z19: =N19-B19 | AA19: =O19-C19 | AB19: =P19-D19 | AC19: =Q19-E19 | AD19: =R19-F19 | AE19: =S19-G19 | AF19: =T19-H19 | AG19: =SUM(Z19:AF19)
A20: 广告单量 | B20: =B16*B18 | C20: =C16*C18 | D20: =D16*D18 | E20: =E16*E18 | F20: =F16*F18 | G20: =G16*G18 | H20: =H16*H18 | I20: =SUM(B20:H20) | M20: 广告单量 | N20: =N16*N18 | O20: =O16*O18 | P20: =P16*P18 | Q20: =Q16*Q18 | R20: =R16*R18 | S20: =S16*S18 | T20: =T16*T18 | U20: =SUM(N20:T20) | Y20: 广告单量 | Z20: =N20-B20 | AA20: =O20-C20 | AB20: =P20-D20 | AC20: =Q20-E20 | AD20: =R20-F20 | AE20: =S20-G20 | AF20: =T20-H20 | AG20: =SUM(Z20:AF20)
A21: CPC | B21: 3.8 | C21: 3.8 | D21: 3.8 | E21: 3.8 | F21: 3.8 | G21: 3.8 | H21: 3.8 | I21: =AVERAGE(B21:H21) | M21: CPC | N21: 3.8 | O21: 3.8 | P21: 3.8 | Q21: 3.8 | R21: 3.8 | S21: 3.8 | T21: 3.8 | U21: =AVERAGE(N21:T21) | Y21: CPC | Z21: =N21-B21 | AA21: =O21-C21 | AB21: =P21-D21 | AC21: =Q21-E21 | AD21: =R21-F21 | AE21: =S21-G21 | AF21: =T21-H21 | AG21: =AVERAGE(Z21:AF21)
A22: 点击率CTR | B22: 0.003 | C22: 0.003 | D22: 0.003 | E22: 0.003 | F22: 0.003 | G22: 0.003 | H22: 0.003 | I22: =AVERAGE(B22:H22) | M22: 点击率CTR | N22: 0.003 | O22: 0.003 | P22: 0.003 | Q22: 0.003 | R22: 0.003 | S22: 0.003 | T22: 0.003 | U22: =AVERAGE(N22:T22) | Y22: 点击率CTR | Z22: =N22-B22 | AA22: =O22-C22 | AB22: =P22-D22 | AC22: =Q22-E22 | AD22: =R22-F22 | AE22: =S22-G22 | AF22: =T22-H22 | AG22: =AVERAGE(Z22:AF22)
A23: 转化率CVR | B23: 0.04 | C23: 0.04 | D23: 0.04 | E23: 0.04 | F23: 0.04 | G23: 0.04 | H23: 0.04 | I23: =AVERAGE(B23:H23) | J23: 累计出单 | K23: =I16 | M23: 转化率CVR | N23: 0.04 | O23: 0.04 | P23: 0.04 | Q23: 0.04 | R23: 0.04 | S23: 0.04 | T23: 0.04 | U23: =AVERAGE(N23:T23) | V23: 累计出单 | W23: =U16 | Y23: 转化率CVR | Z23: =N23-B23 | AA23: =O23-C23 | AB23: =P23-D23 | AC23: =Q23-E23 | AD23: =R23-F23 | AE23: =S23-G23 | AF23: =T23-H23 | AG23: =AVERAGE(Z23:AF23) | AH23: 累计出单 | AI23: =AG16
A24: 广告点击量 | B24: =B20/B23 | C24: =C20/C23 | D24: =D20/D23 | E24: =E20/E23 | F24: =F20/F23 | G24: =G20/G23 | H24: =H20/H23 | I24: =SUM(B24:H24) | J24: 本周CPA | K24: =I25/I20 | M24: 广告点击量 | N24: =N20/N23 | O24: =O20/O23 | P24: =P20/P23 | Q24: =Q20/Q23 | R24: =R20/R23 | S24: =S20/S23 | T24: =T20/T23 | U24: =SUM(N24:T24) | V24: 本周CPA | W24: =U25/U20 | Y24: 广告点击量 | Z24: =N24-B24 | AA24: =O24-C24 | AB24: =P24-D24 | AC24: =Q24-E24 | AD24: =R24-F24 | AE24: =S24-G24 | AF24: =T24-H24 | AG24: =SUM(Z24:AF24) | AH24: 本周CPA | AI24: =AG25/AG20
A25: 广告花费 | B25: =B21*B24 | C25: =C21*C24 | D25: =D21*D24 | E25: =E21*E24 | F25: =F21*F24 | G25: =G21*G24 | H25: =H21*H24 | I25: =SUM(B25:H25) | J25: 本周广告占比 | K25: =I25/I28 | M25: 广告花费 | N25: =N21*N24 | O25: =O21*O24 | P25: =P21*P24 | Q25: =Q21*Q24 | R25: =R21*R24 | S25: =S21*S24 | T25: =T21*T24 | U25: =SUM(N25:T25) | V25: 本周广告占比 | W25: =U25/U28 | Y25: 广告花费 | Z25: =N25-B25 | AA25: =O25-C25 | AB25: =P25-D25 | AC25: =Q25-E25 | AD25: =R25-F25 | AE25: =S25-G25 | AF25: =T25-H25 | AG25: =SUM(Z25:AF25) | AH25: 本周广告占比 | AI25: =AG25/AG28
A26: 广告ACOS | B26: =B25/B27 | C26: =C25/C27 | D26: =D25/D27 | E26: =E25/E27 | F26: =F25/F27 | G26: =G25/G27 | H26: =H25/H27 | I26: =I25/I27 | M26: 广告ACOS | N26: =N25/N27 | O26: =O25/O27 | P26: =P25/P27 | Q26: =Q25/Q27 | R26: =R25/R27 | S26: =S25/S27 | T26: =T25/T27 | U26: =U25/U27 | Y26: 广告ACOS | Z26: =N26-B26 | AA26: =O26-C26 | AB26: =P26-D26 | AC26: =Q26-E26 | AD26: =R26-F26 | AE26: =S26-G26 | AF26: =T26-H26 | AG26: =AG25/AG27
A27: 广告销售额 | B27: =B20*$E$11 | C27: =C20*$E$11 | D27: =D20*$E$11 | E27: =E20*$E$11 | F27: =F20*$E$11 | G27: =G20*$E$11 | H27: =H20*$E$11 | I27: =SUM(B27:H27) | J27: 本周利润额 | K27: =I29 | M27: 广告销售额 | N27: =N20*$E$11 | O27: =O20*$E$11 | P27: =P20*$E$11 | Q27: =Q20*$E$11 | R27: =R20*$E$11 | S27: =S20*$E$11 | T27: =T20*$E$11 | U27: =SUM(N27:T27) | V27: 本周利润额 | W27: =U29 | Y27: 广告销售额 | Z27: =N27-B27 | AA27: =O27-C27 | AB27: =P27-D27 | AC27: =Q27-E27 | AD27: =R27-F27 | AE27: =S27-G27 | AF27: =T27-H27 | AG27: =SUM(Z27:AF27) | AH27: 本周利润额 | AI27: =AG29
A28: 总销售额 | B28: =B16*$E$11 | C28: =C16*$E$11 | D28: =D16*$E$11 | E28: =E16*$E$11 | F28: =F16*$E$11 | G28: =G16*$E$11 | H28: =H16*$E$11 | I28: =SUM(B28:H28) | J28: 本周利润率 | K28: =K27/I28 | M28: 总销售额 | N28: =N16*$E$11 | O28: =O16*$E$11 | P28: =P16*$E$11 | Q28: =Q16*$E$11 | R28: =R16*$E$11 | S28: =S16*$E$11 | T28: =T16*$E$11 | U28: =SUM(N28:T28) | V28: 本周利润率 | W28: =W27/U28 | Y28: 总销售额 | Z28: =N28-B28 | AA28: =O28-C28 | AB28: =P28-D28 | AC28: =Q28-E28 | AD28: =R28-F28 | AE28: =S28-G28 | AF28: =T28-H28 | AG28: =SUM(Z28:AF28) | AH28: 本周利润率 | AI28: =AI27/AG28
A29: 利润 | B29: =B16*$E$12-B25 | C29: =C16*$E$12-C25 | D29: =D16*$E$12-D25 | E29: =E16*$E$12-E25 | F29: =F16*$E$12-F25 | G29: =G16*$E$12-G25 | H29: =H16*$E$12-H25 | I29: =SUM(B29:H29) | J29: 结余利润额 | K29: =K27 | M29: 利润 | N29: =N16*$E$12-N25 | O29: =O16*$E$12-O25 | P29: =P16*$E$12-P25 | Q29: =Q16*$E$12-Q25 | R29: =R16*$E$12-R25 | S29: =S16*$E$12-S25 | T29: =T16*$E$12-T25 | U29: =SUM(N29:T29) | V29: 结余利润额 | W29: =W27 | Y29: 利润 | Z29: =N29-B29 | AA29: =O29-C29 | AB29: =P29-D29 | AC29: =Q29-E29 | AD29: =R29-F29 | AE29: =S29-G29 | AF29: =T29-H29 | AG29: =SUM(Z29:AF29) | AH29: 结余利润额 | AI29: =AI27
A30: 执行策略
A34: （目标）第一阶段详细计划 Part1 | C34: 开售W2 | M34: 实际完成数据 | O34: 开售W2 | Y34: 完成差额 | AA34: 开售W2
A35: 数据预测 | B35: Day 1 | C35: Day 2 | D35: Day 3 | E35: Day 4 | F35: Day 5 | G35: Day 6 | H35: Day 7 | I35: 合计 | M35: 数据预测 | N35: Day 1 | O35: Day 2 | P35: Day 3 | Q35: Day 4 | R35: Day 5 | S35: Day 6 | T35: Day 7 | U35: 合计 | Y35: 数据预测 | Z35: Day 1 | AA35: Day 2 | AB35: Day 3 | AC35: Day 4 | AD35: Day 5 | AE35: Day 6 | AF35: Day 7 | AG35: 合计
A36: 目标总单量 | B36: 1 | C36: 2 | D36: 3 | E36: 4 | F36: 5 | G36: 5 | H36: 6 | I36: =SUM(B36:H36) | M36: 总单量 | N36: 12 | O36: 23 | P36: 26 | Q36: 25 | R36: 11 | S36: 52 | T36: 12 | U36: =SUM(N36:T36) | Y36: 总单量 | Z36: =N36-B36 | AA36: =O36-C36 | AB36: =P36-D36 | AC36: =Q36-E36 | AD36: =R36-F36 | AE36: =S36-G36 | AF36: =T36-H36 | AG36: =SUM(Z36:AF36)
A37: 总流量 | B37: =B36/B43 | C37: =C36/C43 | D37: =D36/D43 | E37: =E36/E43 | F37: =F36/F43 | G37: =G36/G43 | H37: =H36/H43 | I37: =SUM(B37:H37) | M37: 总流量 | N37: =N36/N43 | O37: =O36/O43 | P37: =P36/P43 | Q37: =Q36/Q43 | R37: =R36/R43 | S37: =S36/S43 | T37: =T36/T43 | U37: =SUM(N37:T37) | Y37: 总流量 | Z37: =N37-B37 | AA37: =O37-C37 | AB37: =P37-D37 | AC37: =Q37-E37 | AD37: =R37-F37 | AE37: =S37-G37 | AF37: =T37-H37 | AG37: =SUM(Z37:AF37)
A38: 广告单占比 | B38: 1 | C38: 1 | D38: 1 | E38: 1 | F38: 1 | G38: 0.9 | H38: 0.9 | I38: =I40/I36 | M38: 广告单占比 | N38: 1 | O38: 1 | P38: 1 | Q38: 1 | R38: 1 | S38: 0.9 | T38: 0.9 | U38: =U40/U36 | Y38: 广告单占比 | Z38: =N38-B38 | AA38: =O38-C38 | AB38: =P38-D38 | AC38: =Q38-E38 | AD38: =R38-F38 | AE38: =S38-G38 | AF38: =T38-H38 | AG38: =AG40/AG36
A39: 自然单量 | B39: =B36-B40 | C39: =C36-C40 | D39: =D36-D40 | E39: =E36-E40 | F39: =F36-F40 | G39: =G36-G40 | H39: =H36-H40 | I39: =SUM(B39:H39) | M39: 自然单量 | N39: 12 | O39: =O36-O40 | P39: =P36-P40 | Q39: =Q36-Q40 | R39: =R36-R40 | S39: =S36-S40 | T39: =T36-T40 | U39: =SUM(N39:T39) | Y39: 自然单量 | Z39: =N39-B39 | AA39: =O39-C39 | AB39: =P39-D39 | AC39: =Q39-E39 | AD39: =R39-F39 | AE39: =S39-G39 | AF39: =T39-H39 | AG39: =SUM(Z39:AF39)
A40: 广告单量 | B40: =B36*B38 | C40: =C36*C38 | D40: =D36*D38 | E40: =E36*E38 | F40: =F36*F38 | G40: =G36*G38 | H40: =H36*H38 | I40: =SUM(B40:H40) | M40: 广告单量 | N40: =N36*N38 | O40: =O36*O38 | P40: =P36*P38 | Q40: =Q36*Q38 | R40: =R36*R38 | S40: =S36*S38 | T40: =T36*T38 | U40: =SUM(N40:T40) | Y40: 广告单量 | Z40: =N40-B40 | AA40: =O40-C40 | AB40: =P40-D40 | AC40: =Q40-E40 | AD40: =R40-F40 | AE40: =S40-G40 | AF40: =T40-H40 | AG40: =SUM(Z40:AF40)
A41: CPC | B41: 3.8 | C41: 3.8 | D41: 3.8 | E41: 3.8 | F41: 3.8 | G41: 3.8 | H41: 3.8 | I41: =AVERAGE(B41:H41) | M41: CPC | N41: 3.8 | O41: 3.8 | P41: 3.8 | Q41: 3.8 | R41: 3.8 | S41: 3.8 | T41: 3.8 | U41: =AVERAGE(N41:T41) | Y41: CPC | Z41: =N41-B41 | AA41: =O41-C41 | AB41: =P41-D41 | AC41: =Q41-E41 | AD41: =R41-F41 | AE41: =S41-G41 | AF41: =T41-H41 | AG41: =AVERAGE(Z41:AF41)
A42: 点击率CTR | B42: 0.003 | C42: 0.003 | D42: 0.003 | E42: 0.003 | F42: 0.003 | G42: 0.003 | H42: 0.003 | I42: =AVERAGE(B42:H42) | M42: 点击率CTR | N42: 0.003 | O42: 0.003 | P42: 0.003 | Q42: 0.003 | R42: 0.003 | S42: 0.003 | T42: 0.003 | U42: =AVERAGE(N42:T42) | Y42: 点击率CTR | Z42: =N42-B42 | AA42: =O42-C42 | AB42: =P42-D42 | AC42: =Q42-E42 | AD42: =R42-F42 | AE42: =S42-G42 | AF42: =T42-H42 | AG42: =AVERAGE(Z42:AF42)
A43: 转化率CVR | B43: 0.04 | C43: 0.04 | D43: 0.04 | E43: 0.04 | F43: 0.04 | G43: 0.04 | H43: 0.04 | I43: =AVERAGE(B43:H43) | J43: 累计出单 | K43: =I36 | M43: 转化率CVR | N43: 0.04 | O43: 0.04 | P43: 0.04 | Q43: 0.04 | R43: 0.04 | S43: 0.04 | T43: 0.04 | U43: =AVERAGE(N43:T43) | V43: 累计出单 | W43: =U36 | Y43: 转化率CVR | Z43: =N43-B43 | AA43: =O43-C43 | AB43: =P43-D43 | AC43: =Q43-E43 | AD43: =R43-F43 | AE43: =S43-G43 | AF43: =T43-H43 | AG43: =AVERAGE(Z43:AF43) | AH43: 累计出单 | AI43: =AG36
A44: 广告点击量 | B44: =B40/B43 | C44: =C40/C43 | D44: =D40/D43 | E44: =E40/E43 | F44: =F40/F43 | G44: =G40/G43 | H44: =H40/H43 | I44: =SUM(B44:H44) | J44: 本周CPA | K44: =I45/I40 | M44: 广告点击量 | N44: =N40/N43 | O44: =O40/O43 | P44: =P40/P43 | Q44: =Q40/Q43 | R44: =R40/R43 | S44: =S40/S43 | T44: =T40/T43 | U44: =SUM(N44:T44) | V44: 本周CPA | W44: =U45/U40 | Y44: 广告点击量 | Z44: =N44-B44 | AA44: =O44-C44 | AB44: =P44-D44 | AC44: =Q44-E44 | AD44: =R44-F44 | AE44: =S44-G44 | AF44: =T44-H44 | AG44: =SUM(Z44:AF44) | AH44: 本周CPA | AI44: =AG45/AG40
...

Sheet 流量入口布局
A1: 词的定位
A2: 优先级 | B2: Keyword | C2: 月ABA排名 | D2: 相关性 | E2: 词的属性 | F2: 建议CPC | G2: 广告策略
A3: P0 | D3: 高相关 | E3: 核心词 | F3: 1.5
A4: P1 | D4: 中相关 | E4: 长尾词 | F4: 1.1
A5: P2 | D5: 弱相关 | E5: 品牌词 | F5: 0.8
A6: P3 | D6: 不相关 | E6: 流量词 | F6: 0.45
A14: 广告架构及策略（参考）
A15: 序号 | B15: 广告类型 | C15: 广告目的 | D15: 包含词 | E15: 总预算 | F15: 核心指标 | G15: 广告活动命名 | H15: 具体设置
A16: 广告1 | B16: 自动广告-低价 | C16: 捡漏 | E16: 20 | F16: Acos和订单增量 | G16: SKU-Auto-宽泛-捡漏 | H16: 0.1-0.3的竞价，5-10美金预算即可 如果有变体的话，可以把SKU都放进去，低价，捡漏，跑关联位，预算不用太高5-10美金即可，后续根据表现调整预算
A17: 广告2 | B17: 自动广告-正常价/高价 | C17: 跑词 | E17: 30 | F17: 词的相关性 Acos和订单增量 | G17: SKU-Auto-紧密-跑词 | H17: 前期竞价给高一些（建议竞价+0.2/建议竞价*1.25/极限值竞价），可以更快的跑出来词，更快的积累数据，1周后根据数据优化 可以酌情考虑把宽泛匹配比例调为0，有变体的话，前期测试，选择表现最好的SKU，单SKU测款+跑词（也可以开2个高价自动，在设置页面调整比例，一个跑词，一个跑关联）
A18: 广告3 | B18: 手动广告-大词-广泛 | C18: 跑流量，促进亚马逊收录 | E18: 50 | F18: 词的质量 CVR和Acos | G18: SKU-keyword-广泛-跑词 | H18: 前一周可以给高点竞价，一周之后，竞价逐步优化 单个SKU，1-3个关键词大词，注意词的精准度，曝光和点击率的关系变化，有没有达到自己的预期。还有就是CPC和位置。
A19: 广告4 | B19: 手动广告-大词-词组 | C19: 获取大词相关词组最顶层的精准流量，提升词组的整体自然位 | E19: 20 | F19: 自然位上升速度 CTR和CVR | G19: SKU-keyword-词组-冲位 | H19: 通过关键词广告控制预算来控制单量放量，竞价比广泛高一些，想办法让这些词出广告单，一个订单多买个（适合客单价低的产品），增加转化 单个SKU，可以1-3个核心关键词，方便控制广告预算和广告关键词位置，可以多开几组，把产品的核心大词测试一下看哪一个比较好
A20: 广告5 | B20: 手动广告-大词-精准 | C20: 获取大词单一词最顶层的精准流量，抢广告位，拉升自然位 | E20: 30 | F20: 自然位上升速度 CTR和CVR | G20: SKU-keyword-精准-冲位 | H20: 通过关键词广告控制预算来控制单量放量，竞价比词组高一些，通过CPC和Bid+调控到精准想打的广告位置，大多数用于首行和搜索结果其余位置 在精准组开了的词，在其他组避开相同CPC，错开广告位置或直接精准否定，以免互抢
A21: 广告6 | B21: 手动广告-长尾-精准 | C21: 获取最精准的直接客户搜索，提高做转化率，更好的抢占精准词流量 | E21: 30 | F21: 自然位上升速度 CTR和CVR | G21: SKU-长尾组-精准-冲位 | H21: 高竞价 单个SKU，10-15个关键词一组，根据数据表现可以开多组，通过广告报表筛选CTR>30%，转化>20%的优质词开广告
A22: 广告7 | B22: 商品投放-ASIN | C22: 选择有优势的竞品，提高曝光，蹭关联流量 | E22: 20 | F22: 订单增量 CVR和Acos | G22: SKU-ASIN-互补品-拓单 | H22: 如果有多个互补或者相似的SKU，可以相互投放，打造流量闭环 竞品的新品，还有断货的产品，也可以进行投放
A24: 广告种类集合
A25: 广告类型 | F25: 竞价策略 | I25: 广告位置竞价
A26: 商品推广 SP广告 | B26: 定向策略 | C26: 投放 | D26: 匹配模式 | E26: 筛选条件 | F26: 仅降低 | G26: 提升和降低 | H26: 固定 | I26: 首页 | J26: 详情页 | K26: 商品页面
B27: 自动投放 | C27: 关键字 | D27: 紧密匹配
D28: 宽泛匹配
C29: 商品 | D29: 同类商品
D30: 关联商品
B31: 手动投放 | C31: 商品 | D31: 分类 | E31: 品牌
E32: 价格范围
E33: 星级
E34: 配送
D35: 商品列表
C36: 关键字 | D36: 广泛
D37: 短语
D38: 精准
A40: 广告类型 | E40: 投放格式
A41: 品牌推广 SB广告 | B41: 投放类型 | C41: 投放匹配条件 | D41: 投放条件 | E41: 商品集详情页 | F41: 旗舰店 | G41: 视频 | H41: 竞价
B42: 关键字 | C42: 广泛
C43: 短语
C44: 精准
B45: 商品 | C45: 分类 | D45: 品牌
D46: 价格范围
D47: 星级
D48: 配送
C49: 商品
...

Sheet 日常跟踪表US
A1: 时间 | B1: 星期 | C1: 工作内容 B09DSVFNRW | D1: 售价 | E1: PD | F1: 划线价折扣 | G1: CP | H1: 最低 成交价 | I1: SC最低 成交价毛利率 | J1: VC采购价毛利率 | K1: 移动 | L1: PC | M1: 访问 | N1: 总转化率 | O1: 实际自然订单 | P1: 自然订单 | Q1: 总订单 | R1: VC订单 | S1: 测评计划出单 | T1: 测评总出单 | U1: 测评完成率 | V1: Vine | W1: 销售额 | X1: 核心词ABA排名 | AB1: sif前三页关键词收录数量 | AC1: 大类排名 | AD1: 小类排名 | AE1: 评分 | AF1: 广告数据 | AQ1: 毛利数据 | AY1: 站外 | BC1: 库存监控
X2: dog water fountain | Y2: dog fountain | Z2: dog stainless steel cat water fountain | AA2: dog water fountain stainless steel | AF2: 曝光 | AG2: 点击 | AH2: 点击率 | AI2: 订单 | AJ2: CPC | AK2: ACOS | AL2: 广告转化 | AM2: 广告订单占比 | AN2: 花费（$） | AO2: 广告花费占比 | AP2: CPA | AQ2: 退款率 | AR2: 广告订单毛利P1$ | AS2: 自然订单毛利P1$ | AT2: 总订单毛利P1$ | AU2: 总订单毛利率P1 | AV2: 国内总成本$ | AW2: 回款金额 | AX2: 测评亏损 | AY2: 站外毛利$ | AZ2: 站外出单 | BA2: 站外售价 | BB2: 站外折扣 | BC2: VC仓库存 | BD2: 海外仓库存 | BE2: FBA仓 | BF2: 总库存 | BG2: 超90天以上的库存 | BH2: 备注
A3: 45908 | B3: 日 | C3: \ | D3: 26.98 | F3: 0 | G3: 0 | H3: 26.98 | I3: 0.232 | J3: 0.099 | K3: 669 | L3: 338 | M3: =K3+L3 | N3: =Q3/M3 | O3: =P3-AI3 | P3: =Q3-T3-AZ3 | Q3: 137 | R3: 134 | S3: 2 | T3: 2 | U3: =T3/S3 | V3: 20 | W3: =Q3*D3 | X3: 8 | Y3: 10 | Z3: 4 | AA3: 5 | AB3: 944 | AC3: 2176 | AD3: 24 | AE3: 4.2 | AF3: 52825 | AG3: 508 | AH3: =AG3/AF3 | AI3: 60 | AJ3: =AN3/AG3 | AK3: =AN3/(AI3*D3) | AL3: =AI3/AG3 | AM3: =AI3/P3 | AN3: 721.69 | AO3: =AN3/W3 | AP3: =AN3/AI3 | AQ3: 0 | AR3: =AS3-AP3 | AS3: 4.91 | AT3: =(AY3*AZ3)+(AR3*AI3)+(O3*AS3)+AX3-W3*AQ3 | AU3: =AT3/W3 | AV3: 10.67 | AW3: =Q3*AV3+AT3 | AX3: =-22*T3 | AY3: -2.17 | AZ3: 0 | BA3: 19.99 | BB3: 0.5 | BC3: =BC4+R4 | BD3: 10287 | BF3: =BC3+BD3 | BG3: 0
A4: 45909 | B4: 一 | C4: VC BD结束 | D4: 29.98 | F4: 0 | G4: 0 | H4: 29.98 | I4: 0.232 | J4: 0.099 | K4: 745 | L4: 394 | M4: =K4+L4 | N4: =Q4/M4 | O4: =P4-AI4 | P4: =Q4-T4-AZ4 | Q4: 59 | R4: 27 | S4: 2 | T4: 2 | U4: =T4/S4 | V4: 0 | W4: =Q4*D4 | X4: 8 | Y4: 10 | Z4: 4 | AA4: 5 | AB4: 944 | AC4: 2252 | AD4: 26 | AE4: 4.2 | AF4: 14124 | AG4: 111 | AH4: =AG4/AF4 | AI4: 12 | AJ4: =AN4/AG4 | AK4: =AN4/(AI4*D4) | AL4: =AI4/AG4 | AM4: =AI4/P4 | AN4: 167.76 | AO4: =AN4/W4 | AP4: =AN4/AI4 | AQ4: 0 | AR4: =AS4-AP4 | AS4: 4.91 | AT4: =(AY4*AZ4)+(AR4*AI4)+(O4*AS4)+AX4-W4*AQ4 | AU4: =AT4/W4 | AV4: 10.67 | AW4: =Q4*AV4+AT4 | AX4: =-22*T4 | AY4: -2.17 | AZ4: 0 | BA4: 19.99 | BB4: 0.5 | BC4: =BC5+R5 | BD4: 10287 | BF4: =BC4+BD4 | BG4: 0
A5: 45910 | B5: 二 | C5: \ | D5: 29.98 | F5: 0 | G5: 0 | H5: 29.98 | I5: 0.232 | J5: 0.099 | K5: 278 | L5: 203 | M5: =K5+L5 | N5: =Q5/M5 | O5: =P5-AI5 | P5: =Q5-T5-AZ5 | Q5: 52 | R5: 17 | S5: 2 | T5: 2 | U5: =T5/S5 | V5: 0 | W5: =Q5*D5 | X5: 8 | Y5: 10 | Z5: 4 | AA5: 5 | AB5: 944 | AC5: 2706 | AD5: 28 | AE5: 4.2 | AF5: 14419 | AG5: 71 | AH5: =AG5/AF5 | AI5: 10 | AJ5: =AN5/AG5 | AK5: =AN5/(AI5*D5) | AL5: =AI5/AG5 | AM5: =AI5/P5 | AN5: 90.43 | AO5: =AN5/W5 | AP5: =AN5/AI5 | AQ5: 0 | AR5: =AS5-AP5 | AS5: 4.91 | AT5: =(AY5*AZ5)+(AR5*AI5)+(O5*AS5)+AX5-W5*AQ5 | AU5: =AT5/W5 | AV5: 10.67 | AW5: =Q5*AV5+AT5 | AX5: =-22*T5 | AY5: -2.17 | AZ5: 0 | BA5: 19.99 | BB5: 0.5 | BC5: =BC6+R6 | BD5: 10287 | BF5: =BC5+BD5 | BG5: 0
A6: 45911 | B6: 四 | C6: \ | D6: 29.98 | F6: 0 | G6: 0 | H6: 29.98 | I6: 0.232 | J6: 0.099 | K6: 246 | L6: 187 | M6: =K6+L6 | N6: =Q6/M6 | O6: =P6-AI6 | P6: =Q6-T6-AZ6 | Q6: 66 | R6: 20 | S6: 3 | T6: 2 | U6: =T6/S6 | V6: 0 | W6: =Q6*D6 | X6: 8 | Y6: 10 | Z6: 4 | AA6: 5 | AB6: 944 | AC6: 2589 | AD6: 27 | AE6: 4.2 | AF6: 15000 | AG6: 107 | AH6: =AG6/AF6 | AI6: 23 | AJ6: =AN6/AG6 | AK6: =AN6/(AI6*D6) | AL6: =AI6/AG6 | AM6: =AI6/P6 | AN6: 171.27 | AO6: =AN6/W6 | AP6: =AN6/AI6 | AQ6: 0 | AR6: =AS6-AP6 | AS6: 4.91 | AT6: =(AY6*AZ6)+(AR6*AI6)+(O6*AS6)+AX6-W6*AQ6 | AU6: =AT6/W6 | AV6: 10.67 | AW6: =Q6*AV6+AT6 | AX6: =-22*T6 | AY6: -2.17 | AZ6: 0 | BA6: 19.99 | BB6: 0.5 | BC6: =BC7+R7 | BD6: 10287 | BF6: =BC6+BD6 | BG6: 0
A7: 45912 | B7: 五 | C7: \ | D7: 29.98 | F7: 0 | G7: 0 | H7: 29.98 | I7: 0.232 | J7: 0.099 | K7: 256 | L7: 169 | M7: =K7+L7 | N7: =Q7/M7 | O7: =P7-AI7 | P7: =Q7-T7-AZ7 | Q7: 46 | R7: 17 | S7: 3 | T7: 2 | U7: =T7/S7 | V7: 0 | W7: =Q7*D7 | X7: 8 | Y7: 10 | Z7: 4 | AA7: 5 | AB7: 944 | AC7: 3019 | AD7: 35 | AE7: 4.2 | AF7: 12401 | AG7: 71 | AH7: =AG7/AF7 | AI7: 9 | AJ7: =AN7/AG7 | AK7: =AN7/(AI7*D7) | AL7: =AI7/AG7 | AM7: =AI7/P7 | AN7: 115.22 | AO7: =AN7/W7 | AP7: =AN7/AI7 | AQ7: 0 | AR7: =AS7-AP7 | AS7: 4.91 | AT7: =(AY7*AZ7)+(AR7*AI7)+(O7*AS7)+AX7-W7*AQ7 | AU7: =AT7/W7 | AV7: 10.67 | AW7: =Q7*AV7+AT7 | AX7: =-22*T7 | AY7: -2.17 | AZ7: 0 | BA7: 19.99 | BB7: 0.5 | BC7: =BC8+R8 | BD7: 10287 | BF7: =BC7+BD7 | BG7: 0
A8: 45913 | B8: 六 | C8: VC BD开始 | D8: 26.98 | F8: 0 | G8: 0 | H8: 26.98 | I8: 0.232 | J8: 0.099 | K8: 192 | L8: 139 | M8: =K8+L8 | N8: =Q8/M8 | O8: =P8-AI8 | P8: =Q8-T8-AZ8 | Q8: 93 | R8: 84 | S8: 5 | T8: 3 | U8: =T8/S8 | V8: 0 | W8: =Q8*D8 | X8: 8 | Y8: 10 | Z8: 4 | AA8: 5 | AB8: 944 | AC8: 3153 | AD8: 35 | AE8: 4.2 | AF8: 46831 | AG8: 181 | AH8: =AG8/AF8 | AI8: 23 | AJ8: =AN8/AG8 | AK8: =AN8/(AI8*D8) | AL8: =AI8/AG8 | AM8: =AI8/P8 | AN8: 281.66 | AO8: =AN8/W8 | AP8: =AN8/AI8 | AQ8: 0 | AR8: =AS8-AP8 | AS8: 4.91 | AT8: =(AY8*AZ8)+(AR8*AI8)+(O8*AS8)+AX8-W8*AQ8 | AU8: =AT8/W8 | AV8: 10.67 | AW8: =Q8*AV8+AT8 | AX8: =-22*T8 | AY8: -2.17 | AZ8: 0 | BA8: 19.99 | BB8: 0.5 | BC8: =BC9+R9 | BD8: 10287 | BF8: =BC8+BD8 | BG8: 0
A9: 45914 | B9: 日 | C9: \ | D9: 26.98 | F9: 0 | G9: 0 | H9: 26.98 | I9: 0.232 | J9: 0.099 | K9: 726 | L9: 220 | M9: =K9+L9 | N9: =Q9/M9 | O9: =P9-AI9 | P9: =Q9-T9-AZ9 | Q9: 95 | R9: 95 | S9: 5 | T9: 3 | U9: =T9/S9 | V9: 0 | W9: =Q9*D9 | X9: 8 | Y9: 10 | Z9: 4 | AA9: 5 | AB9: 944 | AC9: 3370 | AD9: 38 | AE9: 4.2 | AF9: 50446 | AG9: 218 | AH9: =AG9/AF9 | AI9: 37 | AJ9: =AN9/AG9 | AK9: =AN9/(AI9*D9) | AL9: =AI9/AG9 | AM9: =AI9/P9 | AN9: 339.9 | AO9: =AN9/W9 | AP9: =AN9/AI9 | AQ9: 0 | AR9: =AS9-AP9 | AS9: 4.91 | AT9: =(AY9*AZ9)+(AR9*AI9)+(O9*AS9)+AX9-W9*AQ9 | AU9: =AT9/W9 | AV9: 10.67 | AW9: =Q9*AV9+AT9 | AX9: =-22*T9 | AY9: -2.17 | AZ9: 0 | BA9: 19.99 | BB9: 0.5 | BC9: =BC10+R10 | BD9: 10287 | BF9: =BC9+BD9 | BG9: 0
A10: 45915 | B10: 一 | C10: \ | D10: 26.98 | F10: 0 | G10: 0 | H10: 26.98 | I10: 0.232 | J10: 0.099 | K10: 539 | L10: 264 | M10: =K10+L10 | N10: =Q10/M10 | O10: =P10-AI10 | P10: =Q10-T10-AZ10 | Q10: 135 | R10: 130 | S10: 5 | T10: 3 | U10: =T10/S10 | V10: 0 | W10: =Q10*D10 | X10: 8 | Y10: 10 | Z10: 4 | AA10: 5 | AB10: 944 | AC10: 2909 | AD10: 33 | AE10: 4.2 | AF10: 63764 | AG10: 299 | AH10: =AG10/AF10 | AI10: 60 | AJ10: =AN10/AG10 | AK10: =AN10/(AI10*D10) | AL10: =AI10/AG10 | AM10: =AI10/P10 | AN10: 484.74 | AO10: =AN10/W10 | AP10: =AN10/AI10 | AQ10: 0 | AR10: =AS10-AP10 | AS10: 4.91 | AT10: =(AY10*AZ10)+(AR10*AI10)+(O10*AS10)+AX10-W10*AQ10 | AU10: =AT10/W10 | AV10: 10.67 | AW10: =Q10*AV10+AT10 | AX10: =-22*T10 | AY10: -2.17 | AZ10: 0 | BA10: 19.99 | BB10: 0.5 | BC10: =BC11+R11 | BD10: 10287 | BF10: =BC10+BD10 | BG10: 0
A11: 45916 | B11: 二 | C11: \ | D11: 26.98 | F11: 0 | G11: 0 | H11: 26.98 | I11: 0.232 | J11: 0.099 | K11: 632 | L11: 295 | M11: =K11+L11 | N11: =Q11/M11 | O11: =P11-AI11 | P11: =Q11-T11-AZ11 | Q11: 107 | R11: 106 | S11: 4 | T11: 3 | U11: =T11/S11 | V11: 0 | W11: =Q11*D11 | X11: 8 | Y11: 10 | Z11: 4 | AA11: 5 | AB11: 944 | AC11: 2550 | AD11: 28 | AE11: 4.2 | AF11: 63713 | AG11: 219 | AH11: =AG11/AF11 | AI11: 38 | AJ11: =AN11/AG11 | AK11: =AN11/(AI11*D11) | AL11: =AI11/AG11 | AM11: =AI11/P11 | AN11: 335.45 | AO11: =AN11/W11 | AP11: =AN11/AI11 | AQ11: 0 | AR11: =AS11-AP11 | AS11: 4.91 | AT11: =(AY11*AZ11)+(AR11*AI11)+(O11*AS11)+AX11-W11*AQ11 | AU11: =AT11/W11 | AV11: 10.67 | AW11: =Q11*AV11+AT11 | AX11: =-22*T11 | AY11: -2.17 | AZ11: 0 | BA11: 19.99 | BB11: 0.5 | BC11: =BC12+R12 | BD11: 10287 | BF11: =BC11+BD11 | BG11: 0
A12: 45917 | B12: 三 | C12: \ | D12: 26.98 | F12: 0 | G12: 0 | H12: 26.98 | I12: 0.232 | J12: 0.099 | K12: 557 | L12: 260 | M12: =K12+L12 | N12: =Q12/M12 | O12: =P12-AI12 | P12: =Q12-T12-AZ12 | Q12: 121 | R12: 118 | S12: 1 | T12: 1 | U12: =T12/S12 | V12: 0 | W12: =Q12*D12 | X12: 8 | Y12: 10 | Z12: 4 | AA12: 5 | AB12: 944 | AC12: 2585 | AD12: 27 | AE12: 4.2 | AF12: 67904 | AG12: 243 | AH12: =AG12/AF12 | AI12: 40 | AJ12: =AN12/AG12 | AK12: =AN12/(AI12*D12) | AL12: =AI12/AG12 | AM12: =AI12/P12 | AN12: 381.37 | AO12: =AN12/W12 | AP12: =AN12/AI12 | AQ12: 0 | AR12: =AS12-AP12 | AS12: 4.91 | AT12: =(AY12*AZ12)+(AR12*AI12)+(O12*AS12)+AX12-W12*AQ12 | AU12: =AT12/W12 | AV12: 10.67 | AW12: =Q12*AV12+AT12 | AX12: =-22*T12 | AY12: -2.17 | AZ12: 0 | BA12: 19.99 | BB12: 0.5 | BC12: =BC13+R13 | BD12: 10287 | BF12: =BC12+BD12 | BG12: 0
A13: 45918 | B13: 四 | C13: \ | D13: 26.98 | F13: 0 | G13: 0 | H13: 26.98 | I13: 0.232 | J13: 0.099 | K13: 556 | L13: 283 | M13: =K13+L13 | N13: =Q13/M13 | O13: =P13-AI13 | P13: =Q13-T13-AZ13 | Q13: 109 | R13: 106 | S13: 1 | T13: 1 | U13: =T13/S13 | V13: 0 | W13: =Q13*D13 | X13: 8 | Y13: 10 | Z13: 4 | AA13: 5 | AB13: 944 | AC13: 2482 | AD13: 26 | AE13: 4.2 | AF13: 66565 | AG13: 195 | AH13: =AG13/AF13 | AI13: 30 | AJ13: =AN13/AG13 | AK13: =AN13/(AI13*D13) | AL13: =AI13/AG13 | AM13: =AI13/P13 | AN13: 294.73 | AO13: =AN13/W13 | AP13: =AN13/AI13 | AQ13: 0 | AR13: =AS13-AP13 | AS13: 4.91 | AT13: =(AY13*AZ13)+(AR13*AI13)+(O13*AS13)+AX13-W13*AQ13 | AU13: =AT13/W13 | AV13: 10.67 | AW13: =Q13*AV13+AT13 | AX13: =-22*T13 | AY13: -2.17 | AZ13: 0 | BA13: 19.99 | BB13: 0.5 | BC13: =BC14+R14 | BD13: 10287 | BF13: =BC13+BD13 | BG13: 0
A14: 45919 | B14: 五 | C14: \ | D14: 26.98 | F14: 0 | G14: 0 | H14: 26.98 | I14: 0.232 | J14: 0.099 | K14: 522 | L14: 272 | M14: =K14+L14 | N14: =Q14/M14 | O14: =P14-AI14 | P14: =Q14-T14-AZ14 | Q14: 112 | R14: 112 | S14: 1 | T14: 1 | U14: =T14/S14 | V14: 0 | W14: =Q14*D14 | X14: 8 | Y14: 10 | Z14: 4 | AA14: 5 | AB14: 944 | AC14: 2466 | AD14: 21 | AE14: 4.2 | AF14: 63826 | AG14: 189 | AH14: =AG14/AF14 | AI14: 35 | AJ14: =AN14/AG14 | AK14: =AN14/(AI14*D14) | AL14: =AI14/AG14 | AM14: =AI14/P14 | AN14: 273.66 | AO14: =AN14/W14 | AP14: =AN14/AI14 | AQ14: 0 | AR14: =AS14-AP14 | AS14: 4.91 | AT14: =(AY14*AZ14)+(AR14*AI14)+(O14*AS14)+AX14-W14*AQ14 | AU14: =AT14/W14 | AV14: 10.67 | AW14: =Q14*AV14+AT14 | AX14: =-22*T14 | AY14: -2.17 | AZ14: 0 | BA14: 19.99 | BB14: 0.5 | BC14: =BC15+R15 | BD14: 10287 | BF14: =BC14+BD14 | BG14: 0
... A22: 45927 | B22: 六 | C22: \ | D22: 26.98 | F22: 0 | G22: 0 | H22: 26.98 | I22: 0.232 | J22: 0.099 | K22: 140 | L22: 140 | M22: =K22+L22 | N22: =Q22/M22 | O22: =P22-AI22 | P22: =Q22-T22-AZ22 | Q22: 79 | R22: 70 | S22: 1 | T22: 1 | U22: =T22/S22 | V22: 0 | W22: =Q22*D22 | X22: 8 | Y22: 10 | Z22: 4 | AA22: 5 | AB22: 944 | AC22: 3515 | AD22: 47 | AE22: 4.2 | AF22: 47185 | AG22: 164 | AH22: =AG22/AF22 | AI22: 21 | AJ22: =AN22/AG22 | AK22: =AN22/(AI22*D22) | AL22: =AI22/AG22 | AM22: =AI22/P22 | AN22: 219.84 | AO22: =AN22/W22 | AP22: =AN22/AI22 | AQ22: 0 | AR22: =AS22-AP22 | AS22: 4.91 | AT22: =(AY22*AZ22)+(AR22*AI22)+(O22*AS22)+AX22-W22*AQ22 | AU22: =AT22/W22 | AV22: 10.67 | AW22: =Q22*AV22+AT22 | AX22: =-22*T22 | AY22: -2.17 | AZ22: 0 | BA22: 19.99 | BB22: 0.5 | BC22: =BC23+R23 | BD22: 10287 | BF22: =BC22+BD22 | BG22: 0
A23: 45928 | B23: 日 | C23: \ | D23: 26.98 | F23: 0 | G23: 0 | H23: 26.98 | I23: 0.232 | J23: 0.099 | K23: 203 | L23: 162 | M23: =K23+L23 | N23: =Q23/M23 | O23: =P23-AI23 | P23: =Q23-T23-AZ23 | Q23: 107 | R23: 97 | S23: 1 | T23: 1 | U23: =T23/S23 | V23: 0 | W23: =Q23*D23 | X23: 8 | Y23: 10 | Z23: 4 | AA23: 5 | AB23: 944 | AC23: 3344 | AD23: 40 | AE23: 4.2 | AF23: 55902 | AG23: 239 | AH23: =AG23/AF23 | AI23: 32 | AJ23: =AN23/AG23 | AK23: =AN23/(AI23*D23) | AL23: =AI23/AG23 | AM23: =AI23/P23 | AN23: 352.08 | AO23: =AN23/W23 | AP23: =AN23/AI23 | AQ23: 0 | AR23: =AS23-AP23 | AS23: 4.91 | AT23: =(AY23*AZ23)+(AR23*AI23)+(O23*AS23)+AX23-W23*AQ23 | AU23: =AT23/W23 | AV23: 10.67 | AW23: =Q23*AV23+AT23 | AX23: =-22*T23 | AY23: -2.17 | AZ23: 0 | BA23: 19.99 | BB23: 0.5 | BC23: =BC24+R24 | BD23: 10287 | BF23: =BC23+BD23+BE23
A24: 45929 | B24: 一 | C24: VC BD结束 | D24: 29.98 | F24: 0 | G24: 0 | H24: 29.98 | I24: 0.232 | J24: 0.099 | K24: 211 | L24: 157 | M24: =K24+L24 | N24: =Q24/M24 | O24: =P24-AI24 | P24: =Q24-T24-AZ24 | Q24: 60 | R24: 28 | S24: 1 | T24: 1 | U24: =T24/S24 | V24: 0 | W24: =Q24*D24 | X24: 8 | Y24: 10 | Z24: 4 | AA24: 5 | AB24: 944 | AC24: 3265 | AD24: 46 | AE24: 4.2 | AF24: 11043 | AG24: 32 | AH24: =AG24/AF24 | AI24: 5 | AJ24: =AN24/AG24 | AK24: =AN24/(AI24*D24) | AL24: =AI24/AG24 | AM24: =AI24/P24 | AN24: 33.2 | AO24: =AN24/W24 | AP24: =AN24/AI24 | AQ24: 0 | AR24: =AS24-AP24 | AS24: 4.91 | AT24: =(AY24*AZ24)+(AR24*AI24)+(O24*AS24)+AX24-W24*AQ24 | AU24: =AT24/W24 | AV24: 10.67 | AW24: =Q24*AV24+AT24 | AX24: =-22*T24 | AY24: -2.17 | AZ24: 0 | BA24: 19.99 | BB24: 0.5 | BC24: =BC25+R25 | BD24: 10287 | BF24: =BC24+BD24+BE24
A25: 45930 | B25: 二 | C25: \ | D25: 29.98 | F25: 0 | G25: 0 | H25: 29.98 | I25: 0.232 | J25: 0.099 | K25: 297 | L25: 196 | M25: =K25+L25 | N25: =Q25/M25 | O25: =P25-AI25 | P25: =Q25-T25-AZ25 | Q25: 45 | R25: 4 | S25: 1 | T25: 1 | U25: =T25/S25 | V25: 0 | W25: =Q25*D25 | X25: 8 | Y25: 10 | Z25: 4 | AA25: 5 | AB25: 944 | AC25: 3412 | AD25: 48 | AE25: 4.2 | AF25: 12528 | AG25: 84 | AH25: =AG25/AF25 | AI25: 12 | AJ25: =AN25/AG25 | AK25: =AN25/(AI25*D25) | AL25: =AI25/AG25 | AM25: =AI25/P25 | AN25: 108.98 | AO25: =AN25/W25 | AP25: =AN25/AI25 | AQ25: 0 | AR25: =AS25-AP25 | AS25: 4.91 | AT25: =(AY25*AZ25)+(AR25*AI25)+(O25*AS25)+AX25-W25*AQ25 | AU25: =AT25/W25 | AV25: 10.67 | AW25: =Q25*AV25+AT25 | AX25: =-22*T25 | AY25: -2.17 | AZ25: 0 | BA25: 19.99 | BB25: 0.5 | BC25: =BC26+R26 | BD25: 10287 | BF25: =BC25+BD25+BE25
