Workbook

Sheet 日常跟踪表 DE
A1: 时间 | B1: 星期 | C1: 工作内容 | D1: 售价 | E1: PD | F1: 划线价 折扣 | G1: CP | H1: 最低 成交价 | I1: SC最低 成交价毛利率 | J1: VC采购价毛利率 | K1: 移动 | L1: PC | M1: 访问 | N1: 总转化率 | O1: 实际自然订单 | P1: 自然订单（除测评、站外） | Q1: 总订单 | R1: VC订单 | S1: B2B订单 | T1: 测评计划出单 | U1: 测评总出单 | V1: 测评完成率 | W1: Vine | X1: 销售额 | Y1: 核心词ABA排名 | AG1: sif前三页关键词收录数量 | AH1: 大类排名 | AI1: 小类排名 | AJ1: 评论 | AK1: 评分 | AL1: 广告数据 | AZ1: 毛利数据 | BG1: 站外 | BM1: 库存监控
Y2: matratzenreiniger | AA2: milbensauger | AC2: milbensauger für matratzen | AE2: milbensauger für matratzen testsieger | AL2: 曝光 | AM2: 点击 | AN2: 点击率 | AO2: 订单 | AP2: CPC | AQ2: ACOS | AR2: 广告转化 | AS2: 广告订单占比 | AT2: 花费（$） | AU2: 广告花费占比 | AV2: CPA | AW2: 广告销售额 | AX2: 广告销售额/店铺总销售额 | AY2: 退款率 | AZ2: 广告订单毛利P1$ | BA2: 自然订单毛利P1$ | BB2: 总订单毛利P1$ | BC2: 总订单毛利率P1 | BD2: 国内总成本$ | BE2: 回款金额 | BF2: 测评亏损 | BG2: 站外毛利$ | BH2: 站外出单 | BI2: 站外售价 | BJ2: 站外折扣 | BK2: 自然流量 | BL2: 自然转化 | BM2: VC仓库存 | BN2: 海外仓库存 | BO2: 总库存 | BP2: VC其他订单数 | BQ2: 备注
A3: 45992 | B3: 星期一 | C3: B0FNMBQFBC | D3: 54.99 | F3: 0 | G3: 0 | H3: 33.43 | I3: - | J3: - | K3: ='德国ERP数据'!BC2 | L3: ='德国ERP数据'!BA2 | M3: =K3+L3 | N3: =IFERROR(Q3/M3,0) | O3: =P3-AO3 | P3: =Q3-U3-BH3 | Q3: ='德国ERP数据'!R2 | T3: 0 | U3: 0 | V3: 0 | W3: 0 | X3: ='德国ERP数据'!Q2 | Y3: / | AA3: / | AC3: / | AE3: 32 | AG3: 0 | AH3: 0 | AI3: 0 | AJ3: 0 | AK3: 5 | AL3: 0 | AM3: 0 | AN3: =IFERROR(AM3/AL3,0) | AO3: 0 | AP3: =IFERROR(AT3/AM3,0) | AQ3: =IFERROR(AT3/AW3,0) | AR3: =IFERROR(AO3/AM3,0) | AS3: =IFERROR(AO3/Q3,0) | AT3: 0 | AU3: =IFERROR(AT3/X3,0) | AV3: =IFERROR(AT3/AO3,0) | AW3: 0 | AX3: =IFERROR(AW3/X3,0)
A4: 45993 | B4: 星期二 | D4: 54.99 | F4: 0 | G4: 0 | H4: 33.43 | I4: - | J4: - | K4: ='德国ERP数据'!BC3 | L4: ='德国ERP数据'!BA3 | M4: =K4+L4 | N4: =IFERROR(Q4/M4,0) | O4: =P4-AO4 | P4: =Q4-U4-BH4 | Q4: ='德国ERP数据'!R3 | R4: - | S4: ='德国ERP数据'!Z3 | T4: 0 | U4: 0 | V4: 0 | W4: 0 | X4: ='德国ERP数据'!Q3 | Y4: / | AA4: / | AC4: / | AE4: 32 | AG4: 0 | AH4: 0 | AI4: 0 | AJ4: 0 | AK4: 5 | AL4: 0 | AM4: 0 | AN4: =IFERROR(AM4/AL4,0) | AO4: 0 | AP4: =IFERROR(AT4/AM4,0) | AQ4: =IFERROR(AT4/AW4,0) | AR4: =IFERROR(AO4/AM4,0) | AS4: =IFERROR(AO4/Q4,0) | AT4: 0 | AU4: =IFERROR(AT4/X4,0) | AV4: =IFERROR(AT4/AO4,0) | AW4: 0 | AX4: =IFERROR(AW4/X4,0)
A5: 45994 | B5: 星期三 | D5: 54.99 | F5: 0 | G5: 0 | H5: 33.43 | I5: - | J5: - | K5: ='德国ERP数据'!BC4 | L5: ='德国ERP数据'!BA4 | M5: =K5+L5 | N5: =IFERROR(Q5/M5,0) | O5: =P5-AO5 | P5: =Q5-U5-BH5 | Q5: ='德国ERP数据'!R4 | R5: - | S5: ='德国ERP数据'!Z4 | T5: 0 | U5: 0 | V5: 0 | W5: 0 | X5: ='德国ERP数据'!Q4 | Y5: / | AA5: / | AC5: / | AE5: 32 | AG5: 0 | AH5: 0 | AI5: 0 | AJ5: 0 | AK5: 5 | AL5: 0 | AM5: 0 | AN5: =IFERROR(AM5/AL5,0) | AO5: 0 | AP5: =IFERROR(AT5/AM5,0) | AQ5: =IFERROR(AT5/AW5,0) | AR5: =IFERROR(AO5/AM5,0) | AS5: =IFERROR(AO5/Q5,0) | AT5: 0 | AU5: =IFERROR(AT5/X5,0) | AV5: =IFERROR(AT5/AO5,0) | AW5: 0 | AX5: =IFERROR(AW5/X5,0)
A6: 45995 | B6: 星期四 | D6: 54.99 | F6: 0 | G6: 0 | H6: 33.43 | I6: - | J6: - | K6: ='德国ERP数据'!BC5 | L6: ='德国ERP数据'!BA5 | M6: =K6+L6 | N6: =IFERROR(Q6/M6,0) | O6: =P6-AO6 | P6: =Q6-U6-BH6 | Q6: ='德国ERP数据'!R5 | R6: - | S6: ='德国ERP数据'!Z5 | T6: 0 | U6: 0 | V6: 0 | W6: 0 | X6: ='德国ERP数据'!Q5 | Y6: / | AA6: / | AC6: / | AE6: 32 | AG6: 0 | AH6: 0 | AI6: 0 | AJ6: 0 | AK6: 5 | AL6: 0 | AM6: 0 | AN6: =IFERROR(AM6/AL6,0) | AO6: 0 | AP6: =IFERROR(AT6/AM6,0) | AQ6: =IFERROR(AT6/AW6,0) | AR6: =IFERROR(AO6/AM6,0) | AS6: =IFERROR(AO6/Q6,0) | AT6: 0 | AU6: =IFERROR(AT6/X6,0) | AV6: =IFERROR(AT6/AO6,0) | AW6: 0 | AX6: =IFERROR(AW6/X6,0)
A7: 45996 | B7: 星期五 | D7: 54.99 | F7: 0 | G7: 0 | H7: 33.43 | I7: - | J7: - | K7: ='德国ERP数据'!BC6 | L7: ='德国ERP数据'!BA6 | M7: =K7+L7 | N7: =IFERROR(Q7/M7,0) | O7: =P7-AO7 | P7: =Q7-U7-BH7 | Q7: ='德国ERP数据'!R6 | R7: - | S7: ='德国ERP数据'!Z6 | T7: 0 | U7: 0 | V7: 0 | W7: 0 | X7: ='德国ERP数据'!Q6 | Y7: / | AA7: / | AC7: / | AE7: 32 | AG7: 0 | AH7: 0 | AI7: 0 | AJ7: 0 | AK7: 5 | AL7: 0 | AM7: 0 | AN7: =IFERROR(AM7/AL7,0) | AO7: 0 | AP7: =IFERROR(AT7/AM7,0) | AQ7: =IFERROR(AT7/AW7,0) | AR7: =IFERROR(AO7/AM7,0) | AS7: =IFERROR(AO7/Q7,0) | AT7: 0 | AU7: =IFERROR(AT7/X7,0) | AV7: =IFERROR(AT7/AO7,0) | AW7: 0 | AX7: =IFERROR(AW7/X7,0)
A8: 45997 | B8: 星期六 | D8: 54.99 | F8: 0 | G8: 0 | H8: 33.43 | I8: - | J8: - | K8: ='德国ERP数据'!BC7 | L8: ='德国ERP数据'!BA7 | M8: =K8+L8 | N8: =IFERROR(Q8/M8,0) | O8: =P8-AO8 | P8: =Q8-U8-BH8 | Q8: ='德国ERP数据'!R7 | R8: - | S8: ='德国ERP数据'!Z7 | T8: 0 | U8: 0 | V8: 0 | W8: 0 | X8: ='德国ERP数据'!Q7 | Y8: / | AA8: / | AC8: / | AE8: 32 | AG8: 0 | AH8: 0 | AI8: 0 | AJ8: 0 | AK8: 5 | AL8: 0 | AM8: 0 | AN8: =IFERROR(AM8/AL8,0) | AO8: 0 | AP8: =IFERROR(AT8/AM8,0) | AQ8: =IFERROR(AT8/AW8,0) | AR8: =IFERROR(AO8/AM8,0) | AS8: =IFERROR(AO8/Q8,0) | AT8: 0 | AU8: =IFERROR(AT8/X8,0) | AV8: =IFERROR(AT8/AO8,0) | AW8: 0 | AX8: =IFERROR(AW8/X8,0)
A9: 45998 | B9: 星期日 | D9: 54.99 | F9: 0 | G9: 0 | H9: 33.43 | I9: - | J9: - | K9: ='德国ERP数据'!BC8 | L9: ='德国ERP数据'!BA8 | M9: =K9+L9 | N9: =IFERROR(Q9/M9,0) | O9: =P9-AO9 | P9: =Q9-U9-BH9 | Q9: ='德国ERP数据'!R8 | R9: - | S9: ='德国ERP数据'!Z8 | T9: 0 | U9: 0 | V9: 0 | W9: 0 | X9: ='德国ERP数据'!Q8 | Y9: / | AA9: / | AC9: / | AE9: 32 | AG9: 0 | AH9: 0 | AI9: 0 | AJ9: 0 | AK9: 5 | AL9: 0 | AM9: 0 | AN9: =IFERROR(AM9/AL9,0) | AO9: 0 | AP9: =IFERROR(AT9/AM9,0) | AQ9: =IFERROR(AT9/AW9,0) | AR9: =IFERROR(AO9/AM9,0) | AS9: =IFERROR(AO9/Q9,0) | AT9: 0 | AU9: =IFERROR(AT9/X9,0) | AV9: =IFERROR(AT9/AO9,0) | AW9: 0 | AX9: =IFERROR(AW9/X9,0)
A10: 45999 | B10: 星期一 | D10: 54.99 | F10: 0 | G10: 0 | H10: 33.43 | I10: - | J10: - | K10: ='德国ERP数据'!BC9 | L10: ='德国ERP数据'!BA9 | M10: =K10+L10 | N10: =IFERROR(Q10/M10,0) | O10: =P10-AO10 | P10: =Q10-U10-BH10 | Q10: ='德国ERP数据'!R9 | R10: - | S10: ='德国ERP数据'!Z9 | T10: 0 | U10: 0 | V10: 0 | W10: 0 | X10: ='德国ERP数据'!Q9 | Y10: / | AA10: / | AC10: / | AE10: 32 | AG10: 0 | AH10: 0 | AI10: 0 | AJ10: 0 | AK10: 5 | AL10: 0 | AM10: 0 | AN10: =IFERROR(AM10/AL10,0) | AO10: 0 | AP10: =IFERROR(AT10/AM10,0) | AQ10: =IFERROR(AT10/AW10,0) | AR10: =IFERROR(AO10/AM10,0) | AS10: =IFERROR(AO10/Q10,0) | AT10: 0 | AU10: =IFERROR(AT10/X10,0) | AV10: =IFERROR(AT10/AO10,0) | AW10: 0 | AX10: =IFERROR(AW10/X10,0)
A11: 46000 | B11: 星期二 | D11: 54.99 | F11: 0 | G11: 0 | H11: 33.43 | I11: - | J11: - | K11: ='德国ERP数据'!BC10 | L11: ='德国ERP数据'!BA10 | M11: =K11+L11 | N11: =IFERROR(Q11/M11,0) | O11: =P11-AO11 | P11: =Q11-U11-BH11 | Q11: ='德国ERP数据'!R10 | R11: - | S11: ='德国ERP数据'!Z10 | T11: 0 | U11: 0 | V11: 0 | W11: 0 | X11: ='德国ERP数据'!Q10 | Y11: / | AA11: / | AC11: / | AE11: 32 | AG11: 0 | AH11: 0 | AI11: 0 | AJ11: 0 | AK11: 5 | AL11: 0 | AM11: 0 | AN11: =IFERROR(AM11/AL11,0) | AO11: 0 | AP11: =IFERROR(AT11/AM11,0) | AQ11: =IFERROR(AT11/AW11,0) | AR11: =IFERROR(AO11/AM11,0) | AS11: =IFERROR(AO11/Q11,0) | AT11: 0 | AU11: =IFERROR(AT11/X11,0) | AV11: =IFERROR(AT11/AO11,0) | AW11: 0 | AX11: =IFERROR(AW11/X11,0)
A12: 46001 | B12: 星期三 | D12: 54.99 | F12: 0 | G12: 0 | H12: 33.43 | I12: - | J12: - | K12: ='德国ERP数据'!BC11 | L12: ='德国ERP数据'!BA11 | M12: =K12+L12 | N12: =IFERROR(Q12/M12,0) | O12: =P12-AO12 | P12: =Q12-U12-BH12 | Q12: ='德国ERP数据'!R11 | R12: - | S12: ='德国ERP数据'!Z11 | T12: 0 | U12: 0 | V12: 0 | W12: 0 | X12: ='德国ERP数据'!Q11 | Y12: / | AA12: / | AC12: / | AE12: 32 | AG12: 0 | AH12: 0 | AI12: 0 | AJ12: 0 | AK12: 5 | AL12: 0 | AM12: 0 | AN12: =IFERROR(AM12/AL12,0) | AO12: 0 | AP12: =IFERROR(AT12/AM12,0) | AQ12: =IFERROR(AT12/AW12,0) | AR12: =IFERROR(AO12/AM12,0) | AS12: =IFERROR(AO12/Q12,0) | AT12: 0 | AU12: =IFERROR(AT12/X12,0) | AV12: =IFERROR(AT12/AO12,0) | AW12: 0 | AX12: =IFERROR(AW12/X12,0)
A13: 46002 | B13: 星期四 | D13: 54.99 | F13: 0 | G13: 0 | H13: 33.43 | I13: - | J13: - | K13: ='德国ERP数据'!BC12 | L13: ='德国ERP数据'!BA12 | M13: =K13+L13 | N13: =IFERROR(Q13/M13,0) | O13: =P13-AO13 | P13: =Q13-U13-BH13 | Q13: ='德国ERP数据'!R12 | R13: - | S13: ='德国ERP数据'!Z12 | T13: 0 | U13: 0 | V13: 0 | W13: 0 | X13: ='德国ERP数据'!Q12 | Y13: / | AA13: / | AC13: / | AE13: 32 | AG13: 0 | AH13: 0 | AI13: 0 | AJ13: 0 | AK13: 5 | AL13: 0 | AM13: 0 | AN13: =IFERROR(AM13/AL13,0) | AO13: 0 | AP13: =IFERROR(AT13/AM13,0) | AQ13: =IFERROR(AT13/AW13,0) | AR13: =IFERROR(AO13/AM13,0) | AS13: =IFERROR(AO13/Q13,0) | AT13: 0 | AU13: =IFERROR(AT13/X13,0) | AV13: =IFERROR(AT13/AO13,0) | AW13: 0 | AX13: =IFERROR(AW13/X13,0)
A14: 46003 | B14: 星期五 | D14: 54.99 | F14: 0 | G14: 0 | H14: 33.43 | I14: - | J14: - | K14: ='德国ERP数据'!BC13 | L14: ='德国ERP数据'!BA13 | M14: =K14+L14 | N14: =IFERROR(Q14/M14,0) | O14: =P14-AO14 | P14: =Q14-U14-BH14 | Q14: ='德国ERP数据'!R13 | R14: - | S14: ='德国ERP数据'!Z13 | T14: 0 | U14: 0 | V14: 0 | W14: 0 | X14: ='德国ERP数据'!Q13 | Y14: / | AA14: / | AC14: / | AE14: 32 | AG14: 0 | AH14: 0 | AI14: 0 | AJ14: 0 | AK14: 5 | AL14: 0 | AM14: 0 | AN14: =IFERROR(AM14/AL14,0) | AO14: 0 | AP14: =IFERROR(AT14/AM14,0) | AQ14: =IFERROR(AT14/AW14,0) | AR14: =IFERROR(AO14/AM14,0) | AS14: =IFERROR(AO14/Q14,0) | AT14: 0 | AU14: =IFERROR(AT14/X14,0) | AV14: =IFERROR(AT14/AO14,0) | AW14: 0 | AX14: =IFERROR(AW14/X14,0)
A15: 46004 | B15: 星期六 | D15: 54.99 | F15: 0 | G15: 0 | H15: 33.43 | I15: - | J15: - | K15: ='德国ERP数据'!BC14 | L15: ='德国ERP数据'!BA14 | M15: =K15+L15 | N15: =IFERROR(Q15/M15,0) | O15: =P15-AO15 | P15: =Q15-U15-BH15 | Q15: ='德国ERP数据'!R14 | R15: - | S15: ='德国ERP数据'!Z14 | T15: 0 | U15: 0 | V15: 0 | W15: 0 | X15: ='德国ERP数据'!Q14 | Y15: / | AA15: / | AC15: / | AE15: 32 | AG15: 0 | AH15: 0 | AI15: 0 | AJ15: 0 | AK15: 5 | AL15: 0 | AM15: 0 | AN15: =IFERROR(AM15/AL15,0) | AO15: 0 | AP15: =IFERROR(AT15/AM15,0) | AQ15: =IFERROR(AT15/AW15,0) | AR15: =IFERROR(AO15/AM15,0) | AS15: =IFERROR(AO15/Q15,0) | AT15: 0 | AU15: =IFERROR(AT15/X15,0) | AV15: =IFERROR(AT15/AO15,0) | AW15: 0 | AX15: =IFERROR(AW15/X15,0)
... A26: 46015 | B26: 星期三 | D26: 54.99 | F26: 0 | G26: 0 | H26: 33.43 | I26: - | J26: - | K26: ='德国ERP数据'!BC25 | L26: ='德国ERP数据'!BA25 | M26: =K26+L26 | N26: =IFERROR(Q26/M26,0) | O26: =P26-AO26 | P26: =Q26-U26-BH26 | Q26: ='德国ERP数据'!R25 | R26: - | S26: ='德国ERP数据'!Z25 | T26: 0 | U26: 0 | V26: 0 | W26: 0 | X26: ='德国ERP数据'!Q25 | Y26: / | AA26: / | AC26: / | AE26: 32 | AG26: 0 | AH26: 0 | AI26: 0 | AJ26: 0 | AK26: 5 | AL26: 0 | AM26: 0 | AN26: =IFERROR(AM26/AL26,0) | AO26: 0 | AP26: =IFERROR(AT26/AM26,0) | AQ26: =IFERROR(AT26/AW26,0) | AR26: =IFERROR(AO26/AM26,0) | AS26: =IFERROR(AO26/Q26,0) | AT26: 0 | AU26: =IFERROR(AT26/X26,0) | AV26: =IFERROR(AT26/AO26,0) | AW26: 0 | AX26: =IFERROR(AW26/X26,0)
A27: 46016 | B27: 星期四 | D27: 54.99 | F27: 0 | G27: 0 | H27: 33.43 | I27: - | J27: - | K27: ='德国ERP数据'!BC226 | L27: ='德国ERP数据'!BA226 | M27: =K27+L27 | N27: =IFERROR(Q27/M27,0) | O27: =P27-AO27 | P27: =Q27-U27-BH27 | Q27: ='德国ERP数据'!R226 | R27: - | S27: ='德国ERP数据'!Z226 | T27: 0 | U27: 0 | V27: 0 | W27: 0 | X27: ='德国ERP数据'!Q226 | Y27: / | AA27: / | AC27: / | AE27: 32 | AG27: 0 | AH27: 0 | AI27: 0 | AJ27: 0 | AK27: 5 | AL27: 0 | AM27: 0 | AN27: =IFERROR(AM27/AL27,0) | AO27: 0 | AP27: =IFERROR(AT27/AM27,0) | AQ27: =IFERROR(AT27/AW27,0) | AR27: =IFERROR(AO27/AM27,0) | AS27: =IFERROR(AO27/Q27,0) | AT27: 0 | AU27: =IFERROR(AT27/X27,0) | AV27: =IFERROR(AT27/AO27,0) | AW27: 0 | AX27: =IFERROR(AW27/X27,0)
A28: 46017 | B28: 星期五 | D28: 54.99 | F28: 0 | G28: 0 | H28: 33.43 | I28: - | J28: - | K28: ='德国ERP数据'!BC227 | L28: ='德国ERP数据'!BA227 | M28: =K28+L28 | N28: =IFERROR(Q28/M28,0) | O28: =P28-AO28 | P28: =Q28-U28-BH28 | Q28: ='德国ERP数据'!R227 | R28: - | S28: ='德国ERP数据'!Z227 | T28: 0 | U28: 0 | V28: 0 | W28: 0 | X28: ='德国ERP数据'!Q227 | Y28: / | AA28: / | AC28: / | AE28: 32 | AG28: 0 | AH28: 0 | AI28: 0 | AJ28: 0 | AK28: 5 | AL28: 0 | AM28: 0 | AN28: =IFERROR(AM28/AL28,0) | AO28: 0 | AP28: =IFERROR(AT28/AM28,0) | AQ28: =IFERROR(AT28/AW28,0) | AR28: =IFERROR(AO28/AM28,0) | AS28: =IFERROR(AO28/Q28,0) | AT28: 0 | AU28: =IFERROR(AT28/X28,0) | AV28: =IFERROR(AT28/AO28,0) | AW28: 0 | AX28: =IFERROR(AW28/X28,0)
A29: 46018 | B29: 星期六 | D29: 54.99 | F29: 0 | G29: 0 | H29: 33.43 | I29: - | J29: - | K29: ='德国ERP数据'!BC228 | L29: ='德国ERP数据'!BA228 | M29: =K29+L29 | N29: =IFERROR(Q29/M29,0) | O29: =P29-AO29 | P29: =Q29-U29-BH29 | Q29: ='德国ERP数据'!R228 | R29: - | S29: ='德国ERP数据'!Z228 | T29: 0 | U29: 0 | V29: 0 | W29: 0 | X29: ='德国ERP数据'!Q228 | Y29: / | AA29: / | AC29: / | AE29: 32 | AG29: 0 | AH29: 0 | AI29: 0 | AJ29: 0 | AK29: 5 | AL29: 0 | AM29: 0 | AN29: =IFERROR(AM29/AL29,0) | AO29: 0 | AP29: =IFERROR(AT29/AM29,0) | AQ29: =IFERROR(AT29/AW29,0) | AR29: =IFERROR(AO29/AM29,0) | AS29: =IFERROR(AO29/Q29,0) | AT29: 0 | AU29: =IFERROR(AT29/X29,0) | AV29: =IFERROR(AT29/AO29,0) | AW29: 0 | AX29: =IFERROR(AW29/X29,0)
A30: 46019 | B30: 星期日 | D30: 54.99 | F30: 0 | G30: 0 | H30: 33.43 | I30: - | J30: - | K30: ='德国ERP数据'!BC229 | L30: ='德国ERP数据'!BA229 | M30: =K30+L30 | N30: =IFERROR(Q30/M30,0) | O30: =P30-AO30 | P30: =Q30-U30-BH30 | Q30: ='德国ERP数据'!R229 | R30: - | S30: ='德国ERP数据'!Z229 | T30: 0 | U30: 0 | V30: 0 | W30: 0 | X30: ='德国ERP数据'!Q229 | Y30: / | AA30: / | AC30: / | AE30: 32 | AG30: 0 | AH30: 0 | AI30: 0 | AJ30: 0 | AK30: 5 | AL30: 0 | AM30: 0 | AN30: =IFERROR(AM30/AL30,0) | AO30: 0 | AP30: =IFERROR(AT30/AM30,0) | AQ30: =IFERROR(AT30/AW30,0) | AR30: =IFERROR(AO30/AM30,0) | AS30: =IFERROR(AO30/Q30,0) | AT30: 0 | AU30: =IFERROR(AT30/X30,0) | AV30: =IFERROR(AT30/AO30,0) | AW30: 0 | AX30: =IFERROR(AW30/X30,0)
A31: 46020 | B31: 星期一 | D31: 54.99 | F31: 0 | G31: 0 | H31: 33.43 | I31: - | J31: - | K31: ='德国ERP数据'!BC230 | L31: ='德国ERP数据'!BA230 | M31: =K31+L31 | N31: =IFERROR(Q31/M31,0) | O31: =P31-AO31 | P31: =Q31-U31-BH31 | Q31: ='德国ERP数据'!R230 | R31: - | S31: ='德国ERP数据'!Z230 | T31: 0 | U31: 0 | V31: 0 | W31: 0 | X31: ='德国ERP数据'!Q230 | Y31: / | AA31: / | AC31: / | AE31: 32 | AG31: 0 | AH31: 0 | AI31: 0 | AJ31: 0 | AK31: 5 | AL31: 0 | AM31: 0 | AN31: =IFERROR(AM31/AL31,0) | AO31: 0 | AP31: =IFERROR(AT31/AM31,0) | AQ31: =IFERROR(AT31/AW31,0) | AR31: =IFERROR(AO31/AM31,0) | AS31: =IFERROR(AO31/Q31,0) | AT31: 0 | AU31: =IFERROR(AT31/X31,0) | AV31: =IFERROR(AT31/AO31,0) | AW31: 0 | AX31: =IFERROR(AW31/X31,0)
A32: 46021 | B32: 星期二 | D32: 54.99 | F32: 0 | G32: 0 | H32: 33.43 | I32: - | J32: - | K32: ='德国ERP数据'!BC231 | L32: ='德国ERP数据'!BA231 | M32: =K32+L32 | N32: =IFERROR(Q32/M32,0) | O32: =P32-AO32 | P32: =Q32-U32-BH32 | Q32: ='德国ERP数据'!R231 | R32: - | S32: ='德国ERP数据'!Z231 | T32: 0 | U32: 0 | V32: 0 | W32: 0 | X32: ='德国ERP数据'!Q231 | Y32: / | AA32: / | AC32: / | AE32: 32 | AG32: 0 | AH32: 0 | AI32: 0 | AJ32: 0 | AK32: 5 | AL32: 0 | AM32: 0 | AN32: =IFERROR(AM32/AL32,0) | AO32: 0 | AP32: =IFERROR(AT32/AM32,0) | AQ32: =IFERROR(AT32/AW32,0) | AR32: =IFERROR(AO32/AM32,0) | AS32: =IFERROR(AO32/Q32,0) | AT32: 0 | AU32: =IFERROR(AT32/X32,0) | AV32: =IFERROR(AT32/AO32,0) | AW32: 0 | AX32: =IFERROR(AW32/X32,0)
A33: 46022 | B33: 星期三 | D33: 54.99 | F33: 0 | G33: 0 | H33: 33.43 | I33: - | J33: - | K33: ='德国ERP数据'!BC232 | L33: ='德国ERP数据'!BA232 | M33: =K33+L33 | N33: =IFERROR(Q33/M33,0) | O33: =P33-AO33 | P33: =Q33-U33-BH33 | Q33: ='德国ERP数据'!R232 | R33: - | S33: ='德国ERP数据'!Z232 | T33: 0 | U33: 0 | V33: 0 | W33: 0 | X33: ='德国ERP数据'!Q232 | Y33: / | AA33: / | AC33: / | AE33: 32 | AG33: 0 | AH33: 0 | AI33: 0 | AJ33: 0 | AK33: 5 | AL33: 0 | AM33: 0 | AN33: =IFERROR(AM33/AL33,0) | AO33: 0 | AP33: =IFERROR(AT33/AM33,0) | AQ33: =IFERROR(AT33/AW33,0) | AR33: =IFERROR(AO33/AM33,0) | AS33: =IFERROR(AO33/Q33,0) | AT33: 0 | AU33: =IFERROR(AT33/X33,0) | AV33: =IFERROR(AT33/AO33,0) | AW33: 0 | AX33: =IFERROR(AW33/X33,0)
A34: 46023 | B34: 星期四 | D34: 54.99 | F34: 0 | G34: 0 | H34: 33.43 | I34: - | J34: - | K34: ='德国ERP数据'!BC233 | L34: ='德国ERP数据'!BA233 | M34: =K34+L34 | N34: =IFERROR(Q34/M34,0) | O34: =P34-AO34 | P34: =Q34-U34-BH34 | Q34: ='德国ERP数据'!R233 | R34: - | S34: ='德国ERP数据'!Z233 | T34: 0 | U34: 0 | V34: 0 | W34: 0 | X34: ='德国ERP数据'!Q233 | Y34: / | AA34: / | AC34: / | AE34: 32 | AG34: 0 | AH34: 0 | AI34: 0 | AJ34: 0 | AK34: 5 | AL34: 0 | AM34: 0 | AN34: =IFERROR(AM34/AL34,0) | AO34: 0 | AP34: =IFERROR(AT34/AM34,0) | AQ34: =IFERROR(AT34/AW34,0) | AR34: =IFERROR(AO34/AM34,0) | AS34: =IFERROR(AO34/Q34,0) | AT34: 0 | AU34: =IFERROR(AT34/X34,0) | AV34: =IFERROR(AT34/AO34,0) | AW34: 0 | AX34: =IFERROR(AW34/X34,0)
A35: 46024 | B35: 星期五 | D35: 54.99 | F35: 0 | G35: 0 | H35: 33.43 | I35: - | J35: - | K35: ='德国ERP数据'!BC234 | L35: ='德国ERP数据'!BA234 | M35: =K35+L35 | N35: =IFERROR(Q35/M35,0) | O35: =P35-AO35 | P35: =Q35-U35-BH35 | Q35: ='德国ERP数据'!R234 | R35: - | S35: ='德国ERP数据'!Z234 | T35: 0 | U35: 0 | V35: 0 | W35: 0 | X35: ='德国ERP数据'!Q234 | Y35: / | AA35: / | AC35: / | AE35: 32 | AG35: 0 | AH35: 0 | AI35: 0 | AJ35: 0 | AK35: 5 | AL35: 0 | AM35: 0 | AN35: =IFERROR(AM35/AL35,0) | AO35: 0 | AP35: =IFERROR(AT35/AM35,0) | AQ35: =IFERROR(AT35/AW35,0) | AR35: =IFERROR(AO35/AM35,0) | AS35: =IFERROR(AO35/Q35,0) | AT35: 0 | AU35: =IFERROR(AT35/X35,0) | AV35: =IFERROR(AT35/AO35,0) | AW35: 0 | AX35: =IFERROR(AW35/X35,0)
A36: 46025 | B36: 星期六 | D36: 54.99 | F36: 0 | G36: 0 | H36: 33.43 | I36: - | J36: - | K36: ='德国ERP数据'!BC235 | L36: ='德国ERP数据'!BA235 | M36: =K36+L36 | N36: =IFERROR(Q36/M36,0) | O36: =P36-AO36 | P36: =Q36-U36-BH36 | Q36: ='德国ERP数据'!R235 | R36: - | S36: ='德国ERP数据'!Z235 | T36: 0 | U36: 0 | V36: 0 | W36: 0 | X36: ='德国ERP数据'!Q235 | Y36: / | AA36: / | AC36: / | AE36: 32 | AG36: 0 | AH36: 0 | AI36: 0 | AJ36: 0 | AK36: 5 | AL36: 0 | AM36: 0 | AN36: =IFERROR(AM36/AL36,0) | AO36: 0 | AP36: =IFERROR(AT36/AM36,0) | AQ36: =IFERROR(AT36/AW36,0) | AR36: =IFERROR(AO36/AM36,0) | AS36: =IFERROR(AO36/Q36,0) | AT36: 0 | AU36: =IFERROR(AT36/X36,0) | AV36: =IFERROR(AT36/AO36,0) | AW36: 0 | AX36: =IFERROR(AW36/X36,0)
A37: 46026 | B37: 星期日 | D37: 54.99 | F37: 0 | G37: 0 | H37: 33.43 | I37: - | J37: - | K37: ='德国ERP数据'!BC236 | L37: ='德国ERP数据'!BA236 | M37: =K37+L37 | N37: =IFERROR(Q37/M37,0) | O37: =P37-AO37 | P37: =Q37-U37-BH37 | Q37: ='德国ERP数据'!R236 | R37: - | S37: ='德国ERP数据'!Z236 | T37: 0 | U37: 0 | V37: 0 | W37: 0 | X37: ='德国ERP数据'!Q236 | Y37: / | AA37: / | AC37: / | AE37: 32 | AG37: 0 | AH37: 0 | AI37: 0 | AJ37: 0 | AK37: 5 | AL37: 0 | AM37: 0 | AN37: =IFERROR(AM37/AL37,0) | AO37: 0 | AP37: =IFERROR(AT37/AM37,0) | AQ37: =IFERROR(AT37/AW37,0) | AR37: =IFERROR(AO37/AM37,0) | AS37: =IFERROR(AO37/Q37,0) | AT37: 0 | AU37: =IFERROR(AT37/X37,0) | AV37: =IFERROR(AT37/AO37,0) | AW37: 0 | AX37: =IFERROR(AW37/X37,0)
A38: 46027 | B38: 星期一 | D38: 54.99 | F38: 0 | G38: 0 | H38: 33.43 | I38: - | J38: - | K38: ='德国ERP数据'!BC237 | L38: ='德国ERP数据'!BA237 | M38: =K38+L38 | N38: =IFERROR(Q38/M38,0) | O38: =P38-AO38 | P38: =Q38-U38-BH38 | Q38: ='德国ERP数据'!R237 | R38: - | S38: ='德国ERP数据'!Z237 | T38: 0 | U38: 0 | V38: 0 | W38: 0 | X38: ='德国ERP数据'!Q237 | Y38: / | AA38: / | AC38: / | AE38: 32 | AG38: 0 | AH38: 0 | AI38: 0 | AJ38: 0 | AK38: 5 | AL38: 0 | AM38: 0 | AN38: =IFERROR(AM38/AL38,0) | AO38: 0 | AP38: =IFERROR(AT38/AM38,0) | AQ38: =IFERROR(AT38/AW38,0) | AR38: =IFERROR(AO38/AM38,0) | AS38: =IFERROR(AO38/Q38,0) | AT38: 0 | AU38: =IFERROR(AT38/X38,0) | AV38: =IFERROR(AT38/AO38,0) | AW38: 0 | AX38: =IFERROR(AW38/X38,0)
... A69: 46058 | B69: 星期四 | D69: 54.99 | F69: 0 | G69: 0 | H69: 33.43 | I69: - | J69: - | K69: ='德国ERP数据'!BC268 | L69: ='德国ERP数据'!BA268 | M69: =K69+L69 | N69: =IFERROR(Q69/M69,0) | O69: =P69-AO69 | P69: =Q69-U69-BH69 | Q69: ='德国ERP数据'!R268 | R69: - | S69: ='德国ERP数据'!Z268 | T69: 0 | U69: 0 | V69: 0 | W69: 0 | X69: ='德国ERP数据'!Q268 | Y69: / | AA69: / | AC69: / | AE69: 32 | AG69: 0 | AH69: 0 | AI69: 0 | AJ69: 0 | AK69: 5 | AL69: 0 | AM69: 0 | AN69: =IFERROR(AM69/AL69,0) | AO69: 0 | AP69: =IFERROR(AT69/AM69,0) | AQ69: =IFERROR(AT69/AW69,0) | AR69: =IFERROR(AO69/AM69,0) | AS69: =IFERROR(AO69/Q69,0) | AT69: 0 | AU69: =IFERROR(AT69/X69,0) | AV69: =IFERROR(AT69/AO69,0) | AW69: 0 | AX69: =IFERROR(AW69/X69,0)
A70: 46059 | B70: 星期五 | D70: 54.99 | F70: 0 | G70: 0 | H70: 33.43 | I70: - | J70: - | K70: ='德国ERP数据'!BC269 | L70: ='德国ERP数据'!BA269 | M70: =K70+L70 | N70: =IFERROR(Q70/M70,0) | O70: =P70-AO70 | P70: =Q70-U70-BH70 | Q70: ='德国ERP数据'!R269 | R70: - | S70: ='德国ERP数据'!Z269 | T70: 0 | U70: 0 | V70: 0 | W70: 0 | X70: ='德国ERP数据'!Q269 | Y70: /
A71: 46060 | B71: 星期六 | D71: 54.99 | F71: 0 | G71: 0 | H71: 33.43 | I71: - | J71: - | K71: ='德国ERP数据'!BC270 | L71: ='德国ERP数据'!BA270 | M71: =K71+L71 | N71: =IFERROR(Q71/M71,0) | O71: =P71-AO71 | P71: =Q71-U71-BH71 | Q71: ='德国ERP数据'!R270 | R71: - | S71: ='德国ERP数据'!Z270 | T71: 0 | U71: 0 | V71: 0 | W71: 0 | X71: ='德国ERP数据'!Q270 | Y71: /
A72: 46061 | B72: 星期日 | D72: 54.99 | F72: 0 | G72: 0 | H72: 33.43 | I72: - | J72: - | K72: ='德国ERP数据'!BC271 | L72: ='德国ERP数据'!BA271 | M72: =K72+L72 | N72: =IFERROR(Q72/M72,0) | O72: =P72-AO72 | P72: =Q72-U72-BH72 | Q72: ='德国ERP数据'!R271 | R72: - | S72: ='德国ERP数据'!Z271 | T72: 0 | U72: 0 | V72: 0 | W72: 0 | X72: ='德国ERP数据'!Q271 | Y72: /
A73: 46062 | B73: 星期一 | D73: 54.99 | F73: 0 | G73: 0 | H73: 33.43 | I73: - | J73: - | K73: ='德国ERP数据'!BC272 | L73: ='德国ERP数据'!BA272 | M73: =K73+L73 | N73: =IFERROR(Q73/M73,0) | O73: =P73-AO73 | P73: =Q73-U73-BH73 | Q73: ='德国ERP数据'!R272 | R73: - | S73: ='德国ERP数据'!Z272 | T73: 0 | U73: 0 | V73: 0 | W73: 0 | X73: ='德国ERP数据'!Q272 | Y73: /
A74: 46063 | B74: 星期二 | D74: 54.99 | F74: 0 | G74: 0 | H74: 33.43 | I74: - | J74: - | K74: ='德国ERP数据'!BC273 | L74: ='德国ERP数据'!BA273 | M74: =K74+L74 | N74: =IFERROR(Q74/M74,0) | O74: =P74-AO74 | P74: =Q74-U74-BH74 | Q74: ='德国ERP数据'!R273 | R74: - | S74: ='德国ERP数据'!Z273 | T74: 0 | U74: 0 | V74: 0 | W74: 0 | X74: ='德国ERP数据'!Q273 | Y74: /
A75: 46064 | B75: 星期三 | D75: 54.99 | F75: 0 | G75: 0 | H75: 33.43 | I75: - | J75: - | K75: ='德国ERP数据'!BC274 | L75: ='德国ERP数据'!BA274 | M75: =K75+L75 | N75: =IFERROR(Q75/M75,0) | O75: =P75-AO75 | P75: =Q75-U75-BH75 | Q75: ='德国ERP数据'!R274 | R75: - | S75: ='德国ERP数据'!Z274 | T75: 0 | U75: 0 | V75: 0 | W75: 0 | X75: ='德国ERP数据'!Q274 | Y75: /
A76: 46065 | B76: 星期四 | D76: 54.99 | F76: 0 | G76: 0 | H76: 33.43 | I76: - | J76: - | K76: ='德国ERP数据'!BC275 | L76: ='德国ERP数据'!BA275 | M76: =K76+L76 | N76: =IFERROR(Q76/M76,0) | O76: =P76-AO76 | P76: =Q76-U76-BH76 | Q76: ='德国ERP数据'!R275 | R76: - | S76: ='德国ERP数据'!Z275 | T76: 0 | U76: 0 | V76: 0 | W76: 0 | X76: ='德国ERP数据'!Q275 | Y76: /
A77: 46066 | B77: 星期五 | D77: 54.99 | F77: 0 | G77: 0 | H77: 33.43 | I77: - | J77: - | K77: ='德国ERP数据'!BC276 | L77: ='德国ERP数据'!BA276 | M77: =K77+L77 | N77: =IFERROR(Q77/M77,0) | O77: =P77-AO77 | P77: =Q77-U77-BH77 | Q77: ='德国ERP数据'!R276 | R77: - | S77: ='德国ERP数据'!Z276 | T77: 0 | U77: 0 | V77: 0 | W77: 0 | X77: ='德国ERP数据'!Q276 | Y77: /
A78: 46067 | B78: 星期六
A79: 46068 | B79: 星期日
A80: 46069 | B80: 星期一
...

Sheet 日常跟踪表 FR
A1: 时间 | B1: 星期 | C1: 工作内容 | D1: 售价 | E1: PD | F1: 划线价 折扣 | G1: CP | H1: 最低 成交价 | I1: SC最低 成交价毛利率 | J1: VC采购价毛利率 | K1: 移动 | L1: PC | M1: 访问 | N1: 总转化率 | O1: 实际自然订单 | P1: 自然订单 | Q1: 总订单 | R1: VC订单 | S1: B2B订单 | T1: 测评计划出单 | U1: 测评总出单 | V1: 测评完成率 | W1: Vine | X1: 销售额 | Y1: 核心词ABA排名 | AC1: sif前三页关键词收录数量 | AD1: 大类排名 | AE1: 小类排名 | AF1: 评论数 | AG1: 评分 | AH1: 广告数据 | AU1: 毛利数据 | BB1: 站外 | BH1: 库存监控
AH2: 曝光 | AI2: 点击 | AJ2: 点击率 | AK2: 订单 | AL2: CPC | AM2: ACOS | AN2: 广告转化 | AO2: 广告订单占比 | AP2: 花费（$） | AQ2: 广告花费占比 | AR2: CPA | AS2: 广告销售额 | AT2: 退款率 | AU2: 广告订单毛利P1$ | AV2: 自然订单毛利P1$ | AW2: 总订单毛利P1$ | AX2: 总订单毛利率P1 | AY2: 国内总成本$ | AZ2: 回款金额 | BA2: 测评亏损 | BB2: 站外毛利$ | BC2: 站外出单 | BD2: 站外售价 | BE2: 站外折扣 | BF2: 自然流量 | BG2: 自然转化 | BH2: VC仓库存 | BI2: 海外仓库存 | BJ2: 总库存 | BK2: VC其他订单数 | BL2: 备注
A3: 45992 | B3: 星期一 | D3: 59.99 | E3: 0 | F3: 0 | G3: 0 | H3: =D3*(1-F3)*(1-G3) | I3: - | J3: - | K3: ='法国ERP数据'!BC2 | L3: ='法国ERP数据'!BA2 | M3: =K3+L3 | N3: =IFERROR(Q3/M3,0) | O3: =P3-AK3 | P3: =Q3-U3-BC3 | Q3: ='法国ERP数据'!R2 | S3: ='法国ERP数据'!Z2 | T3: 0 | U3: 0 | V3: 0 | W3: 0 | X3: 0 | AC3: 8 | AF3: 0 | AG3: 0 | AH3: 0 | AI3: 0 | AJ3: =AI3/AH3 | AK3: 0 | AL3: =AP3/AI3 | AM3: =AP3/AS3 | AN3: =AK3/AI3 | AO3: =AK3/P3 | AP3: 0 | AQ3: =AP3/W3 | AR3: =AP3/AK3 | AS3: 0
A4: 45993 | B4: 星期二 | D4: 59.99 | E4: 0 | F4: 0 | G4: 0 | H4: =D4*(1-F4)*(1-G4) | I4: - | J4: - | K4: ='法国ERP数据'!BC3 | L4: ='法国ERP数据'!BA3 | M4: =K4+L4 | N4: =IFERROR(Q4/M4,0) | O4: =P4-AK4 | P4: =Q4-U4-BC4 | Q4: ='法国ERP数据'!R3 | S4: ='法国ERP数据'!Z3 | T4: 0 | U4: 0 | V4: 0 | W4: 0 | X4: 0 | AC4: 13 | AF4: 0 | AG4: 0 | AH4: 0 | AI4: 0 | AJ4: =AI4/AH4 | AK4: 0 | AL4: =AP4/AI4 | AM4: =AP4/AS4 | AN4: =AK4/AI4 | AO4: =AK4/P4 | AP4: 0 | AQ4: =AP4/W4 | AR4: =AP4/AK4 | AS4: 0
A5: 45994 | B5: 星期三 | D5: 59.99 | E5: 0 | F5: 0 | G5: 0 | H5: =D5*(1-F5)*(1-G5) | I5: - | J5: - | K5: ='法国ERP数据'!BC4 | L5: ='法国ERP数据'!BA4 | M5: =K5+L5 | N5: =IFERROR(Q5/M5,0) | O5: =P5-AK5 | P5: =Q5-U5-BC5 | Q5: ='法国ERP数据'!R4 | S5: ='法国ERP数据'!Z4 | T5: 0 | U5: 0 | V5: 0 | W5: 2 | X5: 0 | AC5: 14 | AF5: 0 | AG5: 0 | AH5: 0 | AI5: 0 | AJ5: =AI5/AH5 | AK5: 0 | AL5: =AP5/AI5 | AM5: =AP5/AS5 | AN5: =AK5/AI5 | AO5: =AK5/P5 | AP5: 0 | AQ5: =AP5/W5 | AR5: =AP5/AK5 | AS5: 0
A6: 45995 | B6: 星期四 | D6: 59.99 | E6: 0 | F6: 0 | G6: 0 | H6: =D6*(1-F6)*(1-G6) | I6: - | J6: - | K6: ='法国ERP数据'!BC5 | L6: ='法国ERP数据'!BA5 | M6: =K6+L6 | N6: =IFERROR(Q6/M6,0) | O6: =P6-AK6 | P6: =Q6-U6-BC6 | Q6: ='法国ERP数据'!R5 | S6: ='法国ERP数据'!Z5 | T6: 0 | U6: 0 | V6: 0 | W6: 0 | X6: 0 | AC6: 23 | AF6: 0 | AG6: 0 | AH6: 0 | AI6: 0 | AJ6: =AI6/AH6 | AK6: 0 | AL6: =AP6/AI6 | AM6: =AP6/AS6 | AN6: =AK6/AI6 | AO6: =AK6/P6 | AP6: 0 | AQ6: =AP6/W6 | AR6: =AP6/AK6 | AS6: 0
A7: 45996 | B7: 星期五 | D7: 59.99 | E7: 0 | F7: 0 | G7: 0 | H7: =D7*(1-F7)*(1-G7) | I7: - | J7: - | K7: ='法国ERP数据'!BC6 | L7: ='法国ERP数据'!BA6 | M7: =K7+L7 | N7: =IFERROR(Q7/M7,0) | O7: =P7-AK7 | P7: =Q7-U7-BC7 | Q7: ='法国ERP数据'!R6 | S7: ='法国ERP数据'!Z6 | T7: 0 | U7: 0 | V7: 0 | W7: 0 | X7: 0 | AF7: 0 | AG7: 0 | AH7: 0 | AI7: 0 | AJ7: =AI7/AH7 | AK7: 0 | AL7: =AP7/AI7 | AM7: =AP7/AS7 | AN7: =AK7/AI7 | AO7: =AK7/P7 | AP7: 0 | AQ7: =AP7/W7 | AR7: =AP7/AK7 | AS7: 0
A8: 45997 | B8: 星期六 | D8: 59.99 | E8: 0 | F8: 0 | G8: 0 | H8: =D8*(1-F8)*(1-G8) | I8: - | J8: - | K8: ='法国ERP数据'!BC7 | L8: ='法国ERP数据'!BA7 | M8: =K8+L8 | N8: =IFERROR(Q8/M8,0) | O8: =P8-AK8 | P8: =Q8-U8-BC8 | Q8: ='法国ERP数据'!R7 | S8: ='法国ERP数据'!Z7 | T8: 0 | U8: 0 | V8: 0 | W8: 0 | X8: 0 | AF8: 0 | AG8: 0 | AH8: 0 | AI8: 0 | AJ8: =AI8/AH8 | AK8: 0 | AL8: =AP8/AI8 | AM8: =AP8/AS8 | AN8: =AK8/AI8 | AO8: =AK8/P8 | AP8: 0 | AQ8: =AP8/W8 | AR8: =AP8/AK8 | AS8: 0
A9: 45998 | B9: 星期日 | D9: 59.99 | E9: 0 | F9: 0 | G9: 0 | H9: =D9*(1-F9)*(1-G9) | I9: - | J9: - | K9: ='法国ERP数据'!BC8 | L9: ='法国ERP数据'!BA8 | M9: =K9+L9 | N9: =IFERROR(Q9/M9,0) | O9: =P9-AK9 | P9: =Q9-U9-BC9 | Q9: ='法国ERP数据'!R8 | S9: ='法国ERP数据'!Z8 | T9: 1 | U9: 1 | V9: =U9/T9 | W9: 0 | X9: 0 | AF9: 0 | AG9: 0 | AH9: 0 | AI9: 0 | AJ9: =AI9/AH9 | AK9: 0 | AL9: =AP9/AI9 | AM9: =AP9/AS9 | AN9: =AK9/AI9 | AO9: =AK9/P9 | AP9: 0 | AQ9: =AP9/W9 | AR9: =AP9/AK9 | AS9: 0
A10: 45999 | B10: 星期一 | D10: 59.99 | E10: 0 | F10: 0 | G10: 0 | H10: =D10*(1-F10)*(1-G10) | I10: - | J10: - | K10: ='法国ERP数据'!BC9 | L10: ='法国ERP数据'!BA9 | M10: =K10+L10 | N10: =IFERROR(Q10/M10,0) | O10: =P10-AK10 | P10: =Q10-U10-BC10 | Q10: ='法国ERP数据'!R9 | S10: ='法国ERP数据'!Z9 | T10: 0 | U10: 0 | V10: 0 | W10: 0 | AF10: 1 | AG10: 4 | AH10: 0 | AI10: 0 | AJ10: =AI10/AH10 | AK10: 0 | AL10: =AP10/AI10 | AM10: =AP10/AS10 | AN10: =AK10/AI10 | AO10: =AK10/P10 | AP10: 0 | AQ10: =AP10/W10 | AR10: =AP10/AK10 | AS10: 0
A11: 46000 | B11: 星期二 | D11: 59.99 | E11: 0 | F11: 0 | G11: 0 | H11: =D11*(1-F11)*(1-G11) | I11: - | J11: - | K11: ='法国ERP数据'!BC10 | L11: ='法国ERP数据'!BA10 | M11: =K11+L11 | N11: =IFERROR(Q11/M11,0) | O11: =P11-AK11 | P11: =Q11-U11-BC11 | Q11: ='法国ERP数据'!R10 | S11: ='法国ERP数据'!Z10 | T11: 0 | U11: 0 | V11: 0 | W11: 0 | AF11: 1 | AG11: 4 | AH11: 0 | AI11: 0 | AJ11: =AI11/AH11 | AK11: 0 | AL11: =AP11/AI11 | AM11: =AP11/AS11 | AN11: =AK11/AI11 | AO11: =AK11/P11 | AP11: 0 | AQ11: =AP11/W11 | AR11: =AP11/AK11 | AS11: 0
A12: 46001 | B12: 星期三 | D12: 59.99 | E12: 0 | F12: 0 | G12: 0 | H12: =D12*(1-F12)*(1-G12) | I12: - | J12: - | K12: ='法国ERP数据'!BC11 | L12: ='法国ERP数据'!BA11 | M12: =K12+L12 | N12: =IFERROR(Q12/M12,0) | O12: =P12-AK12 | P12: =Q12-U12-BC12 | Q12: ='法国ERP数据'!R11 | S12: ='法国ERP数据'!Z11 | T12: 0 | U12: 0 | V12: 0 | W12: 0 | AF12: 1 | AG12: 4 | AH12: 0 | AI12: 0 | AJ12: =AI12/AH12 | AK12: 0 | AL12: =AP12/AI12 | AM12: =AP12/AS12 | AN12: =AK12/AI12 | AO12: =AK12/P12 | AP12: 0 | AQ12: =AP12/W12 | AR12: =AP12/AK12 | AS12: 0
A13: 46002 | B13: 星期四 | D13: 59.99 | E13: 0 | F13: 0 | G13: 0 | H13: =D13*(1-F13)*(1-G13) | I13: - | J13: - | K13: ='法国ERP数据'!BC12 | L13: ='法国ERP数据'!BA12 | M13: =K13+L13 | N13: =IFERROR(Q13/M13,0) | O13: =P13-AK13 | P13: =Q13-U13-BC13 | Q13: ='法国ERP数据'!R12 | S13: ='法国ERP数据'!Z12 | T13: 0 | U13: 0 | V13: 0 | W13: 0 | AF13: 1 | AG13: 4 | AH13: 0 | AI13: 0 | AJ13: =AI13/AH13 | AK13: 0 | AL13: =AP13/AI13 | AM13: =AP13/AS13 | AN13: =AK13/AI13 | AO13: =AK13/P13 | AP13: 0 | AQ13: =AP13/W13 | AR13: =AP13/AK13 | AS13: 0
A14: 46003 | B14: 星期五 | D14: 59.99 | E14: 0 | F14: 0 | G14: 0 | H14: =D14*(1-F14)*(1-G14) | I14: - | J14: - | K14: ='法国ERP数据'!BC13 | L14: ='法国ERP数据'!BA13 | M14: =K14+L14 | N14: =IFERROR(Q14/M14,0) | O14: =P14-AK14 | P14: =Q14-U14-BC14 | Q14: ='法国ERP数据'!R13 | S14: ='法国ERP数据'!Z13 | T14: 0 | U14: 0 | V14: 0 | W14: 0 | AF14: 1 | AG14: 4 | AH14: 0 | AI14: 0 | AJ14: =AI14/AH14 | AK14: 0 | AL14: =AP14/AI14 | AM14: =AP14/AS14 | AN14: =AK14/AI14 | AO14: =AK14/P14 | AP14: 0 | AQ14: =AP14/W14 | AR14: =AP14/AK14 | AS14: 0
A15: 46004 | B15: 星期六 | D15: 59.99 | E15: 0 | F15: 0 | G15: 0 | H15: =D15*(1-F15)*(1-G15) | I15: - | J15: - | K15: ='法国ERP数据'!BC14 | L15: ='法国ERP数据'!BA14 | M15: =K15+L15 | N15: =IFERROR(Q15/M15,0) | O15: =P15-AK15 | P15: =Q15-U15-BC15 | Q15: ='法国ERP数据'!R14 | S15: ='法国ERP数据'!Z14 | T15: 0 | U15: 0 | V15: 0 | W15: 0 | AF15: 1 | AG15: 4 | AH15: 0 | AI15: 0 | AJ15: =AI15/AH15 | AK15: 0 | AL15: =AP15/AI15 | AM15: =AP15/AS15 | AN15: =AK15/AI15 | AO15: =AK15/P15 | AP15: 0 | AQ15: =AP15/W15 | AR15: =AP15/AK15 | AS15: 0
A16: 46005 | B16: 星期日 | D16: 59.99 | E16: 0 | F16: 0 | G16: 0 | H16: =D16*(1-F16)*(1-G16) | I16: - | J16: - | K16: ='法国ERP数据'!BC15 | L16: ='法国ERP数据'!BA15 | M16: =K16+L16 | N16: =IFERROR(Q16/M16,0) | O16: =P16-AK16 | P16: =Q16-U16-BC16 | Q16: ='法国ERP数据'!R15 | S16: ='法国ERP数据'!Z15 | T16: 0 | U16: 0 | V16: 0 | W16: 0 | AF16: 1 | AG16: 4 | AH16: 0 | AI16: 0 | AJ16: =AI16/AH16 | AK16: 0 | AL16: =AP16/AI16 | AM16: =AP16/AS16 | AN16: =AK16/AI16 | AO16: =AK16/P16 | AP16: 0 | AQ16: =AP16/W16 | AR16: =AP16/AK16 | AS16: 0
A17: 46006 | B17: 星期一 | D17: 59.99 | E17: 0 | F17: 0 | G17: 0 | H17: =D17*(1-F17)*(1-G17) | I17: - | J17: - | K17: ='法国ERP数据'!BC16 | L17: ='法国ERP数据'!BA16 | M17: =K17+L17 | N17: =IFERROR(Q17/M17,0) | O17: =P17-AK17 | P17: =Q17-U17-BC17 | Q17: ='法国ERP数据'!R16 | S17: ='法国ERP数据'!Z16 | T17: 0 | U17: 0 | V17: 0 | W17: 0 | AF17: 1 | AG17: 4 | AH17: 0 | AI17: 0 | AJ17: =AI17/AH17 | AK17: 0 | AL17: =AP17/AI17 | AM17: =AP17/AS17 | AN17: =AK17/AI17 | AO17: =AK17/P17 | AP17: 0 | AQ17: =AP17/W17 | AR17: =AP17/AK17 | AS17: 0
A18: 46007 | B18: 星期二 | D18: 59.99 | E18: 0 | F18: 0 | G18: 0 | H18: =D18*(1-F18)*(1-G18) | I18: - | J18: - | K18: ='法国ERP数据'!BC17 | L18: ='法国ERP数据'!BA17 | M18: =K18+L18 | N18: =IFERROR(Q18/M18,0) | O18: =P18-AK18 | P18: =Q18-U18-BC18 | Q18: ='法国ERP数据'!R17 | S18: ='法国ERP数据'!Z17 | T18: 0 | U18: 0 | V18: 0 | W18: 0 | AF18: 1 | AG18: 4 | AH18: 0 | AI18: 0 | AJ18: =AI18/AH18 | AK18: 0 | AL18: =AP18/AI18 | AM18: =AP18/AS18 | AN18: =AK18/AI18 | AO18: =AK18/P18 | AP18: 0 | AQ18: =AP18/W18 | AR18: =AP18/AK18 | AS18: 0
A19: 46008 | B19: 星期三 | D19: 59.99 | E19: 0 | F19: 0 | G19: 0 | H19: =D19*(1-F19)*(1-G19) | I19: - | J19: - | K19: ='法国ERP数据'!BC18 | L19: ='法国ERP数据'!BA18 | M19: =K19+L19 | N19: =IFERROR(Q19/M19,0) | O19: =P19-AK19 | P19: =Q19-U19-BC19 | Q19: ='法国ERP数据'!R18 | S19: ='法国ERP数据'!Z18 | T19: 0 | U19: 0 | V19: 0 | W19: 0 | AF19: 1 | AG19: 4 | AH19: 0 | AI19: 0 | AJ19: =AI19/AH19 | AK19: 0 | AL19: =AP19/AI19 | AM19: =AP19/AS19 | AN19: =AK19/AI19 | AO19: =AK19/P19 | AP19: 0 | AQ19: =AP19/W19 | AR19: =AP19/AK19 | AS19: 0
A20: 46009 | B20: 星期四 | D20: 59.99 | E20: 0 | F20: 0 | G20: 0 | H20: =D20*(1-F20)*(1-G20) | I20: - | J20: - | K20: ='法国ERP数据'!BC19 | L20: ='法国ERP数据'!BA19 | M20: =K20+L20 | N20: =IFERROR(Q20/M20,0) | O20: =P20-AK20 | P20: =Q20-U20-BC20 | Q20: ='法国ERP数据'!R19 | S20: ='法国ERP数据'!Z19 | T20: 0 | U20: 0 | V20: 0 | W20: 0 | AF20: 1 | AG20: 4 | AH20: 0 | AI20: 0 | AJ20: =AI20/AH20 | AK20: 0 | AL20: =AP20/AI20 | AM20: =AP20/AS20 | AN20: =AK20/AI20 | AO20: =AK20/P20 | AP20: 0 | AQ20: =AP20/W20 | AR20: =AP20/AK20 | AS20: 0
A21: 46010 | B21: 星期五 | D21: 59.99 | E21: 0 | F21: 0 | G21: 0 | H21: =D21*(1-F21)*(1-G21) | I21: - | J21: - | K21: ='法国ERP数据'!BC20 | L21: ='法国ERP数据'!BA20 | M21: =K21+L21 | N21: =IFERROR(Q21/M21,0) | O21: =P21-AK21 | P21: =Q21-U21-BC21 | Q21: ='法国ERP数据'!R20 | S21: ='法国ERP数据'!Z20 | T21: 0 | U21: 0 | V21: 0 | W21: 0 | AF21: 1 | AG21: 4 | AH21: 0 | AI21: 0 | AJ21: =AI21/AH21 | AK21: 0 | AL21: =AP21/AI21 | AM21: =AP21/AS21 | AN21: =AK21/AI21 | AO21: =AK21/P21 | AP21: 0 | AQ21: =AP21/W21 | AR21: =AP21/AK21 | AS21: 0
... A47: 46036 | B47: 星期三 | D47: 59.99 | E47: 0 | F47: 0 | G47: 0 | H47: =D47*(1-F47)*(1-G47) | I47: - | J47: - | K47: ='法国ERP数据'!BC46 | L47: ='法国ERP数据'!BA46 | M47: =K47+L47 | N47: =IFERROR(Q47/M47,0) | O47: =P47-AK47 | P47: =Q47-U47-BC47 | Q47: ='法国ERP数据'!R46 | S47: ='法国ERP数据'!Z46 | T47: 0 | U47: 0 | V47: 0 | W47: 0 | AF47: 1 | AG47: 4 | AH47: 0 | AI47: 0 | AJ47: =AI47/AH47 | AK47: 0 | AL47: =AP47/AI47 | AM47: =AP47/AS47 | AN47: =AK47/AI47 | AO47: =AK47/P47 | AP47: 0 | AQ47: =AP47/W47 | AR47: =AP47/AK47 | AS47: 0
A48: 46037 | B48: 星期四 | S48: ='法国ERP数据'!Z47
A49: 46038 | B49: 星期五 | S49: ='法国ERP数据'!Z48
A50: 46039 | B50: 星期六 | S50: ='法国ERP数据'!Z49
A51: 46040 | B51: 星期日 | S51: ='法国ERP数据'!Z50
A52: 46041 | B52: 星期一 | S52: ='法国ERP数据'!Z51
A53: 46042 | B53: 星期二 | S53: ='法国ERP数据'!Z52
A54: 46043 | B54: 星期三 | S54: ='法国ERP数据'!Z53
A55: 46044 | B55: 星期四 | S55: ='法国ERP数据'!Z54
A56: 46045 | B56: 星期五 | S56: ='法国ERP数据'!Z55
A57: 46046 | B57: 星期六 | S57: ='法国ERP数据'!Z56
A58: 46047 | B58: 星期日 | S58: ='法国ERP数据'!Z57
A59: 46048 | B59: 星期一 | S59: ='法国ERP数据'!Z58
... A161: 46150 | B161: 星期五 | S161: ='法国ERP数据'!Z160
A162: 46151 | D162: 39.99 | M162: =SUM(M44:M92) | N162: 0.1746 | O162: =SUM(O44:O92) | P162: =SUM(P44:P92) | Q162: =SUM(Q44:Q92) | S162: ='法国ERP数据'!Z161 | X162: =SUM(X44:X92) | AH162: =SUM(AH44:AH92) | AI162: =SUM(AI44:AI92) | AJ162: =AI162/AH162 | AK162: =SUM(AK44:AK92) | AL162: =AI162/AP162 | AM162: =AP162/(AK162*D162) | AN162: =AK162/AI162 | AO162: =AK162/P162 | AP162: =SUM(AP44:AP92) | AQ162: =AP162/X162 | AS162: =AP162/AK162 | AW162: =SUM(AW44:AW92) | AX162: =AW162/X162 | AZ162: =SUM(AZ44:AZ92) | BB162: =SUM(BB44:BB92) | BC162: =SUM(BC44:BC92) | BF162: =M162-AI162 | BG162: =O162/BF162

Sheet SC定价表
A1: VC活动价 | B1: 汇率 | C1: 报价比例 | D1: 售价欧元 含税 | E1: 售价欧元 不含税 | F1: 报价欧元 不含税 | G1: 采购价 | H1: 头程 | I1: 国内总成本 | J1: 装箱数量 | K1: 移仓费/个 | L1: 换标费 0/个 | M1: 入库费/箱/0/ | N1: 装箱费 /箱 | O1: 箱唛 0/张/箱 | P1: 出库费 0/箱 | Q1: 二程运费 7.5/箱 | R1: 入库总费用 | S1: 入库单个费用rmb | T1: 利润P0 | U1: 回款扣点 | V1: 广告费占比 | W1: 广告费 | X1: 活动促销比例 | Y1: 活动促销/欧元 | Z1: 最低活动价/欧元 不含税 | AA1: 最低活动价/欧元 含税 | AB1: 利润P3 | AC1: P1--VC | AD1: P1--SC | AE1: P3对应的投资回报率=P3/国内成本 | AF1: 国内成本占比 | AG1: 一期回款金额70%/美金 | AI1: 一期回款毛利P2=回款-国内总成本-海外仓费用 | AK1: 一期回款比例=一期回款/商品成本 | AL1: 一期回款比例=一期回款/（国内+海外仓） | AM1: 一期投资回报=70^%部分的毛利/成本 | AN1: 营销费/cost
A2: 德国空净100卡航 | B2: 7.4 | C2: 0.8632 | D2: 119.99 | E2: =D2*0.84 | F2: =E2*C2 | G2: =138.5/1.13 | H2: 67.7 | I2: =SUM(G2:H2) | J2: 4 | K2: 0 | L2: 0 | M2: 0 | N2: 0 | O2: 0 | P2: 0 | Q2: 7.5 | R2: =SUM(M2:Q2)+(K2+L2)*J2 | S2: =R2/J2*B2 | T2: =F2*B2-I2-S2 | U2: 0.02 | V2: 0.15 | W2: =D2*V2*B2 | X2: 0.15 | Y2: =D2*X2 | Z2: =D2-Y2 | AA2: =Z2/0.84 | AB2: =T2-F2*U2*B2-W2-Y2*B2 | AC2: =AB2/(F2*B2) | AD2: =AB2/(E2*B2) | AE2: =AB2/I2 | AF2: =I2/B2/F2 | AG2: =F2*0.7 | AI2: =AG2*B2-S2-I2 | AK2: =AG2*B2/I2 | AL2: =AG2*B2/(I2+S2) | AM2: =AI2/I2 | AN2: =(W2/B2+Y2)/F2
A3: 德国空净100铁路 | B3: 7.4 | C3: 0.8632 | D3: 119.99 | E3: =D3*0.84 | F3: =E3*C3 | G3: =138.5/1.13 | H3: 43.22 | I3: =SUM(G3:H3) | J3: 4 | K3: 0 | L3: 0 | M3: 0 | N3: 0 | O3: 0 | P3: 0 | Q3: 7.5 | R3: =SUM(M3:Q3)+(K3+L3)*J3 | S3: =R3/J3*B3 | T3: =F3*B3-I3-S3 | U3: 0.02 | V3: 0.15 | W3: =D3*V3*B3 | X3: 0.15 | Y3: =D3*X3 | Z3: =D3-Y3 | AA3: =Z3/0.84 | AB3: =T3-F3*U3*B3-W3-Y3*B3 | AC3: =AB3/(F3*B3) | AD3: =AB3/(E3*B3) | AE3: =AB3/I3 | AF3: =I3/B3/F3 | AG3: =F3*0.7 | AI3: =AG3*B3-S3-I3 | AK3: =AG3*B3/I3 | AL3: =AG3*B3/(I3+S3) | AM3: =AI3/I3 | AN3: =(W3/B3+Y3)/F3
A4: 德国空净100海运 | B4: 7.4 | C4: 0.8632 | D4: 119.99 | E4: =D4*0.84 | F4: =E4*C4 | G4: =138.5/1.13 | H4: 20.54 | I4: =SUM(G4:H4) | J4: 4 | K4: 0 | L4: 0 | M4: 0 | N4: 0 | O4: 0 | P4: 0 | Q4: 7.5 | R4: =SUM(M4:Q4)+(K4+L4)*J4 | S4: =R4/J4*B4 | T4: =F4*B4-I4-S4 | U4: 0.02 | V4: 0.15 | W4: =D4*V4*B4 | X4: 0.15 | Y4: =D4*X4 | Z4: =D4-Y4 | AA4: =Z4/0.84 | AB4: =T4-F4*U4*B4-W4-Y4*B4 | AC4: =AB4/(F4*B4) | AD4: =AB4/(E4*B4) | AE4: =AB4/I4 | AF4: =I4/B4/F4 | AG4: =F4*0.7 | AI4: =AG4*B4-S4-I4 | AK4: =AG4*B4/I4 | AL4: =AG4*B4/(I4+S4) | AM4: =AI4/I4 | AN4: =(W4/B4+Y4)/F4
A6: SC站内推广 | B6: 汇率 | C6: 国家 | D6: 国家代码 | E6: 有无VAT | F6: 成本价(0边利) | G6: 建议价(20%边利) | H6: 实际定价 | I6: 采购价 | J6: FBA Fee | K6: 佣金比例 | L6: VAT | M6: 预估退货率 | N6: 推广费率 | O6: FBA仓储费 | P6: 其他费用 | Q6: 长 | R6: 宽 | S6: 高 | T6: 包装后实重 | U6: 体积重 | V6: 计费重 | W6: 运输方式 | X6: 运费单价 | Y6: 运费 | Z6: 利润/欧元 | AA6: 利润率/欧元
A7: 德国空净100日常价走海运 | B7: 7.4 | C7: DE | D7: DE | E7: 有 | F7: =IF(E7="有",(I7/B7+J7+Y7/B7)/(0.99999-K7-L7-M7-N7),(I7/B7+J7+Y7/B7)/(0.99999-K7-M7-N7)) | G7: =IF(E7="有",(I7/B7+J7+Y7/B7)/(0.8-K7-L7-M7-N7-O7-P7),(I7/B7+J7+Y7/B7)/(0.8-K7-M7-N7-O7-P7)) | H7: 129.99 | I7: 122.57 | J7: 5.69 | K7: 0.15 | L7: 0.16 | M7: 0.07 | N7: 0.15 | O7: =0.61/H7 | P7: 0.02 | Q7: 33.5 | R7: 26.5 | S7: 25 | T7: 2.3 | U7: =Q7*R7*S7/6000 | V7: =MAX(T7:U7) | W7: 海运 | X7: 5.55254 | Y7: =V7*X7 | Z7: =H7-SUM(K7:P7)*H7-J7-I7/B7-Y7/B7 | AA7: =Z7/H7
A8: 德国空净100活动价走海运 | B8: 7.4 | C8: DE | D8: DE | E8: 有 | F8: =IF(E8="有",(I8/B8+J8+Y8/B8)/(0.99999-K8-L8-M8-N8),(I8/B8+J8+Y8/B8)/(0.99999-K8-M8-N8)) | G8: =IF(E8="有",(I8/B8+J8+Y8/B8)/(0.8-K8-L8-M8-N8-O8-P8),(I8/B8+J8+Y8/B8)/(0.8-K8-M8-N8-O8-P8)) | H8: 119.99 | I8: 122.57 | J8: 5.69 | K8: 0.15 | L8: 0.16 | M8: 0.07 | N8: 0.15 | O8: =0.61/H8 | P8: 0.02 | Q8: 33.5 | R8: 26.5 | S8: 25 | T8: 2.3 | U8: =Q8*R8*S8/6000 | V8: =MAX(T8:U8) | W8: 海运 | X8: 5.55254 | Y8: =V8*X8 | Z8: =H8-SUM(K8:P8)*H8-J8-I8/B8-Y8/B8 | AA8: =Z8/H8
A9: 德国空净100最底价走海运 | B9: 7.4 | C9: DE | D9: DE | E9: 有 | F9: =IF(E9="有",(I9/B9+J9+Y9/B9)/(0.99999-K9-L9-M9-N9),(I9/B9+J9+Y9/B9)/(0.99999-K9-M9-N9)) | G9: =IF(E9="有",(I9/B9+J9+Y9/B9)/(0.8-K9-L9-M9-N9-O9-P9),(I9/B9+J9+Y9/B9)/(0.8-K9-M9-N9-O9-P9)) | H9: 109.99 | I9: 122.57 | J9: 5.69 | K9: 0.15 | L9: 0.16 | M9: 0.07 | N9: 0.15 | O9: =0.61/H9 | P9: 0.02 | Q9: 33.5 | R9: 26.5 | S9: 25 | T9: 2.3 | U9: =Q9*R9*S9/6000 | V9: =MAX(T9:U9) | W9: 海运 | X9: 5.55254 | Y9: =V9*X9 | Z9: =H9-SUM(K9:P9)*H9-J9-I9/B9-Y9/B9 | AA9: =Z9/H9
A11: 德国空净100最底价走铁路 | B11: 7.4 | C11: DE | D11: DE | E11: 有 | F11: =IF(E11="有",(I11/B11+J11+Y11/B11)/(0.99999-K11-L11-M11-N11),(I11/B11+J11+Y11/B11)/(0.99999-K11-M11-N11)) | G11: =IF(E11="有",(I11/B11+J11+Y11/B11)/(0.8-K11-L11-M11-N11-O11-P11),(I11/B11+J11+Y11/B11)/(0.8-K11-M11-N11-O11-P11)) | H11: 119.99 | I11: 122.57 | J11: 5.69 | K11: 0.15 | L11: 0.16 | M11: 0.07 | N11: 0.15 | O11: =0.61/H11 | P11: 0.02 | Q11: 33.5 | R11: 26.5 | S11: 25 | T11: 2.3 | U11: =Q11*R11*S11/6000 | V11: =MAX(T11:U11) | W11: 铁路 | X11: 11.68408 | Y11: =V11*X11 | Z11: =H11-SUM(K11:P11)*H11-J11-I11/B11-Y11/B11 | AA11: =Z11/H11
A12: 德国空净100最底价走铁路 | B12: 7.4 | C12: DE | D12: DE | E12: 有 | F12: =IF(E12="有",(I12/B12+J12+Y12/B12)/(0.99999-K12-L12-M12-N12),(I12/B12+J12+Y12/B12)/(0.99999-K12-M12-N12)) | G12: =IF(E12="有",(I12/B12+J12+Y12/B12)/(0.8-K12-L12-M12-N12-O12-P12),(I12/B12+J12+Y12/B12)/(0.8-K12-M12-N12-O12-P12)) | H12: 114.99 | I12: 122.57 | J12: 5.69 | K12: 0.15 | L12: 0.16 | M12: 0.07 | N12: 0.15 | O12: =0.61/H12 | P12: 0.02 | Q12: 33.5 | R12: 26.5 | S12: 25 | T12: 2.3 | U12: =Q12*R12*S12/6000 | V12: =MAX(T12:U12) | W12: 铁路 | X12: 11.68408 | Y12: =V12*X12 | Z12: =H12-SUM(K12:P12)*H12-J12-I12/B12-Y12/B12 | AA12: =Z12/H12
A13: 德国空净100最底价走铁路 | B13: 7.4 | C13: DE | D13: DE | E13: 有 | F13: =IF(E13="有",(I13/B13+J13+Y13/B13)/(0.99999-K13-L13-M13-N13),(I13/B13+J13+Y13/B13)/(0.99999-K13-M13-N13)) | G13: =IF(E13="有",(I13/B13+J13+Y13/B13)/(0.8-K13-L13-M13-N13-O13-P13),(I13/B13+J13+Y13/B13)/(0.8-K13-M13-N13-O13-P13)) | H13: 109.99 | I13: 122.57 | J13: 5.69 | K13: 0.15 | L13: 0.16 | M13: 0.07 | N13: 0.15 | O13: =0.61/H13 | P13: 0.02 | Q13: 33.5 | R13: 26.5 | S13: 25 | T13: 2.3 | U13: =Q13*R13*S13/6000 | V13: =MAX(T13:U13) | W13: 铁路 | X13: 11.68408 | Y13: =V13*X13 | Z13: =H13-SUM(K13:P13)*H13-J13-I13/B13-Y13/B13 | AA13: =Z13/H13
A16: 站外推广 | B16: 汇率 | C16: 国家 | D16: 国家代码 | E16: 有无VAT | F16: 成本价(0边利) | G16: 建议价(20%边利) | H16: 实际定价 | I16: 采购价 | J16: FBA Fee | K16: 佣金比例 | L16: VAT | M16: 预估退货率 | N16: 折扣力度 | O16: FBA仓储费 | P16: 其他费用 | Q16: 长 | R16: 宽 | S16: 高 | T16: 包装后实重 | U16: 体积重 | V16: 计费重 | W16: 运输方式 | X16: 运费单价 | Y16: 运费 | Z16: 利润/欧元 | AA16: 利润率/欧元
A17: 除螨仪站外 | B17: 7.4 | C17: DE | D17: DE | E17: 有 | F17: =I17/B17+J17+Y17/B17+(H17*(1-N17)*(K17+M17+O17+P17)) | G17: =(I17/B17+J17+Y17/B17+(H17*(1-N17)*(K17+M17+O17+P17)))/0.8 | H17: 129.99 | I17: 122.57 | J17: 5.69 | K17: 0.15 | L17: 0.16 | M17: 0.07 | N17: 0.6 | O17: =0.02/H17 | P17: 0.02 | Q17: 33.5 | R17: 26.5 | S17: 25 | T17: 2.3 | U17: =Q17*R17*S17/6000 | V17: =MAX(T17:U17) | W17: 铁路 | X17: 14.65 | Y17: =V17*X17 | Z17: =(H17*(1-N17))-I17/B17-J17-Y17/B17-(K17+M17+O17+P17)*(H17*(1-N17)) | AA17: =Z17/H17
AB18: 国家 | AC18: 二程费用 | AD18: 二程*销量占比 | AE18: 佣金 | AF18: 销量占比 | AH18: 佣金*销量占比 | AI18: 百分百-佣金，报价 | AJ18: 整箱 | AK18: 单个产品
A20: Woot美国 | B20: 汇率 | C20: 报价比例 | D20: 国家代码 | E20: 售价欧元 | F20: 报价欧元 | G20: 采购价 | H20: 头程 | I20: 国内总成本 | J20: 广告费占比 | K20: 广告费 | L20: 利润/RMB | M20: Woot利润率 | N20: 活动价 | AB20: 德国DHL | AC20: 7.5 | AD20: =AC20*AF20 | AE20: 0.1695 | AF20: 0.3 | AG20: 0.0509 | AH20: =AE20*AF20 | AI20: =100%-AE20
A21: 除螨仪 | B21: 7.4 | C21: 0.44 | D21: / | E21: 129.99 | F21: =E21*C21 | G21: 122.57 | H21: 5.69 | I21: =SUM(G21:H21) | J21: 0.15 | K21: =E21*B21*J21 | L21: =F21*B21-I21-K21 | M21: =L21/(E21*B21) | N21: =E21*C21 | AB21: 法国 | AC21: 14 | AD21: =AC21*AF21 | AE21: 0.198 | AF21: 0.2 | AG21: 0.0396 | AH21: =AE21*AF21 | AI21: =100%-AE21
AB22: 意大利 | AC22: 15 | AD22: =AC22*AF22 | AE22: 0.1846 | AF22: 0.15 | AG22: 0.0277 | AH22: =AE22*AF22 | AI22: =100%-AE22
AB23: 西班牙 | AC23: 19 | AD23: =AC23*AF23 | AE23: 0.1646 | AF23: 0.1 | AG23: 0.0165 | AH23: =AE23*AF23 | AI23: =100%-AE23
AB24: 波兰 | AC24: 13.8 | AD24: =AC24*AF24 | AE24: 0.158 | AF24: 0.1 | AG24: 0.0158 | AH24: =AE24*AF24 | AI24: =100%-AE24
AB25: 捷克 | AC25: 12.8 | AD25: =AC25*AF25 | AE25: 0.158 | AF25: 0.15 | AG25: 0.0237 | AH25: =AE25*AF25 | AI25: =100%-AE25
AB26: 英国 | AC26: 7.6 | AD26: =AC26*AF26 | AE26: 0.158 | AF26: 0.05 | AG26: 0.0237 | AH26: 0.0237 | AI26: =100%-AE26
P33: V

Sheet VC定价表
A1: 站点 | B1: SKU | C1: ASIN | D1: 产品名称 | E1: Brand | F1: 原PO售价 外币 | G1: 原建议售价(含税) 亚马逊售价-外币 | H1: 后台PO价 | I1: 对比 PO价 | J1: PO售价 外币 | K1: 建议售价(含税) 亚马逊售价-外币 | L1: 毛利 外币 | M1: 毛利率 | N1: 建议售价 不含税外币 | O1: Profit Margin (%) | P1: 亚马逊毛利 外币 | Q1: 成本 | R1: 二程外币 | S1: 装箱数 | T1: 汇率 | U1: 广告 占比 | V1: 前台广告 占比 | W1: 促销 占比 | X1: 其他 占比 | Y1: 成本 占比 | Z1: 尾程 占比 | AA1: 佣金 占比 | AB1: 广告 外币 | AC1: 促销 外币 | AD1: 其它 外币 | AE1: 佣金 外币 | AF1: 采购成本 ¥含税 | AG1: 采购成本 ¥不含税 | AH1: 头程 欧元 | AI1: 采购占比 | AJ1: 头程占比 | AK1: 头程 RMB | AL1: NET PPM | AM1: 说明 | AN1: 佣金 占比 | AO1: 2025年 3月 | AP1: 4月 | AQ1: 5月 | AR1: 6月 | AS1: 7月 | AT1: 8月 | AU1: 9月 | AV1: 10月 | AW1: 11月 | AX1: 12月 | AY1: 24年 1月 | AZ1: 2月 | BA1: 3月 | BB1: 4月 | BC1: 5月 | BD1: 6月 | BE1: 7月 | BF1: 8月 | BG1: 9月 | BH1: 10月 | BI1: 11月 | BJ1: 12月 | BK1: 25年 1月 | BL1: 2月 | BM1: 3月 | BN1: 4月 | BO1: 5月 | BP1: 6月 | BQ1: 7月 | BR1: 8月 | BS1: 9月 | BT1: 10月 | BU1: 11月 | BV1: 12月 | BW1: PO价 监控 | BX1: 运营
A2: UK | B2: R0001UK | C2: B0F1F535PC | D2: 空净100P英国灰色 | E2: HYCHIKA | F2: 87 | G2: =K2 | H2: =INDEX(#NULL!,MATCH(1,(#NULL!=A2)*(#NULL!=C2),0)) | I2: =H2=J2 | J2: 87 | K2: 119.99 | L2: =J2-Q2/T2-AE2-AB2-R2-AC2-AD2 | M2: =L2/J2 | N2: =K2/1.2 | O2: =(N2-J2)/N2 | P2: =K2/1.2-J2 | Q2: =AG2+AH2 | R2: =IFERROR(IF(A2="UK",8.95/S2,IF(A2="DE",11.43/S2,IF(A2="FR",15.27/S2,IF(A2="IT",16.34/S2,IF(A2="ES",20.62/S2,IF(A2="NL",12/S2,IF(A2="PL",15.06/S2,IF(A2="SE",18.5/S2,IF(A2="BE",15.27/S2))))))))),0) | S2: 4 | T2: 8.5 | U2: 0.1 | V2: =AB2/K2 | W2: 0.15 | X2: 0.01 | Y2: =Q2/(J2*T2) | Z2: =R2/J2 | AA2: 0.158 | AB2: =J2*U2 | AC2: =J2*W2 | AD2: =J2*X2 | AE2: =J2*AA2 | AF2: 138.5 | AG2: =AF2/1.13 | AH2: =49.7/8.5 | AI2: =AG2/(J2*T2) | AJ2: =AH2/T2/J2 | AK2: 54.2 | AL2: =(N2-J2+AE2-AC2)/N2 | AM2: (N2-J2+AE2-AC2)/N2 | AN2: UK是15.80% | AY2: ☆ | AZ2: ☆ | BA2: ☆ | BB2: ☆ | BC2: ☆ | BD2: ☆ | BE2: ☆ | BF2: ☆ | BG2: ☆ | BH2: ☆ | BI2: ☆ | BJ2: ☆ | BK2: ☆ | BL2: ☆ | BM2: ☆ | BN2: ☆ | BO2: ☆ | BP2: ☆ | BQ2: ☆ | BR2: ☆ | BS2: ☆ | BT2: ☆ | BU2: ☆ | BV2: ☆ | BX2: #VALUE!
A3: DE | B3: R0001EU | C3: B0F1F7J8V3 | D3: 空净100P德国灰色 | E3: HYCHIKA | F3: 87 | G3: =K3 | H3: =INDEX(#NULL!,MATCH(1,(#NULL!=A3)*(#NULL!=C3),0)) | I3: =H3=J3 | J3: 87 | K3: 119.99 | L3: =J3-Q3/T3-AE3-AB3-R3-AC3-AD3 | M3: =L3/J3 | N3: =K3/1.2 | O3: =(N3-J3)/N3 | P3: =K3/1.2-J3 | Q3: =AG3+AH3 | R3: =IFERROR(IF(A3="UK",8.95/S3,IF(A3="DE",11.43/S3,IF(A3="FR",15.27/S3,IF(A3="IT",16.34/S3,IF(A3="ES",20.62/S3,IF(A3="NL",12/S3,IF(A3="PL",15.06/S3,IF(A3="SE",18.5/S3,IF(A3="BE",15.27/S3))))))))),0) | S3: 4 | T3: 7.4 | U3: 0.1 | V3: =AB3/K3 | W3: 0.15 | X3: 0.01 | Y3: =Q3/(J3*T3) | Z3: =R3/J3 | AA3: 0.1695 | AB3: =J3*U3 | AC3: =J3*W3 | AD3: =J3*X3 | AE3: =J3*AA3 | AF3: 138.5 | AG3: =AF3/1.13 | AH3: =49.7/7.4 | AI3: =AG3/(J3*T3) | AJ3: =AH3/T3/J3 | AK3: 54.2 | AL3: =(N3-J3+AE3-AC3)/N3 | AM3: （建议售价 不含税外币-PO售价外币+佣金外币-促销外币）/建议售价 不含税外币 | AN3: DE是16.95% | AY3: ☆ | AZ3: ☆ | BA3: ☆ | BB3: ☆ | BC3: ☆ | BD3: ☆ | BE3: ☆ | BF3: ☆ | BG3: ☆ | BH3: ☆ | BI3: ☆ | BJ3: ☆ | BK3: ☆ | BL3: ☆ | BM3: ☆ | BN3: ☆ | BO3: ☆ | BP3: ☆ | BQ3: ☆ | BR3: ☆ | BS3: ☆ | BT3: ☆ | BU3: ☆ | BV3: ☆ | BX3: #VALUE!
A4: FR | B4: R0001EU | C4: B0F1F7J8V3 | D4: 空净100P法国灰色 | E4: HYCHIKA | F4: 87 | G4: =K4 | H4: =INDEX(#NULL!,MATCH(1,(#NULL!=A4)*(#NULL!=C4),0)) | I4: =H4=J4 | J4: 87 | K4: 119.99 | L4: =J4-Q4/T4-AE4-AB4-R4-AC4-AD4 | M4: =L4/J4 | N4: =K4/1.2 | O4: =(N4-J4)/N4 | P4: =K4/1.2-J4 | Q4: =AG4+AH4 | R4: =IFERROR(IF(A4="UK",8.95/S4,IF(A4="DE",11.43/S4,IF(A4="FR",15.27/S4,IF(A4="IT",16.34/S4,IF(A4="ES",20.62/S4,IF(A4="NL",12/S4,IF(A4="PL",15.06/S4,IF(A4="SE",18.5/S4,IF(A4="BE",15.27/S4))))))))),0) | S4: 4 | T4: 7.4 | U4: 0.1 | V4: =AB4/K4 | W4: 0.05 | X4: 0.01 | Y4: =Q4/(J4*T4) | Z4: =R4/J4 | AA4: 0.198 | AB4: =J4*U4 | AC4: =J4*W4 | AD4: =J4*X4 | AE4: =J4*AA4 | AF4: 138.5 | AG4: =AF4/1.13 | AH4: =49.7/7.4 | AI4: =AG4/(J4*T4) | AJ4: =AH4/T4/J4 | AK4: 54.2 | AL4: =(N4-J4+AE4-AC4)/N4 | AM4: (不含税MSRP-COST+佣金-促销)/不含税MSRP | AN4: FR是19.80% | AY4: ☆ | AZ4: ☆ | BA4: ☆ | BB4: ☆ | BC4: ☆ | BD4: ☆ | BE4: ☆ | BF4: ☆ | BG4: ☆ | BH4: ☆ | BI4: ☆ | BJ4: ☆ | BK4: ☆ | BL4: ☆ | BM4: ☆ | BN4: ☆ | BO4: ☆ | BP4: ☆ | BQ4: ☆ | BR4: ☆ | BS4: ☆ | BT4: ☆ | BU4: ☆ | BV4: ☆ | BX4: #VALUE!
A5: IT | B5: R0001EU | C5: B0F1F7J8V3 | D5: 空净100P意大利灰 | E5: HYCHIKA | F5: 87 | G5: =K5 | H5: =INDEX(#NULL!,MATCH(1,(#NULL!=A5)*(#NULL!=C5),0)) | I5: =H5=J5 | J5: 87 | K5: 119.99 | L5: =J5-Q5/T5-AE5-AB5-R5-AC5-AD5 | M5: =L5/J5 | N5: =K5/1.2 | O5: =(N5-J5)/N5 | P5: =K5/1.2-J5 | Q5: =AG5+AH5 | R5: =IFERROR(IF(A5="UK",8.95/S5,IF(A5="DE",11.43/S5,IF(A5="FR",15.27/S5,IF(A5="IT",16.34/S5,IF(A5="ES",20.62/S5,IF(A5="NL",12/S5,IF(A5="PL",15.06/S5,IF(A5="SE",18.5/S5,IF(A5="BE",15.27/S5))))))))),0) | S5: 4 | T5: 7.4 | U5: 0.1 | V5: =AB5/K5 | W5: 0.05 | X5: 0.01 | Y5: =Q5/(J5*T5) | Z5: =R5/J5 | AA5: 0.1846 | AB5: =J5*U5 | AC5: =J5*W5 | AD5: =J5*X5 | AE5: =J5*AA5 | AF5: 138.5 | AG5: =AF5/1.13 | AH5: =49.7/7.4 | AI5: =AG5/(J5*T5) | AJ5: =AH5/T5/J5 | AK5: 54.2 | AL5: =(N5-J5+AE5-AC5)/N5 | AM5: {(不含税MSRP-COST+COST*佣金占比-COST*促销占比)/不含税MSRP} | AN5: IT是18.46% | AY5: ☆ | AZ5: ☆ | BA5: ☆ | BB5: ☆ | BC5: ☆ | BD5: ☆ | BE5: ☆ | BF5: ☆ | BG5: ☆ | BH5: ☆ | BI5: ☆ | BJ5: ☆ | BK5: ☆ | BL5: ☆ | BM5: ☆ | BN5: ☆ | BO5: ☆ | BP5: ☆ | BQ5: ☆ | BR5: ☆ | BS5: ☆ | BT5: ☆ | BU5: ☆ | BV5: ☆ | BX5: #VALUE!
A6: ES | B6: R0001EU | C6: B0F1F7J8V3 | D6: 空净100P西班牙灰 | E6: HYCHIKA | F6: 87 | G6: =K6 | H6: =INDEX(#NULL!,MATCH(1,(#NULL!=A6)*(#NULL!=C6),0)) | I6: =H6=J6 | J6: 87 | K6: 119.99 | L6: =J6-Q6/T6-AE6-AB6-R6-AC6-AD6 | M6: =L6/J6 | N6: =K6/1.2 | O6: =(N6-J6)/N6 | P6: =K6/1.2-J6 | Q6: =AG6+AH6 | R6: =IFERROR(IF(A6="UK",8.95/S6,IF(A6="DE",11.43/S6,IF(A6="FR",15.27/S6,IF(A6="IT",16.34/S6,IF(A6="ES",20.62/S6,IF(A6="NL",12/S6,IF(A6="PL",15.06/S6,IF(A6="SE",18.5/S6,IF(A6="BE",15.27/S6))))))))),0) | S6: 4 | T6: 7.4 | U6: 0.1 | V6: =AB6/K6 | W6: 0.05 | X6: 0.01 | Y6: =Q6/(J6*T6) | Z6: =R6/J6 | AA6: 0.1646 | AB6: =J6*U6 | AC6: =J6*W6 | AD6: =J6*X6 | AE6: =J6*AA6 | AF6: 138.5 | AG6: =AF6/1.13 | AH6: =49.7/7.4 | AI6: =AG6/(J6*T6) | AJ6: =AH6/T6/J6 | AK6: 54.2 | AL6: =(N6-J6+AE6-AC6)/N6 | AM6: COST就是PO不含税售价 外币 不含税价 | AN6: ES是16.46% | AY6: ☆ | AZ6: ☆ | BA6: ☆ | BB6: ☆ | BC6: ☆ | BD6: ☆ | BE6: ☆ | BF6: ☆ | BG6: ☆ | BH6: ☆ | BI6: ☆ | BJ6: ☆ | BK6: ☆ | BL6: ☆ | BM6: ☆ | BN6: ☆ | BO6: ☆ | BP6: ☆ | BQ6: ☆ | BR6: ☆ | BS6: ☆ | BT6: ☆ | BU6: ☆ | BV6: ☆ | BX6: #VALUE!
A7: NL | B7: R0001EU | C7: B0F1F7J8V3 | D7: 空净100P荷兰灰色 | E7: HYCHIKA | F7: 97.09 | G7: =K7 | H7: =INDEX(#NULL!,MATCH(1,(#NULL!=A7)*(#NULL!=C7),0)) | I7: =H7=J7 | J7: 97.09 | K7: 135.99 | L7: =J7-Q7/T7-AE7-AB7-R7-AC7-AD7 | M7: =L7/J7 | N7: =K7/1.2 | O7: =(N7-J7)/N7 | P7: =K7/1.2-J7 | Q7: =AG7+AH7 | R7: =IFERROR(IF(A7="UK",8.95/S7,IF(A7="DE",11.43/S7,IF(A7="FR",15.27/S7,IF(A7="IT",16.34/S7,IF(A7="ES",20.62/S7,IF(A7="NL",12/S7,IF(A7="PL",15.06/S7,IF(A7="SE",18.5/S7,IF(A7="BE",15.27/S7))))))))),0) | S7: 4 | T7: 7.4 | U7: 0.1 | V7: =AB7/K7 | W7: 0.05 | X7: 0.01 | Y7: =Q7/(J7*T7) | Z7: =R7/J7 | AA7: 0.158 | AB7: =J7*U7 | AC7: =J7*W7 | AD7: =J7*X7 | AE7: =J7*AA7 | AF7: 138.5 | AG7: =AF7/1.13 | AH7: =49.7/7.4 | AI7: =AG7/(J7*T7) | AJ7: =AH7/T7/J7 | AK7: 54.2 | AL7: =(N7-J7+AE7-AC7)/N7 | AM7: COST就是PO不含税售价 外币 不含税价 | AN7: NL是15.80% | AY7: ☆ | AZ7: ☆ | BA7: ☆ | BB7: ☆ | BC7: ☆ | BD7: ☆ | BE7: ☆ | BF7: ☆ | BG7: ☆ | BH7: ☆ | BI7: ☆ | BJ7: ☆ | BK7: ☆ | BL7: ☆ | BM7: ☆ | BN7: ☆ | BO7: ☆ | BP7: ☆ | BQ7: ☆ | BR7: ☆ | BS7: ☆ | BT7: ☆ | BU7: ☆ | BV7: ☆ | BW7: =IF(H7<J7,1,0) | BX7: #VALUE!
A8: PL | B8: R0001EU | C8: B0F1F7J8V3 | D8: 空净100P波兰灰色 | E8: HYCHIKA | F8: 138.54 | G8: =K8 | H8: =INDEX(#NULL!,MATCH(1,(#NULL!=A8)*(#NULL!=C8),0)) | I8: =H8=J8 | J8: 128.54 | K8: 168 | L8: =J8-Q8/T8-AE8-AB8-R8-AC8-AD8 | M8: =L8/J8 | N8: =K8/1.2 | O8: =(N8-J8)/N8 | P8: =K8/1.2-J8 | Q8: =AG8+AH8 | R8: =IFERROR(IF(A8="UK",8.95/S8,IF(A8="DE",11.43/S8,IF(A8="FR",15.27/S8,IF(A8="IT",16.34/S8,IF(A8="ES",20.62/S8,IF(A8="NL",12/S8,IF(A8="PL",15.06/S8,IF(A8="SE",18.5/S8,IF(A8="BE",15.27/S8))))))))),0) | S8: 4 | T8: 1.6 | U8: 0.1 | V8: =AB8/K8 | W8: 0.05 | X8: 0.01 | Y8: =Q8/(J8*T8) | Z8: =R8/J8 | AA8: 0.158 | AB8: =J8*U8 | AC8: =J8*W8 | AD8: =J8*X8 | AE8: =J8*AA8 | AF8: 138.5 | AG8: =AF8/1.13 | AH8: =49.7/7.4 | AI8: =AG8/(J8*T8) | AJ8: =AH8/T8/J8 | AK8: 54.2 | AL8: =(N8-J8+AE8-AC8)/N8 | AM8: COST就是PO不含税售价 外币 不含税价 | AN8: PL是15.80% | AY8: ☆ | AZ8: ☆ | BA8: ☆ | BB8: ☆ | BC8: ☆ | BD8: ☆ | BE8: ☆ | BF8: ☆ | BG8: ☆ | BH8: ☆ | BI8: ☆ | BJ8: ☆ | BK8: ☆ | BL8: ☆ | BM8: ☆ | BN8: ☆ | BO8: ☆ | BP8: ☆ | BQ8: ☆ | BR8: ☆ | BS8: ☆ | BT8: ☆ | BU8: ☆ | BV8: ☆ | BW8: =IF(H8<J8,1,0) | BX8: #VALUE!
A9: SE | B9: R0001EU | C9: B0F1F7J8V3 | D9: 空净100P瑞典灰色 | E9: HYCHIKA | F9: 389.61 | G9: =K9 | H9: =INDEX(#NULL!,MATCH(1,(#NULL!=A9)*(#NULL!=C9),0)) | I9: =H9=J9 | J9: 389.61 | K9: 538 | L9: =J9-Q9/T9-AE9-AB9-R9-AC9-AD9 | M9: =L9/J9 | N9: =K9/1.2 | O9: =(N9-J9)/N9 | P9: =K9/1.2-J9 | Q9: =AG9+AH9 | R9: =IFERROR(IF(A9="UK",8.95/S9,IF(A9="DE",11.43/S9,IF(A9="FR",15.27/S9,IF(A9="IT",16.34/S9,IF(A9="ES",20.62/S9,IF(A9="NL",12/S9,IF(A9="PL",15.06/S9,IF(A9="SE",18.5/S9,IF(A9="BE",15.27/S9))))))))),0) | S9: 4 | T9: 0.6 | U9: 0.1 | V9: =AB9/K9 | W9: 0.05 | X9: 0.01 | Y9: =Q9/(J9*T9) | Z9: =R9/J9 | AA9: 0.223 | AB9: =J9*U9 | AC9: =J9*W9 | AD9: =J9*X9 | AE9: =J9*AA9 | AF9: 138.5 | AG9: =AF9/1.13 | AH9: =49.7/7.4 | AI9: =AG9/(J9*T9) | AJ9: =AH9/T9/J9 | AK9: 54.2 | AL9: =(N9-J9+AE9-AC9)/N9 | AM9: COST就是PO不含税售价 外币 不含税价 | AN9: SE是22.30% | AY9: ☆ | AZ9: ☆ | BA9: ☆ | BB9: ☆ | BC9: ☆ | BD9: ☆ | BE9: ☆ | BF9: ☆ | BG9: ☆ | BH9: ☆ | BI9: ☆ | BJ9: ☆ | BK9: ☆ | BL9: ☆ | BM9: ☆ | BN9: ☆ | BO9: ☆ | BP9: ☆ | BQ9: ☆ | BR9: ☆ | BS9: ☆ | BT9: ☆ | BU9: ☆ | BV9: ☆ | BW9: =IF(H9<J9,1,0) | BX9: #VALUE!
A10: BE | B10: R0001EU | C10: B0F1F7J8V3 | D10: 空净100P比利时灰 | E10: HYCHIKA | F10: 87 | G10: =K10 | H10: =INDEX(#NULL!,MATCH(1,(#NULL!=A10)*(#NULL!=C10),0)) | I10: =H10=J10 | J10: 87 | K10: 119.99 | L10: =J10-Q10/T10-AE10-AB10-R10-AC10-AD10 | M10: =L10/J10 | N10: =K10/1.2 | O10: =(N10-J10)/N10 | P10: =K10/1.2-J10 | Q10: =AG10+AH10 | R10: =IFERROR(IF(A10="UK",8.95/S10,IF(A10="DE",11.43/S10,IF(A10="FR",15.27/S10,IF(A10="IT",16.34/S10,IF(A10="ES",20.62/S10,IF(A10="NL",12/S10,IF(A10="PL",15.06/S10,IF(A10="SE",18.5/S10,IF(A10="BE",15.27/S10))))))))),0) | S10: 4 | T10: 7.4 | U10: 0.1 | V10: =AB10/K10 | W10: 0.05 | X10: 0.01 | Y10: =Q10/(J10*T10) | Z10: =R10/J10 | AA10: 0.158 | AB10: =J10*U10 | AC10: =J10*W10 | AD10: =J10*X10 | AE10: =J10*AA10 | AF10: 138.5 | AG10: =AF10/1.13 | AH10: =49.7/7.4 | AI10: =AG10/(J10*T10) | AJ10: =AH10/T10/J10 | AK10: 54.2 | AL10: =(N10-J10+AE10-AC10)/N10 | AM10: COST就是PO不含税售价 外币 不含税价 | AN10: BE是15.80% | AY10: ☆ | AZ10: ☆ | BA10: ☆ | BB10: ☆ | BC10: ☆ | BD10: ☆ | BE10: ☆ | BF10: ☆ | BG10: ☆ | BH10: ☆ | BI10: ☆ | BJ10: ☆ | BK10: ☆ | BL10: ☆ | BM10: ☆ | BN10: ☆ | BO10: ☆ | BP10: ☆ | BQ10: ☆ | BR10: ☆ | BS10: ☆ | BT10: ☆ | BU10: ☆ | BV10: ☆ | BW10: =IF(H10<J10,1,0) | BX10: #VALUE!
A11: AE | B11: R0001EU | C11: B0F1F7J8V3 | D11: 空净100P AE时灰 | E11: HYCHIKA | F11: 87 | G11: =K11 | H11: =INDEX(#NULL!,MATCH(1,(#NULL!=A11)*(#NULL!=C11),0)) | I11: =H11=J11 | J11: 87 | K11: 119.99 | L11: =J11-Q11/T11-AE11-AB11-R11-AC11-AD11 | M11: =L11/J11 | N11: =K11/1.2 | O11: =(N11-J11)/N11 | P11: =K11/1.2-J11 | Q11: =AG11+AH11 | R11: =IFERROR(IF(A11="UK",8.95/S11,IF(A11="DE",11.43/S11,IF(A11="FR",15.27/S11,IF(A11="IT",16.34/S11,IF(A11="ES",20.62/S11,IF(A11="NL",12/S11,IF(A11="PL",15.06/S11,IF(A11="SE",18.5/S11,IF(A11="BE",15.27/S11))))))))),0) | S11: 4 | T11: 7.4 | U11: 0.1 | V11: =AB11/K11 | W11: 0.05 | X11: 0.01 | Y11: =Q11/(J11*T11) | Z11: =R11/J11 | AA11: 0.158 | AB11: =J11*U11 | AC11: =J11*W11 | AD11: =J11*X11 | AE11: =J11*AA11 | AF11: 138.5 | AG11: =AF11/1.13 | AH11: =49.7/7.4 | AI11: =AG11/(J11*T11) | AJ11: =AH11/T11/J11 | AK11: 54.2 | AL11: =(N11-J11+AE11-AC11)/N11 | AM11: COST就是PO不含税售价 外币 不含税价 | AN11: BE是15.80% | AY11: ☆ | AZ11: ☆ | BA11: ☆ | BB11: ☆ | BC11: ☆ | BD11: ☆ | BE11: ☆ | BF11: ☆ | BG11: ☆ | BH11: ☆ | BI11: ☆ | BJ11: ☆ | BK11: ☆ | BL11: ☆ | BM11: ☆ | BN11: ☆ | BO11: ☆ | BP11: ☆ | BQ11: ☆ | BR11: ☆ | BS11: ☆ | BT11: ☆ | BU11: ☆ | BV11: ☆ | BW11: =IF(H11<J11,1,0) | BX11: #VALUE!

Sheet 欧洲测评总表格
A1: 站点 | B1: 类别 | C1: 提交时间 | D1: 订单号 | E1: 订单价格 | F1: 返款比率 | G1: 佣金币种 | H1: 佣金价格 | I1: 备注 | J1: 下单日期 | K1: 回评时间 | L1: 星级 | M1: reveiw链接 | N1: 删评时间 | O1: ASIN | P1: 品名 | Q1: 订单编号 | R1: 订单日期 | S1: 店铺名称 | T1: 订单状态 | U1: 销售渠道 | V1: 国家 | W1: 单价 | X1: 订单金额 | Y1: 发货日期
A2: 德国 | B2: 直评 | C2: 45791 | D2: - | H2: 30 | I2: 2025年5月25日评价于德国 | J2: - | K2: 45802 | L2: 5星 | M2: https://www.amazon.de/-/en/gp/customer-reviews/R2TXX03FE6F4KN/ref=cm_cr_arp_d_rvw_ttl?ie=UTF8&ASIN=B0F1F7J8V3 | O2: B0F1F7J8V3 | P2: 德国除螨仪 | Q2: 407-7914060-9458750 | R2: 45817.7 | S2: XLN_EU_IT | T2: Pending | U2: Amazon.it | V2: 意大利 | W2: 97.99 | X2: 97.99 | Y2: 2025-6-10周二~2025-6-10周二
A3: 德国
A4: 德国
A5: 德国
A6: 德国
A7: 德国
A8: 德国
A9: 德国
A10: 德国
A11: 德国
A12: 德国
A13: 德国
A14: 德国
... A105: 德国

Sheet 目标&经营分析
A1: 里程碑（以欧元核算）KJ | C1: 第一阶段（SC推广为主‎） | G1: 第二阶段（ po在途，SC/VC过渡期 ‎） | K1: 第三阶段（ VC主推 BD活动 ‎） | O1: 第四阶段（ VC主推 BD活动 ‎ ‎） | S1: 第五阶段（ VC主推 BD活动 ‎ ‎） | W1: 第六阶段（ VC主推 BD活动 ‎ ‎）
A2: 8 | C2: 1. 此阶段为SC售卖，主要目的为完善listing基本面，同时刺激销量来PO单； 2. SC根据推广计划表备足1个月库存，同时VC根据预测销量8周备货量分批次发往海外仓； 3. SC根据以目标为主的运营端流程完善基本面，包括前期评论布局，关键词库建立，网红视频等； 4. 根据推广计划制定营销策略，以达到目标单量从而刺激VCPO来单； 5. 预估VC上架时间，提前至少23天提报BD，一次性把能报的都报上，后续可随时取消和调整； | G2: 1. 后台关注货件入海外仓时间，提前预约入库，提醒仓库人员上架； 2. 一旦入库上架成功，及时通知Spotter业务开启PO接单； 3. 每周一和每周四关注PO来单情况，确认可用库存，24h内完成接单； 4. 关注货件实际提货时间，及实际运输时长及到仓时间； 5. VCPO库存一旦入仓，就会抢走SC购物车，但此时前台处于预售阶段，会影响转化，SC可尝试适当降低价格抢回购物车，降级幅度不得低于VC活动价； 6. 若第一周未来PO单，可同步创建手动订单刺激来PO，注意手动订单上架77天内未卖完会有罚款； | K2: 1. 切换购物车到VC，重新在广告子账号开广告推广，由于广告权重清零，这期间广告效果波动较大，需要盯紧广告预算和转化，尽快调整到稳定的状态； 2. 现在BD时长为28天，中间间隔3天，然后又是28天BD，BD价格为报价的90%（大促及节假日折扣要求为85%）； 3. 根据销量预测，PO来单及现有库存情况及时补货； 4. SC库存保留半个月左右库存，在秒杀间隔期根据库存情况及时调整购物车，或及时从海外仓补货到FBA仓； 5. 关注库存转运及其他导致库存不可售等异常情况； | O2: 1. 持续关注海外仓，VC亚马逊仓，国内到海外仓在途，海外仓到VC亚马逊仓在途库存情况，及时补货保证能接PO单，随时准备发手动订单刺激和补货PO库存； 2. 持续调整广告效果，保证VC亚马逊销量预测持续走高，保证PO单持续不断； 3. 关注库存转运及其他导致库存不可售等异常情况； 4. 关注链接BD状态，变体合并情况导致链接异常； 5. 因为转VC后，售后问题由亚马逊官方负责，需要持续关注客诉问题和每月退货情况变化，防止链接被下架； | S2: 1. 持续关注海外仓，VC亚马逊仓，国内到海外仓在途，海外仓到VC亚马逊仓在途库存情况，及时补货保证能接PO单，随时准备发手动订单刺激和补货PO库存； 2. 持续调整广告效果，保证VC亚马逊销量预测持续走高，保证PO单持续不断； 3. 关注库存转运及其他导致库存不可售等异常情况； 4. 关注链接BD状态，变体合并情况导致链接异常； 5. 因为转VC后，售后问题由亚马逊官方负责，需要持续关注客诉问题和每月退货情况变化，防止链接被下架； | W2: 1. 持续关注海外仓，VC亚马逊仓，国内到海外仓在途，海外仓到VC亚马逊仓在途库存情况，及时补货保证能接PO单，随时准备发手动订单刺激和补货PO库存； 2. 持续调整广告效果，保证VC亚马逊销量预测持续走高，保证PO单持续不断； 3. 关注库存转运及其他导致库存不可售等异常情况； 4. 关注链接BD状态，变体合并情况导致链接异常； 5. 因为转VC后，售后问题由亚马逊官方负责，需要持续关注客诉问题和每月退货情况变化，防止链接被下架；
A3: 销售周期 | C3: 第一周 | D3: 第二周 | E3: 第三周 | F3: 第四周 | G3: 第一周 | H3: 第二周 | I3: 第三周 | J3: 第四周 | K3: 第一周 | L3: 第二周 | M3: 第三周 | N3: 第四周 | O3: 第一周 | P3: 第二周 | Q3: 第三周 | R3: 第四周 | S3: 第一周 | T3: 第二周 | U3: 第三周 | V3: 第四周 | W3: 第一周 | X3: 第二周 | Y3: 第三周 | Z3: 第四周
A4: 具体时间 | B4: 日期 | C4: 5.26-6.1 | D4: 6.2-6.8 | E4: 6.9-6.15 | F4: 6.16-6.22 | G4: 6.23-6.29 | H4: 6.30-7.6 | I4: 7.7-7.13 | J4: 7.14-7.20 | K4: 7.21-7.27 | L4: 7.28-8.3 | M4: 8.4-8.10 | N4: 8.11-8.17 | O4: 8.18-8.24 | P4: 8.25-8.31 | Q4: 9.1-9.7 | R4: 9.8-9.14 | S4: 9.15-9.21 | T4: 9.22-9.28 | U4: 9.29-10.5 | V4: 10.6-10.12 | W4: 10.13-10.19 | X4: 10.20-10.26 | Y4: 10.27-11.2 | Z4: 11.3-11.9
A5: 目标竞对 | B5: 竞对综合信息（附上链接） | C5: 1. 竞对第一个月销量: 165-229 2.竞对第一个月结束时排名:从376-到了24，目前稳定在前20-30 129.99减38% 折后价79.99 3.竞对第一个月是否有参加站外,站外效果有多少倍: 没有站外 0倍无站外 4.竞对是否有woot等活动资格，跑活动时销量提升多少倍: 无 5.竞对链接： https://www.amazon.de/dp/B0DKPGKSYS | G5: 1.竞对第一个月销量: 2.竞对第一个月结束时排名: 3.竞对第一个月是否有参加站外,站外效果有多少倍: 是否有BD 7DD秒杀 4.竞对是否有woot等活动资格，跑活动时销量提升多少倍: 5.竞对链接： https://www.amazon.de/dp/B0DL5J6MK4 | K5: 1.竞对第一个月销量: 2.竞对第一个月结束时排名: 3.竞对第一个月是否有参加站外,站外效果有多少倍: 是否有BD 7DD秒杀 4.竞对是否有woot等活动资格，跑活动时销量提升多少倍: 5.竞对链接： https://www.amazon.de/dp/B0DQT1MKZ3
A6: 售价 | B6: 销售定价（日常价） | C6: 139.99 | D6: 139.99 | E6: =139.99*0.7 | F6: =139.99*0.7 | G6: =139.99*0.7 | H6: =139.99*0.7 | I6: =139.99*0.7 | J6: =139.99*0.7 | K6: =139.99*0.7 | L6: =139.99*0.7 | ... Z6: =139.99*0.7
B7: 成交价 （活动价/促销价） | C7: =C6 | D7: =D6 | E7: =E6*1 | F7: =F6*0.9 | G7: =G6*0.9 | H7: =H6*0.9 | I7: =I6*0.9*0.8 | J7: =J6*0.9 | K7: =K6*0.9*0.8 | L7: =L6*0.9 | M7: =M6*0.9*0.8 | N7: =N6*0.9 | O7: =O6*0.9*0.8 | P7: =P6*0.9 | Q7: =Q6*0.9*0.8 | R7: =R6*0.9 | S7: =S6*0.9*0.8 | T7: =T6*0.9 | U7: =U6*0.9*0.8 | V7: =V6*0.9 | W7: =W6*0.9*0.8 | X7: =X6*0.9 | Y7: =Y6*0.9*0.8 | Z7: =Z6*0.9
A8: 产品排名 | B8: 目标排名 | C8: 162 | D8: 150 | E8: 140 | F8: 120
B9: 实际排名(取周均值) | C9: 225 | D9: 115
A10: 销量 | B10: 目标总销售额 | C10: 0 | D10: =(D12-32)*D7*$A$2 | E10: =E12*E7*$A$2 | F10: =F12*F7*$A$2 | G10: =G12*G7*$A$2 | H10: =H12*H7*$A$2 | I10: =I12*I7*$A$2 | J10: =J12*J7*$A$2 | K10: =K12*K7*$A$2 | L10: =L12*L7*$A$2 | ... Z10: =Z12*Z7*$A$2
B11: 实际总销售额 | C11: =(C13-26)*C7*$A$2 | D11: =(D13-5)*D7*$A$2 | E11: =(E13)*E7*$A$2 | F11: =(F13)*F7*$A$2 | G11: =(G13)*G7*$A$2 | H11: =(H13)*H7*$A$2 | I11: =(I13)*I7*$A$2 | J11: =(J13)*J7*$A$2 | K11: =(K13)*K7*$A$2 | L11: =(L13)*L7*$A$2 | ... Z11: =(Z13)*Z7*$A$2
B12: 目标总销量 | C12: 0 | D12: 38 | E12: =3+1+2 | F12: 29 | G12: 33 | H12: 40 | I12: 51 | J12: 54 | K12: 68 | L12: 70 | M12: 80 | N12: 90 | O12: 100 | P12: 110 | Q12: 120 | R12: 130 | S12: 140 | T12: 140 | U12: 150 | V12: 150 | W12: 160 | X12: 160 | Y12: 170 | Z12: 170
B13: 实际总销量 | C13: 28 | D13: 15 | E13: 8 | F13: 29
B14: 目标日均 | C14: =C12/7 | D14: =D12/7 | E14: =E12/7 | F14: =F12/7 | G14: =G12/7 | H14: =H12/7 | I14: =I12/7 | J14: =J12/7 | ... Z14: =Z12/7
B15: 实际日均 | C15: =C13/7 | D15: =D13/7 | E15: =E13/7 | F15: =F13/7 | G15: =G13/7 | H15: =H13/7 | I15: =I13/7 | J15: =J13/7 | ... Z15: =Z13/7
B16: 预计PO单量 | C16: - | D16: - | E16: - | F16: - | G16: - | H16: - | I16: - | J16: - | K16: - | L16: - | M16: - | N16: -
B17: 实际PO单量 | C17: - | D17: - | E17: - | F17: - | G17: - | H17: - | I17: - | J17: - | K17: - | L17: - | M17: - | N17: -
A18: 利润 | B18: 目标利润额 | C18: =C10-C28-C46 | D18: =D10-D28-D46 | E18: =E10-E28-E46 | F18: =F10-F28-F46 | G18: =G10-G28-G46 | H18: =H10-H28-H46 | I18: =I10-I28-I46 | J18: =J10-J28-J46 | ... Z18: =Z10-Z28-Z46
